Workbook

Sheet TABLEAU DE BORD
B2: TABLEAU DE BORD — SOUDAGE & CONTRÔLE QUALITÉ PIPELINE
B3: =PARAMÈTRES!$C$4&" • Affaire N° "&PARAMÈTRES!$C$5&" • Mis à jour le "&TEXT(TODAY(),"dd/mm/yyyy") -> Développement des champs gaziers TFT II — réseau de collecte TFT Sud (LIGNE-16) • Affaire N° 8546 • Mis à jour le 28/09/2026
B5: Ligne / Puits : | C5: TOUTES | E5: ◄ choisir une ligne pour filtrer tous les indicateurs | O5: =IF(C5="TOUTES","*",C5) -> *
B7: JOINTS SOUDÉS (JN + DJ) | D7: AVANCEMENT SOUDAGE (JN) | F7: JOINTS RADIOGRAPHIÉS | H7: JOINTS ACCEPTÉS | J7: EN ATTENTE RT | L7: TAUX DE RÉPARATION
B8: =COUNTIFS('CARNET DE SOUDURE'!$B$7:$B$3006,$O$5,'CARNET DE SOUDURE'!$U$7:$U$3006,"<>") -> 1313 | D8: =IFERROR(COUNTIFS('CARNET DE SOUDURE'!$B$7:$B$3006,$O$5,'CARNET DE SOUDURE'!$U$7:$U$3006,"<>",'CARNET DE SOUDURE'!$F$7:$F$3006,"JN")/IF($C$5="TOUTES",SUM(PARAMÈTRES!$E$12:$E$19),SUMIF(PARAMÈTRES!$B$12:$B$19,$C$5,PARAMÈTRES!$E$12:$E$19)),0) -> 0.49117647 | F8: =COUNTIFS('CARNET DE SOUDURE'!$B$7:$B$3006,$O$5,'CARNET DE SOUDURE'!$AA$7:$AA$3006,"<>") -> 1205 | H8: =COUNTIFS('CARNET DE SOUDURE'!$B$7:$B$3006,$O$5,'CARNET DE SOUDURE'!$AQ$7:$AQ$3006,"ACCEPTÉ") -> 1139 | J8: =COUNTIFS('CARNET DE SOUDURE'!$B$7:$B$3006,$O$5,'CARNET DE SOUDURE'!$AQ$7:$AQ$3006,"À RADIOGRAPHIER")+COUNTIFS('CARNET DE SOUDURE'!$B$7:$B$3006,$O$5,'CARNET DE SOUDURE'!$AQ$7:$AQ$3006,"RÉPARÉ – À RADIOGRAPHIER")+COUNTIFS('CARNET DE SOUDURE'!$B$7:$B$3006,$O$5,'CARNET DE SOUDURE'!$AQ$7:$AQ$3006,"NX – RT À REFAIRE") -> 119 | L8: =IFERROR((COUNTIFS('CARNET DE SOUDURE'!$B$7:$B$3006,$O$5,'CARNET DE SOUDURE'!$AA$7:$AA$3006,"R")+COUNTIFS('CARNET DE SOUDURE'!$B$7:$B$3006,$O$5,'CARNET DE SOUDURE'!$AA$7:$AA$3006,"NT")+COUNTIFS('CARNET DE SOUDURE'!$B$7:$B$3006,$O$5,'CARNET DE SOUDURE'!$AA$7:$AA$3006,"CO"))/(COUNTIFS('CARNET DE SOUDURE'!$B$7:$B$3006,$O$5,'CARNET DE SOUDURE'!$AA$7:$AA$3006,"A")+(COUNTIFS('CARNET DE SOUDURE'!$B$7:$B$3006,$O$5,'CARNET DE SOUDURE'!$AA$7:$AA$3006,"R")+COUNTIFS('CARNET DE SOUDURE'!$B$7:$B$3006,$O$5,'CARNET DE SOUDURE'!$AA$7:$AA$3006,"NT")+COUNTIFS('CARNET DE SOUDURE'!$B$7:$B$3006,$O$5,'CARNET DE SOUDURE'!$AA$7:$AA$3006,"CO"))),0) -> 0.046063652
B10: ="JN "&TEXT(COUNTIFS('CARNET DE SOUDURE'!$B$7:$B$3006,$O$5,'CARNET DE SOUDURE'!$U$7:$U$3006,"<>",'CARNET DE SOUDURE'!$F$7:$F$3006,"JN"),"#,##0")&" • DJ "&TEXT(COUNTIFS('CARNET DE SOUDURE'!$B$7:$B$3006,$O$5,'CARNET DE SOUDURE'!$U$7:$U$3006,"<>",'CARNET DE SOUDURE'!$F$7:$F$3006,"DJ"),"#,##0") -> JN 835 • DJ 478 | D10: ="JN : reste "&TEXT(MAX(0,IF($C$5="TOUTES",SUM(PARAMÈTRES!$E$12:$E$19),SUMIF(PARAMÈTRES!$B$12:$B$19,$C$5,PARAMÈTRES!$E$12:$E$19))-COUNTIFS('CARNET DE SOUDURE'!$B$7:$B$3006,$O$5,'CARNET DE SOUDURE'!$U$7:$U$3006,"<>",'CARNET DE SOUDURE'!$F$7:$F$3006,"JN")),"#,##0")&" sur "&TEXT(IF($C$5="TOUTES",SUM(PARAMÈTRES!$E$12:$E$19),SUMIF(PARAMÈTRES!$B$12:$B$19,$C$5,PARAMÈTRES!$E$12:$E$19)),"#,##0") -> JN : reste 865 sur 1,700 | F10: =TEXT(IFERROR(COUNTIFS('CARNET DE SOUDURE'!$B$7:$B$3006,$O$5,'CARNET DE SOUDURE'!$AA$7:$AA$3006,"<>")/COUNTIFS('CARNET DE SOUDURE'!$B$7:$B$3006,$O$5,'CARNET DE SOUDURE'!$U$7:$U$3006,"<>"),0),"0.0%")&" des joints soudés" -> 91.8% des joints soudés | H10: =TEXT(IFERROR(COUNTIFS('CARNET DE SOUDURE'!$B$7:$B$3006,$O$5,'CARNET DE SOUDURE'!$AQ$7:$AQ$3006,"ACCEPTÉ")/COUNTIFS('CARNET DE SOUDURE'!$B$7:$B$3006,$O$5,'CARNET DE SOUDURE'!$U$7:$U$3006,"<>"),0),"0.0%")&" des joints soudés" -> 86.7% des joints soudés | J10: ="voir PROGRAMME RT" -> voir PROGRAMME RT | L10: =TEXT((COUNTIFS('CARNET DE SOUDURE'!$B$7:$B$3006,$O$5,'CARNET DE SOUDURE'!$AA$7:$AA$3006,"R")+COUNTIFS('CARNET DE SOUDURE'!$B$7:$B$3006,$O$5,'CARNET DE SOUDURE'!$AA$7:$AA$3006,"NT")+COUNTIFS('CARNET DE SOUDURE'!$B$7:$B$3006,$O$5,'CARNET DE SOUDURE'!$AA$7:$AA$3006,"CO")),"0")&" rejet(s) au RT-01" -> 55 rejet(s) au RT-01
B12: À RÉPARER (R) | D12: COUPE (CO) | F12: NX – RT À REFAIRE | H12: RÉPARÉS → RT | J12: VT EN ATTENTE / REJETÉ | L12: À SOUDER (listés)
B13: =COUNTIFS('CARNET DE SOUDURE'!$B$7:$B$3006,$O$5,'CARNET DE SOUDURE'!$AQ$7:$AQ$3006,"À RÉPARER") -> 54 | D13: =COUNTIFS('CARNET DE SOUDURE'!$B$7:$B$3006,$O$5,'CARNET DE SOUDURE'!$AQ$7:$AQ$3006,"COUPE – À RESOUDER") -> 1 | F13: =COUNTIFS('CARNET DE SOUDURE'!$B$7:$B$3006,$O$5,'CARNET DE SOUDURE'!$AQ$7:$AQ$3006,"NX – RT À REFAIRE") -> 11 | H13: =COUNTIFS('CARNET DE SOUDURE'!$B$7:$B$3006,$O$5,'CARNET DE SOUDURE'!$AQ$7:$AQ$3006,"RÉPARÉ – À RADIOGRAPHIER") -> 0 | J13: =COUNTIFS('CARNET DE SOUDURE'!$B$7:$B$3006,$O$5,'CARNET DE SOUDURE'!$AQ$7:$AQ$3006,"VT EN ATTENTE")+COUNTIFS('CARNET DE SOUDURE'!$B$7:$B$3006,$O$5,'CARNET DE SOUDURE'!$AQ$7:$AQ$3006,"VT REJETÉ – À REPRENDRE") -> 0 | L13: =COUNTIFS('CARNET DE SOUDURE'!$B$7:$B$3006,$O$5,'CARNET DE SOUDURE'!$AQ$7:$AQ$3006,"À SOUDER") -> 1165
B16: SITUATION PAR LIGNE ET TYPE DE JOINT (JN / DJ)
B17: Ligne / type | C17: Joints estimés | D17: Joints soudés | E17: Reste à souder | F17: % Soudage | G17: Radiographiés | H17: % RT | I17: Acceptés | J17: % Accepté | K17: En réparation | L17: Taux de réparation | M17: En attente RT
B18: =$P18&" — JN — joints de ligne" -> MFD-ISW → MFD-CPF — JN — joints de ligne | C18: =N(PARAMÈTRES!$E$12) -> 1700 | D18: =COUNTIFS('CARNET DE SOUDURE'!$B$7:$B$3006,$P18,'CARNET DE SOUDURE'!$F$7:$F$3006,$Q18,'CARNET DE SOUDURE'!$U$7:$U$3006,"<>") -> 835 | E18: =MAX(0,C18-D18) -> 865 | F18: =IFERROR(D18/C18,0) -> 0.49117647 | G18: =COUNTIFS('CARNET DE SOUDURE'!$B$7:$B$3006,$P18,'CARNET DE SOUDURE'!$F$7:$F$3006,$Q18,'CARNET DE SOUDURE'!$AA$7:$AA$3006,"<>") -> 727 | H18: =IFERROR(G18/D18,0) -> 0.87065868 | I18: =COUNTIFS('CARNET DE SOUDURE'!$B$7:$B$3006,$P18,'CARNET DE SOUDURE'!$F$7:$F$3006,$Q18,'CARNET DE SOUDURE'!$AQ$7:$AQ$3006,"ACCEPTÉ") -> 664 | J18: =IFERROR(I18/D18,0) -> 0.79520958 | K18: =COUNTIFS('CARNET DE SOUDURE'!$B$7:$B$3006,$P18,'CARNET DE SOUDURE'!$F$7:$F$3006,$Q18,'CARNET DE SOUDURE'!$AQ$7:$AQ$3006,"À RÉPARER")+COUNTIFS('CARNET DE SOUDURE'!$B$7:$B$3006,$P18,'CARNET DE SOUDURE'!$F$7:$F$3006,$Q18,'CARNET DE SOUDURE'!$AQ$7:$AQ$3006,"COUPE – À RESOUDER")+COUNTIFS('CARNET DE SOUDURE'!$B$7:$B$3006,$P18,'CARNET DE SOUDURE'!$F$7:$F$3006,$Q18,'CARNET DE SOUDURE'!$AQ$7:$AQ$3006,"VT REJETÉ – À REPRENDRE") -> 52 | L18: =IFERROR((COUNTIFS('CARNET DE SOUDURE'!$B$7:$B$3006,$P18,'CARNET DE SOUDURE'!$F$7:$F$3006,$Q18,'CARNET DE SOUDURE'!$AA$7:$AA$3006,"R")+COUNTIFS('CARNET DE SOUDURE'!$B$7:$B$3006,$P18,'CARNET DE SOUDURE'!$F$7:$F$3006,$Q18,'CARNET DE SOUDURE'!$AA$7:$AA$3006,"NT")+COUNTIFS('CARNET DE SOUDURE'!$B$7:$B$3006,$P18,'CARNET DE SOUDURE'!$F$7:$F$3006,$Q18,'CARNET DE SOUDURE'!$AA$7:$AA$3006,"CO"))/(COUNTIFS('CARNET DE SOUDURE'!$B$7:$B$3006,$P18,'CARNET DE SOUDURE'!$F$7:$F$3006,$Q18,'CARNET DE SOUDURE'!$AA$7:$AA$3006,"A")+(COUNTIFS('CARNET DE SOUDURE'!$B$7:$B$3006,$P18,'CARNET DE SOUDURE'!$F$7:$F$3006,$Q18,'CARNET DE SOUDURE'!$AA$7:$AA$3006,"R")+COUNTIFS('CARNET DE SOUDURE'!$B$7:$B$3006,$P18,'CARNET DE SOUDURE'!$F$7:$F$3006,$Q18,'CARNET DE SOUDURE'!$AA$7:$AA$3006,"NT")+COUNTIFS('CARNET DE SOUDURE'!$B$7:$B$3006,$P18,'CARNET DE SOUDURE'!$F$7:$F$3006,$Q18,'CARNET DE SOUDURE'!$AA$7:$AA$3006,"CO"))),0) -> 0.072625698 | M18: =COUNTIFS('CARNET DE SOUDURE'!$B$7:$B$3006,$P18,'CARNET DE SOUDURE'!$F$7:$F$3006,$Q18,'CARNET DE SOUDURE'!$AQ$7:$AQ$3006,"À RADIOGRAPHIER")+COUNTIFS('CARNET DE SOUDURE'!$B$7:$B$3006,$P18,'CARNET DE SOUDURE'!$F$7:$F$3006,$Q18,'CARNET DE SOUDURE'!$AQ$7:$AQ$3006,"RÉPARÉ – À RADIOGRAPHIER")+COUNTIFS('CARNET DE SOUDURE'!$B$7:$B$3006,$P18,'CARNET DE SOUDURE'!$F$7:$F$3006,$Q18,'CARNET DE SOUDURE'!$AQ$7:$AQ$3006,"NX – RT À REFAIRE") -> 119 | P18: =PARAMÈTRES!$B$12 -> MFD-ISW → MFD-CPF | Q18: JN
B19: =$P19&" — DJ — doubles joints" -> MFD-ISW → MFD-CPF — DJ — doubles joints | C19: ="—" -> — | D19: =COUNTIFS('CARNET DE SOUDURE'!$B$7:$B$3006,$P19,'CARNET DE SOUDURE'!$F$7:$F$3006,$Q19,'CARNET DE SOUDURE'!$U$7:$U$3006,"<>") -> 478 | E19: ="—" -> — | F19: ="—" -> — | G19: =COUNTIFS('CARNET DE SOUDURE'!$B$7:$B$3006,$P19,'CARNET DE SOUDURE'!$F$7:$F$3006,$Q19,'CARNET DE SOUDURE'!$AA$7:$AA$3006,"<>") -> 478 | H19: =IFERROR(G19/D19,0) -> 1 | I19: =COUNTIFS('CARNET DE SOUDURE'!$B$7:$B$3006,$P19,'CARNET DE SOUDURE'!$F$7:$F$3006,$Q19,'CARNET DE SOUDURE'!$AQ$7:$AQ$3006,"ACCEPTÉ") -> 475 | J19: =IFERROR(I19/D19,0) -> 0.99372385 | K19: =COUNTIFS('CARNET DE SOUDURE'!$B$7:$B$3006,$P19,'CARNET DE SOUDURE'!$F$7:$F$3006,$Q19,'CARNET DE SOUDURE'!$AQ$7:$AQ$3006,"À RÉPARER")+COUNTIFS('CARNET DE SOUDURE'!$B$7:$B$3006,$P19,'CARNET DE SOUDURE'!$F$7:$F$3006,$Q19,'CARNET DE SOUDURE'!$AQ$7:$AQ$3006,"COUPE – À RESOUDER")+COUNTIFS('CARNET DE SOUDURE'!$B$7:$B$3006,$P19,'CARNET DE SOUDURE'!$F$7:$F$3006,$Q19,'CARNET DE SOUDURE'!$AQ$7:$AQ$3006,"VT REJETÉ – À REPRENDRE") -> 3 | L19: =IFERROR((COUNTIFS('CARNET DE SOUDURE'!$B$7:$B$3006,$P19,'CARNET DE SOUDURE'!$F$7:$F$3006,$Q19,'CARNET DE SOUDURE'!$AA$7:$AA$3006,"R")+COUNTIFS('CARNET DE SOUDURE'!$B$7:$B$3006,$P19,'CARNET DE SOUDURE'!$F$7:$F$3006,$Q19,'CARNET DE SOUDURE'!$AA$7:$AA$3006,"NT")+COUNTIFS('CARNET DE SOUDURE'!$B$7:$B$3006,$P19,'CARNET DE SOUDURE'!$F$7:$F$3006,$Q19,'CARNET DE SOUDURE'!$AA$7:$AA$3006,"CO"))/(COUNTIFS('CARNET DE SOUDURE'!$B$7:$B$3006,$P19,'CARNET DE SOUDURE'!$F$7:$F$3006,$Q19,'CARNET DE SOUDURE'!$AA$7:$AA$3006,"A")+(COUNTIFS('CARNET DE SOUDURE'!$B$7:$B$3006,$P19,'CARNET DE SOUDURE'!$F$7:$F$3006,$Q19,'CARNET DE SOUDURE'!$AA$7:$AA$3006,"R")+COUNTIFS('CARNET DE SOUDURE'!$B$7:$B$3006,$P19,'CARNET DE SOUDURE'!$F$7:$F$3006,$Q19,'CARNET DE SOUDURE'!$AA$7:$AA$3006,"NT")+COUNTIFS('CARNET DE SOUDURE'!$B$7:$B$3006,$P19,'CARNET DE SOUDURE'!$F$7:$F$3006,$Q19,'CARNET DE SOUDURE'!$AA$7:$AA$3006,"CO"))),0) -> 0.0062761506 | M19: =COUNTIFS('CARNET DE SOUDURE'!$B$7:$B$3006,$P19,'CARNET DE SOUDURE'!$F$7:$F$3006,$Q19,'CARNET DE SOUDURE'!$AQ$7:$AQ$3006,"À RADIOGRAPHIER")+COUNTIFS('CARNET DE SOUDURE'!$B$7:$B$3006,$P19,'CARNET DE SOUDURE'!$F$7:$F$3006,$Q19,'CARNET DE SOUDURE'!$AQ$7:$AQ$3006,"RÉPARÉ – À RADIOGRAPHIER")+COUNTIFS('CARNET DE SOUDURE'!$B$7:$B$3006,$P19,'CARNET DE SOUDURE'!$F$7:$F$3006,$Q19,'CARNET DE SOUDURE'!$AQ$7:$AQ$3006,"NX – RT À REFAIRE") -> 0 | P19: =PARAMÈTRES!$B$12 -> MFD-ISW → MFD-CPF | Q19: DJ
B20: TOTAL | C20: =SUM(C18:C19) -> 1700 | D20: =SUM(D18:D19) -> 1313 | E20: =SUM(E18:E19) -> 865 | F20: =IFERROR(SUMIF($Q$18:$Q$19,"JN",D18:D19)/C20,0) -> 0.49117647 | G20: =SUM(G18:G19) -> 1205 | H20: =IFERROR(G20/D20,0) -> 0.91774562 | I20: =SUM(I18:I19) -> 1139 | J20: =IFERROR(I20/D20,0) -> 0.86747906 | K20: =SUM(K18:K19) -> 55 | L20: =IFERROR((COUNTIF('CARNET DE SOUDURE'!$AA$7:$AA$3006,"R")+COUNTIF('CARNET DE SOUDURE'!$AA$7:$AA$3006,"NT")+COUNTIF('CARNET DE SOUDURE'!$AA$7:$AA$3006,"CO"))/(COUNTIF('CARNET DE SOUDURE'!$AA$7:$AA$3006,"A")+COUNTIF('CARNET DE SOUDURE'!$AA$7:$AA$3006,"R")+COUNTIF('CARNET DE SOUDURE'!$AA$7:$AA$3006,"NT")+COUNTIF('CARNET DE SOUDURE'!$AA$7:$AA$3006,"CO")),0) -> 0.046063652 | M20: =SUM(M18:M19) -> 119
J22: Statut | L22: Joints | M22: %
J23: ACCEPTÉ | L23: =COUNTIFS('CARNET DE SOUDURE'!$B$7:$B$3006,$O$5,'CARNET DE SOUDURE'!$AQ$7:$AQ$3006,"ACCEPTÉ") -> 1139 | M23: =IFERROR(L23/SUM($L$23:$L$31),0) -> 0.45964487
J24: À RADIOGRAPHIER | L24: =COUNTIFS('CARNET DE SOUDURE'!$B$7:$B$3006,$O$5,'CARNET DE SOUDURE'!$AQ$7:$AQ$3006,"À RADIOGRAPHIER") -> 108 | M24: =IFERROR(L24/SUM($L$23:$L$31),0) -> 0.043583535
J25: RÉPARÉ – À RADIOGRAPHIER | L25: =COUNTIFS('CARNET DE SOUDURE'!$B$7:$B$3006,$O$5,'CARNET DE SOUDURE'!$AQ$7:$AQ$3006,"RÉPARÉ – À RADIOGRAPHIER") -> 0 | M25: =IFERROR(L25/SUM($L$23:$L$31),0) -> 0
J26: NX – RT À REFAIRE | L26: =COUNTIFS('CARNET DE SOUDURE'!$B$7:$B$3006,$O$5,'CARNET DE SOUDURE'!$AQ$7:$AQ$3006,"NX – RT À REFAIRE") -> 11 | M26: =IFERROR(L26/SUM($L$23:$L$31),0) -> 0.0044390638
J27: À RÉPARER | L27: =COUNTIFS('CARNET DE SOUDURE'!$B$7:$B$3006,$O$5,'CARNET DE SOUDURE'!$AQ$7:$AQ$3006,"À RÉPARER") -> 54 | M27: =IFERROR(L27/SUM($L$23:$L$31),0) -> 0.021791768
J28: COUPE – À RESOUDER | L28: =COUNTIFS('CARNET DE SOUDURE'!$B$7:$B$3006,$O$5,'CARNET DE SOUDURE'!$AQ$7:$AQ$3006,"COUPE – À RESOUDER") -> 1 | M28: =IFERROR(L28/SUM($L$23:$L$31),0) -> 0.00040355125
J29: VT REJETÉ – À REPRENDRE | L29: =COUNTIFS('CARNET DE SOUDURE'!$B$7:$B$3006,$O$5,'CARNET DE SOUDURE'!$AQ$7:$AQ$3006,"VT REJETÉ – À REPRENDRE") -> 0 | M29: =IFERROR(L29/SUM($L$23:$L$31),0) -> 0
J30: VT EN ATTENTE | L30: =COUNTIFS('CARNET DE SOUDURE'!$B$7:$B$3006,$O$5,'CARNET DE SOUDURE'!$AQ$7:$AQ$3006,"VT EN ATTENTE") -> 0 | M30: =IFERROR(L30/SUM($L$23:$L$31),0) -> 0
J31: À SOUDER | L31: =COUNTIFS('CARNET DE SOUDURE'!$B$7:$B$3006,$O$5,'CARNET DE SOUDURE'!$AQ$7:$AQ$3006,"À SOUDER") -> 1165 | M31: =IFERROR(L31/SUM($L$23:$L$31),0) -> 0.47013721
B49: PERFORMANCE DES SOUDEURS (toutes lignes)
B50: WR / équipe | C50: Nom(s) | E50: Joints soudés | F50: Radiographiés | G50: Rejetés | H50: Taux de réparation | I50: Évaluation
B51: =IF(SOUDEURS!B6="","",SOUDEURS!B6) -> WR-039 | C51: =IF(SOUDEURS!C6="","",SOUDEURS!C6) | E51: =SOUDEURS!F6 -> 100 | F51: =SOUDEURS!G6 -> 100 | G51: =SOUDEURS!H6 -> 0 | H51: =SOUDEURS!I6 -> 0 | I51: =SOUDEURS!K6 -> Excellent
B52: =IF(SOUDEURS!B7="","",SOUDEURS!B7) -> WR-46-44/36-33/30-52/50-51/43-45 | C52: =IF(SOUDEURS!C7="","",SOUDEURS!C7) | E52: =SOUDEURS!F7 -> 99 | F52: =SOUDEURS!G7 -> 94 | G52: =SOUDEURS!H7 -> 16 | H52: =SOUDEURS!I7 -> 0.17021277 | I52: =SOUDEURS!K7 -> À surveiller
B53: =IF(SOUDEURS!B8="","",SOUDEURS!B8) -> WR-029 | C53: =IF(SOUDEURS!C8="","",SOUDEURS!C8) | E53: =SOUDEURS!F8 -> 87 | F53: =SOUDEURS!G8 -> 87 | G53: =SOUDEURS!H8 -> 0 | H53: =SOUDEURS!I8 -> 0 | I53: =SOUDEURS!K8 -> Excellent
B54: =IF(SOUDEURS!B9="","",SOUDEURS!B9) -> WR-037 | C54: =IF(SOUDEURS!C9="","",SOUDEURS!C9) | E54: =SOUDEURS!F9 -> 82 | F54: =SOUDEURS!G9 -> 82 | G54: =SOUDEURS!H9 -> 0 | H54: =SOUDEURS!I9 -> 0 | I54: =SOUDEURS!K9 -> Excellent
B55: =IF(SOUDEURS!B10="","",SOUDEURS!B10) -> WR-46-44/32-33/43-30/45-36 | C55: =IF(SOUDEURS!C10="","",SOUDEURS!C10) | E55: =SOUDEURS!F10 -> 72 | F55: =SOUDEURS!G10 -> 72 | G55: =SOUDEURS!H10 -> 0 | H55: =SOUDEURS!I10 -> 0 | I55: =SOUDEURS!K10 -> Excellent
B56: =IF(SOUDEURS!B11="","",SOUDEURS!B11) -> WR-040 | C56: =IF(SOUDEURS!C11="","",SOUDEURS!C11) | E56: =SOUDEURS!F11 -> 67 | F56: =SOUDEURS!G11 -> 67 | G56: =SOUDEURS!H11 -> 1 | H56: =SOUDEURS!I11 -> 0.014925373 | I56: =SOUDEURS!K11 -> Excellent
B57: =IF(SOUDEURS!B12="","",SOUDEURS!B12) -> WR-46-44/32-33/45-43 | C57: =IF(SOUDEURS!C12="","",SOUDEURS!C12) | E57: =SOUDEURS!F12 -> 61 | F57: =SOUDEURS!G12 -> 58 | G57: =SOUDEURS!H12 -> 5 | H57: =SOUDEURS!I12 -> 0.086206897 | I57: =SOUDEURS!K12 -> À surveiller
B58: =IF(SOUDEURS!B13="","",SOUDEURS!B13) -> WR-46-44/30-33/47-48/45-36 | C58: =IF(SOUDEURS!C13="","",SOUDEURS!C13) | E58: =SOUDEURS!F13 -> 61 | F58: =SOUDEURS!G13 -> 59 | G58: =SOUDEURS!H13 -> 0 | H58: =SOUDEURS!I13 -> 0 | I58: =SOUDEURS!K13 -> Excellent
B59: =IF(SOUDEURS!B14="","",SOUDEURS!B14) -> WR-038 | C59: =IF(SOUDEURS!C14="","",SOUDEURS!C14) | E59: =SOUDEURS!F14 -> 53 | F59: =SOUDEURS!G14 -> 53 | G59: =SOUDEURS!H14 -> 1 | H59: =SOUDEURS!I14 -> 0.018867925 | I59: =SOUDEURS!K14 -> Excellent
B60: =IF(SOUDEURS!B15="","",SOUDEURS!B15) -> WR-030-036/043-044 | C60: =IF(SOUDEURS!C15="","",SOUDEURS!C15) | E60: =SOUDEURS!F15 -> 49 | F60: =SOUDEURS!G15 -> 49 | G60: =SOUDEURS!H15 -> 0 | H60: =SOUDEURS!I15 -> 0 | I60: =SOUDEURS!K15 -> Excellent
B61: =IF(SOUDEURS!B16="","",SOUDEURS!B16) -> WR-041 | C61: =IF(SOUDEURS!C16="","",SOUDEURS!C16) | E61: =SOUDEURS!F16 -> 43 | F61: =SOUDEURS!G16 -> 43 | G61: =SOUDEURS!H16 -> 0 | H61: =SOUDEURS!I16 -> 0 | I61: =SOUDEURS!K16 -> Excellent
B62: =IF(SOUDEURS!B17="","",SOUDEURS!B17) -> WR-46-51/33-45 | C62: =IF(SOUDEURS!C17="","",SOUDEURS!C17) | E62: =SOUDEURS!F17 -> 41 | F62: =SOUDEURS!G17 -> 5 | G62: =SOUDEURS!H17 -> 0 | H62: =SOUDEURS!I17 -> 0 | I62: =SOUDEURS!K17 -> Excellent
... B107: =IF(SOUDEURS!B62="","",SOUDEURS!B62) | C107: =IF(SOUDEURS!C62="","",SOUDEURS!C62) | E107: =SOUDEURS!F62 | F107: =SOUDEURS!G62 | G107: =SOUDEURS!H62 | H107: =SOUDEURS!I62 | I107: =SOUDEURS!K62

Sheet CARNET DE SOUDURE
A1: CARNET DE SOUDURE — PIPELINE
A2: =PARAMÈTRES!$C$4&" • Affaire N° "&PARAMÈTRES!$C$5&" • Saisir uniquement les colonnes en bleu — les colonnes N°, Nb RT, Dernier RT, STATUT et Attente sont automatiques" -> Développement des champs gaziers TFT II — réseau de collecte TFT Sud (LIGNE-16) • Affaire N° 8546 • Saisir uniquement les colonnes en bleu — les colonnes N°, Nb RT, Dernier RT, STATUT et Attente sont automatiques
B3: Joints : | C3: =COUNTA(E7:E3006) -> 2478 | E3: Soudés : | F3: =COUNT(U7:U3006) -> 1313 | I3: Acceptés : | J3: =COUNTIF(AQ7:AQ3006,"ACCEPTÉ") -> 1139 | M3: À radiographier : | P3: =SUMPRODUCT((AQ7:AQ3006="À RADIOGRAPHIER")+(AQ7:AQ3006="RÉPARÉ – À RADIOGRAPHIER")+(AQ7:AQ3006="NX – RT À REFAIRE")) -> 119 | S3: À réparer : | V3: =SUMPRODUCT((AQ7:AQ3006="À RÉPARER")+(AQ7:AQ3006="COUPE – À RESOUDER")+(AQ7:AQ3006="VT REJETÉ – À REPRENDRE")) -> 55
A5: IDENTIFICATION DU JOINT | R5: SOUDAGE | V5: CONTRÔLE VISUEL (VT) | Y5: RADIOGRAPHIE RT-01 | AC5: RÉPARATION 1 → VT → RT | AH5: RÉPARATION 2 → VT → RT | AM5: PROGRAMME & SUIVI
A6: N° | B6: Ligne | C6: Tronçon | D6: PK | E6: N° Joint | F6: Type | G6: Zone | H6: Ø | I6: Ép. (mm) | J6: Nuance | K6: WPS | L6: Tube 1 | M6: Coulée 1 | N6: Long. 1 | O6: Tube 2 | P6: Coulée 2 | Q6: Long. 2 | R6: WR 1ère passe | S6: WR 2ème passe | T6: WR B+F | U6: Date soudage | V6: VT Date | W6: VT PV N° | X6: VT Rés. | Y6: RT1 Date | Z6: RT1 PV N° | AA6: RT1 Rés. | AB6: Défaut / paramètre rép. | AC6: R1 WR | AD6: R1 VT Rés. | AE6: R1 RT Date | AF6: R1 RT PV N° | AG6: R1 RT Rés. | AH6: R2 WR | AI6: R2 VT Rés. | AJ6: R2 RT Date | AK6: R2 RT PV N° | AL6: R2 RT Rés. | AM6: RT programmé le | AN6: Remarques | AO6: Nb RT | AP6: Dernier RT | AQ6: STATUT | AR6: Attente (j) | AS6: hRT | AT6: hRTn | AU6: hREP | AV6: hREPn | AW6: hKEY
A7: =IF(E7="","",ROW()-6) -> 1 | B7: MFD-ISW → MFD-CPF | E7: JN°001 | F7: =IF(E7="","",IF(LEFT(E7,2)="DJ","DJ","JN")) -> JN | AO7: =IF(E7="","",(AA7<>"")+(AG7<>"")+(AL7<>"")) -> 0 | AP7: =IF(AL7<>"",AL7,IF(AG7<>"",AG7,IF(AA7<>"",AA7,""))) | AQ7: =IF(E7="","",IF(U7="","À SOUDER",IF(X7="","VT EN ATTENTE",IF(X7="R","VT REJETÉ – À REPRENDRE",IF(AP7="","À RADIOGRAPHIER",IF(AP7="A","ACCEPTÉ",IF(AP7="NX","NX – RT À REFAIRE",IF(IF(AO7=1,AD7,IF(AO7=2,AI7,""))="A","RÉPARÉ – À RADIOGRAPHIER",IF(IF(AO7=1,AD7,IF(AO7=2,AI7,""))="R","VT REJETÉ – À REPRENDRE",IF(OR(AP7="CO",AP7="NT"),"COUPE – À RESOUDER","À RÉPARER")))))))))) -> À SOUDER | AR7: =IF(AND(ISNUMBER(U7),OR(AQ7="À RADIOGRAPHIER",AQ7="RÉPARÉ – À RADIOGRAPHIER",AQ7="NX – RT À REFAIRE",AQ7="À RÉPARER",AQ7="COUPE – À RESOUDER",AQ7="VT REJETÉ – À REPRENDRE")),MAX(0,'PROGRAMME RT'!$C$4-U7),"") | AS7: =IF(AND(OR(AQ7="À RADIOGRAPHIER",AQ7="RÉPARÉ – À RADIOGRAPHIER",AQ7="NX – RT À REFAIRE"),OR('PROGRAMME RT'!$D$5="TOUTES",B7='PROGRAMME RT'!$D$5)),1,0) -> 0 | AT7: =IF(AS7=1,SUM(AS$7:AS7),"") | AU7: =IF(AND(OR(AA7="R",AA7="NX",AA7="NT",AA7="CO"),OR('JOINTS DE RÉPARATION'!$D$5="TOUTES",B7='JOINTS DE RÉPARATION'!$D$5),OR('JOINTS DE RÉPARATION'!$L$4="TOUS",AQ7<>"ACCEPTÉ")),1,0) -> 0 | AV7: =IF(AU7=1,SUM(AU$7:AU7),"") | AW7: =IF(E7="","",B7&"|"&E7) -> MFD-ISW → MFD-CPF|JN°001
A8: =IF(E8="","",ROW()-6) -> 2 | B8: MFD-ISW → MFD-CPF | E8: JN°002 | F8: =IF(E8="","",IF(LEFT(E8,2)="DJ","DJ","JN")) -> JN | AO8: =IF(E8="","",(AA8<>"")+(AG8<>"")+(AL8<>"")) -> 0 | AP8: =IF(AL8<>"",AL8,IF(AG8<>"",AG8,IF(AA8<>"",AA8,""))) | AQ8: =IF(E8="","",IF(U8="","À SOUDER",IF(X8="","VT EN ATTENTE",IF(X8="R","VT REJETÉ – À REPRENDRE",IF(AP8="","À RADIOGRAPHIER",IF(AP8="A","ACCEPTÉ",IF(AP8="NX","NX – RT À REFAIRE",IF(IF(AO8=1,AD8,IF(AO8=2,AI8,""))="A","RÉPARÉ – À RADIOGRAPHIER",IF(IF(AO8=1,AD8,IF(AO8=2,AI8,""))="R","VT REJETÉ – À REPRENDRE",IF(OR(AP8="CO",AP8="NT"),"COUPE – À RESOUDER","À RÉPARER")))))))))) -> À SOUDER | AR8: =IF(AND(ISNUMBER(U8),OR(AQ8="À RADIOGRAPHIER",AQ8="RÉPARÉ – À RADIOGRAPHIER",AQ8="NX – RT À REFAIRE",AQ8="À RÉPARER",AQ8="COUPE – À RESOUDER",AQ8="VT REJETÉ – À REPRENDRE")),MAX(0,'PROGRAMME RT'!$C$4-U8),"") | AS8: =IF(AND(OR(AQ8="À RADIOGRAPHIER",AQ8="RÉPARÉ – À RADIOGRAPHIER",AQ8="NX – RT À REFAIRE"),OR('PROGRAMME RT'!$D$5="TOUTES",B8='PROGRAMME RT'!$D$5)),1,0) -> 0 | AT8: =IF(AS8=1,SUM(AS$7:AS8),"") | AU8: =IF(AND(OR(AA8="R",AA8="NX",AA8="NT",AA8="CO"),OR('JOINTS DE RÉPARATION'!$D$5="TOUTES",B8='JOINTS DE RÉPARATION'!$D$5),OR('JOINTS DE RÉPARATION'!$L$4="TOUS",AQ8<>"ACCEPTÉ")),1,0) -> 0 | AV8: =IF(AU8=1,SUM(AU$7:AU8),"") | AW8: =IF(E8="","",B8&"|"&E8) -> MFD-ISW → MFD-CPF|JN°002
A9: =IF(E9="","",ROW()-6) -> 3 | B9: MFD-ISW → MFD-CPF | E9: JN°003 | F9: =IF(E9="","",IF(LEFT(E9,2)="DJ","DJ","JN")) -> JN | AO9: =IF(E9="","",(AA9<>"")+(AG9<>"")+(AL9<>"")) -> 0 | AP9: =IF(AL9<>"",AL9,IF(AG9<>"",AG9,IF(AA9<>"",AA9,""))) | AQ9: =IF(E9="","",IF(U9="","À SOUDER",IF(X9="","VT EN ATTENTE",IF(X9="R","VT REJETÉ – À REPRENDRE",IF(AP9="","À RADIOGRAPHIER",IF(AP9="A","ACCEPTÉ",IF(AP9="NX","NX – RT À REFAIRE",IF(IF(AO9=1,AD9,IF(AO9=2,AI9,""))="A","RÉPARÉ – À RADIOGRAPHIER",IF(IF(AO9=1,AD9,IF(AO9=2,AI9,""))="R","VT REJETÉ – À REPRENDRE",IF(OR(AP9="CO",AP9="NT"),"COUPE – À RESOUDER","À RÉPARER")))))))))) -> À SOUDER | AR9: =IF(AND(ISNUMBER(U9),OR(AQ9="À RADIOGRAPHIER",AQ9="RÉPARÉ – À RADIOGRAPHIER",AQ9="NX – RT À REFAIRE",AQ9="À RÉPARER",AQ9="COUPE – À RESOUDER",AQ9="VT REJETÉ – À REPRENDRE")),MAX(0,'PROGRAMME RT'!$C$4-U9),"") | AS9: =IF(AND(OR(AQ9="À RADIOGRAPHIER",AQ9="RÉPARÉ – À RADIOGRAPHIER",AQ9="NX – RT À REFAIRE"),OR('PROGRAMME RT'!$D$5="TOUTES",B9='PROGRAMME RT'!$D$5)),1,0) -> 0 | AT9: =IF(AS9=1,SUM(AS$7:AS9),"") | AU9: =IF(AND(OR(AA9="R",AA9="NX",AA9="NT",AA9="CO"),OR('JOINTS DE RÉPARATION'!$D$5="TOUTES",B9='JOINTS DE RÉPARATION'!$D$5),OR('JOINTS DE RÉPARATION'!$L$4="TOUS",AQ9<>"ACCEPTÉ")),1,0) -> 0 | AV9: =IF(AU9=1,SUM(AU$7:AU9),"") | AW9: =IF(E9="","",B9&"|"&E9) -> MFD-ISW → MFD-CPF|JN°003
A10: =IF(E10="","",ROW()-6) -> 4 | B10: MFD-ISW → MFD-CPF | E10: JN°004 | F10: =IF(E10="","",IF(LEFT(E10,2)="DJ","DJ","JN")) -> JN | AO10: =IF(E10="","",(AA10<>"")+(AG10<>"")+(AL10<>"")) -> 0 | AP10: =IF(AL10<>"",AL10,IF(AG10<>"",AG10,IF(AA10<>"",AA10,""))) | AQ10: =IF(E10="","",IF(U10="","À SOUDER",IF(X10="","VT EN ATTENTE",IF(X10="R","VT REJETÉ – À REPRENDRE",IF(AP10="","À RADIOGRAPHIER",IF(AP10="A","ACCEPTÉ",IF(AP10="NX","NX – RT À REFAIRE",IF(IF(AO10=1,AD10,IF(AO10=2,AI10,""))="A","RÉPARÉ – À RADIOGRAPHIER",IF(IF(AO10=1,AD10,IF(AO10=2,AI10,""))="R","VT REJETÉ – À REPRENDRE",IF(OR(AP10="CO",AP10="NT"),"COUPE – À RESOUDER","À RÉPARER")))))))))) -> À SOUDER | AR10: =IF(AND(ISNUMBER(U10),OR(AQ10="À RADIOGRAPHIER",AQ10="RÉPARÉ – À RADIOGRAPHIER",AQ10="NX – RT À REFAIRE",AQ10="À RÉPARER",AQ10="COUPE – À RESOUDER",AQ10="VT REJETÉ – À REPRENDRE")),MAX(0,'PROGRAMME RT'!$C$4-U10),"") | AS10: =IF(AND(OR(AQ10="À RADIOGRAPHIER",AQ10="RÉPARÉ – À RADIOGRAPHIER",AQ10="NX – RT À REFAIRE"),OR('PROGRAMME RT'!$D$5="TOUTES",B10='PROGRAMME RT'!$D$5)),1,0) -> 0 | AT10: =IF(AS10=1,SUM(AS$7:AS10),"") | AU10: =IF(AND(OR(AA10="R",AA10="NX",AA10="NT",AA10="CO"),OR('JOINTS DE RÉPARATION'!$D$5="TOUTES",B10='JOINTS DE RÉPARATION'!$D$5),OR('JOINTS DE RÉPARATION'!$L$4="TOUS",AQ10<>"ACCEPTÉ")),1,0) -> 0 | AV10: =IF(AU10=1,SUM(AU$7:AU10),"") | AW10: =IF(E10="","",B10&"|"&E10) -> MFD-ISW → MFD-CPF|JN°004
A11: =IF(E11="","",ROW()-6) -> 5 | B11: MFD-ISW → MFD-CPF | E11: JN°005 | F11: =IF(E11="","",IF(LEFT(E11,2)="DJ","DJ","JN")) -> JN | AO11: =IF(E11="","",(AA11<>"")+(AG11<>"")+(AL11<>"")) -> 0 | AP11: =IF(AL11<>"",AL11,IF(AG11<>"",AG11,IF(AA11<>"",AA11,""))) | AQ11: =IF(E11="","",IF(U11="","À SOUDER",IF(X11="","VT EN ATTENTE",IF(X11="R","VT REJETÉ – À REPRENDRE",IF(AP11="","À RADIOGRAPHIER",IF(AP11="A","ACCEPTÉ",IF(AP11="NX","NX – RT À REFAIRE",IF(IF(AO11=1,AD11,IF(AO11=2,AI11,""))="A","RÉPARÉ – À RADIOGRAPHIER",IF(IF(AO11=1,AD11,IF(AO11=2,AI11,""))="R","VT REJETÉ – À REPRENDRE",IF(OR(AP11="CO",AP11="NT"),"COUPE – À RESOUDER","À RÉPARER")))))))))) -> À SOUDER | AR11: =IF(AND(ISNUMBER(U11),OR(AQ11="À RADIOGRAPHIER",AQ11="RÉPARÉ – À RADIOGRAPHIER",AQ11="NX – RT À REFAIRE",AQ11="À RÉPARER",AQ11="COUPE – À RESOUDER",AQ11="VT REJETÉ – À REPRENDRE")),MAX(0,'PROGRAMME RT'!$C$4-U11),"") | AS11: =IF(AND(OR(AQ11="À RADIOGRAPHIER",AQ11="RÉPARÉ – À RADIOGRAPHIER",AQ11="NX – RT À REFAIRE"),OR('PROGRAMME RT'!$D$5="TOUTES",B11='PROGRAMME RT'!$D$5)),1,0) -> 0 | AT11: =IF(AS11=1,SUM(AS$7:AS11),"") | AU11: =IF(AND(OR(AA11="R",AA11="NX",AA11="NT",AA11="CO"),OR('JOINTS DE RÉPARATION'!$D$5="TOUTES",B11='JOINTS DE RÉPARATION'!$D$5),OR('JOINTS DE RÉPARATION'!$L$4="TOUS",AQ11<>"ACCEPTÉ")),1,0) -> 0 | AV11: =IF(AU11=1,SUM(AU$7:AU11),"") | AW11: =IF(E11="","",B11&"|"&E11) -> MFD-ISW → MFD-CPF|JN°005
A12: =IF(E12="","",ROW()-6) -> 6 | B12: MFD-ISW → MFD-CPF | E12: JN°006 | F12: =IF(E12="","",IF(LEFT(E12,2)="DJ","DJ","JN")) -> JN | AO12: =IF(E12="","",(AA12<>"")+(AG12<>"")+(AL12<>"")) -> 0 | AP12: =IF(AL12<>"",AL12,IF(AG12<>"",AG12,IF(AA12<>"",AA12,""))) | AQ12: =IF(E12="","",IF(U12="","À SOUDER",IF(X12="","VT EN ATTENTE",IF(X12="R","VT REJETÉ – À REPRENDRE",IF(AP12="","À RADIOGRAPHIER",IF(AP12="A","ACCEPTÉ",IF(AP12="NX","NX – RT À REFAIRE",IF(IF(AO12=1,AD12,IF(AO12=2,AI12,""))="A","RÉPARÉ – À RADIOGRAPHIER",IF(IF(AO12=1,AD12,IF(AO12=2,AI12,""))="R","VT REJETÉ – À REPRENDRE",IF(OR(AP12="CO",AP12="NT"),"COUPE – À RESOUDER","À RÉPARER")))))))))) -> À SOUDER | AR12: =IF(AND(ISNUMBER(U12),OR(AQ12="À RADIOGRAPHIER",AQ12="RÉPARÉ – À RADIOGRAPHIER",AQ12="NX – RT À REFAIRE",AQ12="À RÉPARER",AQ12="COUPE – À RESOUDER",AQ12="VT REJETÉ – À REPRENDRE")),MAX(0,'PROGRAMME RT'!$C$4-U12),"") | AS12: =IF(AND(OR(AQ12="À RADIOGRAPHIER",AQ12="RÉPARÉ – À RADIOGRAPHIER",AQ12="NX – RT À REFAIRE"),OR('PROGRAMME RT'!$D$5="TOUTES",B12='PROGRAMME RT'!$D$5)),1,0) -> 0 | AT12: =IF(AS12=1,SUM(AS$7:AS12),"") | AU12: =IF(AND(OR(AA12="R",AA12="NX",AA12="NT",AA12="CO"),OR('JOINTS DE RÉPARATION'!$D$5="TOUTES",B12='JOINTS DE RÉPARATION'!$D$5),OR('JOINTS DE RÉPARATION'!$L$4="TOUS",AQ12<>"ACCEPTÉ")),1,0) -> 0 | AV12: =IF(AU12=1,SUM(AU$7:AU12),"") | AW12: =IF(E12="","",B12&"|"&E12) -> MFD-ISW → MFD-CPF|JN°006
A13: =IF(E13="","",ROW()-6) -> 7 | B13: MFD-ISW → MFD-CPF | E13: JN°007 | F13: =IF(E13="","",IF(LEFT(E13,2)="DJ","DJ","JN")) -> JN | AO13: =IF(E13="","",(AA13<>"")+(AG13<>"")+(AL13<>"")) -> 0 | AP13: =IF(AL13<>"",AL13,IF(AG13<>"",AG13,IF(AA13<>"",AA13,""))) | AQ13: =IF(E13="","",IF(U13="","À SOUDER",IF(X13="","VT EN ATTENTE",IF(X13="R","VT REJETÉ – À REPRENDRE",IF(AP13="","À RADIOGRAPHIER",IF(AP13="A","ACCEPTÉ",IF(AP13="NX","NX – RT À REFAIRE",IF(IF(AO13=1,AD13,IF(AO13=2,AI13,""))="A","RÉPARÉ – À RADIOGRAPHIER",IF(IF(AO13=1,AD13,IF(AO13=2,AI13,""))="R","VT REJETÉ – À REPRENDRE",IF(OR(AP13="CO",AP13="NT"),"COUPE – À RESOUDER","À RÉPARER")))))))))) -> À SOUDER | AR13: =IF(AND(ISNUMBER(U13),OR(AQ13="À RADIOGRAPHIER",AQ13="RÉPARÉ – À RADIOGRAPHIER",AQ13="NX – RT À REFAIRE",AQ13="À RÉPARER",AQ13="COUPE – À RESOUDER",AQ13="VT REJETÉ – À REPRENDRE")),MAX(0,'PROGRAMME RT'!$C$4-U13),"") | AS13: =IF(AND(OR(AQ13="À RADIOGRAPHIER",AQ13="RÉPARÉ – À RADIOGRAPHIER",AQ13="NX – RT À REFAIRE"),OR('PROGRAMME RT'!$D$5="TOUTES",B13='PROGRAMME RT'!$D$5)),1,0) -> 0 | AT13: =IF(AS13=1,SUM(AS$7:AS13),"") | AU13: =IF(AND(OR(AA13="R",AA13="NX",AA13="NT",AA13="CO"),OR('JOINTS DE RÉPARATION'!$D$5="TOUTES",B13='JOINTS DE RÉPARATION'!$D$5),OR('JOINTS DE RÉPARATION'!$L$4="TOUS",AQ13<>"ACCEPTÉ")),1,0) -> 0 | AV13: =IF(AU13=1,SUM(AU$7:AU13),"") | AW13: =IF(E13="","",B13&"|"&E13) -> MFD-ISW → MFD-CPF|JN°007
A14: =IF(E14="","",ROW()-6) -> 8 | B14: MFD-ISW → MFD-CPF | E14: JN°008 | F14: =IF(E14="","",IF(LEFT(E14,2)="DJ","DJ","JN")) -> JN | AO14: =IF(E14="","",(AA14<>"")+(AG14<>"")+(AL14<>"")) -> 0 | AP14: =IF(AL14<>"",AL14,IF(AG14<>"",AG14,IF(AA14<>"",AA14,""))) | AQ14: =IF(E14="","",IF(U14="","À SOUDER",IF(X14="","VT EN ATTENTE",IF(X14="R","VT REJETÉ – À REPRENDRE",IF(AP14="","À RADIOGRAPHIER",IF(AP14="A","ACCEPTÉ",IF(AP14="NX","NX – RT À REFAIRE",IF(IF(AO14=1,AD14,IF(AO14=2,AI14,""))="A","RÉPARÉ – À RADIOGRAPHIER",IF(IF(AO14=1,AD14,IF(AO14=2,AI14,""))="R","VT REJETÉ – À REPRENDRE",IF(OR(AP14="CO",AP14="NT"),"COUPE – À RESOUDER","À RÉPARER")))))))))) -> À SOUDER | AR14: =IF(AND(ISNUMBER(U14),OR(AQ14="À RADIOGRAPHIER",AQ14="RÉPARÉ – À RADIOGRAPHIER",AQ14="NX – RT À REFAIRE",AQ14="À RÉPARER",AQ14="COUPE – À RESOUDER",AQ14="VT REJETÉ – À REPRENDRE")),MAX(0,'PROGRAMME RT'!$C$4-U14),"") | AS14: =IF(AND(OR(AQ14="À RADIOGRAPHIER",AQ14="RÉPARÉ – À RADIOGRAPHIER",AQ14="NX – RT À REFAIRE"),OR('PROGRAMME RT'!$D$5="TOUTES",B14='PROGRAMME RT'!$D$5)),1,0) -> 0 | AT14: =IF(AS14=1,SUM(AS$7:AS14),"") | AU14: =IF(AND(OR(AA14="R",AA14="NX",AA14="NT",AA14="CO"),OR('JOINTS DE RÉPARATION'!$D$5="TOUTES",B14='JOINTS DE RÉPARATION'!$D$5),OR('JOINTS DE RÉPARATION'!$L$4="TOUS",AQ14<>"ACCEPTÉ")),1,0) -> 0 | AV14: =IF(AU14=1,SUM(AU$7:AU14),"") | AW14: =IF(E14="","",B14&"|"&E14) -> MFD-ISW → MFD-CPF|JN°008
A15: =IF(E15="","",ROW()-6) -> 9 | B15: MFD-ISW → MFD-CPF | E15: JN°009 | F15: =IF(E15="","",IF(LEFT(E15,2)="DJ","DJ","JN")) -> JN | AO15: =IF(E15="","",(AA15<>"")+(AG15<>"")+(AL15<>"")) -> 0 | AP15: =IF(AL15<>"",AL15,IF(AG15<>"",AG15,IF(AA15<>"",AA15,""))) | AQ15: =IF(E15="","",IF(U15="","À SOUDER",IF(X15="","VT EN ATTENTE",IF(X15="R","VT REJETÉ – À REPRENDRE",IF(AP15="","À RADIOGRAPHIER",IF(AP15="A","ACCEPTÉ",IF(AP15="NX","NX – RT À REFAIRE",IF(IF(AO15=1,AD15,IF(AO15=2,AI15,""))="A","RÉPARÉ – À RADIOGRAPHIER",IF(IF(AO15=1,AD15,IF(AO15=2,AI15,""))="R","VT REJETÉ – À REPRENDRE",IF(OR(AP15="CO",AP15="NT"),"COUPE – À RESOUDER","À RÉPARER")))))))))) -> À SOUDER | AR15: =IF(AND(ISNUMBER(U15),OR(AQ15="À RADIOGRAPHIER",AQ15="RÉPARÉ – À RADIOGRAPHIER",AQ15="NX – RT À REFAIRE",AQ15="À RÉPARER",AQ15="COUPE – À RESOUDER",AQ15="VT REJETÉ – À REPRENDRE")),MAX(0,'PROGRAMME RT'!$C$4-U15),"") | AS15: =IF(AND(OR(AQ15="À RADIOGRAPHIER",AQ15="RÉPARÉ – À RADIOGRAPHIER",AQ15="NX – RT À REFAIRE"),OR('PROGRAMME RT'!$D$5="TOUTES",B15='PROGRAMME RT'!$D$5)),1,0) -> 0 | AT15: =IF(AS15=1,SUM(AS$7:AS15),"") | AU15: =IF(AND(OR(AA15="R",AA15="NX",AA15="NT",AA15="CO"),OR('JOINTS DE RÉPARATION'!$D$5="TOUTES",B15='JOINTS DE RÉPARATION'!$D$5),OR('JOINTS DE RÉPARATION'!$L$4="TOUS",AQ15<>"ACCEPTÉ")),1,0) -> 0 | AV15: =IF(AU15=1,SUM(AU$7:AU15),"") | AW15: =IF(E15="","",B15&"|"&E15) -> MFD-ISW → MFD-CPF|JN°009
A16: =IF(E16="","",ROW()-6) -> 10 | B16: MFD-ISW → MFD-CPF | E16: JN°010 | F16: =IF(E16="","",IF(LEFT(E16,2)="DJ","DJ","JN")) -> JN | AO16: =IF(E16="","",(AA16<>"")+(AG16<>"")+(AL16<>"")) -> 0 | AP16: =IF(AL16<>"",AL16,IF(AG16<>"",AG16,IF(AA16<>"",AA16,""))) | AQ16: =IF(E16="","",IF(U16="","À SOUDER",IF(X16="","VT EN ATTENTE",IF(X16="R","VT REJETÉ – À REPRENDRE",IF(AP16="","À RADIOGRAPHIER",IF(AP16="A","ACCEPTÉ",IF(AP16="NX","NX – RT À REFAIRE",IF(IF(AO16=1,AD16,IF(AO16=2,AI16,""))="A","RÉPARÉ – À RADIOGRAPHIER",IF(IF(AO16=1,AD16,IF(AO16=2,AI16,""))="R","VT REJETÉ – À REPRENDRE",IF(OR(AP16="CO",AP16="NT"),"COUPE – À RESOUDER","À RÉPARER")))))))))) -> À SOUDER | AR16: =IF(AND(ISNUMBER(U16),OR(AQ16="À RADIOGRAPHIER",AQ16="RÉPARÉ – À RADIOGRAPHIER",AQ16="NX – RT À REFAIRE",AQ16="À RÉPARER",AQ16="COUPE – À RESOUDER",AQ16="VT REJETÉ – À REPRENDRE")),MAX(0,'PROGRAMME RT'!$C$4-U16),"") | AS16: =IF(AND(OR(AQ16="À RADIOGRAPHIER",AQ16="RÉPARÉ – À RADIOGRAPHIER",AQ16="NX – RT À REFAIRE"),OR('PROGRAMME RT'!$D$5="TOUTES",B16='PROGRAMME RT'!$D$5)),1,0) -> 0 | AT16: =IF(AS16=1,SUM(AS$7:AS16),"") | AU16: =IF(AND(OR(AA16="R",AA16="NX",AA16="NT",AA16="CO"),OR('JOINTS DE RÉPARATION'!$D$5="TOUTES",B16='JOINTS DE RÉPARATION'!$D$5),OR('JOINTS DE RÉPARATION'!$L$4="TOUS",AQ16<>"ACCEPTÉ")),1,0) -> 0 | AV16: =IF(AU16=1,SUM(AU$7:AU16),"") | AW16: =IF(E16="","",B16&"|"&E16) -> MFD-ISW → MFD-CPF|JN°010
A17: =IF(E17="","",ROW()-6) -> 11 | B17: MFD-ISW → MFD-CPF | E17: JN°011 | F17: =IF(E17="","",IF(LEFT(E17,2)="DJ","DJ","JN")) -> JN | AO17: =IF(E17="","",(AA17<>"")+(AG17<>"")+(AL17<>"")) -> 0 | AP17: =IF(AL17<>"",AL17,IF(AG17<>"",AG17,IF(AA17<>"",AA17,""))) | AQ17: =IF(E17="","",IF(U17="","À SOUDER",IF(X17="","VT EN ATTENTE",IF(X17="R","VT REJETÉ – À REPRENDRE",IF(AP17="","À RADIOGRAPHIER",IF(AP17="A","ACCEPTÉ",IF(AP17="NX","NX – RT À REFAIRE",IF(IF(AO17=1,AD17,IF(AO17=2,AI17,""))="A","RÉPARÉ – À RADIOGRAPHIER",IF(IF(AO17=1,AD17,IF(AO17=2,AI17,""))="R","VT REJETÉ – À REPRENDRE",IF(OR(AP17="CO",AP17="NT"),"COUPE – À RESOUDER","À RÉPARER")))))))))) -> À SOUDER | AR17: =IF(AND(ISNUMBER(U17),OR(AQ17="À RADIOGRAPHIER",AQ17="RÉPARÉ – À RADIOGRAPHIER",AQ17="NX – RT À REFAIRE",AQ17="À RÉPARER",AQ17="COUPE – À RESOUDER",AQ17="VT REJETÉ – À REPRENDRE")),MAX(0,'PROGRAMME RT'!$C$4-U17),"") | AS17: =IF(AND(OR(AQ17="À RADIOGRAPHIER",AQ17="RÉPARÉ – À RADIOGRAPHIER",AQ17="NX – RT À REFAIRE"),OR('PROGRAMME RT'!$D$5="TOUTES",B17='PROGRAMME RT'!$D$5)),1,0) -> 0 | AT17: =IF(AS17=1,SUM(AS$7:AS17),"") | AU17: =IF(AND(OR(AA17="R",AA17="NX",AA17="NT",AA17="CO"),OR('JOINTS DE RÉPARATION'!$D$5="TOUTES",B17='JOINTS DE RÉPARATION'!$D$5),OR('JOINTS DE RÉPARATION'!$L$4="TOUS",AQ17<>"ACCEPTÉ")),1,0) -> 0 | AV17: =IF(AU17=1,SUM(AU$7:AU17),"") | AW17: =IF(E17="","",B17&"|"&E17) -> MFD-ISW → MFD-CPF|JN°011
A18: =IF(E18="","",ROW()-6) -> 12 | B18: MFD-ISW → MFD-CPF | E18: JN°012 | F18: =IF(E18="","",IF(LEFT(E18,2)="DJ","DJ","JN")) -> JN | AO18: =IF(E18="","",(AA18<>"")+(AG18<>"")+(AL18<>"")) -> 0 | AP18: =IF(AL18<>"",AL18,IF(AG18<>"",AG18,IF(AA18<>"",AA18,""))) | AQ18: =IF(E18="","",IF(U18="","À SOUDER",IF(X18="","VT EN ATTENTE",IF(X18="R","VT REJETÉ – À REPRENDRE",IF(AP18="","À RADIOGRAPHIER",IF(AP18="A","ACCEPTÉ",IF(AP18="NX","NX – RT À REFAIRE",IF(IF(AO18=1,AD18,IF(AO18=2,AI18,""))="A","RÉPARÉ – À RADIOGRAPHIER",IF(IF(AO18=1,AD18,IF(AO18=2,AI18,""))="R","VT REJETÉ – À REPRENDRE",IF(OR(AP18="CO",AP18="NT"),"COUPE – À RESOUDER","À RÉPARER")))))))))) -> À SOUDER | AR18: =IF(AND(ISNUMBER(U18),OR(AQ18="À RADIOGRAPHIER",AQ18="RÉPARÉ – À RADIOGRAPHIER",AQ18="NX – RT À REFAIRE",AQ18="À RÉPARER",AQ18="COUPE – À RESOUDER",AQ18="VT REJETÉ – À REPRENDRE")),MAX(0,'PROGRAMME RT'!$C$4-U18),"") | AS18: =IF(AND(OR(AQ18="À RADIOGRAPHIER",AQ18="RÉPARÉ – À RADIOGRAPHIER",AQ18="NX – RT À REFAIRE"),OR('PROGRAMME RT'!$D$5="TOUTES",B18='PROGRAMME RT'!$D$5)),1,0) -> 0 | AT18: =IF(AS18=1,SUM(AS$7:AS18),"") | AU18: =IF(AND(OR(AA18="R",AA18="NX",AA18="NT",AA18="CO"),OR('JOINTS DE RÉPARATION'!$D$5="TOUTES",B18='JOINTS DE RÉPARATION'!$D$5),OR('JOINTS DE RÉPARATION'!$L$4="TOUS",AQ18<>"ACCEPTÉ")),1,0) -> 0 | AV18: =IF(AU18=1,SUM(AU$7:AU18),"") | AW18: =IF(E18="","",B18&"|"&E18) -> MFD-ISW → MFD-CPF|JN°012
... A763: =IF(E763="","",ROW()-6) -> 757 | B763: MFD-ISW → MFD-CPF | E763: JN°757 | F763: =IF(E763="","",IF(LEFT(E763,2)="DJ","DJ","JN")) -> JN | AO763: =IF(E763="","",(AA763<>"")+(AG763<>"")+(AL763<>"")) -> 0 | AP763: =IF(AL763<>"",AL763,IF(AG763<>"",AG763,IF(AA763<>"",AA763,""))) | AQ763: =IF(E763="","",IF(U763="","À SOUDER",IF(X763="","VT EN ATTENTE",IF(X763="R","VT REJETÉ – À REPRENDRE",IF(AP763="","À RADIOGRAPHIER",IF(AP763="A","ACCEPTÉ",IF(AP763="NX","NX – RT À REFAIRE",IF(IF(AO763=1,AD763,IF(AO763=2,AI763,""))="A","RÉPARÉ – À RADIOGRAPHIER",IF(IF(AO763=1,AD763,IF(AO763=2,AI763,""))="R","VT REJETÉ – À REPRENDRE",IF(OR(AP763="CO",AP763="NT"),"COUPE – À RESOUDER","À RÉPARER")))))))))) -> À SOUDER | AR763: =IF(AND(ISNUMBER(U763),OR(AQ763="À RADIOGRAPHIER",AQ763="RÉPARÉ – À RADIOGRAPHIER",AQ763="NX – RT À REFAIRE",AQ763="À RÉPARER",AQ763="COUPE – À RESOUDER",AQ763="VT REJETÉ – À REPRENDRE")),MAX(0,'PROGRAMME RT'!$C$4-U763),"") | AS763: =IF(AND(OR(AQ763="À RADIOGRAPHIER",AQ763="RÉPARÉ – À RADIOGRAPHIER",AQ763="NX – RT À REFAIRE"),OR('PROGRAMME RT'!$D$5="TOUTES",B763='PROGRAMME RT'!$D$5)),1,0) -> 0 | AT763: =IF(AS763=1,SUM(AS$7:AS763),"") | AU763: =IF(AND(OR(AA763="R",AA763="NX",AA763="NT",AA763="CO"),OR('JOINTS DE RÉPARATION'!$D$5="TOUTES",B763='JOINTS DE RÉPARATION'!$D$5),OR('JOINTS DE RÉPARATION'!$L$4="TOUS",AQ763<>"ACCEPTÉ")),1,0) -> 0 | AV763: =IF(AU763=1,SUM(AU$7:AU763),"") | AW763: =IF(E763="","",B763&"|"&E763) -> MFD-ISW → MFD-CPF|JN°757
A764: =IF(E764="","",ROW()-6) -> 758 | B764: MFD-ISW → MFD-CPF | C764: BRD | D764: / | E764: DJ°522 | F764: =IF(E764="","",IF(LEFT(E764,2)="DJ","DJ","JN")) -> DJ | H764: 16" | I764: 9.53 | J764: API 5L_X52 | K764: TFTII-PL04 | L764: 2091210 | M764: 15421109 | N764: 11.94 | O764: 2095480 | P764: 15421107 | Q764: 11.94 | R764: WR-040 | U764: 46290 | V764: 46290 | W764: DJ-VT-046 | X764: A | Y764: 46291 | Z764: DJ-RT-054 | AA764: A | AO764: =IF(E764="","",(AA764<>"")+(AG764<>"")+(AL764<>"")) -> 1 | AP764: =IF(AL764<>"",AL764,IF(AG764<>"",AG764,IF(AA764<>"",AA764,""))) -> A | AQ764: =IF(E764="","",IF(U764="","À SOUDER",IF(X764="","VT EN ATTENTE",IF(X764="R","VT REJETÉ – À REPRENDRE",IF(AP764="","À RADIOGRAPHIER",IF(AP764="A","ACCEPTÉ",IF(AP764="NX","NX – RT À REFAIRE",IF(IF(AO764=1,AD764,IF(AO764=2,AI764,""))="A","RÉPARÉ – À RADIOGRAPHIER",IF(IF(AO764=1,AD764,IF(AO764=2,AI764,""))="R","VT REJETÉ – À REPRENDRE",IF(OR(AP764="CO",AP764="NT"),"COUPE – À RESOUDER","À RÉPARER")))))))))) -> ACCEPTÉ | AR764: =IF(AND(ISNUMBER(U764),OR(AQ764="À RADIOGRAPHIER",AQ764="RÉPARÉ – À RADIOGRAPHIER",AQ764="NX – RT À REFAIRE",AQ764="À RÉPARER",AQ764="COUPE – À RESOUDER",AQ764="VT REJETÉ – À REPRENDRE")),MAX(0,'PROGRAMME RT'!$C$4-U764),"") | AS764: =IF(AND(OR(AQ764="À RADIOGRAPHIER",AQ764="RÉPARÉ – À RADIOGRAPHIER",AQ764="NX – RT À REFAIRE"),OR('PROGRAMME RT'!$D$5="TOUTES",B764='PROGRAMME RT'!$D$5)),1,0) -> 0 | AT764: =IF(AS764=1,SUM(AS$7:AS764),"") | AU764: =IF(AND(OR(AA764="R",AA764="NX",AA764="NT",AA764="CO"),OR('JOINTS DE RÉPARATION'!$D$5="TOUTES",B764='JOINTS DE RÉPARATION'!$D$5),OR('JOINTS DE RÉPARATION'!$L$4="TOUS",AQ764<>"ACCEPTÉ")),1,0) -> 0 | AV764: =IF(AU764=1,SUM(AU$7:AU764),"") | AW764: =IF(E764="","",B764&"|"&E764) -> MFD-ISW → MFD-CPF|DJ°522
A765: =IF(E765="","",ROW()-6) -> 759 | B765: MFD-ISW → MFD-CPF | D765: 4 | E765: JN°758 | F765: =IF(E765="","",IF(LEFT(E765,2)="DJ","DJ","JN")) -> JN | H765: 16" | I765: 9.53 | J765: API 5L_X52 | K765: TFTII-PL03 | L765: 2095480 | M765: 15421107 | N765: 11.94 | O765: 2084910 | P765: 15421106 | Q765: 11.94 | R765: WR-33-51/40-45 | U765: 46291 | V765: 46291 | X765: A | AO765: =IF(E765="","",(AA765<>"")+(AG765<>"")+(AL765<>"")) -> 0 | AP765: =IF(AL765<>"",AL765,IF(AG765<>"",AG765,IF(AA765<>"",AA765,""))) | AQ765: =IF(E765="","",IF(U765="","À SOUDER",IF(X765="","VT EN ATTENTE",IF(X765="R","VT REJETÉ – À REPRENDRE",IF(AP765="","À RADIOGRAPHIER",IF(AP765="A","ACCEPTÉ",IF(AP765="NX","NX – RT À REFAIRE",IF(IF(AO765=1,AD765,IF(AO765=2,AI765,""))="A","RÉPARÉ – À RADIOGRAPHIER",IF(IF(AO765=1,AD765,IF(AO765=2,AI765,""))="R","VT REJETÉ – À REPRENDRE",IF(OR(AP765="CO",AP765="NT"),"COUPE – À RESOUDER","À RÉPARER")))))))))) -> À RADIOGRAPHIER | AR765: =IF(AND(ISNUMBER(U765),OR(AQ765="À RADIOGRAPHIER",AQ765="RÉPARÉ – À RADIOGRAPHIER",AQ765="NX – RT À REFAIRE",AQ765="À RÉPARER",AQ765="COUPE – À RESOUDER",AQ765="VT REJETÉ – À REPRENDRE")),MAX(0,'PROGRAMME RT'!$C$4-U765),"") -> 2 | AS765: =IF(AND(OR(AQ765="À RADIOGRAPHIER",AQ765="RÉPARÉ – À RADIOGRAPHIER",AQ765="NX – RT À REFAIRE"),OR('PROGRAMME RT'!$D$5="TOUTES",B765='PROGRAMME RT'!$D$5)),1,0) -> 1 | AT765: =IF(AS765=1,SUM(AS$7:AS765),"") -> 1 | AU765: =IF(AND(OR(AA765="R",AA765="NX",AA765="NT",AA765="CO"),OR('JOINTS DE RÉPARATION'!$D$5="TOUTES",B765='JOINTS DE RÉPARATION'!$D$5),OR('JOINTS DE RÉPARATION'!$L$4="TOUS",AQ765<>"ACCEPTÉ")),1,0) -> 0 | AV765: =IF(AU765=1,SUM(AU$7:AU765),"") | AW765: =IF(E765="","",B765&"|"&E765) -> MFD-ISW → MFD-CPF|JN°758
A766: =IF(E766="","",ROW()-6) -> 760 | B766: MFD-ISW → MFD-CPF | C766: BRD | D766: 4 | E766: DJ°507 | F766: =IF(E766="","",IF(LEFT(E766,2)="DJ","DJ","JN")) -> DJ | H766: 16" | I766: 9.53 | J766: API 5L_X52 | K766: TFTII-PL04 | L766: 2084910 | M766: 15421106 | N766: 11.94 | O766: 2085870 | P766: 15421106 | Q766: 11.94 | R766: WR-028 | U766: 46289 | V766: 46289 | W766: DJ-VT-045 | X766: A | Y766: 46290 | Z766: DJ-RT-053 | AA766: A | AO766: =IF(E766="","",(AA766<>"")+(AG766<>"")+(AL766<>"")) -> 1 | AP766: =IF(AL766<>"",AL766,IF(AG766<>"",AG766,IF(AA766<>"",AA766,""))) -> A | AQ766: =IF(E766="","",IF(U766="","À SOUDER",IF(X766="","VT EN ATTENTE",IF(X766="R","VT REJETÉ – À REPRENDRE",IF(AP766="","À RADIOGRAPHIER",IF(AP766="A","ACCEPTÉ",IF(AP766="NX","NX – RT À REFAIRE",IF(IF(AO766=1,AD766,IF(AO766=2,AI766,""))="A","RÉPARÉ – À RADIOGRAPHIER",IF(IF(AO766=1,AD766,IF(AO766=2,AI766,""))="R","VT REJETÉ – À REPRENDRE",IF(OR(AP766="CO",AP766="NT"),"COUPE – À RESOUDER","À RÉPARER")))))))))) -> ACCEPTÉ | AR766: =IF(AND(ISNUMBER(U766),OR(AQ766="À RADIOGRAPHIER",AQ766="RÉPARÉ – À RADIOGRAPHIER",AQ766="NX – RT À REFAIRE",AQ766="À RÉPARER",AQ766="COUPE – À RESOUDER",AQ766="VT REJETÉ – À REPRENDRE")),MAX(0,'PROGRAMME RT'!$C$4-U766),"") | AS766: =IF(AND(OR(AQ766="À RADIOGRAPHIER",AQ766="RÉPARÉ – À RADIOGRAPHIER",AQ766="NX – RT À REFAIRE"),OR('PROGRAMME RT'!$D$5="TOUTES",B766='PROGRAMME RT'!$D$5)),1,0) -> 0 | AT766: =IF(AS766=1,SUM(AS$7:AS766),"") | AU766: =IF(AND(OR(AA766="R",AA766="NX",AA766="NT",AA766="CO"),OR('JOINTS DE RÉPARATION'!$D$5="TOUTES",B766='JOINTS DE RÉPARATION'!$D$5),OR('JOINTS DE RÉPARATION'!$L$4="TOUS",AQ766<>"ACCEPTÉ")),1,0) -> 0 | AV766: =IF(AU766=1,SUM(AU$7:AU766),"") | AW766: =IF(E766="","",B766&"|"&E766) -> MFD-ISW → MFD-CPF|DJ°507
A767: =IF(E767="","",ROW()-6) -> 761 | B767: MFD-ISW → MFD-CPF | D767: 4 | E767: JN°759 | F767: =IF(E767="","",IF(LEFT(E767,2)="DJ","DJ","JN")) -> JN | H767: 16" | I767: 9.53 | J767: API 5L_X52 | K767: TFTII-PL03 | L767: 2085870 | M767: 15421106 | N767: 11.94 | O767: 2089470 | P767: 15421109 | Q767: 11.94 | R767: WR-33-51/40-45 | U767: 46291 | V767: 46291 | W767: L-VT-069 | X767: A | AO767: =IF(E767="","",(AA767<>"")+(AG767<>"")+(AL767<>"")) -> 0 | AP767: =IF(AL767<>"",AL767,IF(AG767<>"",AG767,IF(AA767<>"",AA767,""))) | AQ767: =IF(E767="","",IF(U767="","À SOUDER",IF(X767="","VT EN ATTENTE",IF(X767="R","VT REJETÉ – À REPRENDRE",IF(AP767="","À RADIOGRAPHIER",IF(AP767="A","ACCEPTÉ",IF(AP767="NX","NX – RT À REFAIRE",IF(IF(AO767=1,AD767,IF(AO767=2,AI767,""))="A","RÉPARÉ – À RADIOGRAPHIER",IF(IF(AO767=1,AD767,IF(AO767=2,AI767,""))="R","VT REJETÉ – À REPRENDRE",IF(OR(AP767="CO",AP767="NT"),"COUPE – À RESOUDER","À RÉPARER")))))))))) -> À RADIOGRAPHIER | AR767: =IF(AND(ISNUMBER(U767),OR(AQ767="À RADIOGRAPHIER",AQ767="RÉPARÉ – À RADIOGRAPHIER",AQ767="NX – RT À REFAIRE",AQ767="À RÉPARER",AQ767="COUPE – À RESOUDER",AQ767="VT REJETÉ – À REPRENDRE")),MAX(0,'PROGRAMME RT'!$C$4-U767),"") -> 2 | AS767: =IF(AND(OR(AQ767="À RADIOGRAPHIER",AQ767="RÉPARÉ – À RADIOGRAPHIER",AQ767="NX – RT À REFAIRE"),OR('PROGRAMME RT'!$D$5="TOUTES",B767='PROGRAMME RT'!$D$5)),1,0) -> 1 | AT767: =IF(AS767=1,SUM(AS$7:AS767),"") -> 2 | AU767: =IF(AND(OR(AA767="R",AA767="NX",AA767="NT",AA767="CO"),OR('JOINTS DE RÉPARATION'!$D$5="TOUTES",B767='JOINTS DE RÉPARATION'!$D$5),OR('JOINTS DE RÉPARATION'!$L$4="TOUS",AQ767<>"ACCEPTÉ")),1,0) -> 0 | AV767: =IF(AU767=1,SUM(AU$7:AU767),"") | AW767: =IF(E767="","",B767&"|"&E767) -> MFD-ISW → MFD-CPF|JN°759
A768: =IF(E768="","",ROW()-6) -> 762 | B768: MFD-ISW → MFD-CPF | C768: BRD | D768: 4 | E768: DJ°520 | F768: =IF(E768="","",IF(LEFT(E768,2)="DJ","DJ","JN")) -> DJ | H768: 16" | I768: 9.53 | J768: API 5L_X52 | K768: TFTII-PL04 | L768: 2089470 | M768: 15421109 | N768: 11.94 | O768: 2091760 | P768: 15421109 | Q768: 11.94 | R768: WR-028 | U768: 46290 | V768: 46290 | W768: DJ-VT-046 | X768: A | Y768: 46291 | Z768: DJ-RT-054 | AA768: A | AO768: =IF(E768="","",(AA768<>"")+(AG768<>"")+(AL768<>"")) -> 1 | AP768: =IF(AL768<>"",AL768,IF(AG768<>"",AG768,IF(AA768<>"",AA768,""))) -> A | AQ768: =IF(E768="","",IF(U768="","À SOUDER",IF(X768="","VT EN ATTENTE",IF(X768="R","VT REJETÉ – À REPRENDRE",IF(AP768="","À RADIOGRAPHIER",IF(AP768="A","ACCEPTÉ",IF(AP768="NX","NX – RT À REFAIRE",IF(IF(AO768=1,AD768,IF(AO768=2,AI768,""))="A","RÉPARÉ – À RADIOGRAPHIER",IF(IF(AO768=1,AD768,IF(AO768=2,AI768,""))="R","VT REJETÉ – À REPRENDRE",IF(OR(AP768="CO",AP768="NT"),"COUPE – À RESOUDER","À RÉPARER")))))))))) -> ACCEPTÉ | AR768: =IF(AND(ISNUMBER(U768),OR(AQ768="À RADIOGRAPHIER",AQ768="RÉPARÉ – À RADIOGRAPHIER",AQ768="NX – RT À REFAIRE",AQ768="À RÉPARER",AQ768="COUPE – À RESOUDER",AQ768="VT REJETÉ – À REPRENDRE")),MAX(0,'PROGRAMME RT'!$C$4-U768),"") | AS768: =IF(AND(OR(AQ768="À RADIOGRAPHIER",AQ768="RÉPARÉ – À RADIOGRAPHIER",AQ768="NX – RT À REFAIRE"),OR('PROGRAMME RT'!$D$5="TOUTES",B768='PROGRAMME RT'!$D$5)),1,0) -> 0 | AT768: =IF(AS768=1,SUM(AS$7:AS768),"") | AU768: =IF(AND(OR(AA768="R",AA768="NX",AA768="NT",AA768="CO"),OR('JOINTS DE RÉPARATION'!$D$5="TOUTES",B768='JOINTS DE RÉPARATION'!$D$5),OR('JOINTS DE RÉPARATION'!$L$4="TOUS",AQ768<>"ACCEPTÉ")),1,0) -> 0 | AV768: =IF(AU768=1,SUM(AU$7:AU768),"") | AW768: =IF(E768="","",B768&"|"&E768) -> MFD-ISW → MFD-CPF|DJ°520
A769: =IF(E769="","",ROW()-6) -> 763 | B769: MFD-ISW → MFD-CPF | D769: 4 | E769: JN°760 | F769: =IF(E769="","",IF(LEFT(E769,2)="DJ","DJ","JN")) -> JN | H769: 16" | I769: 9.53 | J769: API 5L_X52 | K769: TFTII-PL03 | L769: 2091760 | M769: 15421109 | N769: 11.94 | O769: 2085850 | P769: 15421107 | Q769: 11.94 | R769: WR-33-51/40-45 | U769: 46291 | V769: 46291 | W769: L-VT-069 | X769: A | AO769: =IF(E769="","",(AA769<>"")+(AG769<>"")+(AL769<>"")) -> 0 | AP769: =IF(AL769<>"",AL769,IF(AG769<>"",AG769,IF(AA769<>"",AA769,""))) | AQ769: =IF(E769="","",IF(U769="","À SOUDER",IF(X769="","VT EN ATTENTE",IF(X769="R","VT REJETÉ – À REPRENDRE",IF(AP769="","À RADIOGRAPHIER",IF(AP769="A","ACCEPTÉ",IF(AP769="NX","NX – RT À REFAIRE",IF(IF(AO769=1,AD769,IF(AO769=2,AI769,""))="A","RÉPARÉ – À RADIOGRAPHIER",IF(IF(AO769=1,AD769,IF(AO769=2,AI769,""))="R","VT REJETÉ – À REPRENDRE",IF(OR(AP769="CO",AP769="NT"),"COUPE – À RESOUDER","À RÉPARER")))))))))) -> À RADIOGRAPHIER | AR769: =IF(AND(ISNUMBER(U769),OR(AQ769="À RADIOGRAPHIER",AQ769="RÉPARÉ – À RADIOGRAPHIER",AQ769="NX – RT À REFAIRE",AQ769="À RÉPARER",AQ769="COUPE – À RESOUDER",AQ769="VT REJETÉ – À REPRENDRE")),MAX(0,'PROGRAMME RT'!$C$4-U769),"") -> 2 | AS769: =IF(AND(OR(AQ769="À RADIOGRAPHIER",AQ769="RÉPARÉ – À RADIOGRAPHIER",AQ769="NX – RT À REFAIRE"),OR('PROGRAMME RT'!$D$5="TOUTES",B769='PROGRAMME RT'!$D$5)),1,0) -> 1 | AT769: =IF(AS769=1,SUM(AS$7:AS769),"") -> 3 | AU769: =IF(AND(OR(AA769="R",AA769="NX",AA769="NT",AA769="CO"),OR('JOINTS DE RÉPARATION'!$D$5="TOUTES",B769='JOINTS DE RÉPARATION'!$D$5),OR('JOINTS DE RÉPARATION'!$L$4="TOUS",AQ769<>"ACCEPTÉ")),1,0) -> 0 | AV769: =IF(AU769=1,SUM(AU$7:AU769),"") | AW769: =IF(E769="","",B769&"|"&E769) -> MFD-ISW → MFD-CPF|JN°760
A770: =IF(E770="","",ROW()-6) -> 764 | B770: MFD-ISW → MFD-CPF | C770: BRD | D770: 4 | E770: DJ°505 | F770: =IF(E770="","",IF(LEFT(E770,2)="DJ","DJ","JN")) -> DJ | H770: 16" | I770: 9.53 | J770: API 5L_X52 | K770: TFTII-PL04 | L770: 2085850 | M770: 15421107 | N770: 11.94 | O770: 2096300 | P770: 15421111 | Q770: 11.94 | R770: WR-028 | U770: 46289 | V770: 46289 | W770: DJ-VT-045 | X770: A | Y770: 46290 | Z770: DJ-RT-053 | AA770: A | AO770: =IF(E770="","",(AA770<>"")+(AG770<>"")+(AL770<>"")) -> 1 | AP770: =IF(AL770<>"",AL770,IF(AG770<>"",AG770,IF(AA770<>"",AA770,""))) -> A | AQ770: =IF(E770="","",IF(U770="","À SOUDER",IF(X770="","VT EN ATTENTE",IF(X770="R","VT REJETÉ – À REPRENDRE",IF(AP770="","À RADIOGRAPHIER",IF(AP770="A","ACCEPTÉ",IF(AP770="NX","NX – RT À REFAIRE",IF(IF(AO770=1,AD770,IF(AO770=2,AI770,""))="A","RÉPARÉ – À RADIOGRAPHIER",IF(IF(AO770=1,AD770,IF(AO770=2,AI770,""))="R","VT REJETÉ – À REPRENDRE",IF(OR(AP770="CO",AP770="NT"),"COUPE – À RESOUDER","À RÉPARER")))))))))) -> ACCEPTÉ | AR770: =IF(AND(ISNUMBER(U770),OR(AQ770="À RADIOGRAPHIER",AQ770="RÉPARÉ – À RADIOGRAPHIER",AQ770="NX – RT À REFAIRE",AQ770="À RÉPARER",AQ770="COUPE – À RESOUDER",AQ770="VT REJETÉ – À REPRENDRE")),MAX(0,'PROGRAMME RT'!$C$4-U770),"") | AS770: =IF(AND(OR(AQ770="À RADIOGRAPHIER",AQ770="RÉPARÉ – À RADIOGRAPHIER",AQ770="NX – RT À REFAIRE"),OR('PROGRAMME RT'!$D$5="TOUTES",B770='PROGRAMME RT'!$D$5)),1,0) -> 0 | AT770: =IF(AS770=1,SUM(AS$7:AS770),"") | AU770: =IF(AND(OR(AA770="R",AA770="NX",AA770="NT",AA770="CO"),OR('JOINTS DE RÉPARATION'!$D$5="TOUTES",B770='JOINTS DE RÉPARATION'!$D$5),OR('JOINTS DE RÉPARATION'!$L$4="TOUS",AQ770<>"ACCEPTÉ")),1,0) -> 0 | AV770: =IF(AU770=1,SUM(AU$7:AU770),"") | AW770: =IF(E770="","",B770&"|"&E770) -> MFD-ISW → MFD-CPF|DJ°505
A771: =IF(E771="","",ROW()-6) -> 765 | B771: MFD-ISW → MFD-CPF | D771: 4 | E771: JN°761 | F771: =IF(E771="","",IF(LEFT(E771,2)="DJ","DJ","JN")) -> JN | H771: 16" | I771: 9.53 | J771: API 5L_X52 | K771: TFTII-PL03 | L771: 2096300 | M771: 15421111 | N771: 11.94 | O771: 2092850 | P771: 15421110 | Q771: 11.94 | R771: WR-33-51/40-45 | U771: 46291 | V771: 46291 | W771: L-VT-069 | X771: A | AO771: =IF(E771="","",(AA771<>"")+(AG771<>"")+(AL771<>"")) -> 0 | AP771: =IF(AL771<>"",AL771,IF(AG771<>"",AG771,IF(AA771<>"",AA771,""))) | AQ771: =IF(E771="","",IF(U771="","À SOUDER",IF(X771="","VT EN ATTENTE",IF(X771="R","VT REJETÉ – À REPRENDRE",IF(AP771="","À RADIOGRAPHIER",IF(AP771="A","ACCEPTÉ",IF(AP771="NX","NX – RT À REFAIRE",IF(IF(AO771=1,AD771,IF(AO771=2,AI771,""))="A","RÉPARÉ – À RADIOGRAPHIER",IF(IF(AO771=1,AD771,IF(AO771=2,AI771,""))="R","VT REJETÉ – À REPRENDRE",IF(OR(AP771="CO",AP771="NT"),"COUPE – À RESOUDER","À RÉPARER")))))))))) -> À RADIOGRAPHIER | AR771: =IF(AND(ISNUMBER(U771),OR(AQ771="À RADIOGRAPHIER",AQ771="RÉPARÉ – À RADIOGRAPHIER",AQ771="NX – RT À REFAIRE",AQ771="À RÉPARER",AQ771="COUPE – À RESOUDER",AQ771="VT REJETÉ – À REPRENDRE")),MAX(0,'PROGRAMME RT'!$C$4-U771),"") -> 2 | AS771: =IF(AND(OR(AQ771="À RADIOGRAPHIER",AQ771="RÉPARÉ – À RADIOGRAPHIER",AQ771="NX – RT À REFAIRE"),OR('PROGRAMME RT'!$D$5="TOUTES",B771='PROGRAMME RT'!$D$5)),1,0) -> 1 | AT771: =IF(AS771=1,SUM(AS$7:AS771),"") -> 4 | AU771: =IF(AND(OR(AA771="R",AA771="NX",AA771="NT",AA771="CO"),OR('JOINTS DE RÉPARATION'!$D$5="TOUTES",B771='JOINTS DE RÉPARATION'!$D$5),OR('JOINTS DE RÉPARATION'!$L$4="TOUS",AQ771<>"ACCEPTÉ")),1,0) -> 0 | AV771: =IF(AU771=1,SUM(AU$7:AU771),"") | AW771: =IF(E771="","",B771&"|"&E771) -> MFD-ISW → MFD-CPF|JN°761
A772: =IF(E772="","",ROW()-6) -> 766 | B772: MFD-ISW → MFD-CPF | C772: BRD | D772: 4 | E772: DJ°466 | F772: =IF(E772="","",IF(LEFT(E772,2)="DJ","DJ","JN")) -> DJ | H772: 16" | I772: 9.53 | J772: API 5L_X52 | K772: TFTII-PL04 | L772: 2092850 | M772: 15421110 | N772: 11.94 | O772: 2083450 | P772: 15421103 | Q772: 11.94 | R772: WR-040 | U772: 46286 | V772: 46286 | W772: DJ-VT-042 | X772: A | Y772: 46291 | Z772: DJ-RT-054 | AA772: A | AO772: =IF(E772="","",(AA772<>"")+(AG772<>"")+(AL772<>"")) -> 1 | AP772: =IF(AL772<>"",AL772,IF(AG772<>"",AG772,IF(AA772<>"",AA772,""))) -> A | AQ772: =IF(E772="","",IF(U772="","À SOUDER",IF(X772="","VT EN ATTENTE",IF(X772="R","VT REJETÉ – À REPRENDRE",IF(AP772="","À RADIOGRAPHIER",IF(AP772="A","ACCEPTÉ",IF(AP772="NX","NX – RT À REFAIRE",IF(IF(AO772=1,AD772,IF(AO772=2,AI772,""))="A","RÉPARÉ – À RADIOGRAPHIER",IF(IF(AO772=1,AD772,IF(AO772=2,AI772,""))="R","VT REJETÉ – À REPRENDRE",IF(OR(AP772="CO",AP772="NT"),"COUPE – À RESOUDER","À RÉPARER")))))))))) -> ACCEPTÉ | AR772: =IF(AND(ISNUMBER(U772),OR(AQ772="À RADIOGRAPHIER",AQ772="RÉPARÉ – À RADIOGRAPHIER",AQ772="NX – RT À REFAIRE",AQ772="À RÉPARER",AQ772="COUPE – À RESOUDER",AQ772="VT REJETÉ – À REPRENDRE")),MAX(0,'PROGRAMME RT'!$C$4-U772),"") | AS772: =IF(AND(OR(AQ772="À RADIOGRAPHIER",AQ772="RÉPARÉ – À RADIOGRAPHIER",AQ772="NX – RT À REFAIRE"),OR('PROGRAMME RT'!$D$5="TOUTES",B772='PROGRAMME RT'!$D$5)),1,0) -> 0 | AT772: =IF(AS772=1,SUM(AS$7:AS772),"") | AU772: =IF(AND(OR(AA772="R",AA772="NX",AA772="NT",AA772="CO"),OR('JOINTS DE RÉPARATION'!$D$5="TOUTES",B772='JOINTS DE RÉPARATION'!$D$5),OR('JOINTS DE RÉPARATION'!$L$4="TOUS",AQ772<>"ACCEPTÉ")),1,0) -> 0 | AV772: =IF(AU772=1,SUM(AU$7:AU772),"") | AW772: =IF(E772="","",B772&"|"&E772) -> MFD-ISW → MFD-CPF|DJ°466
A773: =IF(E773="","",ROW()-6) -> 767 | B773: MFD-ISW → MFD-CPF | D773: 4 | E773: JN°762 | F773: =IF(E773="","",IF(LEFT(E773,2)="DJ","DJ","JN")) -> JN | H773: 16" | I773: 9.53 | J773: API 5L_X52 | K773: TFTII-PL03 | L773: 2083450 | M773: 15421103 | N773: 11.94 | O773: 2093110 | P773: 15421110 | Q773: 11.94 | R773: WR-33-51/40-45 | U773: 46291 | V773: 46291 | W773: L-VT-069 | X773: A | AO773: =IF(E773="","",(AA773<>"")+(AG773<>"")+(AL773<>"")) -> 0 | AP773: =IF(AL773<>"",AL773,IF(AG773<>"",AG773,IF(AA773<>"",AA773,""))) | AQ773: =IF(E773="","",IF(U773="","À SOUDER",IF(X773="","VT EN ATTENTE",IF(X773="R","VT REJETÉ – À REPRENDRE",IF(AP773="","À RADIOGRAPHIER",IF(AP773="A","ACCEPTÉ",IF(AP773="NX","NX – RT À REFAIRE",IF(IF(AO773=1,AD773,IF(AO773=2,AI773,""))="A","RÉPARÉ – À RADIOGRAPHIER",IF(IF(AO773=1,AD773,IF(AO773=2,AI773,""))="R","VT REJETÉ – À REPRENDRE",IF(OR(AP773="CO",AP773="NT"),"COUPE – À RESOUDER","À RÉPARER")))))))))) -> À RADIOGRAPHIER | AR773: =IF(AND(ISNUMBER(U773),OR(AQ773="À RADIOGRAPHIER",AQ773="RÉPARÉ – À RADIOGRAPHIER",AQ773="NX – RT À REFAIRE",AQ773="À RÉPARER",AQ773="COUPE – À RESOUDER",AQ773="VT REJETÉ – À REPRENDRE")),MAX(0,'PROGRAMME RT'!$C$4-U773),"") -> 2 | AS773: =IF(AND(OR(AQ773="À RADIOGRAPHIER",AQ773="RÉPARÉ – À RADIOGRAPHIER",AQ773="NX – RT À REFAIRE"),OR('PROGRAMME RT'!$D$5="TOUTES",B773='PROGRAMME RT'!$D$5)),1,0) -> 1 | AT773: =IF(AS773=1,SUM(AS$7:AS773),"") -> 5 | AU773: =IF(AND(OR(AA773="R",AA773="NX",AA773="NT",AA773="CO"),OR('JOINTS DE RÉPARATION'!$D$5="TOUTES",B773='JOINTS DE RÉPARATION'!$D$5),OR('JOINTS DE RÉPARATION'!$L$4="TOUS",AQ773<>"ACCEPTÉ")),1,0) -> 0 | AV773: =IF(AU773=1,SUM(AU$7:AU773),"") | AW773: =IF(E773="","",B773&"|"&E773) -> MFD-ISW → MFD-CPF|JN°762
A774: =IF(E774="","",ROW()-6) -> 768 | B774: MFD-ISW → MFD-CPF | C774: BRD | D774: 4 | E774: DJ°477 | F774: =IF(E774="","",IF(LEFT(E774,2)="DJ","DJ","JN")) -> DJ | H774: 16" | I774: 9.53 | J774: API 5L_X52 | K774: TFTII-PL04 | L774: 2093110 | M774: 15421110 | N774: 11.94 | O774: 2094210 | P774: 15421110 | Q774: 11.94 | R774: WR-040 | U774: 46286 | V774: 46286 | W774: DJ-VT-042 | X774: A | Y774: 46291 | Z774: DJ-RT-054 | AA774: A | AO774: =IF(E774="","",(AA774<>"")+(AG774<>"")+(AL774<>"")) -> 1 | AP774: =IF(AL774<>"",AL774,IF(AG774<>"",AG774,IF(AA774<>"",AA774,""))) -> A | AQ774: =IF(E774="","",IF(U774="","À SOUDER",IF(X774="","VT EN ATTENTE",IF(X774="R","VT REJETÉ – À REPRENDRE",IF(AP774="","À RADIOGRAPHIER",IF(AP774="A","ACCEPTÉ",IF(AP774="NX","NX – RT À REFAIRE",IF(IF(AO774=1,AD774,IF(AO774=2,AI774,""))="A","RÉPARÉ – À RADIOGRAPHIER",IF(IF(AO774=1,AD774,IF(AO774=2,AI774,""))="R","VT REJETÉ – À REPRENDRE",IF(OR(AP774="CO",AP774="NT"),"COUPE – À RESOUDER","À RÉPARER")))))))))) -> ACCEPTÉ | AR774: =IF(AND(ISNUMBER(U774),OR(AQ774="À RADIOGRAPHIER",AQ774="RÉPARÉ – À RADIOGRAPHIER",AQ774="NX – RT À REFAIRE",AQ774="À RÉPARER",AQ774="COUPE – À RESOUDER",AQ774="VT REJETÉ – À REPRENDRE")),MAX(0,'PROGRAMME RT'!$C$4-U774),"") | AS774: =IF(AND(OR(AQ774="À RADIOGRAPHIER",AQ774="RÉPARÉ – À RADIOGRAPHIER",AQ774="NX – RT À REFAIRE"),OR('PROGRAMME RT'!$D$5="TOUTES",B774='PROGRAMME RT'!$D$5)),1,0) -> 0 | AT774: =IF(AS774=1,SUM(AS$7:AS774),"") | AU774: =IF(AND(OR(AA774="R",AA774="NX",AA774="NT",AA774="CO"),OR('JOINTS DE RÉPARATION'!$D$5="TOUTES",B774='JOINTS DE RÉPARATION'!$D$5),OR('JOINTS DE RÉPARATION'!$L$4="TOUS",AQ774<>"ACCEPTÉ")),1,0) -> 0 | AV774: =IF(AU774=1,SUM(AU$7:AU774),"") | AW774: =IF(E774="","",B774&"|"&E774) -> MFD-ISW → MFD-CPF|DJ°477
A775: =IF(E775="","",ROW()-6) -> 769 | B775: MFD-ISW → MFD-CPF | D775: N,S | E775: JN°763 | F775: =IF(E775="","",IF(LEFT(E775,2)="DJ","DJ","JN")) -> JN | H775: 16" | I775: 9.53 | J775: API 5L_X52 | AO775: =IF(E775="","",(AA775<>"")+(AG775<>"")+(AL775<>"")) -> 0 | AP775: =IF(AL775<>"",AL775,IF(AG775<>"",AG775,IF(AA775<>"",AA775,""))) | AQ775: =IF(E775="","",IF(U775="","À SOUDER",IF(X775="","VT EN ATTENTE",IF(X775="R","VT REJETÉ – À REPRENDRE",IF(AP775="","À RADIOGRAPHIER",IF(AP775="A","ACCEPTÉ",IF(AP775="NX","NX – RT À REFAIRE",IF(IF(AO775=1,AD775,IF(AO775=2,AI775,""))="A","RÉPARÉ – À RADIOGRAPHIER",IF(IF(AO775=1,AD775,IF(AO775=2,AI775,""))="R","VT REJETÉ – À REPRENDRE",IF(OR(AP775="CO",AP775="NT"),"COUPE – À RESOUDER","À RÉPARER")))))))))) -> À SOUDER | AR775: =IF(AND(ISNUMBER(U775),OR(AQ775="À RADIOGRAPHIER",AQ775="RÉPARÉ – À RADIOGRAPHIER",AQ775="NX – RT À REFAIRE",AQ775="À RÉPARER",AQ775="COUPE – À RESOUDER",AQ775="VT REJETÉ – À REPRENDRE")),MAX(0,'PROGRAMME RT'!$C$4-U775),"") | AS775: =IF(AND(OR(AQ775="À RADIOGRAPHIER",AQ775="RÉPARÉ – À RADIOGRAPHIER",AQ775="NX – RT À REFAIRE"),OR('PROGRAMME RT'!$D$5="TOUTES",B775='PROGRAMME RT'!$D$5)),1,0) -> 0 | AT775: =IF(AS775=1,SUM(AS$7:AS775),"") | AU775: =IF(AND(OR(AA775="R",AA775="NX",AA775="NT",AA775="CO"),OR('JOINTS DE RÉPARATION'!$D$5="TOUTES",B775='JOINTS DE RÉPARATION'!$D$5),OR('JOINTS DE RÉPARATION'!$L$4="TOUS",AQ775<>"ACCEPTÉ")),1,0) -> 0 | AV775: =IF(AU775=1,SUM(AU$7:AU775),"") | AW775: =IF(E775="","",B775&"|"&E775) -> MFD-ISW → MFD-CPF|JN°763
A776: =IF(E776="","",ROW()-6) -> 770 | B776: MFD-ISW → MFD-CPF | D776: N,S | E776: JN°764 | F776: =IF(E776="","",IF(LEFT(E776,2)="DJ","DJ","JN")) -> JN | H776: 16" | I776: 9.53 | J776: API 5L_X52 | AO776: =IF(E776="","",(AA776<>"")+(AG776<>"")+(AL776<>"")) -> 0 | AP776: =IF(AL776<>"",AL776,IF(AG776<>"",AG776,IF(AA776<>"",AA776,""))) | AQ776: =IF(E776="","",IF(U776="","À SOUDER",IF(X776="","VT EN ATTENTE",IF(X776="R","VT REJETÉ – À REPRENDRE",IF(AP776="","À RADIOGRAPHIER",IF(AP776="A","ACCEPTÉ",IF(AP776="NX","NX – RT À REFAIRE",IF(IF(AO776=1,AD776,IF(AO776=2,AI776,""))="A","RÉPARÉ – À RADIOGRAPHIER",IF(IF(AO776=1,AD776,IF(AO776=2,AI776,""))="R","VT REJETÉ – À REPRENDRE",IF(OR(AP776="CO",AP776="NT"),"COUPE – À RESOUDER","À RÉPARER")))))))))) -> À SOUDER | AR776: =IF(AND(ISNUMBER(U776),OR(AQ776="À RADIOGRAPHIER",AQ776="RÉPARÉ – À RADIOGRAPHIER",AQ776="NX – RT À REFAIRE",AQ776="À RÉPARER",AQ776="COUPE – À RESOUDER",AQ776="VT REJETÉ – À REPRENDRE")),MAX(0,'PROGRAMME RT'!$C$4-U776),"") | AS776: =IF(AND(OR(AQ776="À RADIOGRAPHIER",AQ776="RÉPARÉ – À RADIOGRAPHIER",AQ776="NX – RT À REFAIRE"),OR('PROGRAMME RT'!$D$5="TOUTES",B776='PROGRAMME RT'!$D$5)),1,0) -> 0 | AT776: =IF(AS776=1,SUM(AS$7:AS776),"") | AU776: =IF(AND(OR(AA776="R",AA776="NX",AA776="NT",AA776="CO"),OR('JOINTS DE RÉPARATION'!$D$5="TOUTES",B776='JOINTS DE RÉPARATION'!$D$5),OR('JOINTS DE RÉPARATION'!$L$4="TOUS",AQ776<>"ACCEPTÉ")),1,0) -> 0 | AV776: =IF(AU776=1,SUM(AU$7:AU776),"") | AW776: =IF(E776="","",B776&"|"&E776) -> MFD-ISW → MFD-CPF|JN°764
A777: =IF(E777="","",ROW()-6) -> 771 | B777: MFD-ISW → MFD-CPF | C777: BRD | D777: 4 | E777: DJ°506 | F777: =IF(E777="","",IF(LEFT(E777,2)="DJ","DJ","JN")) -> DJ | H777: 16" | I777: 9.53 | J777: API 5L_X52 | K777: TFTII-PL04 | L777: 2078980 | M777: 15421102 | N777: 11.94 | O777: 2095190 | P777: 15421111 | Q777: 11.94 | R777: WR-041 | U777: 46289 | V777: 46289 | W777: DJ-VT-045 | X777: A | Y777: 46290 | Z777: DJ-RT-053 | AA777: A | AO777: =IF(E777="","",(AA777<>"")+(AG777<>"")+(AL777<>"")) -> 1 | AP777: =IF(AL777<>"",AL777,IF(AG777<>"",AG777,IF(AA777<>"",AA777,""))) -> A | AQ777: =IF(E777="","",IF(U777="","À SOUDER",IF(X777="","VT EN ATTENTE",IF(X777="R","VT REJETÉ – À REPRENDRE",IF(AP777="","À RADIOGRAPHIER",IF(AP777="A","ACCEPTÉ",IF(AP777="NX","NX – RT À REFAIRE",IF(IF(AO777=1,AD777,IF(AO777=2,AI777,""))="A","RÉPARÉ – À RADIOGRAPHIER",IF(IF(AO777=1,AD777,IF(AO777=2,AI777,""))="R","VT REJETÉ – À REPRENDRE",IF(OR(AP777="CO",AP777="NT"),"COUPE – À RESOUDER","À RÉPARER")))))))))) -> ACCEPTÉ | AR777: =IF(AND(ISNUMBER(U777),OR(AQ777="À RADIOGRAPHIER",AQ777="RÉPARÉ – À RADIOGRAPHIER",AQ777="NX – RT À REFAIRE",AQ777="À RÉPARER",AQ777="COUPE – À RESOUDER",AQ777="VT REJETÉ – À REPRENDRE")),MAX(0,'PROGRAMME RT'!$C$4-U777),"") | AS777: =IF(AND(OR(AQ777="À RADIOGRAPHIER",AQ777="RÉPARÉ – À RADIOGRAPHIER",AQ777="NX – RT À REFAIRE"),OR('PROGRAMME RT'!$D$5="TOUTES",B777='PROGRAMME RT'!$D$5)),1,0) -> 0 | AT777: =IF(AS777=1,SUM(AS$7:AS777),"") | AU777: =IF(AND(OR(AA777="R",AA777="NX",AA777="NT",AA777="CO"),OR('JOINTS DE RÉPARATION'!$D$5="TOUTES",B777='JOINTS DE RÉPARATION'!$D$5),OR('JOINTS DE RÉPARATION'!$L$4="TOUS",AQ777<>"ACCEPTÉ")),1,0) -> 0 | AV777: =IF(AU777=1,SUM(AU$7:AU777),"") | AW777: =IF(E777="","",B777&"|"&E777) -> MFD-ISW → MFD-CPF|DJ°506
