Workbook
Name _1_2: WPS!#REF!
Name _1_2: #REF!
Name _1_2: WPS!#REF!
Name _1_PASSE: #REF!
Name _1_PASSE: #REF!
Name _1_PASSE: #REF!
Name _1_PASSE: #REF!
Name _1_PASSE: #REF!
Name A: #REF!
Name A: #REF!
Name A: #REF!
Name A105_A105: #REF!
Name A105_A105: #REF!
Name A105_A105: #REF!
Name A105_A106GrB: #REF!
Name A105_A106GrB: #REF!
Name A105_A106GrB: #REF!
Name A105_A234WPB: #REF!
Name A105_A234WPB: #REF!
Name A105_A234WPB: #REF!
Name A105_A694F60: #REF!
Name A105_A694F60: #REF!
Name A105_A694F60: #REF!
Name A106GrB_A105: #REF!
Name A106GrB_A105: #REF!
Name A106GrB_A105: #REF!
Name A106GrB_A106GrB: #REF!
Name A106GrB_A106GrB: #REF!
Name A106GrB_A106GrB: #REF!
Name A106GrB_A234WPB: #REF!
Name A106GrB_A234WPB: #REF!
Name A106GrB_A234WPB: #REF!
Name A106GrB_A694F60: #REF!
Name A106GrB_A694F60: #REF!
Name A106GrB_A694F60: #REF!
Name A234WPB_A105: #REF!
Name A234WPB_A105: #REF!
Name A234WPB_A105: #REF!
Name A234WPB_A106GrB: #REF!
Name A234WPB_A106GrB: #REF!
Name A234WPB_A106GrB: #REF!
Name A234WPB_A234WPB: #REF!
Name A234WPB_A234WPB: #REF!
Name A234WPB_A234WPB: #REF!
Name A234WPB_A694F60: #REF!
Name A234WPB_A694F60: #REF!
Name A234WPB_A694F60: #REF!
Name A333Gr6_A333Gr6: #REF!
Name A333Gr6_A333Gr6: #REF!
Name A333Gr6_A333Gr6: #REF!
Name A333Gr6_A350LF2: #REF!
Name A333Gr6_A350LF2: #REF!
Name A333Gr6_A350LF2: #REF!
Name A333Gr6_A420WPL: #REF!
Name A333Gr6_A420WPL: #REF!
Name A333Gr6_A420WPL: #REF!
Name A333Gr6_A694F60: #REF!
Name A333Gr6_A694F60: #REF!
Name A333Gr6_A694F60: #REF!
Name A350LF2_A333Gr6: #REF!

Sheet HOMO
O1: 8557 | P1: Développement des champs gaziers de TFT II Contrat construction& commissionning « réseau de collecte TFT sud offsite-raccordement de vingt-quatre (24) puits producteurs de gaz » a TFT- Hassi Rmel
O2: 8546 | P2: Raccordement de onze (11) nouveaux puits au réseau de collects a TFT- Hassi Rmel
C4: Département Construction | H4: GTFT / ENGTP le | K4: 46316 | L4: =#REF! -> #REF!
C5: Service Soudage | K5: AFFAIRE : | L5: 8557
C6: =VLOOKUP($L$5,$O$1:$P$2,2,0) -> Développement des champs gaziers de TFT II Contrat construction& commissionning « réseau de collecte TFT sud offsite-raccordement de vingt-quatre (24) puits producteurs de gaz » a TFT- Hassi Rmel
D7: Homologation Des Soudeurs Pour | G7: =K4 -> 46316
F8: RFI: | G8: =IF(B11="","",INDEX('liste des soudeurs'!Q:Q,MATCH(B11,'liste des soudeurs'!$BI:$BI,0))) -> 21063-G0-PPL-RFI-0203
C10: NOM & PRENOM | D10: Repère soudeur | E10: WPS N° | F10: PROCESS | G10: NUANCE MATERIAL | H10: DIAMETER SIZE Ø | I10: EPAISSEUR THK (mm) | J10: position | K10: PreHeat | L10: Filler Metal Root & Hot | M10: Filler Metal Fill Cap | N10: VISUEL ACC/REJ
A11: 1 | B11: =IF(A11<=MAX('liste des soudeurs'!BI:BI),A11,"") -> 1 | C11: =IF(B11="","",INDEX('liste des soudeurs'!F:F,MATCH(B11,'liste des soudeurs'!$BI:$BI,0))) -> BITAM RABAH | D11: =IF(B11="","",INDEX('liste des soudeurs'!E:E,MATCH(B11,'liste des soudeurs'!$BI:$BI,0))) -> WR-068 | E11: =IF(B11="","",INDEX('liste des soudeurs'!G:G,MATCH(B11,'liste des soudeurs'!$BI:$BI,0))) -> TFT-II-PL-03 | F11: =IF(B11="","",INDEX('liste des soudeurs'!AE:AE,MATCH(B11,'liste des soudeurs'!$BI:$BI,0))) -> SMAW Mixte UP HILL/ Down hill | G11: =IF(B11="","",INDEX('liste des soudeurs'!H:H,MATCH(B11,'liste des soudeurs'!$BI:$BI,0))) -> API5L_X52 | H11: =IF(B11="","",INDEX('liste des soudeurs'!I:I,MATCH(B11,'liste des soudeurs'!$BI:$BI,0))) -> 12 | I11: =IF(B11="","",INDEX('liste des soudeurs'!J:J,MATCH(B11,'liste des soudeurs'!$BI:$BI,0))) -> 11.13 | J11: =IF(B11="","",INDEX('liste des soudeurs'!AH:AH,MATCH(B11,'liste des soudeurs'!$BI:$BI,0))) -> 5G | K11: =IF(B11="","",INDEX('liste des soudeurs'!AX:AX,MATCH(B11,'liste des soudeurs'!$BI:$BI,0))) -> 50°C Min | L11: =IF(B11="","",INDEX('liste des soudeurs'!AQ:AQ,MATCH(B11,'liste des soudeurs'!$BI:$BI,0))) -> E 6010 | M11: =IF(B11="","",INDEX('liste des soudeurs'!AR:AR,MATCH(B11,'liste des soudeurs'!$BI:$BI,0))) -> E 7010-P1
A12: 2 | B12: =IF(A12<=MAX('liste des soudeurs'!BI:BI),A12,"") -> 2 | C12: =IF(B12="","",INDEX('liste des soudeurs'!F:F,MATCH(B12,'liste des soudeurs'!$BI:$BI,0))) -> MEBARKI RABAH | D12: =IF(B12="","",INDEX('liste des soudeurs'!E:E,MATCH(B12,'liste des soudeurs'!$BI:$BI,0))) -> WR-069 | E12: =IF(B12="","",INDEX('liste des soudeurs'!G:G,MATCH(B12,'liste des soudeurs'!$BI:$BI,0))) -> TFT-II-PL-03 | F12: =IF(B12="","",INDEX('liste des soudeurs'!AE:AE,MATCH(B12,'liste des soudeurs'!$BI:$BI,0))) -> SMAW Mixte UP HILL/ Down hill | G12: =IF(B12="","",INDEX('liste des soudeurs'!H:H,MATCH(B12,'liste des soudeurs'!$BI:$BI,0))) -> API5L_X52 | H12: =IF(B12="","",INDEX('liste des soudeurs'!I:I,MATCH(B12,'liste des soudeurs'!$BI:$BI,0))) -> 12 | I12: =IF(B12="","",INDEX('liste des soudeurs'!J:J,MATCH(B12,'liste des soudeurs'!$BI:$BI,0))) -> 11.13 | J12: =IF(B12="","",INDEX('liste des soudeurs'!AH:AH,MATCH(B12,'liste des soudeurs'!$BI:$BI,0))) -> 5G | K12: =IF(B12="","",INDEX('liste des soudeurs'!AX:AX,MATCH(B12,'liste des soudeurs'!$BI:$BI,0))) -> 50°C Min | L12: =IF(B12="","",INDEX('liste des soudeurs'!AQ:AQ,MATCH(B12,'liste des soudeurs'!$BI:$BI,0))) -> E 6010 | M12: =IF(B12="","",INDEX('liste des soudeurs'!AR:AR,MATCH(B12,'liste des soudeurs'!$BI:$BI,0))) -> E 7010-P1
A13: 3 | B13: =IF(A13<=MAX('liste des soudeurs'!BI:BI),A13,"") | C13: =IF(B13="","",INDEX('liste des soudeurs'!F:F,MATCH(B13,'liste des soudeurs'!$BI:$BI,0))) | D13: =IF(B13="","",INDEX('liste des soudeurs'!E:E,MATCH(B13,'liste des soudeurs'!$BI:$BI,0))) | E13: =IF(B13="","",INDEX('liste des soudeurs'!G:G,MATCH(B13,'liste des soudeurs'!$BI:$BI,0))) | F13: =IF(B13="","",INDEX('liste des soudeurs'!AE:AE,MATCH(B13,'liste des soudeurs'!$BI:$BI,0))) | G13: =IF(B13="","",INDEX('liste des soudeurs'!H:H,MATCH(B13,'liste des soudeurs'!$BI:$BI,0))) | H13: =IF(B13="","",INDEX('liste des soudeurs'!I:I,MATCH(B13,'liste des soudeurs'!$BI:$BI,0))) | I13: =IF(B13="","",INDEX('liste des soudeurs'!J:J,MATCH(B13,'liste des soudeurs'!$BI:$BI,0))) | J13: =IF(B13="","",INDEX('liste des soudeurs'!AH:AH,MATCH(B13,'liste des soudeurs'!$BI:$BI,0))) | K13: =IF(B13="","",INDEX('liste des soudeurs'!AX:AX,MATCH(B13,'liste des soudeurs'!$BI:$BI,0))) | L13: =IF(B13="","",INDEX('liste des soudeurs'!AQ:AQ,MATCH(B13,'liste des soudeurs'!$BI:$BI,0))) | M13: =IF(B13="","",INDEX('liste des soudeurs'!AR:AR,MATCH(B13,'liste des soudeurs'!$BI:$BI,0)))
A14: 4 | B14: =IF(A14<=MAX('liste des soudeurs'!BI:BI),A14,"") | C14: =IF(B14="","",INDEX('liste des soudeurs'!F:F,MATCH(B14,'liste des soudeurs'!$BI:$BI,0))) | D14: =IF(B14="","",INDEX('liste des soudeurs'!E:E,MATCH(B14,'liste des soudeurs'!$BI:$BI,0))) | E14: =IF(B14="","",INDEX('liste des soudeurs'!G:G,MATCH(B14,'liste des soudeurs'!$BI:$BI,0))) | F14: =IF(B14="","",INDEX('liste des soudeurs'!AE:AE,MATCH(B14,'liste des soudeurs'!$BI:$BI,0))) | G14: =IF(B14="","",INDEX('liste des soudeurs'!H:H,MATCH(B14,'liste des soudeurs'!$BI:$BI,0))) | H14: =IF(B14="","",INDEX('liste des soudeurs'!I:I,MATCH(B14,'liste des soudeurs'!$BI:$BI,0))) | I14: =IF(B14="","",INDEX('liste des soudeurs'!J:J,MATCH(B14,'liste des soudeurs'!$BI:$BI,0))) | J14: =IF(B14="","",INDEX('liste des soudeurs'!AH:AH,MATCH(B14,'liste des soudeurs'!$BI:$BI,0))) | K14: =IF(B14="","",INDEX('liste des soudeurs'!AX:AX,MATCH(B14,'liste des soudeurs'!$BI:$BI,0))) | L14: =IF(B14="","",INDEX('liste des soudeurs'!AQ:AQ,MATCH(B14,'liste des soudeurs'!$BI:$BI,0))) | M14: =IF(B14="","",INDEX('liste des soudeurs'!AR:AR,MATCH(B14,'liste des soudeurs'!$BI:$BI,0)))
A15: 5 | B15: =IF(A15<=MAX('liste des soudeurs'!BI:BI),A15,"") | C15: =IF(B15="","",INDEX('liste des soudeurs'!F:F,MATCH(B15,'liste des soudeurs'!$BI:$BI,0))) | D15: =IF(B15="","",INDEX('liste des soudeurs'!E:E,MATCH(B15,'liste des soudeurs'!$BI:$BI,0))) | E15: =IF(B15="","",INDEX('liste des soudeurs'!G:G,MATCH(B15,'liste des soudeurs'!$BI:$BI,0))) | F15: =IF(B15="","",INDEX('liste des soudeurs'!AE:AE,MATCH(B15,'liste des soudeurs'!$BI:$BI,0))) | G15: =IF(B15="","",INDEX('liste des soudeurs'!H:H,MATCH(B15,'liste des soudeurs'!$BI:$BI,0))) | H15: =IF(B15="","",INDEX('liste des soudeurs'!I:I,MATCH(B15,'liste des soudeurs'!$BI:$BI,0))) | I15: =IF(B15="","",INDEX('liste des soudeurs'!J:J,MATCH(B15,'liste des soudeurs'!$BI:$BI,0))) | J15: =IF(B15="","",INDEX('liste des soudeurs'!AH:AH,MATCH(B15,'liste des soudeurs'!$BI:$BI,0))) | K15: =IF(B15="","",INDEX('liste des soudeurs'!AX:AX,MATCH(B15,'liste des soudeurs'!$BI:$BI,0))) | L15: =IF(B15="","",INDEX('liste des soudeurs'!AQ:AQ,MATCH(B15,'liste des soudeurs'!$BI:$BI,0))) | M15: =IF(B15="","",INDEX('liste des soudeurs'!AR:AR,MATCH(B15,'liste des soudeurs'!$BI:$BI,0)))
A16: 6 | B16: =IF(A16<=MAX('liste des soudeurs'!BI:BI),A16,"") | C16: =IF(B16="","",INDEX('liste des soudeurs'!F:F,MATCH(B16,'liste des soudeurs'!$BI:$BI,0))) | D16: =IF(B16="","",INDEX('liste des soudeurs'!E:E,MATCH(B16,'liste des soudeurs'!$BI:$BI,0))) | E16: =IF(B16="","",INDEX('liste des soudeurs'!G:G,MATCH(B16,'liste des soudeurs'!$BI:$BI,0))) | F16: =IF(B16="","",INDEX('liste des soudeurs'!AE:AE,MATCH(B16,'liste des soudeurs'!$BI:$BI,0))) | G16: =IF(B16="","",INDEX('liste des soudeurs'!H:H,MATCH(B16,'liste des soudeurs'!$BI:$BI,0))) | H16: =IF(B16="","",INDEX('liste des soudeurs'!I:I,MATCH(B16,'liste des soudeurs'!$BI:$BI,0))) | I16: =IF(B16="","",INDEX('liste des soudeurs'!J:J,MATCH(B16,'liste des soudeurs'!$BI:$BI,0))) | J16: =IF(B16="","",INDEX('liste des soudeurs'!AH:AH,MATCH(B16,'liste des soudeurs'!$BI:$BI,0))) | K16: =IF(B16="","",INDEX('liste des soudeurs'!AX:AX,MATCH(B16,'liste des soudeurs'!$BI:$BI,0))) | L16: =IF(B16="","",INDEX('liste des soudeurs'!AQ:AQ,MATCH(B16,'liste des soudeurs'!$BI:$BI,0))) | M16: =IF(B16="","",INDEX('liste des soudeurs'!AR:AR,MATCH(B16,'liste des soudeurs'!$BI:$BI,0)))
A17: 7 | B17: =IF(A17<=MAX('liste des soudeurs'!BI:BI),A17,"") | C17: =IF(B17="","",INDEX('liste des soudeurs'!F:F,MATCH(B17,'liste des soudeurs'!$BI:$BI,0))) | D17: =IF(B17="","",INDEX('liste des soudeurs'!E:E,MATCH(B17,'liste des soudeurs'!$BI:$BI,0))) | E17: =IF(B17="","",INDEX('liste des soudeurs'!G:G,MATCH(B17,'liste des soudeurs'!$BI:$BI,0))) | F17: =IF(B17="","",INDEX('liste des soudeurs'!AE:AE,MATCH(B17,'liste des soudeurs'!$BI:$BI,0))) | G17: =IF(B17="","",INDEX('liste des soudeurs'!H:H,MATCH(B17,'liste des soudeurs'!$BI:$BI,0))) | H17: =IF(B17="","",INDEX('liste des soudeurs'!I:I,MATCH(B17,'liste des soudeurs'!$BI:$BI,0))) | I17: =IF(B17="","",INDEX('liste des soudeurs'!J:J,MATCH(B17,'liste des soudeurs'!$BI:$BI,0))) | J17: =IF(B17="","",INDEX('liste des soudeurs'!AH:AH,MATCH(B17,'liste des soudeurs'!$BI:$BI,0))) | K17: =IF(B17="","",INDEX('liste des soudeurs'!AX:AX,MATCH(B17,'liste des soudeurs'!$BI:$BI,0))) | L17: =IF(B17="","",INDEX('liste des soudeurs'!AQ:AQ,MATCH(B17,'liste des soudeurs'!$BI:$BI,0))) | M17: =IF(B17="","",INDEX('liste des soudeurs'!AR:AR,MATCH(B17,'liste des soudeurs'!$BI:$BI,0)))
A18: 8 | B18: =IF(A18<=MAX('liste des soudeurs'!BI:BI),A18,"") | C18: =IF(B18="","",INDEX('liste des soudeurs'!F:F,MATCH(B18,'liste des soudeurs'!$BI:$BI,0))) | D18: =IF(B18="","",INDEX('liste des soudeurs'!E:E,MATCH(B18,'liste des soudeurs'!$BI:$BI,0))) | E18: =IF(B18="","",INDEX('liste des soudeurs'!G:G,MATCH(B18,'liste des soudeurs'!$BI:$BI,0))) | F18: =IF(B18="","",INDEX('liste des soudeurs'!AE:AE,MATCH(B18,'liste des soudeurs'!$BI:$BI,0))) | G18: =IF(B18="","",INDEX('liste des soudeurs'!H:H,MATCH(B18,'liste des soudeurs'!$BI:$BI,0))) | H18: =IF(B18="","",INDEX('liste des soudeurs'!I:I,MATCH(B18,'liste des soudeurs'!$BI:$BI,0))) | I18: =IF(B18="","",INDEX('liste des soudeurs'!J:J,MATCH(B18,'liste des soudeurs'!$BI:$BI,0))) | J18: =IF(B18="","",INDEX('liste des soudeurs'!AH:AH,MATCH(B18,'liste des soudeurs'!$BI:$BI,0))) | K18: =IF(B18="","",INDEX('liste des soudeurs'!AX:AX,MATCH(B18,'liste des soudeurs'!$BI:$BI,0))) | L18: =IF(B18="","",INDEX('liste des soudeurs'!AQ:AQ,MATCH(B18,'liste des soudeurs'!$BI:$BI,0))) | M18: =IF(B18="","",INDEX('liste des soudeurs'!AR:AR,MATCH(B18,'liste des soudeurs'!$BI:$BI,0)))
A19: 9 | B19: =IF(A19<=MAX('liste des soudeurs'!BI:BI),A19,"") | C19: =IF(B19="","",INDEX('liste des soudeurs'!F:F,MATCH(B19,'liste des soudeurs'!$BI:$BI,0))) | D19: =IF(B19="","",INDEX('liste des soudeurs'!E:E,MATCH(B19,'liste des soudeurs'!$BI:$BI,0))) | E19: =IF(B19="","",INDEX('liste des soudeurs'!G:G,MATCH(B19,'liste des soudeurs'!$BI:$BI,0))) | F19: =IF(B19="","",INDEX('liste des soudeurs'!AE:AE,MATCH(B19,'liste des soudeurs'!$BI:$BI,0))) | G19: =IF(B19="","",INDEX('liste des soudeurs'!H:H,MATCH(B19,'liste des soudeurs'!$BI:$BI,0))) | H19: =IF(B19="","",INDEX('liste des soudeurs'!I:I,MATCH(B19,'liste des soudeurs'!$BI:$BI,0))) | I19: =IF(B19="","",INDEX('liste des soudeurs'!J:J,MATCH(B19,'liste des soudeurs'!$BI:$BI,0))) | J19: =IF(B19="","",INDEX('liste des soudeurs'!AH:AH,MATCH(B19,'liste des soudeurs'!$BI:$BI,0))) | K19: =IF(B19="","",INDEX('liste des soudeurs'!AX:AX,MATCH(B19,'liste des soudeurs'!$BI:$BI,0))) | L19: =IF(B19="","",INDEX('liste des soudeurs'!AQ:AQ,MATCH(B19,'liste des soudeurs'!$BI:$BI,0))) | M19: =IF(B19="","",INDEX('liste des soudeurs'!AR:AR,MATCH(B19,'liste des soudeurs'!$BI:$BI,0)))
A20: 10 | B20: =IF(A20<=MAX('liste des soudeurs'!BI:BI),A20,"") | C20: =IF(B20="","",INDEX('liste des soudeurs'!F:F,MATCH(B20,'liste des soudeurs'!$BI:$BI,0))) | D20: =IF(B20="","",INDEX('liste des soudeurs'!E:E,MATCH(B20,'liste des soudeurs'!$BI:$BI,0))) | E20: =IF(B20="","",INDEX('liste des soudeurs'!G:G,MATCH(B20,'liste des soudeurs'!$BI:$BI,0))) | F20: =IF(B20="","",INDEX('liste des soudeurs'!AE:AE,MATCH(B20,'liste des soudeurs'!$BI:$BI,0))) | G20: =IF(B20="","",INDEX('liste des soudeurs'!H:H,MATCH(B20,'liste des soudeurs'!$BI:$BI,0))) | H20: =IF(B20="","",INDEX('liste des soudeurs'!I:I,MATCH(B20,'liste des soudeurs'!$BI:$BI,0))) | I20: =IF(B20="","",INDEX('liste des soudeurs'!J:J,MATCH(B20,'liste des soudeurs'!$BI:$BI,0))) | J20: =IF(B20="","",INDEX('liste des soudeurs'!AH:AH,MATCH(B20,'liste des soudeurs'!$BI:$BI,0))) | K20: =IF(B20="","",INDEX('liste des soudeurs'!AX:AX,MATCH(B20,'liste des soudeurs'!$BI:$BI,0))) | L20: =IF(B20="","",INDEX('liste des soudeurs'!AQ:AQ,MATCH(B20,'liste des soudeurs'!$BI:$BI,0))) | M20: =IF(B20="","",INDEX('liste des soudeurs'!AR:AR,MATCH(B20,'liste des soudeurs'!$BI:$BI,0)))
C25: CONTROLEUR GTP
C26: NOM
C27: SIGNATURE

Sheet liste des soudeurs
A1: =F1&G1&I1 -> NOM & PRENOM F-NAME & NAME WPS N°DIAMETER SIZE Ø | B1: PROJET | C1: CODE VISUEL | D1: CODE INTERPRETATION | E1: Repère soudeur WELDER | F1: NOM & PRENOM F-NAME & NAME | G1: WPS N° | H1: NUANCE MATERIAL | I1: DIAMETER SIZE Ø | J1: EPAISSEUR THK (mm) | K1: RESULT VT | L1: DATE VT | M1: PV VT-WQT | N1: RESULT RT | O1: DATE RT | P1: PV RT-WQT | Q1: RFI-VT | R1: RFI-RT | S1: WPQ cetificate NO | T1: Date | U1: P-NO | V1: BACKING (YES/NO) | W1: Range Filler Metal F-N Root & Hot2 | X1: Range Filler Metal F-N Fill & Cap | Y1: Range AWS-SFA Root & Hot | Z1: Range AWS-SFA Fill & Cap | AA1: Min Dia (inch) | AB1: Max Dia (inch) | AC1: Min thk (inch) | AD1: Max thk (inch) | AE1: PROCESS | AF1: P-NO 2 | AG1: Rev. | AH1: POSITION | AI1: Type de Procédé | AJ1: PIPE/ PLATE | AK1: Progression de soudage | AL1: Type de gaz/Composition | AM1: Filler Metal F-N Root & Hot2 | AN1: Filler Metal F-N Fill & Cap | AO1: AWS-SFA Root & Hot | AP1: AWS-SFA Fill & Cap | AQ1: Filler Metal Root & Hot | AR1: Filler Metal Fill & Cap | AS1: POSTION | AT1: Courant (DC / AC) | AU1: Polarité Root & Hot | AV1: Polarité Fill & Cap | AW1: Range with / Without | AX1: piping or pipeline | AY1: édition | BD1: ='VT-PPL'!$Y$6 -> VT-WQT-031 | BF1: ='RT-PPL'!$Q$6 -> RT-WQT-031 | BH1: =HOMO!K4 -> 46316 | BK1: programme
A2: =F2&G2&I2 -> CHERNOUG SidaliTFT-II-PL-076 | B2: =IF($G2="","",VLOOKUP($G2,WPS!$D$1:$AN$995,35,0)) -> TFT II / TFT SUD GAZ FIELD DEVELOPMENT | C2: =IF($G2="","",VLOOKUP($G2,WPS!$D$1:$AN$995,33,0)) -> API 1104 | D2: =IF($G2="","",VLOOKUP($G2,WPS!$D$1:$AN$995,34,0)) -> API 1104 | E2: WR-020 | F2: CHERNOUG Sidali | G2: TFT-II-PL-07 | H2: API5L_X52 | I2: 6 | J2: 7.1 | K2: R | L2: 46136 | M2: VT-WQT-001 | Q2: 21063-G0-PPL-RFI-0052 | R2: 21063-G0-PPL-RFI-0052 | U2: =H2 -> API5L_X52 | V2: =IF($G2="","",VLOOKUP($G2,WPS!$D$1:$AL$995,17,0)) -> SMAW :With/Without Backing | W2: =IF($G2="","",VLOOKUP($G2,WPS!$D$1:$AL$995,25,0)) -> WF-1b | X2: =IF($G2="","",VLOOKUP($G2,WPS!$D$1:$AL$995,26,0)) -> WF-1b | Y2: =IF($G2="","",VLOOKUP($G2,WPS!$D$1:$AL$995,27,0)) -> A5.1or A5.5 | Z2: =IF($G2="","",VLOOKUP($G2,WPS!$D$1:$AL$995,28,0)) -> A5.1or A5.5 | AA2: =IF(AND(D2="API 1104",BB2<60.3),"Unlimited ",IF(AND(D2="API 1104",AND(BB2>=60.3,BB2<=323.85)),"≥ 2,3/8'' (60,3mm)",IF(AND(D2="API 1104",BB2>323.85),"> 12,750'' (323,9mm)",IF(AND(D2="ASME IX",BB2<60.3),CONCATENATE("≥ ",I2,"'' ","(",BB2,"mm)"),IF(AND(D2="ASME IX",BB2="60,3"),"≥ 1'' (25mm)",IF(AND(D2="ASME IX",AND(BB2>25,BB2<73)),"≥ 1'' (25mm)",IF(AND(D2="ASME IX",BB2>73),"> 2,7/8'' (73mm)",""))))))) -> ≥ 2,3/8'' (60,3mm) | AB2: =IF(AND(D2="API 1104",BB2<60.3),"< 2,3/8'' 60,3mm",IF(AND(D2="API 1104",AND(BB2>=60.3,BB2<=323.85)),"≤ 12,750'' 323,9mm",IF(AND(D2="API 1104",BB2>323.85),"Unlimited",IF(AND(D2="ASME IX",BB2<25),"Unlimited",IF(AND(D2="ASME IX",AND(BB2>25,BB2<73)),"Unlimited",IF(AND(D2="ASME IX",BB2>73),"Unlimited","")))))) -> ≤ 12,750'' 323,9mm | AC2: =IF(AND(D2="API 1104",J2<3.9)," SMAW <3,9 mm",IF(AND(D2="API 1104",AND(J2>=3.9,J2<19))," SMAW ≥ 3,9 mm",IF(AND(D2="API 1104",J2>=19),"SMAW >=19mm",IF(AND(D2="ASME IX",AE2="gtaw",J2<13),"GTAW ",IF(AND(D2="ASME IX",AE2="GTAW SMAW",J2<13),"GTAW ≤ 8 mm",IF(AND(D2="ASME IX",AE2="GmAW fcAW",J2<13),"GMAW ≤ 8 mm",IF(AND(D2="ASME IX",AE2="gtaw",J2>=13),CONCATENATE("≤ ",J2*2," mm"),IF(AND(D2="ASME IX",J2>=13,AE2="GTAW SMAW"),"GTAW ≤ 8mm",IF(AND(D2="ASME IX",J2>=13,AE2="GmAW fcAW"),"GMAW ≤ 8mm",""))))))))) -> SMAW ≥ 3,9 mm | AD2: =IF(AND(D2="API 1104",AE2="SMAW Mixte UP HILL/ Down hill",J2<3.9),CONCATENATE("≤ ",MAX(1.5*J2,3.9),"mm"),IF(AND(D2="API 1104",AE2="SMAW UP HILL MONTANT",J2<3.9),CONCATENATE("≤ ",MAX(1.5*J2,3.9),"mm"),IF(AND(D2="API 1104",AND(J2>=3.9,J2<19.05)),CONCATENATE("≤ ",MAX(1.5*J2,19.05),"mm"),IF(AND(D2="API 1104",J2>=19.05),"ALL",IF(AND(D2="ASME IX",AE2="SMAW UP HILL MONTANT",J2<17),CONCATENATE("≤ ",((J2)*2)," mm"),IF(AND(D2="ASME IX",J2>=17),CONCATENATE("Unlimited"),IF(AND(D2="ASME IX",AE2="SMAW Mixte UP HILL/ Down hill",J2<17),CONCATENATE("≤ ",((J2)*2)," mm"),IF(AND(D2="ASME IX",J2>=17),CONCATENATE(" SMAW Unlimited"),IF(AND(D2="ASME IX",AE2="GTAW",J2<=17),CONCATENATE( "≤ ",J2*2," mm"),IF(AND(D2="ASME IX",AE2="GTAW SMAW",J2<=17),CONCATENATE("SMAW ≤ ",((J2-4)*2)," mm"),IF(AND(D2="ASME IX",J2>=17,AE2="GTAW SMAW"),"SMAW Unlimited ",IF(AND(D2="ASME IX",AE2="GMAW FCAW",J2<=17),CONCATENATE("FCAW ≤ ",((J2-4)*2)," mm"),IF(AND(D2="ASME IX",J2>=17,AE2="GmAW fcAW"),"FCAW Unlimited ",""))))))))))))) -> ≤ 19,05mm | AE2: =IF(G2="","",VLOOKUP(G2,WPS!$D$1:$AH$4735,3,0)) -> SMAW Mixte UP HILL/ Down hill | AF2: =IF(AND($G2<>"",$D2="API 1104"),U2,IF(AND($G2<>"",$D2="ASME IX"),VLOOKUP($G2,WPS!$D$1:$AZ$995,42,0),"")) -> API5L_X52 | AG2: =IF(G2="","",VLOOKUP(G2,WPS!$D$1:$AH$4735,2,0)) -> A | AH2: =IF(AE2="SMAW Mixte UP HILL/ Down hill","5G",IF(AE2="SMAW UP HILL MONTANT","5G",IF(AE2="SMAW Downhill","5G",IF(AE2="GMAW FCAW","1G",IF(AE2="GTAW","6G",IF(AE2="GTAW SMAW","6G","")))))) -> 5G | AI2: =IF(AE2="SMAW Mixte UP HILL/ Down hill","Manuel",IF(AE2="SMAW UP HILL MONTANT","Manuel",IF(AE2="GMAW FCAW","semi auto",IF(AE2="GTAW","Manuel",IF(AE2="GTAW SMAW","Manuel",IF(AE2="SMAW Downhill","Manuel","")))))) -> Manuel | AJ2: PIPE | AK2: =IF(AE2="SMAW Mixte UP HILL/ Down hill","UP HILL/ Down hill Montant+Descendant",IF(AE2="SMAW UP HILL MONTANT","UP HILL Montant",IF(AE2="GMAW FCAW","Rotation",IF(AE2="GTAW","UP HILL Montant",IF(AE2="SMAW Downhill","SMAW Downhill",IF(AE2="GTAW SMAW","UP HILL Montant","")))))) -> UP HILL/ Down hill Montant+Descendant | AL2: =IF($G2="","",VLOOKUP($G2,WPS!$D$1:$AL$995,18,0)) -> N/A | AM2: =IF($G2="","",VLOOKUP($G2,WPS!$D$1:$AL$995,19,0)) -> Grp F N°1 | AN2: =IF($G2="","",VLOOKUP($G2,WPS!$D$1:$AL$995,20,0)) -> Grp F N°1 | AO2: =IF($G2="","",VLOOKUP($G2,WPS!$D$1:$AL$995,21,0)) -> A5.1 | AP2: =IF($G2="","",VLOOKUP($G2,WPS!$D$1:$AL$995,22,0)) -> A5.5 | AQ2: =IF($G2="","",VLOOKUP($G2,WPS!$D$1:$AL$995,23,0)) -> E 6010 | AR2: =IF($G2="","",VLOOKUP($G2,WPS!$D$1:$AL$995,24,0)) -> E 7010-P1 | AS2: =IF(AH2="1G","F",IF(AH2="5G","V-H-O",IF(AH2="6G","ALL",""))) -> V-H-O | AT2: =IF($G2="","",VLOOKUP($G2,WPS!$D$1:$AL$995,29,0)) -> DC | AU2: =IF($G2="","",VLOOKUP($G2,WPS!$D$1:$AL$995,30,0)) -> (+) | AV2: =IF($G2="","",VLOOKUP($G2,WPS!$D$1:$AL$995,31,0)) -> (+) | AW2: =IF(AE2="SMAW Mixte UP HILL/ Down hill","SMAW :,With/Without SMAW : With",IF(AE2="SMAW UP HILL MONTANT","SMAW :With/Without SMAW : With",IF(AE2="GMAW FCAW","GMAW :With/Without FCAW : With",IF(AE2="GTAW","GTAW :With / Without",IF(AE2="GTAW SMAW","GTAW :With/Without SMAW : With",""))))) -> SMAW :,With/Without SMAW : With | AX2: =IF($G2="","",VLOOKUP($G2,WPS!$D$1:$AL$995,15,0)) -> 50°C Min | AY2: =IF($G2="","",VLOOKUP($G2,WPS!$D$1:$AX$995,44,0)) -> ASME B31.3 édition 2021 | AZ2: =IFERROR(VLOOKUP(I2,Feuil1!$O$4:$P$34,2,0),"") -> 168.3 | BB2: =IFERROR(VLOOKUP(I2,Feuil1!$O$4:$P$32,2,0),"") -> 168.3 | BC2: =IF($G2="","",VLOOKUP($G2,WPS!$D$1:$AL$995,2,0)) -> A | BD2: =IF(M2='VT-PPL'!$Y$6,1,"") | BE2: =IF(BD2="","",COUNTIF(BD$2:$BD2,BD2)) | BF2: =IF(P2='RT-PPL'!$Q$6,1,"") | BG2: =IF(BF2="","",COUNTIF(BF$2:$BF2,BF2)) | BH2: =+IF(L2=HOMO!$K$4,1,"") | BI2: =IF(BH2="","",COUNTIF(BH$2:$BH2,BH2)) | BJ2: =IF(AND(K2="A",M2=Prog!$L$12),1,"") | BK2: =IF(BJ2="","",COUNTIF(BJ$2:$BJ2,BJ2)) | BL2: 1
A3: =F3&G3&I3 -> DJEHID FarisTFT-II-PL-076 | B3: =IF($G3="","",VLOOKUP($G3,WPS!$D$1:$AN$995,35,0)) -> TFT II / TFT SUD GAZ FIELD DEVELOPMENT | C3: =IF($G3="","",VLOOKUP($G3,WPS!$D$1:$AN$995,33,0)) -> API 1104 | D3: =IF($G3="","",VLOOKUP($G3,WPS!$D$1:$AN$995,34,0)) -> API 1104 | E3: WR-021 | F3: DJEHID Faris | G3: TFT-II-PL-07 | H3: API5L_X52 | I3: 6 | J3: 7.1 | K3: R | L3: 46136 | M3: VT-WQT-001 | Q3: 21063-G0-PPL-RFI-0052 | R3: 21063-G0-PPL-RFI-0052 | U3: =H3 -> API5L_X52 | V3: =IF($G3="","",VLOOKUP($G3,WPS!$D$1:$AL$995,17,0)) -> SMAW :With/Without Backing | W3: =IF($G3="","",VLOOKUP($G3,WPS!$D$1:$AL$995,25,0)) -> WF-1b | X3: =IF($G3="","",VLOOKUP($G3,WPS!$D$1:$AL$995,26,0)) -> WF-1b | Y3: =IF($G3="","",VLOOKUP($G3,WPS!$D$1:$AL$995,27,0)) -> A5.1or A5.5 | Z3: =IF($G3="","",VLOOKUP($G3,WPS!$D$1:$AL$995,28,0)) -> A5.1or A5.5 | AA3: =IF(AND(D3="API 1104",BB3<60.3),"Unlimited ",IF(AND(D3="API 1104",AND(BB3>=60.3,BB3<=323.85)),"≥ 2,3/8'' (60,3mm)",IF(AND(D3="API 1104",BB3>323.85),"> 12,750'' (323,9mm)",IF(AND(D3="ASME IX",BB3<60.3),CONCATENATE("≥ ",I3,"'' ","(",BB3,"mm)"),IF(AND(D3="ASME IX",BB3="60,3"),"≥ 1'' (25mm)",IF(AND(D3="ASME IX",AND(BB3>25,BB3<73)),"≥ 1'' (25mm)",IF(AND(D3="ASME IX",BB3>73),"> 2,7/8'' (73mm)",""))))))) -> ≥ 2,3/8'' (60,3mm) | AB3: =IF(AND(D3="API 1104",BB3<60.3),"< 2,3/8'' 60,3mm",IF(AND(D3="API 1104",AND(BB3>=60.3,BB3<=323.85)),"≤ 12,750'' 323,9mm",IF(AND(D3="API 1104",BB3>323.85),"Unlimited",IF(AND(D3="ASME IX",BB3<25),"Unlimited",IF(AND(D3="ASME IX",AND(BB3>25,BB3<73)),"Unlimited",IF(AND(D3="ASME IX",BB3>73),"Unlimited","")))))) -> ≤ 12,750'' 323,9mm | AC3: =IF(AND(D3="API 1104",J3<3.9)," SMAW <3,9 mm",IF(AND(D3="API 1104",AND(J3>=3.9,J3<19))," SMAW ≥ 3,9 mm",IF(AND(D3="API 1104",J3>=19),"SMAW >=19mm",IF(AND(D3="ASME IX",AE3="gtaw",J3<13),"GTAW ",IF(AND(D3="ASME IX",AE3="GTAW SMAW",J3<13),"GTAW ≤ 8 mm",IF(AND(D3="ASME IX",AE3="GmAW fcAW",J3<13),"GMAW ≤ 8 mm",IF(AND(D3="ASME IX",AE3="gtaw",J3>=13),CONCATENATE("≤ ",J3*2," mm"),IF(AND(D3="ASME IX",J3>=13,AE3="GTAW SMAW"),"GTAW ≤ 8mm",IF(AND(D3="ASME IX",J3>=13,AE3="GmAW fcAW"),"GMAW ≤ 8mm",""))))))))) -> SMAW ≥ 3,9 mm | AD3: =IF(AND(D3="API 1104",AE3="SMAW Mixte UP HILL/ Down hill",J3<3.9),CONCATENATE("≤ ",MAX(1.5*J3,3.9),"mm"),IF(AND(D3="API 1104",AE3="SMAW UP HILL MONTANT",J3<3.9),CONCATENATE("≤ ",MAX(1.5*J3,3.9),"mm"),IF(AND(D3="API 1104",AND(J3>=3.9,J3<19.05)),CONCATENATE("≤ ",MAX(1.5*J3,19.05),"mm"),IF(AND(D3="API 1104",J3>=19.05),"ALL",IF(AND(D3="ASME IX",AE3="SMAW UP HILL MONTANT",J3<17),CONCATENATE("≤ ",((J3)*2)," mm"),IF(AND(D3="ASME IX",J3>=17),CONCATENATE("Unlimited"),IF(AND(D3="ASME IX",AE3="SMAW Mixte UP HILL/ Down hill",J3<17),CONCATENATE("≤ ",((J3)*2)," mm"),IF(AND(D3="ASME IX",J3>=17),CONCATENATE(" SMAW Unlimited"),IF(AND(D3="ASME IX",AE3="GTAW",J3<=17),CONCATENATE( "≤ ",J3*2," mm"),IF(AND(D3="ASME IX",AE3="GTAW SMAW",J3<=17),CONCATENATE("SMAW ≤ ",((J3-4)*2)," mm"),IF(AND(D3="ASME IX",J3>=17,AE3="GTAW SMAW"),"SMAW Unlimited ",IF(AND(D3="ASME IX",AE3="GMAW FCAW",J3<=17),CONCATENATE("FCAW ≤ ",((J3-4)*2)," mm"),IF(AND(D3="ASME IX",J3>=17,AE3="GmAW fcAW"),"FCAW Unlimited ",""))))))))))))) -> ≤ 19,05mm | AE3: =IF(G3="","",VLOOKUP(G3,WPS!$D$1:$AH$4735,3,0)) -> SMAW Mixte UP HILL/ Down hill | AF3: =IF(AND($G3<>"",$D3="API 1104"),U3,IF(AND($G3<>"",$D3="ASME IX"),VLOOKUP($G3,WPS!$D$1:$AZ$995,42,0),"")) -> API5L_X52 | AG3: =IF(G3="","",VLOOKUP(G3,WPS!$D$1:$AH$4735,2,0)) -> A | AH3: =IF(AE3="SMAW Mixte UP HILL/ Down hill","5G",IF(AE3="SMAW UP HILL MONTANT","5G",IF(AE3="SMAW Downhill","5G",IF(AE3="GMAW FCAW","1G",IF(AE3="GTAW","6G",IF(AE3="GTAW SMAW","6G","")))))) -> 5G | AI3: =IF(AE3="SMAW Mixte UP HILL/ Down hill","Manuel",IF(AE3="SMAW UP HILL MONTANT","Manuel",IF(AE3="GMAW FCAW","semi auto",IF(AE3="GTAW","Manuel",IF(AE3="GTAW SMAW","Manuel",IF(AE3="SMAW Downhill","Manuel","")))))) -> Manuel | AJ3: PIPE | AK3: =IF(AE3="SMAW Mixte UP HILL/ Down hill","UP HILL/ Down hill Montant+Descendant",IF(AE3="SMAW UP HILL MONTANT","UP HILL Montant",IF(AE3="GMAW FCAW","Rotation",IF(AE3="GTAW","UP HILL Montant",IF(AE3="SMAW Downhill","SMAW Downhill",IF(AE3="GTAW SMAW","UP HILL Montant","")))))) -> UP HILL/ Down hill Montant+Descendant | AL3: =IF($G3="","",VLOOKUP($G3,WPS!$D$1:$AL$995,18,0)) -> N/A | AM3: =IF($G3="","",VLOOKUP($G3,WPS!$D$1:$AL$995,19,0)) -> Grp F N°1 | AN3: =IF($G3="","",VLOOKUP($G3,WPS!$D$1:$AL$995,20,0)) -> Grp F N°1 | AO3: =IF($G3="","",VLOOKUP($G3,WPS!$D$1:$AL$995,21,0)) -> A5.1 | AP3: =IF($G3="","",VLOOKUP($G3,WPS!$D$1:$AL$995,22,0)) -> A5.5 | AQ3: =IF($G3="","",VLOOKUP($G3,WPS!$D$1:$AL$995,23,0)) -> E 6010 | AR3: =IF($G3="","",VLOOKUP($G3,WPS!$D$1:$AL$995,24,0)) -> E 7010-P1 | AS3: =IF(AH3="1G","F",IF(AH3="5G","V-H-O",IF(AH3="6G","ALL",""))) -> V-H-O | AT3: =IF($G3="","",VLOOKUP($G3,WPS!$D$1:$AL$995,29,0)) -> DC | AU3: =IF($G3="","",VLOOKUP($G3,WPS!$D$1:$AL$995,30,0)) -> (+) | AV3: =IF($G3="","",VLOOKUP($G3,WPS!$D$1:$AL$995,31,0)) -> (+) | AW3: =IF(AE3="SMAW Mixte UP HILL/ Down hill","SMAW :,With/Without SMAW : With",IF(AE3="SMAW UP HILL MONTANT","SMAW :With/Without SMAW : With",IF(AE3="GMAW FCAW","GMAW :With/Without FCAW : With",IF(AE3="GTAW","GTAW :With / Without",IF(AE3="GTAW SMAW","GTAW :With/Without SMAW : With",""))))) -> SMAW :,With/Without SMAW : With | AX3: =IF($G3="","",VLOOKUP($G3,WPS!$D$1:$AL$995,15,0)) -> 50°C Min | AY3: =IF($G3="","",VLOOKUP($G3,WPS!$D$1:$AX$995,44,0)) -> ASME B31.3 édition 2021 | AZ3: =IFERROR(VLOOKUP(I3,Feuil1!$O$4:$P$34,2,0),"") -> 168.3 | BB3: =IFERROR(VLOOKUP(I3,Feuil1!$O$4:$P$32,2,0),"") -> 168.3 | BC3: =IF($G3="","",VLOOKUP($G3,WPS!$D$1:$AL$995,2,0)) -> A | BD3: =IF(M3='VT-PPL'!$Y$6,1,"") | BE3: =IF(BD3="","",COUNTIF(BD$2:$BD3,BD3)) | BF3: =IF(P3='RT-PPL'!$Q$6,1,"") | BG3: =IF(BF3="","",COUNTIF(BF$2:$BF3,BF3)) | BH3: =+IF(L3=HOMO!$K$4,1,"") | BI3: =IF(BH3="","",COUNTIF(BH$2:$BH3,BH3)) | BJ3: =IF(AND(K3="A",M3=Prog!$L$12),1,"") | BK3: =IF(BJ3="","",COUNTIF(BJ$2:$BJ3,BJ3)) | BL3: 2
A4: =F4&G4&I4 -> REMINI HalimTFT-II-PL-076 | B4: =IF($G4="","",VLOOKUP($G4,WPS!$D$1:$AN$995,35,0)) -> TFT II / TFT SUD GAZ FIELD DEVELOPMENT | C4: =IF($G4="","",VLOOKUP($G4,WPS!$D$1:$AN$995,33,0)) -> API 1104 | D4: =IF($G4="","",VLOOKUP($G4,WPS!$D$1:$AN$995,34,0)) -> API 1104 | E4: WR-022 | F4: REMINI Halim | G4: TFT-II-PL-07 | H4: API5L_X52 | I4: 6 | J4: 7.1 | K4: A | L4: 46136 | M4: VT-WQT-001 | N4: A | O4: 45772 | P4: RT-WQT-001 | Q4: 21063-G0-PPL-RFI-0052 | R4: 21063-G0-PPL-RFI-0052 | S4: WQT-001 | T4: 46137 | U4: =H4 -> API5L_X52 | V4: =IF($G4="","",VLOOKUP($G4,WPS!$D$1:$AL$995,17,0)) -> SMAW :With/Without Backing | W4: =IF($G4="","",VLOOKUP($G4,WPS!$D$1:$AL$995,25,0)) -> WF-1b | X4: =IF($G4="","",VLOOKUP($G4,WPS!$D$1:$AL$995,26,0)) -> WF-1b | Y4: =IF($G4="","",VLOOKUP($G4,WPS!$D$1:$AL$995,27,0)) -> A5.1or A5.5 | Z4: =IF($G4="","",VLOOKUP($G4,WPS!$D$1:$AL$995,28,0)) -> A5.1or A5.5 | AA4: =IF(AND(D4="API 1104",BB4<60.3),"Unlimited ",IF(AND(D4="API 1104",AND(BB4>=60.3,BB4<=323.85)),"≥ 2,3/8'' (60,3mm)",IF(AND(D4="API 1104",BB4>323.85),"> 12,750'' (323,9mm)",IF(AND(D4="ASME IX",BB4<60.3),CONCATENATE("≥ ",#REF!,"'' ","(",BB4,"mm)"),IF(AND(D4="ASME IX",BB4="60,3"),"≥ 1'' (25mm)",IF(AND(D4="ASME IX",AND(BB4>25,BB4<73)),"≥ 1'' (25mm)",IF(AND(D4="ASME IX",BB4>73),"> 2,7/8'' (73mm)",""))))))) -> ≥ 2,3/8'' (60,3mm) | AB4: =IF(AND(D4="API 1104",BB4<60.3),"< 2,3/8'' 60,3mm",IF(AND(D4="API 1104",AND(BB4>=60.3,BB4<=323.85)),"≤ 12,750'' 323,9mm",IF(AND(D4="API 1104",BB4>323.85),"Unlimited",IF(AND(D4="ASME IX",BB4<25),"Unlimited",IF(AND(D4="ASME IX",AND(BB4>25,BB4<73)),"Unlimited",IF(AND(D4="ASME IX",BB4>73),"Unlimited","")))))) -> ≤ 12,750'' 323,9mm | AC4: =IF(AND(D4="API 1104",J4<3.9)," SMAW <3,9 mm",IF(AND(D4="API 1104",AND(J4>=3.9,J4<19))," SMAW ≥ 3,9 mm",IF(AND(D4="API 1104",J4>=19),"SMAW >=19mm",IF(AND(D4="ASME IX",AE4="gtaw",J4<13),"GTAW ",IF(AND(D4="ASME IX",AE4="GTAW SMAW",J4<13),"GTAW ≤ 8 mm",IF(AND(D4="ASME IX",AE4="GmAW fcAW",J4<13),"GMAW ≤ 8 mm",IF(AND(D4="ASME IX",AE4="gtaw",J4>=13),CONCATENATE("≤ ",J4*2," mm"),IF(AND(D4="ASME IX",J4>=13,AE4="GTAW SMAW"),"GTAW ≤ 8mm",IF(AND(D4="ASME IX",J4>=13,AE4="GmAW fcAW"),"GMAW ≤ 8mm",""))))))))) -> SMAW ≥ 3,9 mm | AD4: =IF(AND(D4="API 1104",AE4="SMAW Mixte UP HILL/ Down hill",J4<3.9),CONCATENATE("≤ ",MAX(1.5*J4,3.9),"mm"),IF(AND(D4="API 1104",AE4="SMAW UP HILL MONTANT",J4<3.9),CONCATENATE("≤ ",MAX(1.5*J4,3.9),"mm"),IF(AND(D4="API 1104",AND(J4>=3.9,J4<19.05)),CONCATENATE("≤ ",MAX(1.5*J4,19.05),"mm"),IF(AND(D4="API 1104",J4>=19.05),"ALL",IF(AND(D4="ASME IX",AE4="SMAW UP HILL MONTANT",J4<17),CONCATENATE("≤ ",((J4)*2)," mm"),IF(AND(D4="ASME IX",J4>=17),CONCATENATE("Unlimited"),IF(AND(D4="ASME IX",AE4="SMAW Mixte UP HILL/ Down hill",J4<17),CONCATENATE("≤ ",((J4)*2)," mm"),IF(AND(D4="ASME IX",J4>=17),CONCATENATE(" SMAW Unlimited"),IF(AND(D4="ASME IX",AE4="GTAW",J4<=17),CONCATENATE( "≤ ",J4*2," mm"),IF(AND(D4="ASME IX",AE4="GTAW SMAW",J4<=17),CONCATENATE("SMAW ≤ ",((J4-4)*2)," mm"),IF(AND(D4="ASME IX",J4>=17,AE4="GTAW SMAW"),"SMAW Unlimited ",IF(AND(D4="ASME IX",AE4="GMAW FCAW",J4<=17),CONCATENATE("FCAW ≤ ",((J4-4)*2)," mm"),IF(AND(D4="ASME IX",J4>=17,AE4="GmAW fcAW"),"FCAW Unlimited ",""))))))))))))) -> ≤ 19,05mm | AE4: =IF(G4="","",VLOOKUP(G4,WPS!$D$1:$AH$4735,3,0)) -> SMAW Mixte UP HILL/ Down hill | AF4: =IF(AND($G4<>"",$D4="API 1104"),U4,IF(AND($G4<>"",$D4="ASME IX"),VLOOKUP($G4,WPS!$D$1:$AZ$995,42,0),"")) -> API5L_X52 | AG4: =IF(G4="","",VLOOKUP(G4,WPS!$D$1:$AH$4735,2,0)) -> A | AH4: =IF(AE4="SMAW Mixte UP HILL/ Down hill","5G",IF(AE4="SMAW UP HILL MONTANT","5G",IF(AE4="SMAW Downhill","5G",IF(AE4="GMAW FCAW","1G",IF(AE4="GTAW","6G",IF(AE4="GTAW SMAW","6G","")))))) -> 5G | AI4: =IF(AE4="SMAW Mixte UP HILL/ Down hill","Manuel",IF(AE4="SMAW UP HILL MONTANT","Manuel",IF(AE4="GMAW FCAW","semi auto",IF(AE4="GTAW","Manuel",IF(AE4="GTAW SMAW","Manuel",IF(AE4="SMAW Downhill","Manuel","")))))) -> Manuel | AJ4: PIPE | AK4: =IF(AE4="SMAW Mixte UP HILL/ Down hill","UP HILL/ Down hill Montant+Descendant",IF(AE4="SMAW UP HILL MONTANT","UP HILL Montant",IF(AE4="GMAW FCAW","Rotation",IF(AE4="GTAW","UP HILL Montant",IF(AE4="SMAW Downhill","SMAW Downhill",IF(AE4="GTAW SMAW","UP HILL Montant","")))))) -> UP HILL/ Down hill Montant+Descendant | AL4: =IF($G4="","",VLOOKUP($G4,WPS!$D$1:$AL$995,18,0)) -> N/A | AM4: =IF($G4="","",VLOOKUP($G4,WPS!$D$1:$AL$995,19,0)) -> Grp F N°1 | AN4: =IF($G4="","",VLOOKUP($G4,WPS!$D$1:$AL$995,20,0)) -> Grp F N°1 | AO4: =IF($G4="","",VLOOKUP($G4,WPS!$D$1:$AL$995,21,0)) -> A5.1 | AP4: =IF($G4="","",VLOOKUP($G4,WPS!$D$1:$AL$995,22,0)) -> A5.5 | AQ4: =IF($G4="","",VLOOKUP($G4,WPS!$D$1:$AL$995,23,0)) -> E 6010 | AR4: =IF($G4="","",VLOOKUP($G4,WPS!$D$1:$AL$995,24,0)) -> E 7010-P1 | AS4: =IF(AH4="1G","F",IF(AH4="5G","V-H-O",IF(AH4="6G","ALL",""))) -> V-H-O | AT4: =IF($G4="","",VLOOKUP($G4,WPS!$D$1:$AL$995,29,0)) -> DC | AU4: =IF($G4="","",VLOOKUP($G4,WPS!$D$1:$AL$995,30,0)) -> (+) | AV4: =IF($G4="","",VLOOKUP($G4,WPS!$D$1:$AL$995,31,0)) -> (+) | AW4: =IF(AE4="SMAW Mixte UP HILL/ Down hill","SMAW :,With/Without SMAW : With",IF(AE4="SMAW UP HILL MONTANT","SMAW :With/Without SMAW : With",IF(AE4="GMAW FCAW","GMAW :With/Without FCAW : With",IF(AE4="GTAW","GTAW :With / Without",IF(AE4="GTAW SMAW","GTAW :With/Without SMAW : With",""))))) -> SMAW :,With/Without SMAW : With | AX4: =IF($G4="","",VLOOKUP($G4,WPS!$D$1:$AL$995,15,0)) -> 50°C Min | AY4: =IF($G4="","",VLOOKUP($G4,WPS!$D$1:$AX$995,44,0)) -> ASME B31.3 édition 2021 | AZ4: =IFERROR(VLOOKUP(I4,Feuil1!$O$4:$P$34,2,0),"") -> 168.3 | BB4: =IFERROR(VLOOKUP(I4,Feuil1!$O$4:$P$32,2,0),"") -> 168.3 | BC4: =IF($G4="","",VLOOKUP($G4,WPS!$D$1:$AL$995,2,0)) -> A | BD4: =IF(M4='VT-PPL'!$Y$6,1,"") | BE4: =IF(BD4="","",COUNTIF(BD$2:$BD4,BD4)) | BF4: =IF(P4='RT-PPL'!$Q$6,1,"") | BG4: =IF(BF4="","",COUNTIF(BF$2:$BF4,BF4)) | BH4: =+IF(L4=HOMO!$K$4,1,"") | BI4: =IF(BH4="","",COUNTIF(BH$2:$BH4,BH4)) | BJ4: =IF(AND(K4="A",M4=Prog!$L$12),1,"") | BK4: =IF(BJ4="","",COUNTIF(BJ$2:$BJ4,BJ4)) | BL4: 3
A5: =F5&G5&I5 -> KEMOUCHE ChoaybTFT-II-PL-076 | B5: =IF($G5="","",VLOOKUP($G5,WPS!$D$1:$AN$995,35,0)) -> TFT II / TFT SUD GAZ FIELD DEVELOPMENT | C5: =IF($G5="","",VLOOKUP($G5,WPS!$D$1:$AN$995,33,0)) -> API 1104 | D5: =IF($G5="","",VLOOKUP($G5,WPS!$D$1:$AN$995,34,0)) -> API 1104 | E5: WR-023 | F5: KEMOUCHE Choayb | G5: TFT-II-PL-07 | H5: API5L_X52 | I5: 6 | J5: 7.1 | K5: A | L5: 46139 | M5: VT-WQT-002 | N5: A | O5: 46139 | P5: RT-WQT-002 | Q5: 21063-G0-PPL-RFI-0055 | R5: 21063-G0-PPL-RFI-0055 | S5: WQT-002 | T5: 46139 | U5: =H5 -> API5L_X52 | V5: =IF($G5="","",VLOOKUP($G5,WPS!$D$1:$AL$995,17,0)) -> SMAW :With/Without Backing | W5: =IF($G5="","",VLOOKUP($G5,WPS!$D$1:$AL$995,25,0)) -> WF-1b | X5: =IF($G5="","",VLOOKUP($G5,WPS!$D$1:$AL$995,26,0)) -> WF-1b | Y5: =IF($G5="","",VLOOKUP($G5,WPS!$D$1:$AL$995,27,0)) -> A5.1or A5.5 | Z5: =IF($G5="","",VLOOKUP($G5,WPS!$D$1:$AL$995,28,0)) -> A5.1or A5.5 | AA5: =IF(AND(D5="API 1104",BB5<60.3),"Unlimited ",IF(AND(D5="API 1104",AND(BB5>=60.3,BB5<=323.85)),"≥ 2,3/8'' (60,3mm)",IF(AND(D5="API 1104",BB5>323.85),"> 12,750'' (323,9mm)",IF(AND(D5="ASME IX",BB5<60.3),CONCATENATE("≥ ",I4,"'' ","(",BB5,"mm)"),IF(AND(D5="ASME IX",BB5="60,3"),"≥ 1'' (25mm)",IF(AND(D5="ASME IX",AND(BB5>25,BB5<73)),"≥ 1'' (25mm)",IF(AND(D5="ASME IX",BB5>73),"> 2,7/8'' (73mm)",""))))))) -> ≥ 2,3/8'' (60,3mm) | AB5: =IF(AND(D5="API 1104",BB5<60.3),"< 2,3/8'' 60,3mm",IF(AND(D5="API 1104",AND(BB5>=60.3,BB5<=323.85)),"≤ 12,750'' 323,9mm",IF(AND(D5="API 1104",BB5>323.85),"Unlimited",IF(AND(D5="ASME IX",BB5<25),"Unlimited",IF(AND(D5="ASME IX",AND(BB5>25,BB5<73)),"Unlimited",IF(AND(D5="ASME IX",BB5>73),"Unlimited","")))))) -> ≤ 12,750'' 323,9mm | AC5: =IF(AND(D5="API 1104",J5<3.9)," SMAW <3,9 mm",IF(AND(D5="API 1104",AND(J5>=3.9,J5<19))," SMAW ≥ 3,9 mm",IF(AND(D5="API 1104",J5>=19),"SMAW >=19mm",IF(AND(D5="ASME IX",AE5="gtaw",J5<13),"GTAW ",IF(AND(D5="ASME IX",AE5="GTAW SMAW",J5<13),"GTAW ≤ 8 mm",IF(AND(D5="ASME IX",AE5="GmAW fcAW",J5<13),"GMAW ≤ 8 mm",IF(AND(D5="ASME IX",AE5="gtaw",J5>=13),CONCATENATE("≤ ",J5*2," mm"),IF(AND(D5="ASME IX",J5>=13,AE5="GTAW SMAW"),"GTAW ≤ 8mm",IF(AND(D5="ASME IX",J5>=13,AE5="GmAW fcAW"),"GMAW ≤ 8mm",""))))))))) -> SMAW ≥ 3,9 mm | AD5: =IF(AND(D5="API 1104",AE5="SMAW Mixte UP HILL/ Down hill",J5<3.9),CONCATENATE("≤ ",MAX(1.5*J5,3.9),"mm"),IF(AND(D5="API 1104",AE5="SMAW UP HILL MONTANT",J5<3.9),CONCATENATE("≤ ",MAX(1.5*J5,3.9),"mm"),IF(AND(D5="API 1104",AND(J5>=3.9,J5<19.05)),CONCATENATE("≤ ",MAX(1.5*J5,19.05),"mm"),IF(AND(D5="API 1104",J5>=19.05),"ALL",IF(AND(D5="ASME IX",AE5="SMAW UP HILL MONTANT",J5<17),CONCATENATE("≤ ",((J5)*2)," mm"),IF(AND(D5="ASME IX",J5>=17),CONCATENATE("Unlimited"),IF(AND(D5="ASME IX",AE5="SMAW Mixte UP HILL/ Down hill",J5<17),CONCATENATE("≤ ",((J5)*2)," mm"),IF(AND(D5="ASME IX",J5>=17),CONCATENATE(" SMAW Unlimited"),IF(AND(D5="ASME IX",AE5="GTAW",J5<=17),CONCATENATE( "≤ ",J5*2," mm"),IF(AND(D5="ASME IX",AE5="GTAW SMAW",J5<=17),CONCATENATE("SMAW ≤ ",((J5-4)*2)," mm"),IF(AND(D5="ASME IX",J5>=17,AE5="GTAW SMAW"),"SMAW Unlimited ",IF(AND(D5="ASME IX",AE5="GMAW FCAW",J5<=17),CONCATENATE("FCAW ≤ ",((J5-4)*2)," mm"),IF(AND(D5="ASME IX",J5>=17,AE5="GmAW fcAW"),"FCAW Unlimited ",""))))))))))))) -> ≤ 19,05mm | AE5: =IF(G5="","",VLOOKUP(G5,WPS!$D$1:$AH$4735,3,0)) -> SMAW Mixte UP HILL/ Down hill | AF5: =IF(AND($G5<>"",$D5="API 1104"),U5,IF(AND($G5<>"",$D5="ASME IX"),VLOOKUP($G5,WPS!$D$1:$AZ$995,42,0),"")) -> API5L_X52 | AG5: =IF(G5="","",VLOOKUP(G5,WPS!$D$1:$AH$4735,2,0)) -> A | AH5: =IF(AE5="SMAW Mixte UP HILL/ Down hill","5G",IF(AE5="SMAW UP HILL MONTANT","5G",IF(AE5="SMAW Downhill","5G",IF(AE5="GMAW FCAW","1G",IF(AE5="GTAW","6G",IF(AE5="GTAW SMAW","6G","")))))) -> 5G | AI5: =IF(AE5="SMAW Mixte UP HILL/ Down hill","Manuel",IF(AE5="SMAW UP HILL MONTANT","Manuel",IF(AE5="GMAW FCAW","semi auto",IF(AE5="GTAW","Manuel",IF(AE5="GTAW SMAW","Manuel",IF(AE5="SMAW Downhill","Manuel","")))))) -> Manuel | AJ5: PIPE | AK5: =IF(AE5="SMAW Mixte UP HILL/ Down hill","UP HILL/ Down hill Montant+Descendant",IF(AE5="SMAW UP HILL MONTANT","UP HILL Montant",IF(AE5="GMAW FCAW","Rotation",IF(AE5="GTAW","UP HILL Montant",IF(AE5="SMAW Downhill","SMAW Downhill",IF(AE5="GTAW SMAW","UP HILL Montant","")))))) -> UP HILL/ Down hill Montant+Descendant | AL5: =IF($G5="","",VLOOKUP($G5,WPS!$D$1:$AL$995,18,0)) -> N/A | AM5: =IF($G5="","",VLOOKUP($G5,WPS!$D$1:$AL$995,19,0)) -> Grp F N°1 | AN5: =IF($G5="","",VLOOKUP($G5,WPS!$D$1:$AL$995,20,0)) -> Grp F N°1 | AO5: =IF($G5="","",VLOOKUP($G5,WPS!$D$1:$AL$995,21,0)) -> A5.1 | AP5: =IF($G5="","",VLOOKUP($G5,WPS!$D$1:$AL$995,22,0)) -> A5.5 | AQ5: =IF($G5="","",VLOOKUP($G5,WPS!$D$1:$AL$995,23,0)) -> E 6010 | AR5: =IF($G5="","",VLOOKUP($G5,WPS!$D$1:$AL$995,24,0)) -> E 7010-P1 | AS5: =IF(AH5="1G","F",IF(AH5="5G","V-H-O",IF(AH5="6G","ALL",""))) -> V-H-O | AT5: =IF($G5="","",VLOOKUP($G5,WPS!$D$1:$AL$995,29,0)) -> DC | AU5: =IF($G5="","",VLOOKUP($G5,WPS!$D$1:$AL$995,30,0)) -> (+) | AV5: =IF($G5="","",VLOOKUP($G5,WPS!$D$1:$AL$995,31,0)) -> (+) | AW5: =IF(AE5="SMAW Mixte UP HILL/ Down hill","SMAW :,With/Without SMAW : With",IF(AE5="SMAW UP HILL MONTANT","SMAW :With/Without SMAW : With",IF(AE5="GMAW FCAW","GMAW :With/Without FCAW : With",IF(AE5="GTAW","GTAW :With / Without",IF(AE5="GTAW SMAW","GTAW :With/Without SMAW : With",""))))) -> SMAW :,With/Without SMAW : With | AX5: =IF($G5="","",VLOOKUP($G5,WPS!$D$1:$AL$995,15,0)) -> 50°C Min | AY5: =IF($G5="","",VLOOKUP($G5,WPS!$D$1:$AX$995,44,0)) -> ASME B31.3 édition 2021 | AZ5: =IFERROR(VLOOKUP(I5,Feuil1!$O$4:$P$34,2,0),"") -> 168.3 | BB5: =IFERROR(VLOOKUP(I5,Feuil1!$O$4:$P$32,2,0),"") -> 168.3 | BC5: =IF($G5="","",VLOOKUP($G5,WPS!$D$1:$AL$995,2,0)) -> A | BD5: =IF(M5='VT-PPL'!$Y$6,1,"") | BE5: =IF(BD5="","",COUNTIF(BD$2:$BD5,BD5)) | BF5: =IF(P5='RT-PPL'!$Q$6,1,"") | BG5: =IF(BF5="","",COUNTIF(BF$2:$BF5,BF5)) | BH5: =+IF(L5=HOMO!$K$4,1,"") | BI5: =IF(BH5="","",COUNTIF(BH$2:$BH5,BH5)) | BJ5: =IF(AND(K5="A",M5=Prog!$L$12),1,"") | BK5: =IF(BJ5="","",COUNTIF(BJ$2:$BJ5,BJ5)) | BL5: 4
A6: =F6&G6&I6 -> HAMDI MagedTFT-II-PL-076 | B6: =IF($G6="","",VLOOKUP($G6,WPS!$D$1:$AN$995,35,0)) -> TFT II / TFT SUD GAZ FIELD DEVELOPMENT | C6: =IF($G6="","",VLOOKUP($G6,WPS!$D$1:$AN$995,33,0)) -> API 1104 | D6: =IF($G6="","",VLOOKUP($G6,WPS!$D$1:$AN$995,34,0)) -> API 1104 | E6: WR-024 | F6: HAMDI Maged | G6: TFT-II-PL-07 | H6: API5L_X52 | I6: 6 | J6: 7.1 | K6: A | L6: 46139 | M6: VT-WQT-002 | N6: A | O6: 46139 | P6: RT-WQT-002 | Q6: 21063-G0-PPL-RFI-0055 | R6: 21063-G0-PPL-RFI-0055 | S6: WQT-003 | T6: 46139 | U6: =H6 -> API5L_X52 | V6: =IF($G6="","",VLOOKUP($G6,WPS!$D$1:$AL$995,17,0)) -> SMAW :With/Without Backing | W6: =IF($G6="","",VLOOKUP($G6,WPS!$D$1:$AL$995,25,0)) -> WF-1b | X6: =IF($G6="","",VLOOKUP($G6,WPS!$D$1:$AL$995,26,0)) -> WF-1b | Y6: =IF($G6="","",VLOOKUP($G6,WPS!$D$1:$AL$995,27,0)) -> A5.1or A5.5 | Z6: =IF($G6="","",VLOOKUP($G6,WPS!$D$1:$AL$995,28,0)) -> A5.1or A5.5 | AA6: =IF(AND(D6="API 1104",BB6<60.3),"Unlimited ",IF(AND(D6="API 1104",AND(BB6>=60.3,BB6<=323.85)),"≥ 2,3/8'' (60,3mm)",IF(AND(D6="API 1104",BB6>323.85),"> 12,750'' (323,9mm)",IF(AND(D6="ASME IX",BB6<60.3),CONCATENATE("≥ ",I5,"'' ","(",BB6,"mm)"),IF(AND(D6="ASME IX",BB6="60,3"),"≥ 1'' (25mm)",IF(AND(D6="ASME IX",AND(BB6>25,BB6<73)),"≥ 1'' (25mm)",IF(AND(D6="ASME IX",BB6>73),"> 2,7/8'' (73mm)",""))))))) -> ≥ 2,3/8'' (60,3mm) | AB6: =IF(AND(D6="API 1104",BB6<60.3),"< 2,3/8'' 60,3mm",IF(AND(D6="API 1104",AND(BB6>=60.3,BB6<=323.85)),"≤ 12,750'' 323,9mm",IF(AND(D6="API 1104",BB6>323.85),"Unlimited",IF(AND(D6="ASME IX",BB6<25),"Unlimited",IF(AND(D6="ASME IX",AND(BB6>25,BB6<73)),"Unlimited",IF(AND(D6="ASME IX",BB6>73),"Unlimited","")))))) -> ≤ 12,750'' 323,9mm | AC6: =IF(AND(D6="API 1104",J6<3.9)," SMAW <3,9 mm",IF(AND(D6="API 1104",AND(J6>=3.9,J6<19))," SMAW ≥ 3,9 mm",IF(AND(D6="API 1104",J6>=19),"SMAW >=19mm",IF(AND(D6="ASME IX",AE6="gtaw",J6<13),"GTAW ",IF(AND(D6="ASME IX",AE6="GTAW SMAW",J6<13),"GTAW ≤ 8 mm",IF(AND(D6="ASME IX",AE6="GmAW fcAW",J6<13),"GMAW ≤ 8 mm",IF(AND(D6="ASME IX",AE6="gtaw",J6>=13),CONCATENATE("≤ ",J6*2," mm"),IF(AND(D6="ASME IX",J6>=13,AE6="GTAW SMAW"),"GTAW ≤ 8mm",IF(AND(D6="ASME IX",J6>=13,AE6="GmAW fcAW"),"GMAW ≤ 8mm",""))))))))) -> SMAW ≥ 3,9 mm | AD6: =IF(AND(D6="API 1104",AE6="SMAW Mixte UP HILL/ Down hill",J6<3.9),CONCATENATE("≤ ",MAX(1.5*J6,3.9),"mm"),IF(AND(D6="API 1104",AE6="SMAW UP HILL MONTANT",J6<3.9),CONCATENATE("≤ ",MAX(1.5*J6,3.9),"mm"),IF(AND(D6="API 1104",AND(J6>=3.9,J6<19.05)),CONCATENATE("≤ ",MAX(1.5*J6,19.05),"mm"),IF(AND(D6="API 1104",J6>=19.05),"ALL",IF(AND(D6="ASME IX",AE6="SMAW UP HILL MONTANT",J6<17),CONCATENATE("≤ ",((J6)*2)," mm"),IF(AND(D6="ASME IX",J6>=17),CONCATENATE("Unlimited"),IF(AND(D6="ASME IX",AE6="SMAW Mixte UP HILL/ Down hill",J6<17),CONCATENATE("≤ ",((J6)*2)," mm"),IF(AND(D6="ASME IX",J6>=17),CONCATENATE(" SMAW Unlimited"),IF(AND(D6="ASME IX",AE6="GTAW",J6<=17),CONCATENATE( "≤ ",J6*2," mm"),IF(AND(D6="ASME IX",AE6="GTAW SMAW",J6<=17),CONCATENATE("SMAW ≤ ",((J6-4)*2)," mm"),IF(AND(D6="ASME IX",J6>=17,AE6="GTAW SMAW"),"SMAW Unlimited ",IF(AND(D6="ASME IX",AE6="GMAW FCAW",J6<=17),CONCATENATE("FCAW ≤ ",((J6-4)*2)," mm"),IF(AND(D6="ASME IX",J6>=17,AE6="GmAW fcAW"),"FCAW Unlimited ",""))))))))))))) -> ≤ 19,05mm | AE6: =IF(G6="","",VLOOKUP(G6,WPS!$D$1:$AH$4735,3,0)) -> SMAW Mixte UP HILL/ Down hill | AF6: =IF(AND($G6<>"",$D6="API 1104"),U6,IF(AND($G6<>"",$D6="ASME IX"),VLOOKUP($G6,WPS!$D$1:$AZ$995,42,0),"")) -> API5L_X52 | AG6: =IF(G6="","",VLOOKUP(G6,WPS!$D$1:$AH$4735,2,0)) -> A | AH6: =IF(AE6="SMAW Mixte UP HILL/ Down hill","5G",IF(AE6="SMAW UP HILL MONTANT","5G",IF(AE6="SMAW Downhill","5G",IF(AE6="GMAW FCAW","1G",IF(AE6="GTAW","6G",IF(AE6="GTAW SMAW","6G","")))))) -> 5G | AI6: =IF(AE6="SMAW Mixte UP HILL/ Down hill","Manuel",IF(AE6="SMAW UP HILL MONTANT","Manuel",IF(AE6="GMAW FCAW","semi auto",IF(AE6="GTAW","Manuel",IF(AE6="GTAW SMAW","Manuel",IF(AE6="SMAW Downhill","Manuel","")))))) -> Manuel | AJ6: PIPE | AK6: =IF(AE6="SMAW Mixte UP HILL/ Down hill","UP HILL/ Down hill Montant+Descendant",IF(AE6="SMAW UP HILL MONTANT","UP HILL Montant",IF(AE6="GMAW FCAW","Rotation",IF(AE6="GTAW","UP HILL Montant",IF(AE6="SMAW Downhill","SMAW Downhill",IF(AE6="GTAW SMAW","UP HILL Montant","")))))) -> UP HILL/ Down hill Montant+Descendant | AL6: =IF($G6="","",VLOOKUP($G6,WPS!$D$1:$AL$995,18,0)) -> N/A | AM6: =IF($G6="","",VLOOKUP($G6,WPS!$D$1:$AL$995,19,0)) -> Grp F N°1 | AN6: =IF($G6="","",VLOOKUP($G6,WPS!$D$1:$AL$995,20,0)) -> Grp F N°1 | AO6: =IF($G6="","",VLOOKUP($G6,WPS!$D$1:$AL$995,21,0)) -> A5.1 | AP6: =IF($G6="","",VLOOKUP($G6,WPS!$D$1:$AL$995,22,0)) -> A5.5 | AQ6: =IF($G6="","",VLOOKUP($G6,WPS!$D$1:$AL$995,23,0)) -> E 6010 | AR6: =IF($G6="","",VLOOKUP($G6,WPS!$D$1:$AL$995,24,0)) -> E 7010-P1 | AS6: =IF(AH6="1G","F",IF(AH6="5G","V-H-O",IF(AH6="6G","ALL",""))) -> V-H-O | AT6: =IF($G6="","",VLOOKUP($G6,WPS!$D$1:$AL$995,29,0)) -> DC | AU6: =IF($G6="","",VLOOKUP($G6,WPS!$D$1:$AL$995,30,0)) -> (+) | AV6: =IF($G6="","",VLOOKUP($G6,WPS!$D$1:$AL$995,31,0)) -> (+) | AW6: =IF(AE6="SMAW Mixte UP HILL/ Down hill","SMAW :,With/Without SMAW : With",IF(AE6="SMAW UP HILL MONTANT","SMAW :With/Without SMAW : With",IF(AE6="GMAW FCAW","GMAW :With/Without FCAW : With",IF(AE6="GTAW","GTAW :With / Without",IF(AE6="GTAW SMAW","GTAW :With/Without SMAW : With",""))))) -> SMAW :,With/Without SMAW : With | AX6: =IF($G6="","",VLOOKUP($G6,WPS!$D$1:$AL$995,15,0)) -> 50°C Min | AY6: =IF($G6="","",VLOOKUP($G6,WPS!$D$1:$AX$995,44,0)) -> ASME B31.3 édition 2021 | AZ6: =IFERROR(VLOOKUP(I6,Feuil1!$O$4:$P$34,2,0),"") -> 168.3 | BB6: =IFERROR(VLOOKUP(I6,Feuil1!$O$4:$P$32,2,0),"") -> 168.3 | BC6: =IF($G6="","",VLOOKUP($G6,WPS!$D$1:$AL$995,2,0)) -> A | BD6: =IF(M6='VT-PPL'!$Y$6,1,"") | BE6: =IF(BD6="","",COUNTIF(BD$2:$BD6,BD6)) | BF6: =IF(P6='RT-PPL'!$Q$6,1,"") | BG6: =IF(BF6="","",COUNTIF(BF$2:$BF6,BF6)) | BH6: =+IF(L6=HOMO!$K$4,1,"") | BI6: =IF(BH6="","",COUNTIF(BH$2:$BH6,BH6)) | BJ6: =IF(AND(K6="A",M6=Prog!$L$12),1,"") | BK6: =IF(BJ6="","",COUNTIF(BJ$2:$BJ6,BJ6)) | BL6: 5
A7: =F7&G7&I7 -> DRARDJA AliTFT-II-PL-076 | B7: =IF($G7="","",VLOOKUP($G7,WPS!$D$1:$AN$995,35,0)) -> TFT II / TFT SUD GAZ FIELD DEVELOPMENT | C7: =IF($G7="","",VLOOKUP($G7,WPS!$D$1:$AN$995,33,0)) -> API 1104 | D7: =IF($G7="","",VLOOKUP($G7,WPS!$D$1:$AN$995,34,0)) -> API 1104 | E7: WR-025 | F7: DRARDJA Ali | G7: TFT-II-PL-07 | H7: API5L_X52 | I7: 6 | J7: 7.1 | K7: A | L7: 46139 | M7: VT-WQT-002 | N7: A | O7: 46139 | P7: RT-WQT-002 | Q7: 21063-G0-PPL-RFI-0055 | R7: 21063-G0-PPL-RFI-0055 | S7: WQT-004 | T7: 46139 | U7: =H7 -> API5L_X52 | V7: =IF($G7="","",VLOOKUP($G7,WPS!$D$1:$AL$995,17,0)) -> SMAW :With/Without Backing | W7: =IF($G7="","",VLOOKUP($G7,WPS!$D$1:$AL$995,25,0)) -> WF-1b | X7: =IF($G7="","",VLOOKUP($G7,WPS!$D$1:$AL$995,26,0)) -> WF-1b | Y7: =IF($G7="","",VLOOKUP($G7,WPS!$D$1:$AL$995,27,0)) -> A5.1or A5.5 | Z7: =IF($G7="","",VLOOKUP($G7,WPS!$D$1:$AL$995,28,0)) -> A5.1or A5.5 | AA7: =IF(AND(D7="API 1104",BB7<60.3),"Unlimited ",IF(AND(D7="API 1104",AND(BB7>=60.3,BB7<=323.85)),"≥ 2,3/8'' (60,3mm)",IF(AND(D7="API 1104",BB7>323.85),"> 12,750'' (323,9mm)",IF(AND(D7="ASME IX",BB7<60.3),CONCATENATE("≥ ",I6,"'' ","(",BB7,"mm)"),IF(AND(D7="ASME IX",BB7="60,3"),"≥ 1'' (25mm)",IF(AND(D7="ASME IX",AND(BB7>25,BB7<73)),"≥ 1'' (25mm)",IF(AND(D7="ASME IX",BB7>73),"> 2,7/8'' (73mm)",""))))))) -> ≥ 2,3/8'' (60,3mm) | AB7: =IF(AND(D7="API 1104",BB7<60.3),"< 2,3/8'' 60,3mm",IF(AND(D7="API 1104",AND(BB7>=60.3,BB7<=323.85)),"≤ 12,750'' 323,9mm",IF(AND(D7="API 1104",BB7>323.85),"Unlimited",IF(AND(D7="ASME IX",BB7<25),"Unlimited",IF(AND(D7="ASME IX",AND(BB7>25,BB7<73)),"Unlimited",IF(AND(D7="ASME IX",BB7>73),"Unlimited","")))))) -> ≤ 12,750'' 323,9mm | AC7: =IF(AND(D7="API 1104",J7<3.9)," SMAW <3,9 mm",IF(AND(D7="API 1104",AND(J7>=3.9,J7<19))," SMAW ≥ 3,9 mm",IF(AND(D7="API 1104",J7>=19),"SMAW >=19mm",IF(AND(D7="ASME IX",AE7="gtaw",J7<13),"GTAW ",IF(AND(D7="ASME IX",AE7="GTAW SMAW",J7<13),"GTAW ≤ 8 mm",IF(AND(D7="ASME IX",AE7="GmAW fcAW",J7<13),"GMAW ≤ 8 mm",IF(AND(D7="ASME IX",AE7="gtaw",J7>=13),CONCATENATE("≤ ",J7*2," mm"),IF(AND(D7="ASME IX",J7>=13,AE7="GTAW SMAW"),"GTAW ≤ 8mm",IF(AND(D7="ASME IX",J7>=13,AE7="GmAW fcAW"),"GMAW ≤ 8mm",""))))))))) -> SMAW ≥ 3,9 mm | AD7: =IF(AND(D7="API 1104",AE7="SMAW Mixte UP HILL/ Down hill",J7<3.9),CONCATENATE("≤ ",MAX(1.5*J7,3.9),"mm"),IF(AND(D7="API 1104",AE7="SMAW UP HILL MONTANT",J7<3.9),CONCATENATE("≤ ",MAX(1.5*J7,3.9),"mm"),IF(AND(D7="API 1104",AND(J7>=3.9,J7<19.05)),CONCATENATE("≤ ",MAX(1.5*J7,19.05),"mm"),IF(AND(D7="API 1104",J7>=19.05),"ALL",IF(AND(D7="ASME IX",AE7="SMAW UP HILL MONTANT",J7<17),CONCATENATE("≤ ",((J7)*2)," mm"),IF(AND(D7="ASME IX",J7>=17),CONCATENATE("Unlimited"),IF(AND(D7="ASME IX",AE7="SMAW Mixte UP HILL/ Down hill",J7<17),CONCATENATE("≤ ",((J7)*2)," mm"),IF(AND(D7="ASME IX",J7>=17),CONCATENATE(" SMAW Unlimited"),IF(AND(D7="ASME IX",AE7="GTAW",J7<=17),CONCATENATE( "≤ ",J7*2," mm"),IF(AND(D7="ASME IX",AE7="GTAW SMAW",J7<=17),CONCATENATE("SMAW ≤ ",((J7-4)*2)," mm"),IF(AND(D7="ASME IX",J7>=17,AE7="GTAW SMAW"),"SMAW Unlimited ",IF(AND(D7="ASME IX",AE7="GMAW FCAW",J7<=17),CONCATENATE("FCAW ≤ ",((J7-4)*2)," mm"),IF(AND(D7="ASME IX",J7>=17,AE7="GmAW fcAW"),"FCAW Unlimited ",""))))))))))))) -> ≤ 19,05mm | AE7: =IF(G7="","",VLOOKUP(G7,WPS!$D$1:$AH$4735,3,0)) -> SMAW Mixte UP HILL/ Down hill | AF7: =IF(AND($G7<>"",$D7="API 1104"),U7,IF(AND($G7<>"",$D7="ASME IX"),VLOOKUP($G7,WPS!$D$1:$AZ$995,42,0),"")) -> API5L_X52 | AG7: =IF(G7="","",VLOOKUP(G7,WPS!$D$1:$AH$4735,2,0)) -> A | AH7: =IF(AE7="SMAW Mixte UP HILL/ Down hill","5G",IF(AE7="SMAW UP HILL MONTANT","5G",IF(AE7="SMAW Downhill","5G",IF(AE7="GMAW FCAW","1G",IF(AE7="GTAW","6G",IF(AE7="GTAW SMAW","6G","")))))) -> 5G | AI7: =IF(AE7="SMAW Mixte UP HILL/ Down hill","Manuel",IF(AE7="SMAW UP HILL MONTANT","Manuel",IF(AE7="GMAW FCAW","semi auto",IF(AE7="GTAW","Manuel",IF(AE7="GTAW SMAW","Manuel",IF(AE7="SMAW Downhill","Manuel","")))))) -> Manuel | AJ7: PIPE | AK7: =IF(AE7="SMAW Mixte UP HILL/ Down hill","UP HILL/ Down hill Montant+Descendant",IF(AE7="SMAW UP HILL MONTANT","UP HILL Montant",IF(AE7="GMAW FCAW","Rotation",IF(AE7="GTAW","UP HILL Montant",IF(AE7="SMAW Downhill","SMAW Downhill",IF(AE7="GTAW SMAW","UP HILL Montant","")))))) -> UP HILL/ Down hill Montant+Descendant | AL7: =IF($G7="","",VLOOKUP($G7,WPS!$D$1:$AL$995,18,0)) -> N/A | AM7: =IF($G7="","",VLOOKUP($G7,WPS!$D$1:$AL$995,19,0)) -> Grp F N°1 | AN7: =IF($G7="","",VLOOKUP($G7,WPS!$D$1:$AL$995,20,0)) -> Grp F N°1 | AO7: =IF($G7="","",VLOOKUP($G7,WPS!$D$1:$AL$995,21,0)) -> A5.1 | AP7: =IF($G7="","",VLOOKUP($G7,WPS!$D$1:$AL$995,22,0)) -> A5.5 | AQ7: =IF($G7="","",VLOOKUP($G7,WPS!$D$1:$AL$995,23,0)) -> E 6010 | AR7: =IF($G7="","",VLOOKUP($G7,WPS!$D$1:$AL$995,24,0)) -> E 7010-P1 | AS7: =IF(AH7="1G","F",IF(AH7="5G","V-H-O",IF(AH7="6G","ALL",""))) -> V-H-O | AT7: =IF($G7="","",VLOOKUP($G7,WPS!$D$1:$AL$995,29,0)) -> DC | AU7: =IF($G7="","",VLOOKUP($G7,WPS!$D$1:$AL$995,30,0)) -> (+) | AV7: =IF($G7="","",VLOOKUP($G7,WPS!$D$1:$AL$995,31,0)) -> (+) | AW7: =IF(AE7="SMAW Mixte UP HILL/ Down hill","SMAW :,With/Without SMAW : With",IF(AE7="SMAW UP HILL MONTANT","SMAW :With/Without SMAW : With",IF(AE7="GMAW FCAW","GMAW :With/Without FCAW : With",IF(AE7="GTAW","GTAW :With / Without",IF(AE7="GTAW SMAW","GTAW :With/Without SMAW : With",""))))) -> SMAW :,With/Without SMAW : With | AX7: =IF($G7="","",VLOOKUP($G7,WPS!$D$1:$AL$995,15,0)) -> 50°C Min | AY7: =IF($G7="","",VLOOKUP($G7,WPS!$D$1:$AX$995,44,0)) -> ASME B31.3 édition 2021 | AZ7: =IFERROR(VLOOKUP(I7,Feuil1!$O$4:$P$34,2,0),"") -> 168.3 | BB7: =IFERROR(VLOOKUP(I7,Feuil1!$O$4:$P$32,2,0),"") -> 168.3 | BC7: =IF($G7="","",VLOOKUP($G7,WPS!$D$1:$AL$995,2,0)) -> A | BD7: =IF(M7='VT-PPL'!$Y$6,1,"") | BE7: =IF(BD7="","",COUNTIF(BD$2:$BD7,BD7)) | BF7: =IF(P7='RT-PPL'!$Q$6,1,"") | BG7: =IF(BF7="","",COUNTIF(BF$2:$BF7,BF7)) | BH7: =+IF(L7=HOMO!$K$4,1,"") | BI7: =IF(BH7="","",COUNTIF(BH$2:$BH7,BH7)) | BJ7: =IF(AND(K7="A",M7=Prog!$L$12),1,"") | BK7: =IF(BJ7="","",COUNTIF(BJ$2:$BJ7,BJ7)) | BL7: 6
A8: =F8&G8&I8 -> BOUSARIA SAMEHTFT-II-PL-076 | B8: =IF($G8="","",VLOOKUP($G8,WPS!$D$1:$AN$995,35,0)) -> TFT II / TFT SUD GAZ FIELD DEVELOPMENT | C8: =IF($G8="","",VLOOKUP($G8,WPS!$D$1:$AN$995,33,0)) -> API 1104 | D8: =IF($G8="","",VLOOKUP($G8,WPS!$D$1:$AN$995,34,0)) -> API 1104 | E8: WR-019 | F8: BOUSARIA SAMEH | G8: TFT-II-PL-07 | H8: API5L_X52 | I8: 6 | J8: 7.1 | K8: R | L8: 46199 | M8: VT-WQT-003 | Q8: 21063-G0-PPL-RFI-0077 | R8: 21063-G0-PPL-RFI-0077 | U8: =H8 -> API5L_X52 | V8: =IF($G8="","",VLOOKUP($G8,WPS!$D$1:$AL$995,17,0)) -> SMAW :With/Without Backing | W8: =IF($G8="","",VLOOKUP($G8,WPS!$D$1:$AL$995,25,0)) -> WF-1b | X8: =IF($G8="","",VLOOKUP($G8,WPS!$D$1:$AL$995,26,0)) -> WF-1b | Y8: =IF($G8="","",VLOOKUP($G8,WPS!$D$1:$AL$995,27,0)) -> A5.1or A5.5 | Z8: =IF($G8="","",VLOOKUP($G8,WPS!$D$1:$AL$995,28,0)) -> A5.1or A5.5 | AA8: =IF(AND(D8="API 1104",BB8<60.3),"Unlimited ",IF(AND(D8="API 1104",AND(BB8>=60.3,BB8<=323.85)),"≥ 2,3/8'' (60,3mm)",IF(AND(D8="API 1104",BB8>323.85),"> 12,750'' (323,9mm)",IF(AND(D8="ASME IX",BB8<60.3),CONCATENATE("≥ ",I7,"'' ","(",BB8,"mm)"),IF(AND(D8="ASME IX",BB8="60,3"),"≥ 1'' (25mm)",IF(AND(D8="ASME IX",AND(BB8>25,BB8<73)),"≥ 1'' (25mm)",IF(AND(D8="ASME IX",BB8>73),"> 2,7/8'' (73mm)",""))))))) -> ≥ 2,3/8'' (60,3mm) | AB8: =IF(AND(D8="API 1104",BB8<60.3),"< 2,3/8'' 60,3mm",IF(AND(D8="API 1104",AND(BB8>=60.3,BB8<=323.85)),"≤ 12,750'' 323,9mm",IF(AND(D8="API 1104",BB8>323.85),"Unlimited",IF(AND(D8="ASME IX",BB8<25),"Unlimited",IF(AND(D8="ASME IX",AND(BB8>25,BB8<73)),"Unlimited",IF(AND(D8="ASME IX",BB8>73),"Unlimited","")))))) -> ≤ 12,750'' 323,9mm | AC8: =IF(AND(D8="API 1104",J8<3.9)," SMAW <3,9 mm",IF(AND(D8="API 1104",AND(J8>=3.9,J8<19))," SMAW ≥ 3,9 mm",IF(AND(D8="API 1104",J8>=19),"SMAW >=19mm",IF(AND(D8="ASME IX",AE8="gtaw",J8<13),"GTAW ",IF(AND(D8="ASME IX",AE8="GTAW SMAW",J8<13),"GTAW ≤ 8 mm",IF(AND(D8="ASME IX",AE8="GmAW fcAW",J8<13),"GMAW ≤ 8 mm",IF(AND(D8="ASME IX",AE8="gtaw",J8>=13),CONCATENATE("≤ ",J8*2," mm"),IF(AND(D8="ASME IX",J8>=13,AE8="GTAW SMAW"),"GTAW ≤ 8mm",IF(AND(D8="ASME IX",J8>=13,AE8="GmAW fcAW"),"GMAW ≤ 8mm",""))))))))) -> SMAW ≥ 3,9 mm | AD8: =IF(AND(D8="API 1104",AE8="SMAW Mixte UP HILL/ Down hill",J8<3.9),CONCATENATE("≤ ",MAX(1.5*J8,3.9),"mm"),IF(AND(D8="API 1104",AE8="SMAW UP HILL MONTANT",J8<3.9),CONCATENATE("≤ ",MAX(1.5*J8,3.9),"mm"),IF(AND(D8="API 1104",AND(J8>=3.9,J8<19.05)),CONCATENATE("≤ ",MAX(1.5*J8,19.05),"mm"),IF(AND(D8="API 1104",J8>=19.05),"ALL",IF(AND(D8="ASME IX",AE8="SMAW UP HILL MONTANT",J8<17),CONCATENATE("≤ ",((J8)*2)," mm"),IF(AND(D8="ASME IX",J8>=17),CONCATENATE("Unlimited"),IF(AND(D8="ASME IX",AE8="SMAW Mixte UP HILL/ Down hill",J8<17),CONCATENATE("≤ ",((J8)*2)," mm"),IF(AND(D8="ASME IX",J8>=17),CONCATENATE(" SMAW Unlimited"),IF(AND(D8="ASME IX",AE8="GTAW",J8<=17),CONCATENATE( "≤ ",J8*2," mm"),IF(AND(D8="ASME IX",AE8="GTAW SMAW",J8<=17),CONCATENATE("SMAW ≤ ",((J8-4)*2)," mm"),IF(AND(D8="ASME IX",J8>=17,AE8="GTAW SMAW"),"SMAW Unlimited ",IF(AND(D8="ASME IX",AE8="GMAW FCAW",J8<=17),CONCATENATE("FCAW ≤ ",((J8-4)*2)," mm"),IF(AND(D8="ASME IX",J8>=17,AE8="GmAW fcAW"),"FCAW Unlimited ",""))))))))))))) -> ≤ 19,05mm | AE8: =IF(G8="","",VLOOKUP(G8,WPS!$D$1:$AH$4735,3,0)) -> SMAW Mixte UP HILL/ Down hill | AF8: =IF(AND($G8<>"",$D8="API 1104"),U8,IF(AND($G8<>"",$D8="ASME IX"),VLOOKUP($G8,WPS!$D$1:$AZ$995,42,0),"")) -> API5L_X52 | AG8: =IF(G8="","",VLOOKUP(G8,WPS!$D$1:$AH$4735,2,0)) -> A | AH8: =IF(AE8="SMAW Mixte UP HILL/ Down hill","5G",IF(AE8="SMAW UP HILL MONTANT","5G",IF(AE8="SMAW Downhill","5G",IF(AE8="GMAW FCAW","1G",IF(AE8="GTAW","6G",IF(AE8="GTAW SMAW","6G","")))))) -> 5G | AI8: =IF(AE8="SMAW Mixte UP HILL/ Down hill","Manuel",IF(AE8="SMAW UP HILL MONTANT","Manuel",IF(AE8="GMAW FCAW","semi auto",IF(AE8="GTAW","Manuel",IF(AE8="GTAW SMAW","Manuel",IF(AE8="SMAW Downhill","Manuel","")))))) -> Manuel | AJ8: PIPE | AK8: =IF(AE8="SMAW Mixte UP HILL/ Down hill","UP HILL/ Down hill Montant+Descendant",IF(AE8="SMAW UP HILL MONTANT","UP HILL Montant",IF(AE8="GMAW FCAW","Rotation",IF(AE8="GTAW","UP HILL Montant",IF(AE8="SMAW Downhill","SMAW Downhill",IF(AE8="GTAW SMAW","UP HILL Montant","")))))) -> UP HILL/ Down hill Montant+Descendant | AL8: =IF($G8="","",VLOOKUP($G8,WPS!$D$1:$AL$995,18,0)) -> N/A | AM8: =IF($G8="","",VLOOKUP($G8,WPS!$D$1:$AL$995,19,0)) -> Grp F N°1 | AN8: =IF($G8="","",VLOOKUP($G8,WPS!$D$1:$AL$995,20,0)) -> Grp F N°1 | AO8: =IF($G8="","",VLOOKUP($G8,WPS!$D$1:$AL$995,21,0)) -> A5.1 | AP8: =IF($G8="","",VLOOKUP($G8,WPS!$D$1:$AL$995,22,0)) -> A5.5 | AQ8: =IF($G8="","",VLOOKUP($G8,WPS!$D$1:$AL$995,23,0)) -> E 6010 | AR8: =IF($G8="","",VLOOKUP($G8,WPS!$D$1:$AL$995,24,0)) -> E 7010-P1 | AS8: =IF(AH8="1G","F",IF(AH8="5G","V-H-O",IF(AH8="6G","ALL",""))) -> V-H-O | AT8: =IF($G8="","",VLOOKUP($G8,WPS!$D$1:$AL$995,29,0)) -> DC | AU8: =IF($G8="","",VLOOKUP($G8,WPS!$D$1:$AL$995,30,0)) -> (+) | AV8: =IF($G8="","",VLOOKUP($G8,WPS!$D$1:$AL$995,31,0)) -> (+) | AW8: =IF(AE8="SMAW Mixte UP HILL/ Down hill","SMAW :,With/Without SMAW : With",IF(AE8="SMAW UP HILL MONTANT","SMAW :With/Without SMAW : With",IF(AE8="GMAW FCAW","GMAW :With/Without FCAW : With",IF(AE8="GTAW","GTAW :With / Without",IF(AE8="GTAW SMAW","GTAW :With/Without SMAW : With",""))))) -> SMAW :,With/Without SMAW : With | AX8: =IF($G8="","",VLOOKUP($G8,WPS!$D$1:$AL$995,15,0)) -> 50°C Min | AY8: =IF($G8="","",VLOOKUP($G8,WPS!$D$1:$AX$995,44,0)) -> ASME B31.3 édition 2021 | AZ8: =IFERROR(VLOOKUP(I8,Feuil1!$O$4:$P$34,2,0),"") -> 168.3 | BB8: =IFERROR(VLOOKUP(I8,Feuil1!$O$4:$P$32,2,0),"") -> 168.3 | BC8: =IF($G8="","",VLOOKUP($G8,WPS!$D$1:$AL$995,2,0)) -> A | BD8: =IF(M8='VT-PPL'!$Y$6,1,"") | BE8: =IF(BD8="","",COUNTIF(BD$2:$BD8,BD8)) | BF8: =IF(P8='RT-PPL'!$Q$6,1,"") | BG8: =IF(BF8="","",COUNTIF(BF$2:$BF8,BF8)) | BH8: =+IF(L8=HOMO!$K$4,1,"") | BI8: =IF(BH8="","",COUNTIF(BH$2:$BH8,BH8)) | BJ8: =IF(AND(K8="A",M8=Prog!$L$12),1,"") | BK8: =IF(BJ8="","",COUNTIF(BJ$2:$BJ8,BJ8)) | BL8: 7
