Workbook

Sheet TABLEAU DE BORD
B2: TABLEAU DE BORD — SOUDAGE & CONTRÔLE QUALITÉ PIPELINE
B3: =PARAMÈTRES!$C$4&" • Affaire N° "&PARAMÈTRES!$C$5&" • Mis à jour le "&TEXT(TODAY(),"dd/mm/yyyy") -> Extension du réseau de collecte de GTFT (11 nouveaux puits) • Affaire N° 8546 • Mis à jour le 28/09/2026
B5: Ligne / Puits : | C5: TOUTES | E5: ◄ choisir une ligne pour filtrer tous les indicateurs | O5: =IF(C5="TOUTES","*",C5) -> *
B7: JOINTS SOUDÉS | D7: AVANCEMENT SOUDAGE | F7: JOINTS RADIOGRAPHIÉS | H7: JOINTS ACCEPTÉS | J7: EN ATTENTE RT | L7: TAUX DE RÉPARATION
B8: =COUNTIFS('CARNET DE SOUDURE'!$B$7:$B$1506,$O$5,'CARNET DE SOUDURE'!$R$7:$R$1506,"<>") -> 197 | D8: =IFERROR(COUNTIFS('CARNET DE SOUDURE'!$B$7:$B$1506,$O$5,'CARNET DE SOUDURE'!$R$7:$R$1506,"<>")/IF($C$5="TOUTES",SUM(PARAMÈTRES!$E$12:$E$19),SUMIF(PARAMÈTRES!$B$12:$B$19,$C$5,PARAMÈTRES!$E$12:$E$19)),0) -> 0.24502488 | F8: =COUNTIFS('CARNET DE SOUDURE'!$B$7:$B$1506,$O$5,'CARNET DE SOUDURE'!$X$7:$X$1506,"<>") -> 188 | H8: =COUNTIFS('CARNET DE SOUDURE'!$B$7:$B$1506,$O$5,'CARNET DE SOUDURE'!$AM$7:$AM$1506,"ACCEPTÉ") -> 188 | J8: =COUNTIFS('CARNET DE SOUDURE'!$B$7:$B$1506,$O$5,'CARNET DE SOUDURE'!$AM$7:$AM$1506,"À RADIOGRAPHIER")+COUNTIFS('CARNET DE SOUDURE'!$B$7:$B$1506,$O$5,'CARNET DE SOUDURE'!$AM$7:$AM$1506,"RÉPARÉ – À RADIOGRAPHIER")+COUNTIFS('CARNET DE SOUDURE'!$B$7:$B$1506,$O$5,'CARNET DE SOUDURE'!$AM$7:$AM$1506,"NX – RT À REFAIRE") -> 9 | L8: =IFERROR((COUNTIFS('CARNET DE SOUDURE'!$B$7:$B$1506,$O$5,'CARNET DE SOUDURE'!$X$7:$X$1506,"R")+COUNTIFS('CARNET DE SOUDURE'!$B$7:$B$1506,$O$5,'CARNET DE SOUDURE'!$X$7:$X$1506,"NT")+COUNTIFS('CARNET DE SOUDURE'!$B$7:$B$1506,$O$5,'CARNET DE SOUDURE'!$X$7:$X$1506,"CO"))/(COUNTIFS('CARNET DE SOUDURE'!$B$7:$B$1506,$O$5,'CARNET DE SOUDURE'!$X$7:$X$1506,"A")+(COUNTIFS('CARNET DE SOUDURE'!$B$7:$B$1506,$O$5,'CARNET DE SOUDURE'!$X$7:$X$1506,"R")+COUNTIFS('CARNET DE SOUDURE'!$B$7:$B$1506,$O$5,'CARNET DE SOUDURE'!$X$7:$X$1506,"NT")+COUNTIFS('CARNET DE SOUDURE'!$B$7:$B$1506,$O$5,'CARNET DE SOUDURE'!$X$7:$X$1506,"CO"))),0) -> 0.010695187
B10: ="sur "&TEXT(IF($C$5="TOUTES",SUM(PARAMÈTRES!$E$12:$E$19),SUMIF(PARAMÈTRES!$B$12:$B$19,$C$5,PARAMÈTRES!$E$12:$E$19)),"#,##0")&" estimés" -> sur 804 estimés | D10: ="Reste : "&TEXT(MAX(0,IF($C$5="TOUTES",SUM(PARAMÈTRES!$E$12:$E$19),SUMIF(PARAMÈTRES!$B$12:$B$19,$C$5,PARAMÈTRES!$E$12:$E$19))-COUNTIFS('CARNET DE SOUDURE'!$B$7:$B$1506,$O$5,'CARNET DE SOUDURE'!$R$7:$R$1506,"<>")),"#,##0")&" joints" -> Reste : 607 joints | F10: =TEXT(IFERROR(COUNTIFS('CARNET DE SOUDURE'!$B$7:$B$1506,$O$5,'CARNET DE SOUDURE'!$X$7:$X$1506,"<>")/COUNTIFS('CARNET DE SOUDURE'!$B$7:$B$1506,$O$5,'CARNET DE SOUDURE'!$R$7:$R$1506,"<>"),0),"0.0%")&" des joints soudés" -> 95.4% des joints soudés | H10: =TEXT(IFERROR(COUNTIFS('CARNET DE SOUDURE'!$B$7:$B$1506,$O$5,'CARNET DE SOUDURE'!$AM$7:$AM$1506,"ACCEPTÉ")/COUNTIFS('CARNET DE SOUDURE'!$B$7:$B$1506,$O$5,'CARNET DE SOUDURE'!$R$7:$R$1506,"<>"),0),"0.0%")&" des joints soudés" -> 95.4% des joints soudés | J10: ="voir PROGRAMME RT" -> voir PROGRAMME RT | L10: =TEXT((COUNTIFS('CARNET DE SOUDURE'!$B$7:$B$1506,$O$5,'CARNET DE SOUDURE'!$X$7:$X$1506,"R")+COUNTIFS('CARNET DE SOUDURE'!$B$7:$B$1506,$O$5,'CARNET DE SOUDURE'!$X$7:$X$1506,"NT")+COUNTIFS('CARNET DE SOUDURE'!$B$7:$B$1506,$O$5,'CARNET DE SOUDURE'!$X$7:$X$1506,"CO")),"0")&" rejet(s) au RT-01" -> 2 rejet(s) au RT-01
B12: À RÉPARER (R) | D12: COUPE (CO) | F12: NX – RT À REFAIRE | H12: RÉPARÉS → RT | J12: VT EN ATTENTE / REJETÉ | L12: À SOUDER (listés)
B13: =COUNTIFS('CARNET DE SOUDURE'!$B$7:$B$1506,$O$5,'CARNET DE SOUDURE'!$AM$7:$AM$1506,"À RÉPARER") -> 0 | D13: =COUNTIFS('CARNET DE SOUDURE'!$B$7:$B$1506,$O$5,'CARNET DE SOUDURE'!$AM$7:$AM$1506,"COUPE – À RESOUDER") -> 0 | F13: =COUNTIFS('CARNET DE SOUDURE'!$B$7:$B$1506,$O$5,'CARNET DE SOUDURE'!$AM$7:$AM$1506,"NX – RT À REFAIRE") -> 0 | H13: =COUNTIFS('CARNET DE SOUDURE'!$B$7:$B$1506,$O$5,'CARNET DE SOUDURE'!$AM$7:$AM$1506,"RÉPARÉ – À RADIOGRAPHIER") -> 0 | J13: =COUNTIFS('CARNET DE SOUDURE'!$B$7:$B$1506,$O$5,'CARNET DE SOUDURE'!$AM$7:$AM$1506,"VT EN ATTENTE")+COUNTIFS('CARNET DE SOUDURE'!$B$7:$B$1506,$O$5,'CARNET DE SOUDURE'!$AM$7:$AM$1506,"VT REJETÉ – À REPRENDRE") -> 0 | L13: =COUNTIFS('CARNET DE SOUDURE'!$B$7:$B$1506,$O$5,'CARNET DE SOUDURE'!$AM$7:$AM$1506,"À SOUDER") -> 608
B16: SITUATION PAR LIGNE
B17: Ligne | C17: Joints estimés | D17: Joints soudés | E17: Reste à souder | F17: % Soudage | G17: Radiographiés | H17: % RT | I17: Acceptés | J17: % Accepté | K17: En réparation | L17: Taux de réparation | M17: En attente RT
B18: =IF(PARAMÈTRES!$B$12="","",PARAMÈTRES!$B$12) -> ISB-302 | C18: =IF($B18="","",N(PARAMÈTRES!$E$12)) -> 200 | D18: =IF($B18="","",COUNTIFS('CARNET DE SOUDURE'!$B$7:$B$1506,$B18,'CARNET DE SOUDURE'!$R$7:$R$1506,"<>")) -> 0 | E18: =IF($B18="","",MAX(0,C18-D18)) -> 200 | F18: =IF($B18="","",IFERROR(D18/C18,0)) -> 0 | G18: =IF($B18="","",COUNTIFS('CARNET DE SOUDURE'!$B$7:$B$1506,$B18,'CARNET DE SOUDURE'!$X$7:$X$1506,"<>")) -> 0 | H18: =IF($B18="","",IFERROR(G18/D18,0)) -> 0 | I18: =IF($B18="","",COUNTIFS('CARNET DE SOUDURE'!$B$7:$B$1506,$B18,'CARNET DE SOUDURE'!$AM$7:$AM$1506,"ACCEPTÉ")) -> 0 | J18: =IF($B18="","",IFERROR(I18/D18,0)) -> 0 | K18: =IF($B18="","",COUNTIFS('CARNET DE SOUDURE'!$B$7:$B$1506,$B18,'CARNET DE SOUDURE'!$AM$7:$AM$1506,"À RÉPARER")+COUNTIFS('CARNET DE SOUDURE'!$B$7:$B$1506,$B18,'CARNET DE SOUDURE'!$AM$7:$AM$1506,"COUPE – À RESOUDER")+COUNTIFS('CARNET DE SOUDURE'!$B$7:$B$1506,$B18,'CARNET DE SOUDURE'!$AM$7:$AM$1506,"VT REJETÉ – À REPRENDRE")) -> 0 | L18: =IF($B18="","",IFERROR((COUNTIFS('CARNET DE SOUDURE'!$B$7:$B$1506,$B18,'CARNET DE SOUDURE'!$X$7:$X$1506,"R")+COUNTIFS('CARNET DE SOUDURE'!$B$7:$B$1506,$B18,'CARNET DE SOUDURE'!$X$7:$X$1506,"NT")+COUNTIFS('CARNET DE SOUDURE'!$B$7:$B$1506,$B18,'CARNET DE SOUDURE'!$X$7:$X$1506,"CO"))/(COUNTIFS('CARNET DE SOUDURE'!$B$7:$B$1506,$B18,'CARNET DE SOUDURE'!$X$7:$X$1506,"A")+(COUNTIFS('CARNET DE SOUDURE'!$B$7:$B$1506,$B18,'CARNET DE SOUDURE'!$X$7:$X$1506,"R")+COUNTIFS('CARNET DE SOUDURE'!$B$7:$B$1506,$B18,'CARNET DE SOUDURE'!$X$7:$X$1506,"NT")+COUNTIFS('CARNET DE SOUDURE'!$B$7:$B$1506,$B18,'CARNET DE SOUDURE'!$X$7:$X$1506,"CO"))),0)) -> 0 | M18: =IF($B18="","",COUNTIFS('CARNET DE SOUDURE'!$B$7:$B$1506,$B18,'CARNET DE SOUDURE'!$AM$7:$AM$1506,"À RADIOGRAPHIER")+COUNTIFS('CARNET DE SOUDURE'!$B$7:$B$1506,$B18,'CARNET DE SOUDURE'!$AM$7:$AM$1506,"RÉPARÉ – À RADIOGRAPHIER")+COUNTIFS('CARNET DE SOUDURE'!$B$7:$B$1506,$B18,'CARNET DE SOUDURE'!$AM$7:$AM$1506,"NX – RT À REFAIRE")) -> 0
B19: =IF(PARAMÈTRES!$B$13="","",PARAMÈTRES!$B$13) -> ISB-303 | C19: =IF($B19="","",N(PARAMÈTRES!$E$13)) -> 200 | D19: =IF($B19="","",COUNTIFS('CARNET DE SOUDURE'!$B$7:$B$1506,$B19,'CARNET DE SOUDURE'!$R$7:$R$1506,"<>")) -> 0 | E19: =IF($B19="","",MAX(0,C19-D19)) -> 200 | F19: =IF($B19="","",IFERROR(D19/C19,0)) -> 0 | G19: =IF($B19="","",COUNTIFS('CARNET DE SOUDURE'!$B$7:$B$1506,$B19,'CARNET DE SOUDURE'!$X$7:$X$1506,"<>")) -> 0 | H19: =IF($B19="","",IFERROR(G19/D19,0)) -> 0 | I19: =IF($B19="","",COUNTIFS('CARNET DE SOUDURE'!$B$7:$B$1506,$B19,'CARNET DE SOUDURE'!$AM$7:$AM$1506,"ACCEPTÉ")) -> 0 | J19: =IF($B19="","",IFERROR(I19/D19,0)) -> 0 | K19: =IF($B19="","",COUNTIFS('CARNET DE SOUDURE'!$B$7:$B$1506,$B19,'CARNET DE SOUDURE'!$AM$7:$AM$1506,"À RÉPARER")+COUNTIFS('CARNET DE SOUDURE'!$B$7:$B$1506,$B19,'CARNET DE SOUDURE'!$AM$7:$AM$1506,"COUPE – À RESOUDER")+COUNTIFS('CARNET DE SOUDURE'!$B$7:$B$1506,$B19,'CARNET DE SOUDURE'!$AM$7:$AM$1506,"VT REJETÉ – À REPRENDRE")) -> 0 | L19: =IF($B19="","",IFERROR((COUNTIFS('CARNET DE SOUDURE'!$B$7:$B$1506,$B19,'CARNET DE SOUDURE'!$X$7:$X$1506,"R")+COUNTIFS('CARNET DE SOUDURE'!$B$7:$B$1506,$B19,'CARNET DE SOUDURE'!$X$7:$X$1506,"NT")+COUNTIFS('CARNET DE SOUDURE'!$B$7:$B$1506,$B19,'CARNET DE SOUDURE'!$X$7:$X$1506,"CO"))/(COUNTIFS('CARNET DE SOUDURE'!$B$7:$B$1506,$B19,'CARNET DE SOUDURE'!$X$7:$X$1506,"A")+(COUNTIFS('CARNET DE SOUDURE'!$B$7:$B$1506,$B19,'CARNET DE SOUDURE'!$X$7:$X$1506,"R")+COUNTIFS('CARNET DE SOUDURE'!$B$7:$B$1506,$B19,'CARNET DE SOUDURE'!$X$7:$X$1506,"NT")+COUNTIFS('CARNET DE SOUDURE'!$B$7:$B$1506,$B19,'CARNET DE SOUDURE'!$X$7:$X$1506,"CO"))),0)) -> 0 | M19: =IF($B19="","",COUNTIFS('CARNET DE SOUDURE'!$B$7:$B$1506,$B19,'CARNET DE SOUDURE'!$AM$7:$AM$1506,"À RADIOGRAPHIER")+COUNTIFS('CARNET DE SOUDURE'!$B$7:$B$1506,$B19,'CARNET DE SOUDURE'!$AM$7:$AM$1506,"RÉPARÉ – À RADIOGRAPHIER")+COUNTIFS('CARNET DE SOUDURE'!$B$7:$B$1506,$B19,'CARNET DE SOUDURE'!$AM$7:$AM$1506,"NX – RT À REFAIRE")) -> 0
B20: =IF(PARAMÈTRES!$B$14="","",PARAMÈTRES!$B$14) -> ISB-304 | C20: =IF($B20="","",N(PARAMÈTRES!$E$14)) -> 200 | D20: =IF($B20="","",COUNTIFS('CARNET DE SOUDURE'!$B$7:$B$1506,$B20,'CARNET DE SOUDURE'!$R$7:$R$1506,"<>")) -> 0 | E20: =IF($B20="","",MAX(0,C20-D20)) -> 200 | F20: =IF($B20="","",IFERROR(D20/C20,0)) -> 0 | G20: =IF($B20="","",COUNTIFS('CARNET DE SOUDURE'!$B$7:$B$1506,$B20,'CARNET DE SOUDURE'!$X$7:$X$1506,"<>")) -> 0 | H20: =IF($B20="","",IFERROR(G20/D20,0)) -> 0 | I20: =IF($B20="","",COUNTIFS('CARNET DE SOUDURE'!$B$7:$B$1506,$B20,'CARNET DE SOUDURE'!$AM$7:$AM$1506,"ACCEPTÉ")) -> 0 | J20: =IF($B20="","",IFERROR(I20/D20,0)) -> 0 | K20: =IF($B20="","",COUNTIFS('CARNET DE SOUDURE'!$B$7:$B$1506,$B20,'CARNET DE SOUDURE'!$AM$7:$AM$1506,"À RÉPARER")+COUNTIFS('CARNET DE SOUDURE'!$B$7:$B$1506,$B20,'CARNET DE SOUDURE'!$AM$7:$AM$1506,"COUPE – À RESOUDER")+COUNTIFS('CARNET DE SOUDURE'!$B$7:$B$1506,$B20,'CARNET DE SOUDURE'!$AM$7:$AM$1506,"VT REJETÉ – À REPRENDRE")) -> 0 | L20: =IF($B20="","",IFERROR((COUNTIFS('CARNET DE SOUDURE'!$B$7:$B$1506,$B20,'CARNET DE SOUDURE'!$X$7:$X$1506,"R")+COUNTIFS('CARNET DE SOUDURE'!$B$7:$B$1506,$B20,'CARNET DE SOUDURE'!$X$7:$X$1506,"NT")+COUNTIFS('CARNET DE SOUDURE'!$B$7:$B$1506,$B20,'CARNET DE SOUDURE'!$X$7:$X$1506,"CO"))/(COUNTIFS('CARNET DE SOUDURE'!$B$7:$B$1506,$B20,'CARNET DE SOUDURE'!$X$7:$X$1506,"A")+(COUNTIFS('CARNET DE SOUDURE'!$B$7:$B$1506,$B20,'CARNET DE SOUDURE'!$X$7:$X$1506,"R")+COUNTIFS('CARNET DE SOUDURE'!$B$7:$B$1506,$B20,'CARNET DE SOUDURE'!$X$7:$X$1506,"NT")+COUNTIFS('CARNET DE SOUDURE'!$B$7:$B$1506,$B20,'CARNET DE SOUDURE'!$X$7:$X$1506,"CO"))),0)) -> 0 | M20: =IF($B20="","",COUNTIFS('CARNET DE SOUDURE'!$B$7:$B$1506,$B20,'CARNET DE SOUDURE'!$AM$7:$AM$1506,"À RADIOGRAPHIER")+COUNTIFS('CARNET DE SOUDURE'!$B$7:$B$1506,$B20,'CARNET DE SOUDURE'!$AM$7:$AM$1506,"RÉPARÉ – À RADIOGRAPHIER")+COUNTIFS('CARNET DE SOUDURE'!$B$7:$B$1506,$B20,'CARNET DE SOUDURE'!$AM$7:$AM$1506,"NX – RT À REFAIRE")) -> 0
B21: =IF(PARAMÈTRES!$B$15="","",PARAMÈTRES!$B$15) -> TFT 716 → TL7-MMFW2 | C21: =IF($B21="","",N(PARAMÈTRES!$E$15)) -> 204 | D21: =IF($B21="","",COUNTIFS('CARNET DE SOUDURE'!$B$7:$B$1506,$B21,'CARNET DE SOUDURE'!$R$7:$R$1506,"<>")) -> 197 | E21: =IF($B21="","",MAX(0,C21-D21)) -> 7 | F21: =IF($B21="","",IFERROR(D21/C21,0)) -> 0.96568627 | G21: =IF($B21="","",COUNTIFS('CARNET DE SOUDURE'!$B$7:$B$1506,$B21,'CARNET DE SOUDURE'!$X$7:$X$1506,"<>")) -> 188 | H21: =IF($B21="","",IFERROR(G21/D21,0)) -> 0.95431472 | I21: =IF($B21="","",COUNTIFS('CARNET DE SOUDURE'!$B$7:$B$1506,$B21,'CARNET DE SOUDURE'!$AM$7:$AM$1506,"ACCEPTÉ")) -> 188 | J21: =IF($B21="","",IFERROR(I21/D21,0)) -> 0.95431472 | K21: =IF($B21="","",COUNTIFS('CARNET DE SOUDURE'!$B$7:$B$1506,$B21,'CARNET DE SOUDURE'!$AM$7:$AM$1506,"À RÉPARER")+COUNTIFS('CARNET DE SOUDURE'!$B$7:$B$1506,$B21,'CARNET DE SOUDURE'!$AM$7:$AM$1506,"COUPE – À RESOUDER")+COUNTIFS('CARNET DE SOUDURE'!$B$7:$B$1506,$B21,'CARNET DE SOUDURE'!$AM$7:$AM$1506,"VT REJETÉ – À REPRENDRE")) -> 0 | L21: =IF($B21="","",IFERROR((COUNTIFS('CARNET DE SOUDURE'!$B$7:$B$1506,$B21,'CARNET DE SOUDURE'!$X$7:$X$1506,"R")+COUNTIFS('CARNET DE SOUDURE'!$B$7:$B$1506,$B21,'CARNET DE SOUDURE'!$X$7:$X$1506,"NT")+COUNTIFS('CARNET DE SOUDURE'!$B$7:$B$1506,$B21,'CARNET DE SOUDURE'!$X$7:$X$1506,"CO"))/(COUNTIFS('CARNET DE SOUDURE'!$B$7:$B$1506,$B21,'CARNET DE SOUDURE'!$X$7:$X$1506,"A")+(COUNTIFS('CARNET DE SOUDURE'!$B$7:$B$1506,$B21,'CARNET DE SOUDURE'!$X$7:$X$1506,"R")+COUNTIFS('CARNET DE SOUDURE'!$B$7:$B$1506,$B21,'CARNET DE SOUDURE'!$X$7:$X$1506,"NT")+COUNTIFS('CARNET DE SOUDURE'!$B$7:$B$1506,$B21,'CARNET DE SOUDURE'!$X$7:$X$1506,"CO"))),0)) -> 0.010695187 | M21: =IF($B21="","",COUNTIFS('CARNET DE SOUDURE'!$B$7:$B$1506,$B21,'CARNET DE SOUDURE'!$AM$7:$AM$1506,"À RADIOGRAPHIER")+COUNTIFS('CARNET DE SOUDURE'!$B$7:$B$1506,$B21,'CARNET DE SOUDURE'!$AM$7:$AM$1506,"RÉPARÉ – À RADIOGRAPHIER")+COUNTIFS('CARNET DE SOUDURE'!$B$7:$B$1506,$B21,'CARNET DE SOUDURE'!$AM$7:$AM$1506,"NX – RT À REFAIRE")) -> 9
B22: =IF(PARAMÈTRES!$B$16="","",PARAMÈTRES!$B$16) | C22: =IF($B22="","",N(PARAMÈTRES!$E$16)) | D22: =IF($B22="","",COUNTIFS('CARNET DE SOUDURE'!$B$7:$B$1506,$B22,'CARNET DE SOUDURE'!$R$7:$R$1506,"<>")) | E22: =IF($B22="","",MAX(0,C22-D22)) | F22: =IF($B22="","",IFERROR(D22/C22,0)) | G22: =IF($B22="","",COUNTIFS('CARNET DE SOUDURE'!$B$7:$B$1506,$B22,'CARNET DE SOUDURE'!$X$7:$X$1506,"<>")) | H22: =IF($B22="","",IFERROR(G22/D22,0)) | I22: =IF($B22="","",COUNTIFS('CARNET DE SOUDURE'!$B$7:$B$1506,$B22,'CARNET DE SOUDURE'!$AM$7:$AM$1506,"ACCEPTÉ")) | J22: =IF($B22="","",IFERROR(I22/D22,0)) | K22: =IF($B22="","",COUNTIFS('CARNET DE SOUDURE'!$B$7:$B$1506,$B22,'CARNET DE SOUDURE'!$AM$7:$AM$1506,"À RÉPARER")+COUNTIFS('CARNET DE SOUDURE'!$B$7:$B$1506,$B22,'CARNET DE SOUDURE'!$AM$7:$AM$1506,"COUPE – À RESOUDER")+COUNTIFS('CARNET DE SOUDURE'!$B$7:$B$1506,$B22,'CARNET DE SOUDURE'!$AM$7:$AM$1506,"VT REJETÉ – À REPRENDRE")) | L22: =IF($B22="","",IFERROR((COUNTIFS('CARNET DE SOUDURE'!$B$7:$B$1506,$B22,'CARNET DE SOUDURE'!$X$7:$X$1506,"R")+COUNTIFS('CARNET DE SOUDURE'!$B$7:$B$1506,$B22,'CARNET DE SOUDURE'!$X$7:$X$1506,"NT")+COUNTIFS('CARNET DE SOUDURE'!$B$7:$B$1506,$B22,'CARNET DE SOUDURE'!$X$7:$X$1506,"CO"))/(COUNTIFS('CARNET DE SOUDURE'!$B$7:$B$1506,$B22,'CARNET DE SOUDURE'!$X$7:$X$1506,"A")+(COUNTIFS('CARNET DE SOUDURE'!$B$7:$B$1506,$B22,'CARNET DE SOUDURE'!$X$7:$X$1506,"R")+COUNTIFS('CARNET DE SOUDURE'!$B$7:$B$1506,$B22,'CARNET DE SOUDURE'!$X$7:$X$1506,"NT")+COUNTIFS('CARNET DE SOUDURE'!$B$7:$B$1506,$B22,'CARNET DE SOUDURE'!$X$7:$X$1506,"CO"))),0)) | M22: =IF($B22="","",COUNTIFS('CARNET DE SOUDURE'!$B$7:$B$1506,$B22,'CARNET DE SOUDURE'!$AM$7:$AM$1506,"À RADIOGRAPHIER")+COUNTIFS('CARNET DE SOUDURE'!$B$7:$B$1506,$B22,'CARNET DE SOUDURE'!$AM$7:$AM$1506,"RÉPARÉ – À RADIOGRAPHIER")+COUNTIFS('CARNET DE SOUDURE'!$B$7:$B$1506,$B22,'CARNET DE SOUDURE'!$AM$7:$AM$1506,"NX – RT À REFAIRE"))
B23: =IF(PARAMÈTRES!$B$17="","",PARAMÈTRES!$B$17) | C23: =IF($B23="","",N(PARAMÈTRES!$E$17)) | D23: =IF($B23="","",COUNTIFS('CARNET DE SOUDURE'!$B$7:$B$1506,$B23,'CARNET DE SOUDURE'!$R$7:$R$1506,"<>")) | E23: =IF($B23="","",MAX(0,C23-D23)) | F23: =IF($B23="","",IFERROR(D23/C23,0)) | G23: =IF($B23="","",COUNTIFS('CARNET DE SOUDURE'!$B$7:$B$1506,$B23,'CARNET DE SOUDURE'!$X$7:$X$1506,"<>")) | H23: =IF($B23="","",IFERROR(G23/D23,0)) | I23: =IF($B23="","",COUNTIFS('CARNET DE SOUDURE'!$B$7:$B$1506,$B23,'CARNET DE SOUDURE'!$AM$7:$AM$1506,"ACCEPTÉ")) | J23: =IF($B23="","",IFERROR(I23/D23,0)) | K23: =IF($B23="","",COUNTIFS('CARNET DE SOUDURE'!$B$7:$B$1506,$B23,'CARNET DE SOUDURE'!$AM$7:$AM$1506,"À RÉPARER")+COUNTIFS('CARNET DE SOUDURE'!$B$7:$B$1506,$B23,'CARNET DE SOUDURE'!$AM$7:$AM$1506,"COUPE – À RESOUDER")+COUNTIFS('CARNET DE SOUDURE'!$B$7:$B$1506,$B23,'CARNET DE SOUDURE'!$AM$7:$AM$1506,"VT REJETÉ – À REPRENDRE")) | L23: =IF($B23="","",IFERROR((COUNTIFS('CARNET DE SOUDURE'!$B$7:$B$1506,$B23,'CARNET DE SOUDURE'!$X$7:$X$1506,"R")+COUNTIFS('CARNET DE SOUDURE'!$B$7:$B$1506,$B23,'CARNET DE SOUDURE'!$X$7:$X$1506,"NT")+COUNTIFS('CARNET DE SOUDURE'!$B$7:$B$1506,$B23,'CARNET DE SOUDURE'!$X$7:$X$1506,"CO"))/(COUNTIFS('CARNET DE SOUDURE'!$B$7:$B$1506,$B23,'CARNET DE SOUDURE'!$X$7:$X$1506,"A")+(COUNTIFS('CARNET DE SOUDURE'!$B$7:$B$1506,$B23,'CARNET DE SOUDURE'!$X$7:$X$1506,"R")+COUNTIFS('CARNET DE SOUDURE'!$B$7:$B$1506,$B23,'CARNET DE SOUDURE'!$X$7:$X$1506,"NT")+COUNTIFS('CARNET DE SOUDURE'!$B$7:$B$1506,$B23,'CARNET DE SOUDURE'!$X$7:$X$1506,"CO"))),0)) | M23: =IF($B23="","",COUNTIFS('CARNET DE SOUDURE'!$B$7:$B$1506,$B23,'CARNET DE SOUDURE'!$AM$7:$AM$1506,"À RADIOGRAPHIER")+COUNTIFS('CARNET DE SOUDURE'!$B$7:$B$1506,$B23,'CARNET DE SOUDURE'!$AM$7:$AM$1506,"RÉPARÉ – À RADIOGRAPHIER")+COUNTIFS('CARNET DE SOUDURE'!$B$7:$B$1506,$B23,'CARNET DE SOUDURE'!$AM$7:$AM$1506,"NX – RT À REFAIRE"))
B24: =IF(PARAMÈTRES!$B$18="","",PARAMÈTRES!$B$18) | C24: =IF($B24="","",N(PARAMÈTRES!$E$18)) | D24: =IF($B24="","",COUNTIFS('CARNET DE SOUDURE'!$B$7:$B$1506,$B24,'CARNET DE SOUDURE'!$R$7:$R$1506,"<>")) | E24: =IF($B24="","",MAX(0,C24-D24)) | F24: =IF($B24="","",IFERROR(D24/C24,0)) | G24: =IF($B24="","",COUNTIFS('CARNET DE SOUDURE'!$B$7:$B$1506,$B24,'CARNET DE SOUDURE'!$X$7:$X$1506,"<>")) | H24: =IF($B24="","",IFERROR(G24/D24,0)) | I24: =IF($B24="","",COUNTIFS('CARNET DE SOUDURE'!$B$7:$B$1506,$B24,'CARNET DE SOUDURE'!$AM$7:$AM$1506,"ACCEPTÉ")) | J24: =IF($B24="","",IFERROR(I24/D24,0)) | K24: =IF($B24="","",COUNTIFS('CARNET DE SOUDURE'!$B$7:$B$1506,$B24,'CARNET DE SOUDURE'!$AM$7:$AM$1506,"À RÉPARER")+COUNTIFS('CARNET DE SOUDURE'!$B$7:$B$1506,$B24,'CARNET DE SOUDURE'!$AM$7:$AM$1506,"COUPE – À RESOUDER")+COUNTIFS('CARNET DE SOUDURE'!$B$7:$B$1506,$B24,'CARNET DE SOUDURE'!$AM$7:$AM$1506,"VT REJETÉ – À REPRENDRE")) | L24: =IF($B24="","",IFERROR((COUNTIFS('CARNET DE SOUDURE'!$B$7:$B$1506,$B24,'CARNET DE SOUDURE'!$X$7:$X$1506,"R")+COUNTIFS('CARNET DE SOUDURE'!$B$7:$B$1506,$B24,'CARNET DE SOUDURE'!$X$7:$X$1506,"NT")+COUNTIFS('CARNET DE SOUDURE'!$B$7:$B$1506,$B24,'CARNET DE SOUDURE'!$X$7:$X$1506,"CO"))/(COUNTIFS('CARNET DE SOUDURE'!$B$7:$B$1506,$B24,'CARNET DE SOUDURE'!$X$7:$X$1506,"A")+(COUNTIFS('CARNET DE SOUDURE'!$B$7:$B$1506,$B24,'CARNET DE SOUDURE'!$X$7:$X$1506,"R")+COUNTIFS('CARNET DE SOUDURE'!$B$7:$B$1506,$B24,'CARNET DE SOUDURE'!$X$7:$X$1506,"NT")+COUNTIFS('CARNET DE SOUDURE'!$B$7:$B$1506,$B24,'CARNET DE SOUDURE'!$X$7:$X$1506,"CO"))),0)) | M24: =IF($B24="","",COUNTIFS('CARNET DE SOUDURE'!$B$7:$B$1506,$B24,'CARNET DE SOUDURE'!$AM$7:$AM$1506,"À RADIOGRAPHIER")+COUNTIFS('CARNET DE SOUDURE'!$B$7:$B$1506,$B24,'CARNET DE SOUDURE'!$AM$7:$AM$1506,"RÉPARÉ – À RADIOGRAPHIER")+COUNTIFS('CARNET DE SOUDURE'!$B$7:$B$1506,$B24,'CARNET DE SOUDURE'!$AM$7:$AM$1506,"NX – RT À REFAIRE"))
B25: =IF(PARAMÈTRES!$B$19="","",PARAMÈTRES!$B$19) | C25: =IF($B25="","",N(PARAMÈTRES!$E$19)) | D25: =IF($B25="","",COUNTIFS('CARNET DE SOUDURE'!$B$7:$B$1506,$B25,'CARNET DE SOUDURE'!$R$7:$R$1506,"<>")) | E25: =IF($B25="","",MAX(0,C25-D25)) | F25: =IF($B25="","",IFERROR(D25/C25,0)) | G25: =IF($B25="","",COUNTIFS('CARNET DE SOUDURE'!$B$7:$B$1506,$B25,'CARNET DE SOUDURE'!$X$7:$X$1506,"<>")) | H25: =IF($B25="","",IFERROR(G25/D25,0)) | I25: =IF($B25="","",COUNTIFS('CARNET DE SOUDURE'!$B$7:$B$1506,$B25,'CARNET DE SOUDURE'!$AM$7:$AM$1506,"ACCEPTÉ")) | J25: =IF($B25="","",IFERROR(I25/D25,0)) | K25: =IF($B25="","",COUNTIFS('CARNET DE SOUDURE'!$B$7:$B$1506,$B25,'CARNET DE SOUDURE'!$AM$7:$AM$1506,"À RÉPARER")+COUNTIFS('CARNET DE SOUDURE'!$B$7:$B$1506,$B25,'CARNET DE SOUDURE'!$AM$7:$AM$1506,"COUPE – À RESOUDER")+COUNTIFS('CARNET DE SOUDURE'!$B$7:$B$1506,$B25,'CARNET DE SOUDURE'!$AM$7:$AM$1506,"VT REJETÉ – À REPRENDRE")) | L25: =IF($B25="","",IFERROR((COUNTIFS('CARNET DE SOUDURE'!$B$7:$B$1506,$B25,'CARNET DE SOUDURE'!$X$7:$X$1506,"R")+COUNTIFS('CARNET DE SOUDURE'!$B$7:$B$1506,$B25,'CARNET DE SOUDURE'!$X$7:$X$1506,"NT")+COUNTIFS('CARNET DE SOUDURE'!$B$7:$B$1506,$B25,'CARNET DE SOUDURE'!$X$7:$X$1506,"CO"))/(COUNTIFS('CARNET DE SOUDURE'!$B$7:$B$1506,$B25,'CARNET DE SOUDURE'!$X$7:$X$1506,"A")+(COUNTIFS('CARNET DE SOUDURE'!$B$7:$B$1506,$B25,'CARNET DE SOUDURE'!$X$7:$X$1506,"R")+COUNTIFS('CARNET DE SOUDURE'!$B$7:$B$1506,$B25,'CARNET DE SOUDURE'!$X$7:$X$1506,"NT")+COUNTIFS('CARNET DE SOUDURE'!$B$7:$B$1506,$B25,'CARNET DE SOUDURE'!$X$7:$X$1506,"CO"))),0)) | M25: =IF($B25="","",COUNTIFS('CARNET DE SOUDURE'!$B$7:$B$1506,$B25,'CARNET DE SOUDURE'!$AM$7:$AM$1506,"À RADIOGRAPHIER")+COUNTIFS('CARNET DE SOUDURE'!$B$7:$B$1506,$B25,'CARNET DE SOUDURE'!$AM$7:$AM$1506,"RÉPARÉ – À RADIOGRAPHIER")+COUNTIFS('CARNET DE SOUDURE'!$B$7:$B$1506,$B25,'CARNET DE SOUDURE'!$AM$7:$AM$1506,"NX – RT À REFAIRE"))
B26: TOTAL | C26: =SUM(C18:C25) -> 804 | D26: =SUM(D18:D25) -> 197 | E26: =SUM(E18:E25) -> 607 | F26: =IFERROR(D26/C26,0) -> 0.24502488 | G26: =SUM(G18:G25) -> 188 | H26: =IFERROR(G26/D26,0) -> 0.95431472 | I26: =SUM(I18:I25) -> 188 | J26: =IFERROR(I26/D26,0) -> 0.95431472 | K26: =SUM(K18:K25) -> 0 | L26: =IFERROR((COUNTIF('CARNET DE SOUDURE'!$X$7:$X$1506,"R")+COUNTIF('CARNET DE SOUDURE'!$X$7:$X$1506,"NT")+COUNTIF('CARNET DE SOUDURE'!$X$7:$X$1506,"CO"))/(COUNTIF('CARNET DE SOUDURE'!$X$7:$X$1506,"A")+COUNTIF('CARNET DE SOUDURE'!$X$7:$X$1506,"R")+COUNTIF('CARNET DE SOUDURE'!$X$7:$X$1506,"NT")+COUNTIF('CARNET DE SOUDURE'!$X$7:$X$1506,"CO")),0) -> 0.010695187 | M26: =SUM(M18:M25) -> 9
J28: Statut | L28: Joints | M28: %
J29: ACCEPTÉ | L29: =COUNTIFS('CARNET DE SOUDURE'!$B$7:$B$1506,$O$5,'CARNET DE SOUDURE'!$AM$7:$AM$1506,"ACCEPTÉ") -> 188 | M29: =IFERROR(L29/SUM($L$29:$L$37),0) -> 0.23354037
J30: À RADIOGRAPHIER | L30: =COUNTIFS('CARNET DE SOUDURE'!$B$7:$B$1506,$O$5,'CARNET DE SOUDURE'!$AM$7:$AM$1506,"À RADIOGRAPHIER") -> 9 | M30: =IFERROR(L30/SUM($L$29:$L$37),0) -> 0.011180124
J31: RÉPARÉ – À RADIOGRAPHIER | L31: =COUNTIFS('CARNET DE SOUDURE'!$B$7:$B$1506,$O$5,'CARNET DE SOUDURE'!$AM$7:$AM$1506,"RÉPARÉ – À RADIOGRAPHIER") -> 0 | M31: =IFERROR(L31/SUM($L$29:$L$37),0) -> 0
J32: NX – RT À REFAIRE | L32: =COUNTIFS('CARNET DE SOUDURE'!$B$7:$B$1506,$O$5,'CARNET DE SOUDURE'!$AM$7:$AM$1506,"NX – RT À REFAIRE") -> 0 | M32: =IFERROR(L32/SUM($L$29:$L$37),0) -> 0
J33: À RÉPARER | L33: =COUNTIFS('CARNET DE SOUDURE'!$B$7:$B$1506,$O$5,'CARNET DE SOUDURE'!$AM$7:$AM$1506,"À RÉPARER") -> 0 | M33: =IFERROR(L33/SUM($L$29:$L$37),0) -> 0
J34: COUPE – À RESOUDER | L34: =COUNTIFS('CARNET DE SOUDURE'!$B$7:$B$1506,$O$5,'CARNET DE SOUDURE'!$AM$7:$AM$1506,"COUPE – À RESOUDER") -> 0 | M34: =IFERROR(L34/SUM($L$29:$L$37),0) -> 0
J35: VT REJETÉ – À REPRENDRE | L35: =COUNTIFS('CARNET DE SOUDURE'!$B$7:$B$1506,$O$5,'CARNET DE SOUDURE'!$AM$7:$AM$1506,"VT REJETÉ – À REPRENDRE") -> 0 | M35: =IFERROR(L35/SUM($L$29:$L$37),0) -> 0
J36: VT EN ATTENTE | L36: =COUNTIFS('CARNET DE SOUDURE'!$B$7:$B$1506,$O$5,'CARNET DE SOUDURE'!$AM$7:$AM$1506,"VT EN ATTENTE") -> 0 | M36: =IFERROR(L36/SUM($L$29:$L$37),0) -> 0
J37: À SOUDER | L37: =COUNTIFS('CARNET DE SOUDURE'!$B$7:$B$1506,$O$5,'CARNET DE SOUDURE'!$AM$7:$AM$1506,"À SOUDER") -> 608 | M37: =IFERROR(L37/SUM($L$29:$L$37),0) -> 0.7552795
B55: PERFORMANCE DES SOUDEURS (toutes lignes)
B56: WR | C56: Nom | E56: Joints soudés | F56: Radiographiés | G56: Rejetés | H56: Taux de réparation | I56: Évaluation
B57: =SOUDEURS!B6 -> WR-01 | C57: =IF(SOUDEURS!C6="","",SOUDEURS!C6) -> BRAHIMI Boumediene | E57: =SOUDEURS!F6 -> 0 | F57: =SOUDEURS!G6 -> 0 | G57: =SOUDEURS!H6 -> 0 | H57: =SOUDEURS!I6 -> 0 | I57: =SOUDEURS!K6 -> —
B58: =SOUDEURS!B7 -> WR-02 | C58: =IF(SOUDEURS!C7="","",SOUDEURS!C7) -> MEHANGUEF Med Amine | E58: =SOUDEURS!F7 -> 86 | F58: =SOUDEURS!G7 -> 80 | G58: =SOUDEURS!H7 -> 1 | H58: =SOUDEURS!I7 -> 0.0125 | I58: =SOUDEURS!K7 -> Excellent
B59: =SOUDEURS!B8 -> WR-03 | C59: =IF(SOUDEURS!C8="","",SOUDEURS!C8) -> BEN KREDDA Mohammed Amine | E59: =SOUDEURS!F8 -> 0 | F59: =SOUDEURS!G8 -> 0 | G59: =SOUDEURS!H8 -> 0 | H59: =SOUDEURS!I8 -> 0 | I59: =SOUDEURS!K8 -> —
B60: =SOUDEURS!B9 -> WR-04 | C60: =IF(SOUDEURS!C9="","",SOUDEURS!C9) -> DEHKEL Ammar | E60: =SOUDEURS!F9 -> 0 | F60: =SOUDEURS!G9 -> 0 | G60: =SOUDEURS!H9 -> 0 | H60: =SOUDEURS!I9 -> 0 | I60: =SOUDEURS!K9 -> —
B61: =SOUDEURS!B10 -> WR-05 | C61: =IF(SOUDEURS!C10="","",SOUDEURS!C10) -> KHOCHNI Sofiane | E61: =SOUDEURS!F10 -> 169 | F61: =SOUDEURS!G10 -> 168 | G61: =SOUDEURS!H10 -> 2 | H61: =SOUDEURS!I10 -> 0.011904762 | I61: =SOUDEURS!K10 -> Excellent
B62: =SOUDEURS!B11 -> WR-06 | C62: =IF(SOUDEURS!C11="","",SOUDEURS!C11) -> ACHOUR Walid | E62: =SOUDEURS!F11 -> 62 | F62: =SOUDEURS!G11 -> 61 | G62: =SOUDEURS!H11 -> 1 | H62: =SOUDEURS!I11 -> 0.016393443 | I62: =SOUDEURS!K11 -> Excellent
B63: =SOUDEURS!B12 -> WR-07 | C63: =IF(SOUDEURS!C12="","",SOUDEURS!C12) | E63: =SOUDEURS!F12 -> 0 | F63: =SOUDEURS!G12 -> 0 | G63: =SOUDEURS!H12 -> 0 | H63: =SOUDEURS!I12 -> 0 | I63: =SOUDEURS!K12 -> —
B64: =SOUDEURS!B13 -> WR-08 | C64: =IF(SOUDEURS!C13="","",SOUDEURS!C13) | E64: =SOUDEURS!F13 -> 0 | F64: =SOUDEURS!G13 -> 0 | G64: =SOUDEURS!H13 -> 0 | H64: =SOUDEURS!I13 -> 0 | I64: =SOUDEURS!K13 -> —
B65: =SOUDEURS!B14 -> WR-09 | C65: =IF(SOUDEURS!C14="","",SOUDEURS!C14) -> LALA Lazhar | E65: =SOUDEURS!F14 -> 14 | F65: =SOUDEURS!G14 -> 10 | G65: =SOUDEURS!H14 -> 0 | H65: =SOUDEURS!I14 -> 0 | I65: =SOUDEURS!K14 -> Excellent
...

Sheet CARNET DE SOUDURE
A1: CARNET DE SOUDURE — PIPELINE
A2: =PARAMÈTRES!$C$4&" • Affaire N° "&PARAMÈTRES!$C$5&" • Saisir uniquement les colonnes en bleu — les colonnes N°, Nb RT, Dernier RT, STATUT et Attente sont automatiques" -> Extension du réseau de collecte de GTFT (11 nouveaux puits) • Affaire N° 8546 • Saisir uniquement les colonnes en bleu — les colonnes N°, Nb RT, Dernier RT, STATUT et Attente sont automatiques
B3: Joints : | C3: =COUNTA(E7:E1506) -> 805 | E3: Soudés : | F3: =COUNT(R7:R1506) -> 197 | I3: Acceptés : | J3: =COUNTIF(AM7:AM1506,"ACCEPTÉ") -> 188 | M3: À radiographier : | P3: =SUMPRODUCT((AM7:AM1506="À RADIOGRAPHIER")+(AM7:AM1506="RÉPARÉ – À RADIOGRAPHIER")+(AM7:AM1506="NX – RT À REFAIRE")) -> 9 | S3: À réparer : | V3: =SUMPRODUCT((AM7:AM1506="À RÉPARER")+(AM7:AM1506="COUPE – À RESOUDER")+(AM7:AM1506="VT REJETÉ – À REPRENDRE")) -> 0
A5: IDENTIFICATION DU JOINT | O5: SOUDAGE | S5: CONTRÔLE VISUEL (VT) | V5: RADIOGRAPHIE RT-01 | Y5: RÉPARATION 1 → VT → RT | AD5: RÉPARATION 2 → VT → RT | AI5: PROGRAMME & SUIVI
A6: N° | B6: Ligne | C6: Tronçon | D6: PK | E6: N° Joint | F6: Zone | G6: Ø | H6: Ép. (mm) | I6: Nuance | J6: WPS | K6: Tube 1 | L6: Coulée 1 | M6: Tube 2 | N6: Coulée 2 | O6: WR 1ère passe | P6: WR 2ème passe | Q6: WR B+F | R6: Date soudage | S6: VT Date | T6: VT PV N° | U6: VT Rés. | V6: RT1 Date | W6: RT1 PV N° | X6: RT1 Rés. | Y6: R1 WR | Z6: R1 VT Rés. | AA6: R1 RT Date | AB6: R1 RT PV N° | AC6: R1 RT Rés. | AD6: R2 WR | AE6: R2 VT Rés. | AF6: R2 RT Date | AG6: R2 RT PV N° | AH6: R2 RT Rés. | AI6: RT programmé le | AJ6: Remarques | AK6: Nb RT | AL6: Dernier RT | AM6: STATUT | AN6: Attente (j) | AO6: hRT | AP6: hRTn | AQ6: hREP | AR6: hREPn
A7: =IF(E7="","",ROW()-6) -> 1 | B7: TFT 716 → TL7-MMFW2 | D7: 0.00 | E7: JN°001 | F7: A | G7: 6" | H7: 11 | L7: =IF(K7="","",IFERROR(INDEX(BARDAGE!$C$7:$C$1506,MATCH(K7,BARDAGE!$B$7:$B$1506,0)),"? hors registre")) | N7: =IF(M7="","",IFERROR(INDEX(BARDAGE!$C$7:$C$1506,MATCH(M7,BARDAGE!$B$7:$B$1506,0)),"? hors registre")) | AK7: =IF(E7="","",(X7<>"")+(AC7<>"")+(AH7<>"")) -> 0 | AL7: =IF(AH7<>"",AH7,IF(AC7<>"",AC7,IF(X7<>"",X7,""))) | AM7: =IF(E7="","",IF(R7="","À SOUDER",IF(U7="","VT EN ATTENTE",IF(U7="R","VT REJETÉ – À REPRENDRE",IF(AL7="","À RADIOGRAPHIER",IF(AL7="A","ACCEPTÉ",IF(AL7="NX","NX – RT À REFAIRE",IF(IF(AK7=1,Z7,IF(AK7=2,AE7,""))="A","RÉPARÉ – À RADIOGRAPHIER",IF(IF(AK7=1,Z7,IF(AK7=2,AE7,""))="R","VT REJETÉ – À REPRENDRE",IF(OR(AL7="CO",AL7="NT"),"COUPE – À RESOUDER","À RÉPARER")))))))))) -> À SOUDER | AN7: =IF(AND(ISNUMBER(R7),OR(AM7="À RADIOGRAPHIER",AM7="RÉPARÉ – À RADIOGRAPHIER",AM7="NX – RT À REFAIRE",AM7="À RÉPARER",AM7="COUPE – À RESOUDER",AM7="VT REJETÉ – À REPRENDRE")),MAX(0,'PROGRAMME RT'!$C$4-R7),"") | AO7: =IF(AND(OR(AM7="À RADIOGRAPHIER",AM7="RÉPARÉ – À RADIOGRAPHIER",AM7="NX – RT À REFAIRE"),OR('PROGRAMME RT'!$D$5="TOUTES",B7='PROGRAMME RT'!$D$5)),1,0) -> 0 | AP7: =IF(AO7=1,SUM(AO$7:AO7),"") | AQ7: =IF(AND(OR(X7="R",X7="NX",X7="NT",X7="CO"),OR('JOINTS DE RÉPARATION'!$D$5="TOUTES",B7='JOINTS DE RÉPARATION'!$D$5),OR('JOINTS DE RÉPARATION'!$L$4="TOUS",AM7<>"ACCEPTÉ")),1,0) -> 0 | AR7: =IF(AQ7=1,SUM(AQ$7:AQ7),"")
A8: =IF(E8="","",ROW()-6) -> 2 | B8: TFT 716 → TL7-MMFW2 | D8: 0.00 | E8: JN°002 | F8: A | G8: 6" | H8: 11 | L8: =IF(K8="","",IFERROR(INDEX(BARDAGE!$C$7:$C$1506,MATCH(K8,BARDAGE!$B$7:$B$1506,0)),"? hors registre")) | N8: =IF(M8="","",IFERROR(INDEX(BARDAGE!$C$7:$C$1506,MATCH(M8,BARDAGE!$B$7:$B$1506,0)),"? hors registre")) | AK8: =IF(E8="","",(X8<>"")+(AC8<>"")+(AH8<>"")) -> 0 | AL8: =IF(AH8<>"",AH8,IF(AC8<>"",AC8,IF(X8<>"",X8,""))) | AM8: =IF(E8="","",IF(R8="","À SOUDER",IF(U8="","VT EN ATTENTE",IF(U8="R","VT REJETÉ – À REPRENDRE",IF(AL8="","À RADIOGRAPHIER",IF(AL8="A","ACCEPTÉ",IF(AL8="NX","NX – RT À REFAIRE",IF(IF(AK8=1,Z8,IF(AK8=2,AE8,""))="A","RÉPARÉ – À RADIOGRAPHIER",IF(IF(AK8=1,Z8,IF(AK8=2,AE8,""))="R","VT REJETÉ – À REPRENDRE",IF(OR(AL8="CO",AL8="NT"),"COUPE – À RESOUDER","À RÉPARER")))))))))) -> À SOUDER | AN8: =IF(AND(ISNUMBER(R8),OR(AM8="À RADIOGRAPHIER",AM8="RÉPARÉ – À RADIOGRAPHIER",AM8="NX – RT À REFAIRE",AM8="À RÉPARER",AM8="COUPE – À RESOUDER",AM8="VT REJETÉ – À REPRENDRE")),MAX(0,'PROGRAMME RT'!$C$4-R8),"") | AO8: =IF(AND(OR(AM8="À RADIOGRAPHIER",AM8="RÉPARÉ – À RADIOGRAPHIER",AM8="NX – RT À REFAIRE"),OR('PROGRAMME RT'!$D$5="TOUTES",B8='PROGRAMME RT'!$D$5)),1,0) -> 0 | AP8: =IF(AO8=1,SUM(AO$7:AO8),"") | AQ8: =IF(AND(OR(X8="R",X8="NX",X8="NT",X8="CO"),OR('JOINTS DE RÉPARATION'!$D$5="TOUTES",B8='JOINTS DE RÉPARATION'!$D$5),OR('JOINTS DE RÉPARATION'!$L$4="TOUS",AM8<>"ACCEPTÉ")),1,0) -> 0 | AR8: =IF(AQ8=1,SUM(AQ$7:AQ8),"")
A9: =IF(E9="","",ROW()-6) -> 3 | B9: TFT 716 → TL7-MMFW2 | D9: 0.00 | E9: JN°003 | F9: A | G9: 6" | H9: 11 | L9: =IF(K9="","",IFERROR(INDEX(BARDAGE!$C$7:$C$1506,MATCH(K9,BARDAGE!$B$7:$B$1506,0)),"? hors registre")) | N9: =IF(M9="","",IFERROR(INDEX(BARDAGE!$C$7:$C$1506,MATCH(M9,BARDAGE!$B$7:$B$1506,0)),"? hors registre")) | AK9: =IF(E9="","",(X9<>"")+(AC9<>"")+(AH9<>"")) -> 0 | AL9: =IF(AH9<>"",AH9,IF(AC9<>"",AC9,IF(X9<>"",X9,""))) | AM9: =IF(E9="","",IF(R9="","À SOUDER",IF(U9="","VT EN ATTENTE",IF(U9="R","VT REJETÉ – À REPRENDRE",IF(AL9="","À RADIOGRAPHIER",IF(AL9="A","ACCEPTÉ",IF(AL9="NX","NX – RT À REFAIRE",IF(IF(AK9=1,Z9,IF(AK9=2,AE9,""))="A","RÉPARÉ – À RADIOGRAPHIER",IF(IF(AK9=1,Z9,IF(AK9=2,AE9,""))="R","VT REJETÉ – À REPRENDRE",IF(OR(AL9="CO",AL9="NT"),"COUPE – À RESOUDER","À RÉPARER")))))))))) -> À SOUDER | AN9: =IF(AND(ISNUMBER(R9),OR(AM9="À RADIOGRAPHIER",AM9="RÉPARÉ – À RADIOGRAPHIER",AM9="NX – RT À REFAIRE",AM9="À RÉPARER",AM9="COUPE – À RESOUDER",AM9="VT REJETÉ – À REPRENDRE")),MAX(0,'PROGRAMME RT'!$C$4-R9),"") | AO9: =IF(AND(OR(AM9="À RADIOGRAPHIER",AM9="RÉPARÉ – À RADIOGRAPHIER",AM9="NX – RT À REFAIRE"),OR('PROGRAMME RT'!$D$5="TOUTES",B9='PROGRAMME RT'!$D$5)),1,0) -> 0 | AP9: =IF(AO9=1,SUM(AO$7:AO9),"") | AQ9: =IF(AND(OR(X9="R",X9="NX",X9="NT",X9="CO"),OR('JOINTS DE RÉPARATION'!$D$5="TOUTES",B9='JOINTS DE RÉPARATION'!$D$5),OR('JOINTS DE RÉPARATION'!$L$4="TOUS",AM9<>"ACCEPTÉ")),1,0) -> 0 | AR9: =IF(AQ9=1,SUM(AQ$7:AQ9),"")
A10: =IF(E10="","",ROW()-6) -> 4 | B10: TFT 716 → TL7-MMFW2 | D10: 0.00 | E10: JN°004 | F10: A | G10: 6" | H10: 11 | L10: =IF(K10="","",IFERROR(INDEX(BARDAGE!$C$7:$C$1506,MATCH(K10,BARDAGE!$B$7:$B$1506,0)),"? hors registre")) | N10: =IF(M10="","",IFERROR(INDEX(BARDAGE!$C$7:$C$1506,MATCH(M10,BARDAGE!$B$7:$B$1506,0)),"? hors registre")) | AK10: =IF(E10="","",(X10<>"")+(AC10<>"")+(AH10<>"")) -> 0 | AL10: =IF(AH10<>"",AH10,IF(AC10<>"",AC10,IF(X10<>"",X10,""))) | AM10: =IF(E10="","",IF(R10="","À SOUDER",IF(U10="","VT EN ATTENTE",IF(U10="R","VT REJETÉ – À REPRENDRE",IF(AL10="","À RADIOGRAPHIER",IF(AL10="A","ACCEPTÉ",IF(AL10="NX","NX – RT À REFAIRE",IF(IF(AK10=1,Z10,IF(AK10=2,AE10,""))="A","RÉPARÉ – À RADIOGRAPHIER",IF(IF(AK10=1,Z10,IF(AK10=2,AE10,""))="R","VT REJETÉ – À REPRENDRE",IF(OR(AL10="CO",AL10="NT"),"COUPE – À RESOUDER","À RÉPARER")))))))))) -> À SOUDER | AN10: =IF(AND(ISNUMBER(R10),OR(AM10="À RADIOGRAPHIER",AM10="RÉPARÉ – À RADIOGRAPHIER",AM10="NX – RT À REFAIRE",AM10="À RÉPARER",AM10="COUPE – À RESOUDER",AM10="VT REJETÉ – À REPRENDRE")),MAX(0,'PROGRAMME RT'!$C$4-R10),"") | AO10: =IF(AND(OR(AM10="À RADIOGRAPHIER",AM10="RÉPARÉ – À RADIOGRAPHIER",AM10="NX – RT À REFAIRE"),OR('PROGRAMME RT'!$D$5="TOUTES",B10='PROGRAMME RT'!$D$5)),1,0) -> 0 | AP10: =IF(AO10=1,SUM(AO$7:AO10),"") | AQ10: =IF(AND(OR(X10="R",X10="NX",X10="NT",X10="CO"),OR('JOINTS DE RÉPARATION'!$D$5="TOUTES",B10='JOINTS DE RÉPARATION'!$D$5),OR('JOINTS DE RÉPARATION'!$L$4="TOUS",AM10<>"ACCEPTÉ")),1,0) -> 0 | AR10: =IF(AQ10=1,SUM(AQ$7:AQ10),"")
A11: =IF(E11="","",ROW()-6) -> 5 | B11: TFT 716 → TL7-MMFW2 | D11: 0.00 | E11: JN°005 | F11: A | G11: 6" | H11: 11 | L11: =IF(K11="","",IFERROR(INDEX(BARDAGE!$C$7:$C$1506,MATCH(K11,BARDAGE!$B$7:$B$1506,0)),"? hors registre")) | M11: Z70235 | N11: =IF(M11="","",IFERROR(INDEX(BARDAGE!$C$7:$C$1506,MATCH(M11,BARDAGE!$B$7:$B$1506,0)),"? hors registre")) -> 24803579 | AK11: =IF(E11="","",(X11<>"")+(AC11<>"")+(AH11<>"")) -> 0 | AL11: =IF(AH11<>"",AH11,IF(AC11<>"",AC11,IF(X11<>"",X11,""))) | AM11: =IF(E11="","",IF(R11="","À SOUDER",IF(U11="","VT EN ATTENTE",IF(U11="R","VT REJETÉ – À REPRENDRE",IF(AL11="","À RADIOGRAPHIER",IF(AL11="A","ACCEPTÉ",IF(AL11="NX","NX – RT À REFAIRE",IF(IF(AK11=1,Z11,IF(AK11=2,AE11,""))="A","RÉPARÉ – À RADIOGRAPHIER",IF(IF(AK11=1,Z11,IF(AK11=2,AE11,""))="R","VT REJETÉ – À REPRENDRE",IF(OR(AL11="CO",AL11="NT"),"COUPE – À RESOUDER","À RÉPARER")))))))))) -> À SOUDER | AN11: =IF(AND(ISNUMBER(R11),OR(AM11="À RADIOGRAPHIER",AM11="RÉPARÉ – À RADIOGRAPHIER",AM11="NX – RT À REFAIRE",AM11="À RÉPARER",AM11="COUPE – À RESOUDER",AM11="VT REJETÉ – À REPRENDRE")),MAX(0,'PROGRAMME RT'!$C$4-R11),"") | AO11: =IF(AND(OR(AM11="À RADIOGRAPHIER",AM11="RÉPARÉ – À RADIOGRAPHIER",AM11="NX – RT À REFAIRE"),OR('PROGRAMME RT'!$D$5="TOUTES",B11='PROGRAMME RT'!$D$5)),1,0) -> 0 | AP11: =IF(AO11=1,SUM(AO$7:AO11),"") | AQ11: =IF(AND(OR(X11="R",X11="NX",X11="NT",X11="CO"),OR('JOINTS DE RÉPARATION'!$D$5="TOUTES",B11='JOINTS DE RÉPARATION'!$D$5),OR('JOINTS DE RÉPARATION'!$L$4="TOUS",AM11<>"ACCEPTÉ")),1,0) -> 0 | AR11: =IF(AQ11=1,SUM(AQ$7:AQ11),"")
A12: =IF(E12="","",ROW()-6) -> 6 | B12: TFT 716 → TL7-MMFW2 | C12: 08 | D12: 0.00 | E12: JN°006 | F12: A | G12: 6" | H12: 11 | I12: API 5L_X60 | J12: TFT-PPL-06 | K12: Z70235 | L12: =IF(K12="","",IFERROR(INDEX(BARDAGE!$C$7:$C$1506,MATCH(K12,BARDAGE!$B$7:$B$1506,0)),"? hors registre")) -> 24803579 | M12: Z69902 | N12: =IF(M12="","",IFERROR(INDEX(BARDAGE!$C$7:$C$1506,MATCH(M12,BARDAGE!$B$7:$B$1506,0)),"? hors registre")) -> 24803579 | O12: WR-09 | P12: WR-09 | Q12: WR-09 | R12: 45915 | S12: 45915 | T12: VT-027 | U12: A | V12: 45917 | W12: L-RT-17 | X12: A | AK12: =IF(E12="","",(X12<>"")+(AC12<>"")+(AH12<>"")) -> 1 | AL12: =IF(AH12<>"",AH12,IF(AC12<>"",AC12,IF(X12<>"",X12,""))) -> A | AM12: =IF(E12="","",IF(R12="","À SOUDER",IF(U12="","VT EN ATTENTE",IF(U12="R","VT REJETÉ – À REPRENDRE",IF(AL12="","À RADIOGRAPHIER",IF(AL12="A","ACCEPTÉ",IF(AL12="NX","NX – RT À REFAIRE",IF(IF(AK12=1,Z12,IF(AK12=2,AE12,""))="A","RÉPARÉ – À RADIOGRAPHIER",IF(IF(AK12=1,Z12,IF(AK12=2,AE12,""))="R","VT REJETÉ – À REPRENDRE",IF(OR(AL12="CO",AL12="NT"),"COUPE – À RESOUDER","À RÉPARER")))))))))) -> ACCEPTÉ | AN12: =IF(AND(ISNUMBER(R12),OR(AM12="À RADIOGRAPHIER",AM12="RÉPARÉ – À RADIOGRAPHIER",AM12="NX – RT À REFAIRE",AM12="À RÉPARER",AM12="COUPE – À RESOUDER",AM12="VT REJETÉ – À REPRENDRE")),MAX(0,'PROGRAMME RT'!$C$4-R12),"") | AO12: =IF(AND(OR(AM12="À RADIOGRAPHIER",AM12="RÉPARÉ – À RADIOGRAPHIER",AM12="NX – RT À REFAIRE"),OR('PROGRAMME RT'!$D$5="TOUTES",B12='PROGRAMME RT'!$D$5)),1,0) -> 0 | AP12: =IF(AO12=1,SUM(AO$7:AO12),"") | AQ12: =IF(AND(OR(X12="R",X12="NX",X12="NT",X12="CO"),OR('JOINTS DE RÉPARATION'!$D$5="TOUTES",B12='JOINTS DE RÉPARATION'!$D$5),OR('JOINTS DE RÉPARATION'!$L$4="TOUS",AM12<>"ACCEPTÉ")),1,0) -> 0 | AR12: =IF(AQ12=1,SUM(AQ$7:AQ12),"")
A13: =IF(E13="","",ROW()-6) -> 7 | B13: TFT 716 → TL7-MMFW2 | C13: 08 | D13: 0.00 | E13: JN°007 | F13: A | G13: 6" | H13: 11 | I13: API 5L_X60 | J13: TFT-PPL-06 | K13: Z69902 | L13: =IF(K13="","",IFERROR(INDEX(BARDAGE!$C$7:$C$1506,MATCH(K13,BARDAGE!$B$7:$B$1506,0)),"? hors registre")) -> 24803579 | M13: Z71206 | N13: =IF(M13="","",IFERROR(INDEX(BARDAGE!$C$7:$C$1506,MATCH(M13,BARDAGE!$B$7:$B$1506,0)),"? hors registre")) -> 24703645 | O13: WR-09 | P13: WR-09 | Q13: WR-09 | R13: 45914 | S13: 45914 | T13: VT-026 | U13: A | V13: 45917 | W13: L-RT-17 | X13: A | AK13: =IF(E13="","",(X13<>"")+(AC13<>"")+(AH13<>"")) -> 1 | AL13: =IF(AH13<>"",AH13,IF(AC13<>"",AC13,IF(X13<>"",X13,""))) -> A | AM13: =IF(E13="","",IF(R13="","À SOUDER",IF(U13="","VT EN ATTENTE",IF(U13="R","VT REJETÉ – À REPRENDRE",IF(AL13="","À RADIOGRAPHIER",IF(AL13="A","ACCEPTÉ",IF(AL13="NX","NX – RT À REFAIRE",IF(IF(AK13=1,Z13,IF(AK13=2,AE13,""))="A","RÉPARÉ – À RADIOGRAPHIER",IF(IF(AK13=1,Z13,IF(AK13=2,AE13,""))="R","VT REJETÉ – À REPRENDRE",IF(OR(AL13="CO",AL13="NT"),"COUPE – À RESOUDER","À RÉPARER")))))))))) -> ACCEPTÉ | AN13: =IF(AND(ISNUMBER(R13),OR(AM13="À RADIOGRAPHIER",AM13="RÉPARÉ – À RADIOGRAPHIER",AM13="NX – RT À REFAIRE",AM13="À RÉPARER",AM13="COUPE – À RESOUDER",AM13="VT REJETÉ – À REPRENDRE")),MAX(0,'PROGRAMME RT'!$C$4-R13),"") | AO13: =IF(AND(OR(AM13="À RADIOGRAPHIER",AM13="RÉPARÉ – À RADIOGRAPHIER",AM13="NX – RT À REFAIRE"),OR('PROGRAMME RT'!$D$5="TOUTES",B13='PROGRAMME RT'!$D$5)),1,0) -> 0 | AP13: =IF(AO13=1,SUM(AO$7:AO13),"") | AQ13: =IF(AND(OR(X13="R",X13="NX",X13="NT",X13="CO"),OR('JOINTS DE RÉPARATION'!$D$5="TOUTES",B13='JOINTS DE RÉPARATION'!$D$5),OR('JOINTS DE RÉPARATION'!$L$4="TOUS",AM13<>"ACCEPTÉ")),1,0) -> 0 | AR13: =IF(AQ13=1,SUM(AQ$7:AQ13),"")
A14: =IF(E14="","",ROW()-6) -> 8 | B14: TFT 716 → TL7-MMFW2 | C14: 08 | D14: 0.00 | E14: JN°008 | F14: A | G14: 6" | H14: 11 | I14: API 5L_X60 | J14: TFT-PPL-06 | K14: Z71206 | L14: =IF(K14="","",IFERROR(INDEX(BARDAGE!$C$7:$C$1506,MATCH(K14,BARDAGE!$B$7:$B$1506,0)),"? hors registre")) -> 24703645 | M14: Z71179 | N14: =IF(M14="","",IFERROR(INDEX(BARDAGE!$C$7:$C$1506,MATCH(M14,BARDAGE!$B$7:$B$1506,0)),"? hors registre")) -> 852404002201 | O14: WR-02 | P14: WR-02 | Q14: WR-02 | R14: 45914 | S14: 45914 | T14: VT-026 | U14: A | V14: 45917 | W14: L-RT-17 | X14: A | AK14: =IF(E14="","",(X14<>"")+(AC14<>"")+(AH14<>"")) -> 1 | AL14: =IF(AH14<>"",AH14,IF(AC14<>"",AC14,IF(X14<>"",X14,""))) -> A | AM14: =IF(E14="","",IF(R14="","À SOUDER",IF(U14="","VT EN ATTENTE",IF(U14="R","VT REJETÉ – À REPRENDRE",IF(AL14="","À RADIOGRAPHIER",IF(AL14="A","ACCEPTÉ",IF(AL14="NX","NX – RT À REFAIRE",IF(IF(AK14=1,Z14,IF(AK14=2,AE14,""))="A","RÉPARÉ – À RADIOGRAPHIER",IF(IF(AK14=1,Z14,IF(AK14=2,AE14,""))="R","VT REJETÉ – À REPRENDRE",IF(OR(AL14="CO",AL14="NT"),"COUPE – À RESOUDER","À RÉPARER")))))))))) -> ACCEPTÉ | AN14: =IF(AND(ISNUMBER(R14),OR(AM14="À RADIOGRAPHIER",AM14="RÉPARÉ – À RADIOGRAPHIER",AM14="NX – RT À REFAIRE",AM14="À RÉPARER",AM14="COUPE – À RESOUDER",AM14="VT REJETÉ – À REPRENDRE")),MAX(0,'PROGRAMME RT'!$C$4-R14),"") | AO14: =IF(AND(OR(AM14="À RADIOGRAPHIER",AM14="RÉPARÉ – À RADIOGRAPHIER",AM14="NX – RT À REFAIRE"),OR('PROGRAMME RT'!$D$5="TOUTES",B14='PROGRAMME RT'!$D$5)),1,0) -> 0 | AP14: =IF(AO14=1,SUM(AO$7:AO14),"") | AQ14: =IF(AND(OR(X14="R",X14="NX",X14="NT",X14="CO"),OR('JOINTS DE RÉPARATION'!$D$5="TOUTES",B14='JOINTS DE RÉPARATION'!$D$5),OR('JOINTS DE RÉPARATION'!$L$4="TOUS",AM14<>"ACCEPTÉ")),1,0) -> 0 | AR14: =IF(AQ14=1,SUM(AQ$7:AQ14),"")
A15: =IF(E15="","",ROW()-6) -> 9 | B15: TFT 716 → TL7-MMFW2 | C15: 08 | D15: 0.00 | E15: JN°009 | F15: A | G15: 6" | H15: 11 | I15: API 5L_X60 | J15: TFT-PPL-06 | K15: Z71179 | L15: =IF(K15="","",IFERROR(INDEX(BARDAGE!$C$7:$C$1506,MATCH(K15,BARDAGE!$B$7:$B$1506,0)),"? hors registre")) -> 852404002201 | M15: Z68652 | N15: =IF(M15="","",IFERROR(INDEX(BARDAGE!$C$7:$C$1506,MATCH(M15,BARDAGE!$B$7:$B$1506,0)),"? hors registre")) -> 852404000882 | O15: WR-09 | P15: WR-09 | Q15: WR-09 | R15: 45908 | S15: 45908 | T15: VT-021 | U15: A | V15: 45915 | W15: L-RT-16 | X15: A | AK15: =IF(E15="","",(X15<>"")+(AC15<>"")+(AH15<>"")) -> 1 | AL15: =IF(AH15<>"",AH15,IF(AC15<>"",AC15,IF(X15<>"",X15,""))) -> A | AM15: =IF(E15="","",IF(R15="","À SOUDER",IF(U15="","VT EN ATTENTE",IF(U15="R","VT REJETÉ – À REPRENDRE",IF(AL15="","À RADIOGRAPHIER",IF(AL15="A","ACCEPTÉ",IF(AL15="NX","NX – RT À REFAIRE",IF(IF(AK15=1,Z15,IF(AK15=2,AE15,""))="A","RÉPARÉ – À RADIOGRAPHIER",IF(IF(AK15=1,Z15,IF(AK15=2,AE15,""))="R","VT REJETÉ – À REPRENDRE",IF(OR(AL15="CO",AL15="NT"),"COUPE – À RESOUDER","À RÉPARER")))))))))) -> ACCEPTÉ | AN15: =IF(AND(ISNUMBER(R15),OR(AM15="À RADIOGRAPHIER",AM15="RÉPARÉ – À RADIOGRAPHIER",AM15="NX – RT À REFAIRE",AM15="À RÉPARER",AM15="COUPE – À RESOUDER",AM15="VT REJETÉ – À REPRENDRE")),MAX(0,'PROGRAMME RT'!$C$4-R15),"") | AO15: =IF(AND(OR(AM15="À RADIOGRAPHIER",AM15="RÉPARÉ – À RADIOGRAPHIER",AM15="NX – RT À REFAIRE"),OR('PROGRAMME RT'!$D$5="TOUTES",B15='PROGRAMME RT'!$D$5)),1,0) -> 0 | AP15: =IF(AO15=1,SUM(AO$7:AO15),"") | AQ15: =IF(AND(OR(X15="R",X15="NX",X15="NT",X15="CO"),OR('JOINTS DE RÉPARATION'!$D$5="TOUTES",B15='JOINTS DE RÉPARATION'!$D$5),OR('JOINTS DE RÉPARATION'!$L$4="TOUS",AM15<>"ACCEPTÉ")),1,0) -> 0 | AR15: =IF(AQ15=1,SUM(AQ$7:AQ15),"")
A16: =IF(E16="","",ROW()-6) -> 10 | B16: TFT 716 → TL7-MMFW2 | C16: 01 | D16: 0.00 | E16: JN°010 | F16: A | G16: 6" | H16: 11 | I16: API 5L_X60 | J16: TFT-PPL-05 | K16: Z68652 | L16: =IF(K16="","",IFERROR(INDEX(BARDAGE!$C$7:$C$1506,MATCH(K16,BARDAGE!$B$7:$B$1506,0)),"? hors registre")) -> 852404000882 | M16: Z68654 | N16: =IF(M16="","",IFERROR(INDEX(BARDAGE!$C$7:$C$1506,MATCH(M16,BARDAGE!$B$7:$B$1506,0)),"? hors registre")) -> 852404000882 | O16: WR-02 | P16: WR-02 | Q16: WR-06 | R16: 45891 | S16: 45891 | T16: VT-016 | U16: A | V16: 45893 | W16: L-RT-08 | X16: A | AK16: =IF(E16="","",(X16<>"")+(AC16<>"")+(AH16<>"")) -> 1 | AL16: =IF(AH16<>"",AH16,IF(AC16<>"",AC16,IF(X16<>"",X16,""))) -> A | AM16: =IF(E16="","",IF(R16="","À SOUDER",IF(U16="","VT EN ATTENTE",IF(U16="R","VT REJETÉ – À REPRENDRE",IF(AL16="","À RADIOGRAPHIER",IF(AL16="A","ACCEPTÉ",IF(AL16="NX","NX – RT À REFAIRE",IF(IF(AK16=1,Z16,IF(AK16=2,AE16,""))="A","RÉPARÉ – À RADIOGRAPHIER",IF(IF(AK16=1,Z16,IF(AK16=2,AE16,""))="R","VT REJETÉ – À REPRENDRE",IF(OR(AL16="CO",AL16="NT"),"COUPE – À RESOUDER","À RÉPARER")))))))))) -> ACCEPTÉ | AN16: =IF(AND(ISNUMBER(R16),OR(AM16="À RADIOGRAPHIER",AM16="RÉPARÉ – À RADIOGRAPHIER",AM16="NX – RT À REFAIRE",AM16="À RÉPARER",AM16="COUPE – À RESOUDER",AM16="VT REJETÉ – À REPRENDRE")),MAX(0,'PROGRAMME RT'!$C$4-R16),"") | AO16: =IF(AND(OR(AM16="À RADIOGRAPHIER",AM16="RÉPARÉ – À RADIOGRAPHIER",AM16="NX – RT À REFAIRE"),OR('PROGRAMME RT'!$D$5="TOUTES",B16='PROGRAMME RT'!$D$5)),1,0) -> 0 | AP16: =IF(AO16=1,SUM(AO$7:AO16),"") | AQ16: =IF(AND(OR(X16="R",X16="NX",X16="NT",X16="CO"),OR('JOINTS DE RÉPARATION'!$D$5="TOUTES",B16='JOINTS DE RÉPARATION'!$D$5),OR('JOINTS DE RÉPARATION'!$L$4="TOUS",AM16<>"ACCEPTÉ")),1,0) -> 0 | AR16: =IF(AQ16=1,SUM(AQ$7:AQ16),"")
A17: =IF(E17="","",ROW()-6) -> 11 | B17: TFT 716 → TL7-MMFW2 | C17: 01 | D17: 0.00 | E17: JN°011 | F17: A | G17: 6" | H17: 11 | I17: API 5L_X60 | J17: TFT-PPL-05 | K17: Z68654 | L17: =IF(K17="","",IFERROR(INDEX(BARDAGE!$C$7:$C$1506,MATCH(K17,BARDAGE!$B$7:$B$1506,0)),"? hors registre")) -> 852404000882 | M17: Z73371 | N17: =IF(M17="","",IFERROR(INDEX(BARDAGE!$C$7:$C$1506,MATCH(M17,BARDAGE!$B$7:$B$1506,0)),"? hors registre")) -> 852405000610 | O17: WR-02 | P17: WR-02 | Q17: WR-06 | R17: 45891 | S17: 45891 | T17: VT-016 | U17: A | V17: 45893 | W17: L-RT-08 | X17: A | AK17: =IF(E17="","",(X17<>"")+(AC17<>"")+(AH17<>"")) -> 1 | AL17: =IF(AH17<>"",AH17,IF(AC17<>"",AC17,IF(X17<>"",X17,""))) -> A | AM17: =IF(E17="","",IF(R17="","À SOUDER",IF(U17="","VT EN ATTENTE",IF(U17="R","VT REJETÉ – À REPRENDRE",IF(AL17="","À RADIOGRAPHIER",IF(AL17="A","ACCEPTÉ",IF(AL17="NX","NX – RT À REFAIRE",IF(IF(AK17=1,Z17,IF(AK17=2,AE17,""))="A","RÉPARÉ – À RADIOGRAPHIER",IF(IF(AK17=1,Z17,IF(AK17=2,AE17,""))="R","VT REJETÉ – À REPRENDRE",IF(OR(AL17="CO",AL17="NT"),"COUPE – À RESOUDER","À RÉPARER")))))))))) -> ACCEPTÉ | AN17: =IF(AND(ISNUMBER(R17),OR(AM17="À RADIOGRAPHIER",AM17="RÉPARÉ – À RADIOGRAPHIER",AM17="NX – RT À REFAIRE",AM17="À RÉPARER",AM17="COUPE – À RESOUDER",AM17="VT REJETÉ – À REPRENDRE")),MAX(0,'PROGRAMME RT'!$C$4-R17),"") | AO17: =IF(AND(OR(AM17="À RADIOGRAPHIER",AM17="RÉPARÉ – À RADIOGRAPHIER",AM17="NX – RT À REFAIRE"),OR('PROGRAMME RT'!$D$5="TOUTES",B17='PROGRAMME RT'!$D$5)),1,0) -> 0 | AP17: =IF(AO17=1,SUM(AO$7:AO17),"") | AQ17: =IF(AND(OR(X17="R",X17="NX",X17="NT",X17="CO"),OR('JOINTS DE RÉPARATION'!$D$5="TOUTES",B17='JOINTS DE RÉPARATION'!$D$5),OR('JOINTS DE RÉPARATION'!$L$4="TOUS",AM17<>"ACCEPTÉ")),1,0) -> 0 | AR17: =IF(AQ17=1,SUM(AQ$7:AQ17),"")
A18: =IF(E18="","",ROW()-6) -> 12 | B18: TFT 716 → TL7-MMFW2 | C18: 01 | D18: 0.00 | E18: JN°012 | F18: A | G18: 6" | H18: 11 | I18: API 5L_X60 | J18: TFT-PPL-05 | K18: Z73371 | L18: =IF(K18="","",IFERROR(INDEX(BARDAGE!$C$7:$C$1506,MATCH(K18,BARDAGE!$B$7:$B$1506,0)),"? hors registre")) -> 852405000610 | M18: Z70844 | N18: =IF(M18="","",IFERROR(INDEX(BARDAGE!$C$7:$C$1506,MATCH(M18,BARDAGE!$B$7:$B$1506,0)),"? hors registre")) -> 852404002201 | O18: WR-05 | P18: WR-05 | Q18: WR-06 | R18: 45891 | S18: 45891 | T18: VT-016 | U18: A | V18: 45893 | W18: L-RT-08 | X18: A | AK18: =IF(E18="","",(X18<>"")+(AC18<>"")+(AH18<>"")) -> 1 | AL18: =IF(AH18<>"",AH18,IF(AC18<>"",AC18,IF(X18<>"",X18,""))) -> A | AM18: =IF(E18="","",IF(R18="","À SOUDER",IF(U18="","VT EN ATTENTE",IF(U18="R","VT REJETÉ – À REPRENDRE",IF(AL18="","À RADIOGRAPHIER",IF(AL18="A","ACCEPTÉ",IF(AL18="NX","NX – RT À REFAIRE",IF(IF(AK18=1,Z18,IF(AK18=2,AE18,""))="A","RÉPARÉ – À RADIOGRAPHIER",IF(IF(AK18=1,Z18,IF(AK18=2,AE18,""))="R","VT REJETÉ – À REPRENDRE",IF(OR(AL18="CO",AL18="NT"),"COUPE – À RESOUDER","À RÉPARER")))))))))) -> ACCEPTÉ | AN18: =IF(AND(ISNUMBER(R18),OR(AM18="À RADIOGRAPHIER",AM18="RÉPARÉ – À RADIOGRAPHIER",AM18="NX – RT À REFAIRE",AM18="À RÉPARER",AM18="COUPE – À RESOUDER",AM18="VT REJETÉ – À REPRENDRE")),MAX(0,'PROGRAMME RT'!$C$4-R18),"") | AO18: =IF(AND(OR(AM18="À RADIOGRAPHIER",AM18="RÉPARÉ – À RADIOGRAPHIER",AM18="NX – RT À REFAIRE"),OR('PROGRAMME RT'!$D$5="TOUTES",B18='PROGRAMME RT'!$D$5)),1,0) -> 0 | AP18: =IF(AO18=1,SUM(AO$7:AO18),"") | AQ18: =IF(AND(OR(X18="R",X18="NX",X18="NT",X18="CO"),OR('JOINTS DE RÉPARATION'!$D$5="TOUTES",B18='JOINTS DE RÉPARATION'!$D$5),OR('JOINTS DE RÉPARATION'!$L$4="TOUS",AM18<>"ACCEPTÉ")),1,0) -> 0 | AR18: =IF(AQ18=1,SUM(AQ$7:AQ18),"")
A19: =IF(E19="","",ROW()-6) -> 13 | B19: TFT 716 → TL7-MMFW2 | C19: 01 | D19: 0.00 | E19: JN°013 | F19: A | G19: 6" | H19: 11 | I19: API 5L_X60 | J19: TFT-PPL-05 | K19: Z70844 | L19: =IF(K19="","",IFERROR(INDEX(BARDAGE!$C$7:$C$1506,MATCH(K19,BARDAGE!$B$7:$B$1506,0)),"? hors registre")) -> 852404002201 | M19: Z73375 | N19: =IF(M19="","",IFERROR(INDEX(BARDAGE!$C$7:$C$1506,MATCH(M19,BARDAGE!$B$7:$B$1506,0)),"? hors registre")) -> 852405000610 | O19: WR-05 | P19: WR-05 | Q19: WR-02 | R19: 45891 | S19: 45891 | T19: VT-016 | U19: A | V19: 45893 | W19: L-RT-08 | X19: A | AK19: =IF(E19="","",(X19<>"")+(AC19<>"")+(AH19<>"")) -> 1 | AL19: =IF(AH19<>"",AH19,IF(AC19<>"",AC19,IF(X19<>"",X19,""))) -> A | AM19: =IF(E19="","",IF(R19="","À SOUDER",IF(U19="","VT EN ATTENTE",IF(U19="R","VT REJETÉ – À REPRENDRE",IF(AL19="","À RADIOGRAPHIER",IF(AL19="A","ACCEPTÉ",IF(AL19="NX","NX – RT À REFAIRE",IF(IF(AK19=1,Z19,IF(AK19=2,AE19,""))="A","RÉPARÉ – À RADIOGRAPHIER",IF(IF(AK19=1,Z19,IF(AK19=2,AE19,""))="R","VT REJETÉ – À REPRENDRE",IF(OR(AL19="CO",AL19="NT"),"COUPE – À RESOUDER","À RÉPARER")))))))))) -> ACCEPTÉ | AN19: =IF(AND(ISNUMBER(R19),OR(AM19="À RADIOGRAPHIER",AM19="RÉPARÉ – À RADIOGRAPHIER",AM19="NX – RT À REFAIRE",AM19="À RÉPARER",AM19="COUPE – À RESOUDER",AM19="VT REJETÉ – À REPRENDRE")),MAX(0,'PROGRAMME RT'!$C$4-R19),"") | AO19: =IF(AND(OR(AM19="À RADIOGRAPHIER",AM19="RÉPARÉ – À RADIOGRAPHIER",AM19="NX – RT À REFAIRE"),OR('PROGRAMME RT'!$D$5="TOUTES",B19='PROGRAMME RT'!$D$5)),1,0) -> 0 | AP19: =IF(AO19=1,SUM(AO$7:AO19),"") | AQ19: =IF(AND(OR(X19="R",X19="NX",X19="NT",X19="CO"),OR('JOINTS DE RÉPARATION'!$D$5="TOUTES",B19='JOINTS DE RÉPARATION'!$D$5),OR('JOINTS DE RÉPARATION'!$L$4="TOUS",AM19<>"ACCEPTÉ")),1,0) -> 0 | AR19: =IF(AQ19=1,SUM(AQ$7:AQ19),"")
A20: =IF(E20="","",ROW()-6) -> 14 | B20: TFT 716 → TL7-MMFW2 | C20: 01 | D20: 0.00 | E20: JN°014 | F20: A | G20: 6" | H20: 11 | I20: API 5L_X60 | J20: TFT-PPL-05 | K20: Z73375 | L20: =IF(K20="","",IFERROR(INDEX(BARDAGE!$C$7:$C$1506,MATCH(K20,BARDAGE!$B$7:$B$1506,0)),"? hors registre")) -> 852405000610 | M20: Z68653 | N20: =IF(M20="","",IFERROR(INDEX(BARDAGE!$C$7:$C$1506,MATCH(M20,BARDAGE!$B$7:$B$1506,0)),"? hors registre")) -> 852404000882 | O20: WR-05 | P20: WR-05 | Q20: WR-02 | R20: 45876 | S20: 45876 | T20: VT-001 | U20: A | V20: 45888 | W20: L-RT-02 | X20: A | AK20: =IF(E20="","",(X20<>"")+(AC20<>"")+(AH20<>"")) -> 1 | AL20: =IF(AH20<>"",AH20,IF(AC20<>"",AC20,IF(X20<>"",X20,""))) -> A | AM20: =IF(E20="","",IF(R20="","À SOUDER",IF(U20="","VT EN ATTENTE",IF(U20="R","VT REJETÉ – À REPRENDRE",IF(AL20="","À RADIOGRAPHIER",IF(AL20="A","ACCEPTÉ",IF(AL20="NX","NX – RT À REFAIRE",IF(IF(AK20=1,Z20,IF(AK20=2,AE20,""))="A","RÉPARÉ – À RADIOGRAPHIER",IF(IF(AK20=1,Z20,IF(AK20=2,AE20,""))="R","VT REJETÉ – À REPRENDRE",IF(OR(AL20="CO",AL20="NT"),"COUPE – À RESOUDER","À RÉPARER")))))))))) -> ACCEPTÉ | AN20: =IF(AND(ISNUMBER(R20),OR(AM20="À RADIOGRAPHIER",AM20="RÉPARÉ – À RADIOGRAPHIER",AM20="NX – RT À REFAIRE",AM20="À RÉPARER",AM20="COUPE – À RESOUDER",AM20="VT REJETÉ – À REPRENDRE")),MAX(0,'PROGRAMME RT'!$C$4-R20),"") | AO20: =IF(AND(OR(AM20="À RADIOGRAPHIER",AM20="RÉPARÉ – À RADIOGRAPHIER",AM20="NX – RT À REFAIRE"),OR('PROGRAMME RT'!$D$5="TOUTES",B20='PROGRAMME RT'!$D$5)),1,0) -> 0 | AP20: =IF(AO20=1,SUM(AO$7:AO20),"") | AQ20: =IF(AND(OR(X20="R",X20="NX",X20="NT",X20="CO"),OR('JOINTS DE RÉPARATION'!$D$5="TOUTES",B20='JOINTS DE RÉPARATION'!$D$5),OR('JOINTS DE RÉPARATION'!$L$4="TOUS",AM20<>"ACCEPTÉ")),1,0) -> 0 | AR20: =IF(AQ20=1,SUM(AQ$7:AQ20),"")
A21: =IF(E21="","",ROW()-6) -> 15 | B21: TFT 716 → TL7-MMFW2 | C21: 01 | D21: 0.00 | E21: JN°015 | F21: A | G21: 6" | H21: 11 | I21: API 5L_X60 | J21: TFT-PPL-05 | K21: Z68653 | L21: =IF(K21="","",IFERROR(INDEX(BARDAGE!$C$7:$C$1506,MATCH(K21,BARDAGE!$B$7:$B$1506,0)),"? hors registre")) -> 852404000882 | M21: Z73592 | N21: =IF(M21="","",IFERROR(INDEX(BARDAGE!$C$7:$C$1506,MATCH(M21,BARDAGE!$B$7:$B$1506,0)),"? hors registre")) -> 852405000564 | O21: WR-05 | P21: WR-05 | Q21: WR-02 | R21: 45876 | S21: 45876 | T21: VT-001 | U21: A | V21: 45888 | W21: L-RT-02 | X21: A | AK21: =IF(E21="","",(X21<>"")+(AC21<>"")+(AH21<>"")) -> 1 | AL21: =IF(AH21<>"",AH21,IF(AC21<>"",AC21,IF(X21<>"",X21,""))) -> A | AM21: =IF(E21="","",IF(R21="","À SOUDER",IF(U21="","VT EN ATTENTE",IF(U21="R","VT REJETÉ – À REPRENDRE",IF(AL21="","À RADIOGRAPHIER",IF(AL21="A","ACCEPTÉ",IF(AL21="NX","NX – RT À REFAIRE",IF(IF(AK21=1,Z21,IF(AK21=2,AE21,""))="A","RÉPARÉ – À RADIOGRAPHIER",IF(IF(AK21=1,Z21,IF(AK21=2,AE21,""))="R","VT REJETÉ – À REPRENDRE",IF(OR(AL21="CO",AL21="NT"),"COUPE – À RESOUDER","À RÉPARER")))))))))) -> ACCEPTÉ | AN21: =IF(AND(ISNUMBER(R21),OR(AM21="À RADIOGRAPHIER",AM21="RÉPARÉ – À RADIOGRAPHIER",AM21="NX – RT À REFAIRE",AM21="À RÉPARER",AM21="COUPE – À RESOUDER",AM21="VT REJETÉ – À REPRENDRE")),MAX(0,'PROGRAMME RT'!$C$4-R21),"") | AO21: =IF(AND(OR(AM21="À RADIOGRAPHIER",AM21="RÉPARÉ – À RADIOGRAPHIER",AM21="NX – RT À REFAIRE"),OR('PROGRAMME RT'!$D$5="TOUTES",B21='PROGRAMME RT'!$D$5)),1,0) -> 0 | AP21: =IF(AO21=1,SUM(AO$7:AO21),"") | AQ21: =IF(AND(OR(X21="R",X21="NX",X21="NT",X21="CO"),OR('JOINTS DE RÉPARATION'!$D$5="TOUTES",B21='JOINTS DE RÉPARATION'!$D$5),OR('JOINTS DE RÉPARATION'!$L$4="TOUS",AM21<>"ACCEPTÉ")),1,0) -> 0 | AR21: =IF(AQ21=1,SUM(AQ$7:AQ21),"")
A22: =IF(E22="","",ROW()-6) -> 16 | B22: TFT 716 → TL7-MMFW2 | C22: 01 | D22: 0.00 | E22: JN°016 | F22: D | G22: 6" | H22: 11 | I22: API 5L_X60 | J22: TFT-PPL-05 | K22: Z73592 | L22: =IF(K22="","",IFERROR(INDEX(BARDAGE!$C$7:$C$1506,MATCH(K22,BARDAGE!$B$7:$B$1506,0)),"? hors registre")) -> 852405000564 | M22: Z73593 | N22: =IF(M22="","",IFERROR(INDEX(BARDAGE!$C$7:$C$1506,MATCH(M22,BARDAGE!$B$7:$B$1506,0)),"? hors registre")) -> 852405000564 | O22: WR-05 | P22: WR-05 | Q22: WR-02 | R22: 45876 | S22: 45876 | T22: VT-001 | U22: A | V22: 45888 | W22: L-RT-02 | X22: A | AK22: =IF(E22="","",(X22<>"")+(AC22<>"")+(AH22<>"")) -> 1 | AL22: =IF(AH22<>"",AH22,IF(AC22<>"",AC22,IF(X22<>"",X22,""))) -> A | AM22: =IF(E22="","",IF(R22="","À SOUDER",IF(U22="","VT EN ATTENTE",IF(U22="R","VT REJETÉ – À REPRENDRE",IF(AL22="","À RADIOGRAPHIER",IF(AL22="A","ACCEPTÉ",IF(AL22="NX","NX – RT À REFAIRE",IF(IF(AK22=1,Z22,IF(AK22=2,AE22,""))="A","RÉPARÉ – À RADIOGRAPHIER",IF(IF(AK22=1,Z22,IF(AK22=2,AE22,""))="R","VT REJETÉ – À REPRENDRE",IF(OR(AL22="CO",AL22="NT"),"COUPE – À RESOUDER","À RÉPARER")))))))))) -> ACCEPTÉ | AN22: =IF(AND(ISNUMBER(R22),OR(AM22="À RADIOGRAPHIER",AM22="RÉPARÉ – À RADIOGRAPHIER",AM22="NX – RT À REFAIRE",AM22="À RÉPARER",AM22="COUPE – À RESOUDER",AM22="VT REJETÉ – À REPRENDRE")),MAX(0,'PROGRAMME RT'!$C$4-R22),"") | AO22: =IF(AND(OR(AM22="À RADIOGRAPHIER",AM22="RÉPARÉ – À RADIOGRAPHIER",AM22="NX – RT À REFAIRE"),OR('PROGRAMME RT'!$D$5="TOUTES",B22='PROGRAMME RT'!$D$5)),1,0) -> 0 | AP22: =IF(AO22=1,SUM(AO$7:AO22),"") | AQ22: =IF(AND(OR(X22="R",X22="NX",X22="NT",X22="CO"),OR('JOINTS DE RÉPARATION'!$D$5="TOUTES",B22='JOINTS DE RÉPARATION'!$D$5),OR('JOINTS DE RÉPARATION'!$L$4="TOUS",AM22<>"ACCEPTÉ")),1,0) -> 0 | AR22: =IF(AQ22=1,SUM(AQ$7:AQ22),"")
A23: =IF(E23="","",ROW()-6) -> 17 | B23: TFT 716 → TL7-MMFW2 | C23: 01 | D23: 0.00 | E23: JN°017 | F23: D | G23: 6" | H23: 11 | I23: API 5L_X60 | J23: TFT-PPL-05 | K23: Z73593 | L23: =IF(K23="","",IFERROR(INDEX(BARDAGE!$C$7:$C$1506,MATCH(K23,BARDAGE!$B$7:$B$1506,0)),"? hors registre")) -> 852405000564 | M23: Z71179 | N23: =IF(M23="","",IFERROR(INDEX(BARDAGE!$C$7:$C$1506,MATCH(M23,BARDAGE!$B$7:$B$1506,0)),"? hors registre")) -> 852404002201 | O23: WR-05 | P23: WR-05 | Q23: WR-02 | R23: 45876 | S23: 45876 | T23: VT-001 | U23: A | V23: 45888 | W23: L-RT-02 | X23: A | AK23: =IF(E23="","",(X23<>"")+(AC23<>"")+(AH23<>"")) -> 1 | AL23: =IF(AH23<>"",AH23,IF(AC23<>"",AC23,IF(X23<>"",X23,""))) -> A | AM23: =IF(E23="","",IF(R23="","À SOUDER",IF(U23="","VT EN ATTENTE",IF(U23="R","VT REJETÉ – À REPRENDRE",IF(AL23="","À RADIOGRAPHIER",IF(AL23="A","ACCEPTÉ",IF(AL23="NX","NX – RT À REFAIRE",IF(IF(AK23=1,Z23,IF(AK23=2,AE23,""))="A","RÉPARÉ – À RADIOGRAPHIER",IF(IF(AK23=1,Z23,IF(AK23=2,AE23,""))="R","VT REJETÉ – À REPRENDRE",IF(OR(AL23="CO",AL23="NT"),"COUPE – À RESOUDER","À RÉPARER")))))))))) -> ACCEPTÉ | AN23: =IF(AND(ISNUMBER(R23),OR(AM23="À RADIOGRAPHIER",AM23="RÉPARÉ – À RADIOGRAPHIER",AM23="NX – RT À REFAIRE",AM23="À RÉPARER",AM23="COUPE – À RESOUDER",AM23="VT REJETÉ – À REPRENDRE")),MAX(0,'PROGRAMME RT'!$C$4-R23),"") | AO23: =IF(AND(OR(AM23="À RADIOGRAPHIER",AM23="RÉPARÉ – À RADIOGRAPHIER",AM23="NX – RT À REFAIRE"),OR('PROGRAMME RT'!$D$5="TOUTES",B23='PROGRAMME RT'!$D$5)),1,0) -> 0 | AP23: =IF(AO23=1,SUM(AO$7:AO23),"") | AQ23: =IF(AND(OR(X23="R",X23="NX",X23="NT",X23="CO"),OR('JOINTS DE RÉPARATION'!$D$5="TOUTES",B23='JOINTS DE RÉPARATION'!$D$5),OR('JOINTS DE RÉPARATION'!$L$4="TOUS",AM23<>"ACCEPTÉ")),1,0) -> 0 | AR23: =IF(AQ23=1,SUM(AQ$7:AQ23),"")
... A51: =IF(E51="","",ROW()-6) -> 45 | B51: TFT 716 → TL7-MMFW2 | C51: 03 | D51: 0.00 | E51: JN°044 | F51: D | G51: 6" | H51: 11 | I51: API 5L_X60 | J51: TFT-PPL-05 | K51: Z71080 | L51: =IF(K51="","",IFERROR(INDEX(BARDAGE!$C$7:$C$1506,MATCH(K51,BARDAGE!$B$7:$B$1506,0)),"? hors registre")) -> 24703643 | M51: Z70792 | N51: =IF(M51="","",IFERROR(INDEX(BARDAGE!$C$7:$C$1506,MATCH(M51,BARDAGE!$B$7:$B$1506,0)),"? hors registre")) -> 24803600 | O51: WR-05 | P51: WR-05 | Q51: WR-06 | R51: 45878 | S51: 45878 | T51: VT-003 | U51: A | V51: 45889 | W51: L-RT-03 | X51: A | AK51: =IF(E51="","",(X51<>"")+(AC51<>"")+(AH51<>"")) -> 1 | AL51: =IF(AH51<>"",AH51,IF(AC51<>"",AC51,IF(X51<>"",X51,""))) -> A | AM51: =IF(E51="","",IF(R51="","À SOUDER",IF(U51="","VT EN ATTENTE",IF(U51="R","VT REJETÉ – À REPRENDRE",IF(AL51="","À RADIOGRAPHIER",IF(AL51="A","ACCEPTÉ",IF(AL51="NX","NX – RT À REFAIRE",IF(IF(AK51=1,Z51,IF(AK51=2,AE51,""))="A","RÉPARÉ – À RADIOGRAPHIER",IF(IF(AK51=1,Z51,IF(AK51=2,AE51,""))="R","VT REJETÉ – À REPRENDRE",IF(OR(AL51="CO",AL51="NT"),"COUPE – À RESOUDER","À RÉPARER")))))))))) -> ACCEPTÉ | AN51: =IF(AND(ISNUMBER(R51),OR(AM51="À RADIOGRAPHIER",AM51="RÉPARÉ – À RADIOGRAPHIER",AM51="NX – RT À REFAIRE",AM51="À RÉPARER",AM51="COUPE – À RESOUDER",AM51="VT REJETÉ – À REPRENDRE")),MAX(0,'PROGRAMME RT'!$C$4-R51),"") | AO51: =IF(AND(OR(AM51="À RADIOGRAPHIER",AM51="RÉPARÉ – À RADIOGRAPHIER",AM51="NX – RT À REFAIRE"),OR('PROGRAMME RT'!$D$5="TOUTES",B51='PROGRAMME RT'!$D$5)),1,0) -> 0 | AP51: =IF(AO51=1,SUM(AO$7:AO51),"") | AQ51: =IF(AND(OR(X51="R",X51="NX",X51="NT",X51="CO"),OR('JOINTS DE RÉPARATION'!$D$5="TOUTES",B51='JOINTS DE RÉPARATION'!$D$5),OR('JOINTS DE RÉPARATION'!$L$4="TOUS",AM51<>"ACCEPTÉ")),1,0) -> 0 | AR51: =IF(AQ51=1,SUM(AQ$7:AQ51),"")
A52: =IF(E52="","",ROW()-6) -> 46 | B52: TFT 716 → TL7-MMFW2 | D52: 0.00 | E52: JN°045Racc | F52: D | G52: 6" | H52: 11 | I52: API 5L_X60 | J52: TFT-PPL-06 | K52: Z70792 | L52: =IF(K52="","",IFERROR(INDEX(BARDAGE!$C$7:$C$1506,MATCH(K52,BARDAGE!$B$7:$B$1506,0)),"? hors registre")) -> 24803600 | M52: Z69291 | N52: =IF(M52="","",IFERROR(INDEX(BARDAGE!$C$7:$C$1506,MATCH(M52,BARDAGE!$B$7:$B$1506,0)),"? hors registre")) -> 24803596 | O52: WR-09 | P52: WR-09 | Q52: WR-09 | R52: 45909 | S52: 45909 | T52: VT-022 | U52: A | AK52: =IF(E52="","",(X52<>"")+(AC52<>"")+(AH52<>"")) -> 0 | AL52: =IF(AH52<>"",AH52,IF(AC52<>"",AC52,IF(X52<>"",X52,""))) | AM52: =IF(E52="","",IF(R52="","À SOUDER",IF(U52="","VT EN ATTENTE",IF(U52="R","VT REJETÉ – À REPRENDRE",IF(AL52="","À RADIOGRAPHIER",IF(AL52="A","ACCEPTÉ",IF(AL52="NX","NX – RT À REFAIRE",IF(IF(AK52=1,Z52,IF(AK52=2,AE52,""))="A","RÉPARÉ – À RADIOGRAPHIER",IF(IF(AK52=1,Z52,IF(AK52=2,AE52,""))="R","VT REJETÉ – À REPRENDRE",IF(OR(AL52="CO",AL52="NT"),"COUPE – À RESOUDER","À RÉPARER")))))))))) -> À RADIOGRAPHIER | AN52: =IF(AND(ISNUMBER(R52),OR(AM52="À RADIOGRAPHIER",AM52="RÉPARÉ – À RADIOGRAPHIER",AM52="NX – RT À REFAIRE",AM52="À RÉPARER",AM52="COUPE – À RESOUDER",AM52="VT REJETÉ – À REPRENDRE")),MAX(0,'PROGRAMME RT'!$C$4-R52),"") -> 384 | AO52: =IF(AND(OR(AM52="À RADIOGRAPHIER",AM52="RÉPARÉ – À RADIOGRAPHIER",AM52="NX – RT À REFAIRE"),OR('PROGRAMME RT'!$D$5="TOUTES",B52='PROGRAMME RT'!$D$5)),1,0) -> 1 | AP52: =IF(AO52=1,SUM(AO$7:AO52),"") -> 1 | AQ52: =IF(AND(OR(X52="R",X52="NX",X52="NT",X52="CO"),OR('JOINTS DE RÉPARATION'!$D$5="TOUTES",B52='JOINTS DE RÉPARATION'!$D$5),OR('JOINTS DE RÉPARATION'!$L$4="TOUS",AM52<>"ACCEPTÉ")),1,0) -> 0 | AR52: =IF(AQ52=1,SUM(AQ$7:AQ52),"")
