Workbook
Name Liste_OUV: OFFSET(Listes!$O$2,0,0,MAX(1,COUNTIF(Listes!$O$2:$O$501,"?*")),1)
Name Liste_PIS: OFFSET(Listes!$P$2,0,0,MAX(1,COUNTIF(Listes!$P$2:$P$501,"?*")),1)
Name Liste_BAR: OFFSET(Listes!$Q$2,0,0,MAX(1,COUNTIF(Listes!$Q$2:$Q$501,"?*")),1)
Name Liste_CIN: OFFSET(Listes!$R$2,0,0,MAX(1,COUNTIF(Listes!$R$2:$R$501,"?*")),1)
Name Liste_ENR: OFFSET(Listes!$S$2,0,0,MAX(1,COUNTIF(Listes!$S$2:$S$501,"?*")),1)
Name Liste_LIT: OFFSET(Listes!$T$2,0,0,MAX(1,COUNTIF(Listes!$T$2:$T$501,"?*")),1)
Name Liste_MEF: OFFSET(Listes!$U$2,0,0,MAX(1,COUNTIF(Listes!$U$2:$U$501,"?*")),1)
Name Liste_PRE: OFFSET(Listes!$V$2,0,0,MAX(1,COUNTIF(Listes!$V$2:$V$501,"?*")),1)
Name Liste_RFI: OFFSET(Registre!$B$2,0,0,MAX(1,COUNTA(Registre!$B$2:$B$2001)),1)

Sheet Mode d'emploi
B2: REGISTRE QA/QC – PV & RFI (sans macro)
B4: 1. Saisie
B5: • Feuille « Registre » : une ligne par inspection. Choisissez le Type, saisissez le RFI No (unique), le N° de rapport, l'ouvrage, le plan, la désignation, le tronçon et la conclusion.
B6: • Feuilles grises « Données … » / « Tubes Bardage » / « Joints Enrobage » : informations propres à certains PV (une ligne par RFI, ou une ligne par tube / joint).
B8: 2. Édition
B9: • Ouvrez la feuille du PV (onglets bleus) ou la feuille « RFI » (onglet rouge).
B10: • Cliquez sur la case jaune et choisissez le RFI No : la liste ne propose que les RFI du bon type, et la fiche se remplit automatiquement.
B11: • Imprimez (Ctrl+P) ou Fichier > Exporter > PDF : la fiche tient sur une page A4.
B13: 3. Cases à cocher
B14: • La conclusion (Accepté / Rejeté / Non applicable) saisie dans le Registre coche automatiquement la bonne case.
B15: • Les points d'inspection sans colonne dédiée sont cochés « C » quand la conclusion est « Accepté » ; sinon ils restent vides pour être cochés à la main.
B17: 4. Paramètres
... B23: • Les colonnes sont au format Texte : les zéros de « 0001 » sont conservés.

Sheet Registre
A1: Type | B1: RFI No | C1: N° Rapport | D1: Date d'inspection | E1: Ouvrage | F1: Plan nº | G1: Désignation | H1: Tronçon N° | I1: Joint début | J1: Joint fin | K1: PK début | L1: PK fin | M1: Longueur (ml) | N1: Conclusion | O1: Remarques | P1: Discipline (RFI) | Q1: Lieu (RFI) – vide = Ouvrage | R1: Item No (RFI) | S1: Heure (RFI) | T1: Description (RFI) – vide = Désignation | U1: CST | V1: QCI | W1: C1 | X1: CA | Y1: TPI1 | Z1: TPI2 | AA1: Clé (auto)
A2: Ouverture de la tranchée | B2: 21063-G26-PPL-RFI-0016 | C2: 0001 | E2: TRUNKLINE FROM ISW MFD TO TFTⅡCPF | F2: 21061-0000-PPL-TDW-0009 | G2: Ouverture de la tranchée | K2: 23+350 | L2: 23+800 | P2: PPL | U2: P | V2: P | W2: W | X2: W | Y2: - | Z2: - | AA2: =IF(A2="","",A2&"|"&COUNTIF($A$2:A2,A2))
A3: Ouverture de la tranchée | B3: 21063-G26-PPL-RFI-0062 | D3: 46152 | E3: TRUNKLINE FROM ISW MFD TO TFTⅡCPF | G3: Inspection final de la tranchée | P3: PPL | Q3: TRUNKLINE FROM ISW MFD TO TFTⅡCPF PK (9+380 au 9+700 et 11+078 au 114+430) | R3: 04 | S3: 14 :00 | U3: P | V3: P | W3: W | X3: W | Y3: - | Z3: - | AA3: =IF(A3="","",A3&"|"&COUNTIF($A$2:A3,A3))
A4: Piste de travail | B4: 21063-G26-PPL-RFI-0002 | C4: 0001 | E4: TRUNKLINE FROM ISW MFD TO TFTⅡCPF | F4: 21061-0000-PPL-TDW-0008 | G4: Inspection final de la Piste de travail | K4: 018+650 | L4: 019+450 | P4: PPL | U4: P | V4: P | W4: W | X4: W | Y4: - | Z4: - | AA4: =IF(A4="","",A4&"|"&COUNTIF($A$2:A4,A4))
A5: Transport et bardage | B5: 21063-G2-PPL-RFI-0050 | C5: 0014 | E5: ISB-302 to MFD ISB | F5: 21063-G0-PPL-PR-0009 | G5: Bardage de pipe | K5: 0+100 | L5: 0+320 | P5: PPL | U5: P | V5: P | W5: W | X5: W | Y5: - | Z5: - | AA5: =IF(A5="","",A5&"|"&COUNTIF($A$2:A5,A5))
A6: Cintrage | B6: 21063-G26-PPL-RFI-00188 | C6: 0001 | E6: ISW TO CPF pk 22+902 | F6: 21061-0000-PPL-SPC-0008 | G6: Cintrage à Froid de pipe 16" Api 5L X52 | P6: PPL | U6: P | V6: P | W6: W | X6: W | Y6: - | Z6: - | AA6: =IF(A6="","",A6&"|"&COUNTIF($A$2:A6,A6))
A7: Enrobage | B7: 21063-G26-PPL-RFI-0194 | C7: 38 | D7: 46295 | E7: TRUNKLINE FROM CPF TO ISW MFD | F7: 21061-0000-COP-SPC-0005 | G7: Enrobage des joints de soudage | H7: 13 | K7: 19+600 | L7: 16+000 | M7: 135 | P7: PPL | U7: P | V7: P | W7: W | X7: W | Y7: - | Z7: - | AA7: =IF(A7="","",A7&"|"&COUNTIF($A$2:A7,A7))
A8: Lit de pose | B8: 0197 | C8: 01 | E8: trunkline From CPF To ISW MFD | F8: 21061-0000-PPL-TDW-0009 | G8: Lit de pose | H8: 01 – 02 - 03 | I8: 38 | K8: 24+000 | M8: 645.3 | P8: PPL | U8: P | V8: P | W8: W | X8: W | Y8: - | Z8: - | AA8: =IF(A8="","",A8&"|"&COUNTIF($A$2:A8,A8))
A9: Mise en fouille | B9: 0127 | C9: 02 | E9: Flowline From ISB 302z To ISB MFD | F9: 21063-G0-PPL-PR-0011 | G9: Inspection Préparation pour la mise en fouille des tronçons de canalisation | H9: 02 | I9: 013 | J9: 087 | K9: 0 | L9: 1 | M9: 995.55 | P9: PPL | U9: P | V9: P | W9: W | X9: W | Y9: - | Z9: - | AA9: =IF(A9="","",A9&"|"&COUNTIF($A$2:A9,A9))
A10: Pré-remblai | B10: 0195 | C10: 001 | E10: FLOWLINE FROM ISB 303 TO ISB MFD | F10: 21061-0000-PPL-SPC-0006 | G10: Pose de Petit-remblai | K10: 0+020 | L10: 0+590 | M10: 570 | P10: PPL | U10: P | V10: P | W10: W | X10: W | Y10: - | Z10: - | AA10: =IF(A10="","",A10&"|"&COUNTIF($A$2:A10,A10))
AA11: =IF(A11="","",A11&"|"&COUNTIF($A$2:A11,A11))
AA12: =IF(A12="","",A12&"|"&COUNTIF($A$2:A12,A12))
AA13: =IF(A13="","",A13&"|"&COUNTIF($A$2:A13,A13))
AA14: =IF(A14="","",A14&"|"&COUNTIF($A$2:A14,A14))
AA15: =IF(A15="","",A15&"|"&COUNTIF($A$2:A15,A15))
AA16: =IF(A16="","",A16&"|"&COUNTIF($A$2:A16,A16))
AA17: =IF(A17="","",A17&"|"&COUNTIF($A$2:A17,A17))
AA18: =IF(A18="","",A18&"|"&COUNTIF($A$2:A18,A18))
AA19: =IF(A19="","",A19&"|"&COUNTIF($A$2:A19,A19))
AA20: =IF(A20="","",A20&"|"&COUNTIF($A$2:A20,A20))
AA21: =IF(A21="","",A21&"|"&COUNTIF($A$2:A21,A21))
AA22: =IF(A22="","",A22&"|"&COUNTIF($A$2:A22,A22))
... AA2001: =IF(A2001="","",A2001&"|"&COUNTIF($A$2:A2001,A2001))

Sheet RFI
C1: =Paramètres!$C$2 | I1: =Paramètres!$D$2 | L1: Calcul (ne pas modifier) – ligne registre :
I2: ="Date: "&Paramètres!$E$2 | L2: =IFERROR(MATCH($G$5,Registre!$B$2:$B$2001,0),0)
I3: Page 1/1
A4: Demande d’inspection ( RFI )
A5: ="Discipline : "&IFERROR(INDEX(Registre!$P$2:$P$2001,$L$2)&"","") | F5: RFI No: | G5: 21063-G26-PPL-RFI-0062
A6: ="Date d'inspection : "&IFERROR(TEXT(INDEX(Registre!$D$2:$D$2001,$L$2),"dd/mm/yyyy"),"") | L6: ◀ Choisissez le RFI dans la case jaune
A7: ="Lieu : "&IF(IFERROR(INDEX(Registre!$Q$2:$Q$2001,$L$2)&"","")<>"",IFERROR(INDEX(Registre!$Q$2:$Q$2001,$L$2)&"",""),IFERROR(INDEX(Registre!$E$2:$E$2001,$L$2)&"",""))
A8: Heure de réception | C8: CPECC QA/QC | G8: GTFT QA/QC
C9: Nom/Date : | G9: Nom/Date :
A10: Item No. | B10: heure | C10: Description de l'inspection | E10: Point d'inspection
E11: C3 | G11: C1 | H11: CA | I11: TPI1 | J11: TPI2
E12: CST | F12: QCI
A13: =IFERROR(INDEX(Registre!$R$2:$R$2001,$L$2)&"","") | B13: =IFERROR(INDEX(Registre!$S$2:$S$2001,$L$2)&"","") | C13: =IF(IFERROR(INDEX(Registre!$T$2:$T$2001,$L$2)&"","")<>"",IFERROR(INDEX(Registre!$T$2:$T$2001,$L$2)&"",""),IFERROR(INDEX(Registre!$G$2:$G$2001,$L$2)&"","")) | E13: =IFERROR(INDEX(Registre!$U$2:$U$2001,$L$2)&"","") | F13: =IFERROR(INDEX(Registre!$V$2:$V$2001,$L$2)&"","") | G13: =IFERROR(INDEX(Registre!$W$2:$W$2001,$L$2)&"","") | H13: =IFERROR(INDEX(Registre!$X$2:$X$2001,$L$2)&"","") | I13: =IFERROR(INDEX(Registre!$Y$2:$Y$2001,$L$2)&"","") | J13: =IFERROR(INDEX(Registre!$Z$2:$Z$2001,$L$2)&"","")
A14: CONCLUSION DE L'INSPECTION
A15: PV No. | B15: =IF(IFERROR(INDEX(Registre!$C$2:$C$2001,$L$2)&"","")="","",IFERROR(INDEX(Registre!$A$2:$A$2001,$L$2)&"","")&" – Rapport nº "&IFERROR(INDEX(Registre!$C$2:$C$2001,$L$2)&"",""))
A16: =IF(IFERROR(INDEX(Registre!$N$2:$N$2001,$L$2)&"","")="Accepté","☒","☐")&" Approuvé" | D16: =IF(IFERROR(INDEX(Registre!$N$2:$N$2001,$L$2)&"","")="Approuvé avec commentaires","☒","☐")&" Approuvé avec commentaires" | H16: =IF(IFERROR(INDEX(Registre!$N$2:$N$2001,$L$2)&"","")="Rejeté","☒","☐")&" Rejeté"
A17: ="Remarques : "&IFERROR(INDEX(Registre!$O$2:$O$2001,$L$2)&"","")
A18: APPROBATION | C18: C3 | G18: C1 | I18: CA
C19: CST | E19: QCI
A20: Nom
A21: Signature
A22: Date

Sheet PV Ouverture
C1: =Paramètres!$C$3 | I1: =Paramètres!$D$3 | L1: Calcul (ne pas modifier) – ligne registre :
I2: ="Date: "&Paramètres!$E$3 | L2: =IFERROR(MATCH($H$8,Registre!$B$2:$B$2001,0),0)
I3: Page 1/1 | L3: =IFERROR(MATCH($H$8,'Données Ouverture'!$A$2:$A$501,0),0)
A4: PROCÈS-VERBAL OUVERTURE DE LA TRANCHÉE | L4: =IF($H$8="","",IF($L$2=0,"⚠ RFI absent du Registre",IF(INDEX(Registre!$A$2:$A$2001,$L$2)<>"Ouverture de la tranchée","⚠ Ce RFI est de type : "&INDEX(Registre!$A$2:$A$2001,$L$2),"")))
A5: Ouvrages | C5: =IFERROR(INDEX(Registre!$E$2:$E$2001,$L$2)&"","")
A6: Plan nº | C6: =IFERROR(INDEX(Registre!$F$2:$F$2001,$L$2)&"","") | L6: ◀ Choisissez le RFI dans la case jaune
A7: Désignation | C7: =IFERROR(INDEX(Registre!$G$2:$G$2001,$L$2)&"","")
A8: Rapport nº | C8: =IFERROR(INDEX(Registre!$C$2:$C$2001,$L$2)&"","") | E8: RFI nº | H8: 21063-G26-PPL-RFI-0016
A9: ="Tronçon n° : "&IFERROR(INDEX(Registre!$H$2:$H$2001,$L$2)&"","")&" du "&IF(IFERROR(INDEX(Registre!$I$2:$I$2001,$L$2)&"","")<>"","Joint N° "&IFERROR(INDEX(Registre!$I$2:$I$2001,$L$2)&"","")&" ","")&"PK "&IFERROR(INDEX(Registre!$K$2:$K$2001,$L$2)&"","")&IF(OR(IFERROR(INDEX(Registre!$L$2:$L$2001,$L$2)&"","")<>"",IFERROR(INDEX(Registre!$J$2:$J$2001,$L$2)&"","")<>"")," au "&IF(IFERROR(INDEX(Registre!$J$2:$J$2001,$L$2)&"","")<>"","Joint N° "&IFERROR(INDEX(Registre!$J$2:$J$2001,$L$2)&"","")&" ","")&IF(IFERROR(INDEX(Registre!$L$2:$L$2001,$L$2)&"","")<>"","PK "&IFERROR(INDEX(Registre!$L$2:$L$2001,$L$2)&"",""),""),"") | I9: =IF(IFERROR(INDEX(Registre!$M$2:$M$2001,$L$2)&"","")="","Long :","Long : "&IFERROR(INDEX(Registre!$M$2:$M$2001,$L$2)&"","")&" ml")
A10: Inspection | I10: jugement
A11: Vérification de la profondeur de la tranchée selon diamètre de pipe et zone | I11: =IF(IFERROR(INDEX('Données Ouverture'!$B$2:$B$501,$L$3)&"","")="C","☒","☐")&" C"&" "&IF(IFERROR(INDEX('Données Ouverture'!$B$2:$B$501,$L$3)&"","")="NC","☒","☐")&" NC"
A12: Vérification de la largeur de la tranchée | I12: =IF(IFERROR(INDEX('Données Ouverture'!$C$2:$C$501,$L$3)&"","")="C","☒","☐")&" C"&" "&IF(IFERROR(INDEX('Données Ouverture'!$C$2:$C$501,$L$3)&"","")="NC","☒","☐")&" NC"
A13: ="Nature du terrain : "&IF(IFERROR(INDEX('Données Ouverture'!$D$2:$D$501,$L$3)&"","")="Dune de sable","☒","☐")&" Dune de sable"&" "&IF(IFERROR(INDEX('Données Ouverture'!$D$2:$D$501,$L$3)&"","")="Rocheux","☒","☐")&" Rocheux"&" "&IF(IFERROR(INDEX('Données Ouverture'!$D$2:$D$501,$L$3)&"","")="semi rocheux","☒","☐")&" semi rocheux"&" "&IF(IFERROR(INDEX('Données Ouverture'!$D$2:$D$501,$L$3)&"","")="Autres","☒","☐")&" Autres"
A14: ="Remarques : "&IFERROR(INDEX(Registre!$O$2:$O$2001,$L$2)&"","")
A15: Conclusion de l’inspection | C15: =IF(IFERROR(INDEX(Registre!$N$2:$N$2001,$L$2)&"","")="Non applicable","☒","☐")&" Non applicable" | G15: =IF(IFERROR(INDEX(Registre!$N$2:$N$2001,$L$2)&"","")="Accepté","☒","☐")&" Accepté" | I15: =IF(IFERROR(INDEX(Registre!$N$2:$N$2001,$L$2)&"","")="Rejeté","☒","☐")&" Rejeté"
A16: APPROBATION | C16: C3 | G16: C1 | I16: CA
C17: CST | E17: QCI
A18: Nom
A19: Signature
A20: Date

Sheet PV Piste
C1: =Paramètres!$C$4 | I1: =Paramètres!$D$4 | L1: Calcul (ne pas modifier) – ligne registre :
I2: ="Date: "&Paramètres!$E$4 | L2: =IFERROR(MATCH($H$8,Registre!$B$2:$B$2001,0),0)
I3: Page 1/1 | L3: =IFERROR(MATCH($H$8,'Données Piste'!$A$2:$A$501,0),0)
A4: PROCÈS VERBAL D’AMENAGEMENT DE LA PISTE DE TRAVAIL / PISTE DE SERVICE | L4: =IF($H$8="","",IF($L$2=0,"⚠ RFI absent du Registre",IF(INDEX(Registre!$A$2:$A$2001,$L$2)<>"Piste de travail","⚠ Ce RFI est de type : "&INDEX(Registre!$A$2:$A$2001,$L$2),"")))
A5: Ouvrages | C5: =IFERROR(INDEX(Registre!$E$2:$E$2001,$L$2)&"","")
A6: Plan nº | C6: =IFERROR(INDEX(Registre!$F$2:$F$2001,$L$2)&"","") | L6: ◀ Choisissez le RFI dans la case jaune
A7: Désignation | C7: =IFERROR(INDEX(Registre!$G$2:$G$2001,$L$2)&"","")
A8: Rapport nº | C8: =IFERROR(INDEX(Registre!$C$2:$C$2001,$L$2)&"","") | E8: RFI nº | H8: 21063-G26-PPL-RFI-0002
A9: ="Tronçon n° : "&IFERROR(INDEX(Registre!$H$2:$H$2001,$L$2)&"","")&" du "&IF(IFERROR(INDEX(Registre!$I$2:$I$2001,$L$2)&"","")<>"","Joint N° "&IFERROR(INDEX(Registre!$I$2:$I$2001,$L$2)&"","")&" ","")&"PK "&IFERROR(INDEX(Registre!$K$2:$K$2001,$L$2)&"","")&IF(OR(IFERROR(INDEX(Registre!$L$2:$L$2001,$L$2)&"","")<>"",IFERROR(INDEX(Registre!$J$2:$J$2001,$L$2)&"","")<>"")," au "&IF(IFERROR(INDEX(Registre!$J$2:$J$2001,$L$2)&"","")<>"","Joint N° "&IFERROR(INDEX(Registre!$J$2:$J$2001,$L$2)&"","")&" ","")&IF(IFERROR(INDEX(Registre!$L$2:$L$2001,$L$2)&"","")<>"","PK "&IFERROR(INDEX(Registre!$L$2:$L$2001,$L$2)&"",""),""),"") | I9: =IF(IFERROR(INDEX(Registre!$M$2:$M$2001,$L$2)&"","")="","Long :","Long : "&IFERROR(INDEX(Registre!$M$2:$M$2001,$L$2)&"","")&" ml")
A10: ="Type de végétation : "&IF(IFERROR(INDEX('Données Piste'!$B$2:$B$501,$L$3)&"","")="Zone dégagée","☒","☐")&" Zone dégagée"&" "&IF(IFERROR(INDEX('Données Piste'!$B$2:$B$501,$L$3)&"","")="Cultivée","☒","☐")&" Cultivée"&" "&IF(IFERROR(INDEX('Données Piste'!$B$2:$B$501,$L$3)&"","")="Désertique","☒","☐")&" Désertique"&" "&IF(IFERROR(INDEX('Données Piste'!$B$2:$B$501,$L$3)&"","")="Marécageuses","☒","☐")&" Marécageuses"&" "&IF(IFERROR(INDEX('Données Piste'!$B$2:$B$501,$L$3)&"","")="Bois","☒","☐")&" Bois"&" "&IF(IFERROR(INDEX('Données Piste'!$B$2:$B$501,$L$3)&"","")="Autres","☒","☐")&" Autres"
A11: ="Nature de terrain : "&IF(IFERROR(INDEX('Données Piste'!$C$2:$C$501,$L$3)&"","")="nature","☒","☐")&" nature"&" "&IF(IFERROR(INDEX('Données Piste'!$C$2:$C$501,$L$3)&"","")="Relief","☒","☐")&" Relief"&" "&IF(IFERROR(INDEX('Données Piste'!$C$2:$C$501,$L$3)&"","")="Terrain désertique","☒","☐")&" Terrain désertique"&" "&IF(IFERROR(INDEX('Données Piste'!$C$2:$C$501,$L$3)&"","")="dunes de sable","☒","☐")&" dunes de sable"
A12: Certificat des matériaux utilisés | G12: =IF(IFERROR(INDEX('Données Piste'!$D$2:$D$501,$L$3)&"","")="Oui","☒","☐")&" Oui"&" "&IF(IFERROR(INDEX('Données Piste'!$D$2:$D$501,$L$3)&"","")="Non","☒","☐")&" Non"&" "&IF(IFERROR(INDEX('Données Piste'!$D$2:$D$501,$L$3)&"","")="NA","☒","☐")&" NA"
A13: Compactage selon spec projet | G13: =IF(IFERROR(INDEX('Données Piste'!$E$2:$E$501,$L$3)&"","")="Oui","☒","☐")&" Oui"&" "&IF(IFERROR(INDEX('Données Piste'!$E$2:$E$501,$L$3)&"","")="Non","☒","☐")&" Non"&" "&IF(IFERROR(INDEX('Données Piste'!$E$2:$E$501,$L$3)&"","")="NA","☒","☐")&" NA"
A14: Marquage et repérage de la limite de la piste | G14: =IF(IFERROR(INDEX('Données Piste'!$F$2:$F$501,$L$3)&"","")="C","☒","☐")&" C"&" "&IF(IFERROR(INDEX('Données Piste'!$F$2:$F$501,$L$3)&"","")="NC","☒","☐")&" NC"
A15: Largeur de la piste | G15: =IF(IFERROR(INDEX('Données Piste'!$G$2:$G$501,$L$3)&"","")="C","☒","☐")&" C"&" "&IF(IFERROR(INDEX('Données Piste'!$G$2:$G$501,$L$3)&"","")="NC","☒","☐")&" NC"
A16: Localisation et Protection des Installations Existantes | G16: =IF(IFERROR(INDEX('Données Piste'!$H$2:$H$501,$L$3)&"","")="C","☒","☐")&" C"&" "&IF(IFERROR(INDEX('Données Piste'!$H$2:$H$501,$L$3)&"","")="NC","☒","☐")&" NC"&" "&IF(IFERROR(INDEX('Données Piste'!$H$2:$H$501,$L$3)&"","")="NA","☒","☐")&" NA"
A17: ="Remarques : "&IFERROR(INDEX(Registre!$O$2:$O$2001,$L$2)&"","")
A18: Conclusion de l’inspection | C18: =IF(IFERROR(INDEX(Registre!$N$2:$N$2001,$L$2)&"","")="Non applicable","☒","☐")&" Non applicable" | G18: =IF(IFERROR(INDEX(Registre!$N$2:$N$2001,$L$2)&"","")="Accepté","☒","☐")&" Accepté" | I18: =IF(IFERROR(INDEX(Registre!$N$2:$N$2001,$L$2)&"","")="Rejeté","☒","☐")&" Rejeté"
A19: APPROBATION | C19: C3 | G19: C1 | I19: CA
C20: CST | E20: QCI
A21: Nom
A22: Signature
A23: Date

Sheet PV Bardage
C1: =Paramètres!$C$5 | I1: =Paramètres!$D$5 | L1: Calcul (ne pas modifier) – ligne registre :
I2: ="Date: "&Paramètres!$E$5 | L2: =IFERROR(MATCH($H$8,Registre!$B$2:$B$2001,0),0)
I3: Page 1/1
A4: Procès-Verbal de transport et bardage Pipe | L4: =IF($H$8="","",IF($L$2=0,"⚠ RFI absent du Registre",IF(INDEX(Registre!$A$2:$A$2001,$L$2)<>"Transport et bardage","⚠ Ce RFI est de type : "&INDEX(Registre!$A$2:$A$2001,$L$2),"")))
A5: Ouvrages | C5: =IFERROR(INDEX(Registre!$E$2:$E$2001,$L$2)&"","")
A6: Plan nº | C6: =IFERROR(INDEX(Registre!$F$2:$F$2001,$L$2)&"","") | L6: ◀ Choisissez le RFI dans la case jaune
A7: Désignation | C7: =IFERROR(INDEX(Registre!$G$2:$G$2001,$L$2)&"","")
A8: Rapport nº | C8: =IFERROR(INDEX(Registre!$C$2:$C$2001,$L$2)&"","") | E8: DI/ (RFI) nº | H8: 21063-G2-PPL-RFI-0050
A9: ="Tronçon n° : "&IFERROR(INDEX(Registre!$H$2:$H$2001,$L$2)&"","")&" du "&IF(IFERROR(INDEX(Registre!$I$2:$I$2001,$L$2)&"","")<>"","Joint N° "&IFERROR(INDEX(Registre!$I$2:$I$2001,$L$2)&"","")&" ","")&"PK "&IFERROR(INDEX(Registre!$K$2:$K$2001,$L$2)&"","")&IF(OR(IFERROR(INDEX(Registre!$L$2:$L$2001,$L$2)&"","")<>"",IFERROR(INDEX(Registre!$J$2:$J$2001,$L$2)&"","")<>"")," au "&IF(IFERROR(INDEX(Registre!$J$2:$J$2001,$L$2)&"","")<>"","Joint N° "&IFERROR(INDEX(Registre!$J$2:$J$2001,$L$2)&"","")&" ","")&IF(IFERROR(INDEX(Registre!$L$2:$L$2001,$L$2)&"","")<>"","PK "&IFERROR(INDEX(Registre!$L$2:$L$2001,$L$2)&"",""),""),"") | I9: =IF(IFERROR(INDEX(Registre!$M$2:$M$2001,$L$2)&"","")="","Long :","Long : "&IFERROR(INDEX(Registre!$M$2:$M$2001,$L$2)&"","")&" ml")
A10: Inspection | I10: jugement
A11: N° | B11: N° pipe | C11: N° de coulée | D11: Diamètre | E11: EP mm | F11: Long (ml) | G11: Contrôle visuel
A12: =IF(IFERROR(INDEX('Tubes Bardage'!$B$2:$B$501,MATCH($H$8&"|1",'Tubes Bardage'!$I$2:$I$501,0))&"","")="","",TEXT(1,"00")) | B12: =IFERROR(INDEX('Tubes Bardage'!$B$2:$B$501,MATCH($H$8&"|1",'Tubes Bardage'!$I$2:$I$501,0))&"","") | C12: =IFERROR(INDEX('Tubes Bardage'!$C$2:$C$501,MATCH($H$8&"|1",'Tubes Bardage'!$I$2:$I$501,0))&"","") | D12: =IFERROR(INDEX('Tubes Bardage'!$D$2:$D$501,MATCH($H$8&"|1",'Tubes Bardage'!$I$2:$I$501,0))&"","") | E12: =IFERROR(INDEX('Tubes Bardage'!$E$2:$E$501,MATCH($H$8&"|1",'Tubes Bardage'!$I$2:$I$501,0))&"","") | F12: =IFERROR(INDEX('Tubes Bardage'!$F$2:$F$501,MATCH($H$8&"|1",'Tubes Bardage'!$I$2:$I$501,0))&"","") | G12: =IFERROR(INDEX('Tubes Bardage'!$G$2:$G$501,MATCH($H$8&"|1",'Tubes Bardage'!$I$2:$I$501,0))&"","") | I12: =IF(IFERROR(INDEX('Tubes Bardage'!$H$2:$H$501,MATCH($H$8&"|1",'Tubes Bardage'!$I$2:$I$501,0))&"","")="C","☒","☐")&" C"&" "&IF(IFERROR(INDEX('Tubes Bardage'!$H$2:$H$501,MATCH($H$8&"|1",'Tubes Bardage'!$I$2:$I$501,0))&"","")="NC","☒","☐")&" NC"
A13: =IF(IFERROR(INDEX('Tubes Bardage'!$B$2:$B$501,MATCH($H$8&"|2",'Tubes Bardage'!$I$2:$I$501,0))&"","")="","",TEXT(2,"00")) | B13: =IFERROR(INDEX('Tubes Bardage'!$B$2:$B$501,MATCH($H$8&"|2",'Tubes Bardage'!$I$2:$I$501,0))&"","") | C13: =IFERROR(INDEX('Tubes Bardage'!$C$2:$C$501,MATCH($H$8&"|2",'Tubes Bardage'!$I$2:$I$501,0))&"","") | D13: =IFERROR(INDEX('Tubes Bardage'!$D$2:$D$501,MATCH($H$8&"|2",'Tubes Bardage'!$I$2:$I$501,0))&"","") | E13: =IFERROR(INDEX('Tubes Bardage'!$E$2:$E$501,MATCH($H$8&"|2",'Tubes Bardage'!$I$2:$I$501,0))&"","") | F13: =IFERROR(INDEX('Tubes Bardage'!$F$2:$F$501,MATCH($H$8&"|2",'Tubes Bardage'!$I$2:$I$501,0))&"","") | G13: =IFERROR(INDEX('Tubes Bardage'!$G$2:$G$501,MATCH($H$8&"|2",'Tubes Bardage'!$I$2:$I$501,0))&"","") | I13: =IF(IFERROR(INDEX('Tubes Bardage'!$H$2:$H$501,MATCH($H$8&"|2",'Tubes Bardage'!$I$2:$I$501,0))&"","")="C","☒","☐")&" C"&" "&IF(IFERROR(INDEX('Tubes Bardage'!$H$2:$H$501,MATCH($H$8&"|2",'Tubes Bardage'!$I$2:$I$501,0))&"","")="NC","☒","☐")&" NC"
A14: =IF(IFERROR(INDEX('Tubes Bardage'!$B$2:$B$501,MATCH($H$8&"|3",'Tubes Bardage'!$I$2:$I$501,0))&"","")="","",TEXT(3,"00")) | B14: =IFERROR(INDEX('Tubes Bardage'!$B$2:$B$501,MATCH($H$8&"|3",'Tubes Bardage'!$I$2:$I$501,0))&"","") | C14: =IFERROR(INDEX('Tubes Bardage'!$C$2:$C$501,MATCH($H$8&"|3",'Tubes Bardage'!$I$2:$I$501,0))&"","") | D14: =IFERROR(INDEX('Tubes Bardage'!$D$2:$D$501,MATCH($H$8&"|3",'Tubes Bardage'!$I$2:$I$501,0))&"","") | E14: =IFERROR(INDEX('Tubes Bardage'!$E$2:$E$501,MATCH($H$8&"|3",'Tubes Bardage'!$I$2:$I$501,0))&"","") | F14: =IFERROR(INDEX('Tubes Bardage'!$F$2:$F$501,MATCH($H$8&"|3",'Tubes Bardage'!$I$2:$I$501,0))&"","") | G14: =IFERROR(INDEX('Tubes Bardage'!$G$2:$G$501,MATCH($H$8&"|3",'Tubes Bardage'!$I$2:$I$501,0))&"","") | I14: =IF(IFERROR(INDEX('Tubes Bardage'!$H$2:$H$501,MATCH($H$8&"|3",'Tubes Bardage'!$I$2:$I$501,0))&"","")="C","☒","☐")&" C"&" "&IF(IFERROR(INDEX('Tubes Bardage'!$H$2:$H$501,MATCH($H$8&"|3",'Tubes Bardage'!$I$2:$I$501,0))&"","")="NC","☒","☐")&" NC"
A15: =IF(IFERROR(INDEX('Tubes Bardage'!$B$2:$B$501,MATCH($H$8&"|4",'Tubes Bardage'!$I$2:$I$501,0))&"","")="","",TEXT(4,"00")) | B15: =IFERROR(INDEX('Tubes Bardage'!$B$2:$B$501,MATCH($H$8&"|4",'Tubes Bardage'!$I$2:$I$501,0))&"","") | C15: =IFERROR(INDEX('Tubes Bardage'!$C$2:$C$501,MATCH($H$8&"|4",'Tubes Bardage'!$I$2:$I$501,0))&"","") | D15: =IFERROR(INDEX('Tubes Bardage'!$D$2:$D$501,MATCH($H$8&"|4",'Tubes Bardage'!$I$2:$I$501,0))&"","") | E15: =IFERROR(INDEX('Tubes Bardage'!$E$2:$E$501,MATCH($H$8&"|4",'Tubes Bardage'!$I$2:$I$501,0))&"","") | F15: =IFERROR(INDEX('Tubes Bardage'!$F$2:$F$501,MATCH($H$8&"|4",'Tubes Bardage'!$I$2:$I$501,0))&"","") | G15: =IFERROR(INDEX('Tubes Bardage'!$G$2:$G$501,MATCH($H$8&"|4",'Tubes Bardage'!$I$2:$I$501,0))&"","") | I15: =IF(IFERROR(INDEX('Tubes Bardage'!$H$2:$H$501,MATCH($H$8&"|4",'Tubes Bardage'!$I$2:$I$501,0))&"","")="C","☒","☐")&" C"&" "&IF(IFERROR(INDEX('Tubes Bardage'!$H$2:$H$501,MATCH($H$8&"|4",'Tubes Bardage'!$I$2:$I$501,0))&"","")="NC","☒","☐")&" NC"
A16: =IF(IFERROR(INDEX('Tubes Bardage'!$B$2:$B$501,MATCH($H$8&"|5",'Tubes Bardage'!$I$2:$I$501,0))&"","")="","",TEXT(5,"00")) | B16: =IFERROR(INDEX('Tubes Bardage'!$B$2:$B$501,MATCH($H$8&"|5",'Tubes Bardage'!$I$2:$I$501,0))&"","") | C16: =IFERROR(INDEX('Tubes Bardage'!$C$2:$C$501,MATCH($H$8&"|5",'Tubes Bardage'!$I$2:$I$501,0))&"","") | D16: =IFERROR(INDEX('Tubes Bardage'!$D$2:$D$501,MATCH($H$8&"|5",'Tubes Bardage'!$I$2:$I$501,0))&"","") | E16: =IFERROR(INDEX('Tubes Bardage'!$E$2:$E$501,MATCH($H$8&"|5",'Tubes Bardage'!$I$2:$I$501,0))&"","") | F16: =IFERROR(INDEX('Tubes Bardage'!$F$2:$F$501,MATCH($H$8&"|5",'Tubes Bardage'!$I$2:$I$501,0))&"","") | G16: =IFERROR(INDEX('Tubes Bardage'!$G$2:$G$501,MATCH($H$8&"|5",'Tubes Bardage'!$I$2:$I$501,0))&"","") | I16: =IF(IFERROR(INDEX('Tubes Bardage'!$H$2:$H$501,MATCH($H$8&"|5",'Tubes Bardage'!$I$2:$I$501,0))&"","")="C","☒","☐")&" C"&" "&IF(IFERROR(INDEX('Tubes Bardage'!$H$2:$H$501,MATCH($H$8&"|5",'Tubes Bardage'!$I$2:$I$501,0))&"","")="NC","☒","☐")&" NC"
A17: =IF(IFERROR(INDEX('Tubes Bardage'!$B$2:$B$501,MATCH($H$8&"|6",'Tubes Bardage'!$I$2:$I$501,0))&"","")="","",TEXT(6,"00")) | B17: =IFERROR(INDEX('Tubes Bardage'!$B$2:$B$501,MATCH($H$8&"|6",'Tubes Bardage'!$I$2:$I$501,0))&"","") | C17: =IFERROR(INDEX('Tubes Bardage'!$C$2:$C$501,MATCH($H$8&"|6",'Tubes Bardage'!$I$2:$I$501,0))&"","") | D17: =IFERROR(INDEX('Tubes Bardage'!$D$2:$D$501,MATCH($H$8&"|6",'Tubes Bardage'!$I$2:$I$501,0))&"","") | E17: =IFERROR(INDEX('Tubes Bardage'!$E$2:$E$501,MATCH($H$8&"|6",'Tubes Bardage'!$I$2:$I$501,0))&"","") | F17: =IFERROR(INDEX('Tubes Bardage'!$F$2:$F$501,MATCH($H$8&"|6",'Tubes Bardage'!$I$2:$I$501,0))&"","") | G17: =IFERROR(INDEX('Tubes Bardage'!$G$2:$G$501,MATCH($H$8&"|6",'Tubes Bardage'!$I$2:$I$501,0))&"","") | I17: =IF(IFERROR(INDEX('Tubes Bardage'!$H$2:$H$501,MATCH($H$8&"|6",'Tubes Bardage'!$I$2:$I$501,0))&"","")="C","☒","☐")&" C"&" "&IF(IFERROR(INDEX('Tubes Bardage'!$H$2:$H$501,MATCH($H$8&"|6",'Tubes Bardage'!$I$2:$I$501,0))&"","")="NC","☒","☐")&" NC"
A18: =IF(IFERROR(INDEX('Tubes Bardage'!$B$2:$B$501,MATCH($H$8&"|7",'Tubes Bardage'!$I$2:$I$501,0))&"","")="","",TEXT(7,"00")) | B18: =IFERROR(INDEX('Tubes Bardage'!$B$2:$B$501,MATCH($H$8&"|7",'Tubes Bardage'!$I$2:$I$501,0))&"","") | C18: =IFERROR(INDEX('Tubes Bardage'!$C$2:$C$501,MATCH($H$8&"|7",'Tubes Bardage'!$I$2:$I$501,0))&"","") | D18: =IFERROR(INDEX('Tubes Bardage'!$D$2:$D$501,MATCH($H$8&"|7",'Tubes Bardage'!$I$2:$I$501,0))&"","") | E18: =IFERROR(INDEX('Tubes Bardage'!$E$2:$E$501,MATCH($H$8&"|7",'Tubes Bardage'!$I$2:$I$501,0))&"","") | F18: =IFERROR(INDEX('Tubes Bardage'!$F$2:$F$501,MATCH($H$8&"|7",'Tubes Bardage'!$I$2:$I$501,0))&"","") | G18: =IFERROR(INDEX('Tubes Bardage'!$G$2:$G$501,MATCH($H$8&"|7",'Tubes Bardage'!$I$2:$I$501,0))&"","") | I18: =IF(IFERROR(INDEX('Tubes Bardage'!$H$2:$H$501,MATCH($H$8&"|7",'Tubes Bardage'!$I$2:$I$501,0))&"","")="C","☒","☐")&" C"&" "&IF(IFERROR(INDEX('Tubes Bardage'!$H$2:$H$501,MATCH($H$8&"|7",'Tubes Bardage'!$I$2:$I$501,0))&"","")="NC","☒","☐")&" NC"
A19: =IF(IFERROR(INDEX('Tubes Bardage'!$B$2:$B$501,MATCH($H$8&"|8",'Tubes Bardage'!$I$2:$I$501,0))&"","")="","",TEXT(8,"00")) | B19: =IFERROR(INDEX('Tubes Bardage'!$B$2:$B$501,MATCH($H$8&"|8",'Tubes Bardage'!$I$2:$I$501,0))&"","") | C19: =IFERROR(INDEX('Tubes Bardage'!$C$2:$C$501,MATCH($H$8&"|8",'Tubes Bardage'!$I$2:$I$501,0))&"","") | D19: =IFERROR(INDEX('Tubes Bardage'!$D$2:$D$501,MATCH($H$8&"|8",'Tubes Bardage'!$I$2:$I$501,0))&"","") | E19: =IFERROR(INDEX('Tubes Bardage'!$E$2:$E$501,MATCH($H$8&"|8",'Tubes Bardage'!$I$2:$I$501,0))&"","") | F19: =IFERROR(INDEX('Tubes Bardage'!$F$2:$F$501,MATCH($H$8&"|8",'Tubes Bardage'!$I$2:$I$501,0))&"","") | G19: =IFERROR(INDEX('Tubes Bardage'!$G$2:$G$501,MATCH($H$8&"|8",'Tubes Bardage'!$I$2:$I$501,0))&"","") | I19: =IF(IFERROR(INDEX('Tubes Bardage'!$H$2:$H$501,MATCH($H$8&"|8",'Tubes Bardage'!$I$2:$I$501,0))&"","")="C","☒","☐")&" C"&" "&IF(IFERROR(INDEX('Tubes Bardage'!$H$2:$H$501,MATCH($H$8&"|8",'Tubes Bardage'!$I$2:$I$501,0))&"","")="NC","☒","☐")&" NC"
A20: =IF(IFERROR(INDEX('Tubes Bardage'!$B$2:$B$501,MATCH($H$8&"|9",'Tubes Bardage'!$I$2:$I$501,0))&"","")="","",TEXT(9,"00")) | B20: =IFERROR(INDEX('Tubes Bardage'!$B$2:$B$501,MATCH($H$8&"|9",'Tubes Bardage'!$I$2:$I$501,0))&"","") | C20: =IFERROR(INDEX('Tubes Bardage'!$C$2:$C$501,MATCH($H$8&"|9",'Tubes Bardage'!$I$2:$I$501,0))&"","") | D20: =IFERROR(INDEX('Tubes Bardage'!$D$2:$D$501,MATCH($H$8&"|9",'Tubes Bardage'!$I$2:$I$501,0))&"","") | E20: =IFERROR(INDEX('Tubes Bardage'!$E$2:$E$501,MATCH($H$8&"|9",'Tubes Bardage'!$I$2:$I$501,0))&"","") | F20: =IFERROR(INDEX('Tubes Bardage'!$F$2:$F$501,MATCH($H$8&"|9",'Tubes Bardage'!$I$2:$I$501,0))&"","") | G20: =IFERROR(INDEX('Tubes Bardage'!$G$2:$G$501,MATCH($H$8&"|9",'Tubes Bardage'!$I$2:$I$501,0))&"","") | I20: =IF(IFERROR(INDEX('Tubes Bardage'!$H$2:$H$501,MATCH($H$8&"|9",'Tubes Bardage'!$I$2:$I$501,0))&"","")="C","☒","☐")&" C"&" "&IF(IFERROR(INDEX('Tubes Bardage'!$H$2:$H$501,MATCH($H$8&"|9",'Tubes Bardage'!$I$2:$I$501,0))&"","")="NC","☒","☐")&" NC"
A21: =IF(IFERROR(INDEX('Tubes Bardage'!$B$2:$B$501,MATCH($H$8&"|10",'Tubes Bardage'!$I$2:$I$501,0))&"","")="","",TEXT(10,"00")) | B21: =IFERROR(INDEX('Tubes Bardage'!$B$2:$B$501,MATCH($H$8&"|10",'Tubes Bardage'!$I$2:$I$501,0))&"","") | C21: =IFERROR(INDEX('Tubes Bardage'!$C$2:$C$501,MATCH($H$8&"|10",'Tubes Bardage'!$I$2:$I$501,0))&"","") | D21: =IFERROR(INDEX('Tubes Bardage'!$D$2:$D$501,MATCH($H$8&"|10",'Tubes Bardage'!$I$2:$I$501,0))&"","") | E21: =IFERROR(INDEX('Tubes Bardage'!$E$2:$E$501,MATCH($H$8&"|10",'Tubes Bardage'!$I$2:$I$501,0))&"","") | F21: =IFERROR(INDEX('Tubes Bardage'!$F$2:$F$501,MATCH($H$8&"|10",'Tubes Bardage'!$I$2:$I$501,0))&"","") | G21: =IFERROR(INDEX('Tubes Bardage'!$G$2:$G$501,MATCH($H$8&"|10",'Tubes Bardage'!$I$2:$I$501,0))&"","") | I21: =IF(IFERROR(INDEX('Tubes Bardage'!$H$2:$H$501,MATCH($H$8&"|10",'Tubes Bardage'!$I$2:$I$501,0))&"","")="C","☒","☐")&" C"&" "&IF(IFERROR(INDEX('Tubes Bardage'!$H$2:$H$501,MATCH($H$8&"|10",'Tubes Bardage'!$I$2:$I$501,0))&"","")="NC","☒","☐")&" NC"
A22: =IF(IFERROR(INDEX('Tubes Bardage'!$B$2:$B$501,MATCH($H$8&"|11",'Tubes Bardage'!$I$2:$I$501,0))&"","")="","",TEXT(11,"00")) | B22: =IFERROR(INDEX('Tubes Bardage'!$B$2:$B$501,MATCH($H$8&"|11",'Tubes Bardage'!$I$2:$I$501,0))&"","") | C22: =IFERROR(INDEX('Tubes Bardage'!$C$2:$C$501,MATCH($H$8&"|11",'Tubes Bardage'!$I$2:$I$501,0))&"","") | D22: =IFERROR(INDEX('Tubes Bardage'!$D$2:$D$501,MATCH($H$8&"|11",'Tubes Bardage'!$I$2:$I$501,0))&"","") | E22: =IFERROR(INDEX('Tubes Bardage'!$E$2:$E$501,MATCH($H$8&"|11",'Tubes Bardage'!$I$2:$I$501,0))&"","") | F22: =IFERROR(INDEX('Tubes Bardage'!$F$2:$F$501,MATCH($H$8&"|11",'Tubes Bardage'!$I$2:$I$501,0))&"","") | G22: =IFERROR(INDEX('Tubes Bardage'!$G$2:$G$501,MATCH($H$8&"|11",'Tubes Bardage'!$I$2:$I$501,0))&"","") | I22: =IF(IFERROR(INDEX('Tubes Bardage'!$H$2:$H$501,MATCH($H$8&"|11",'Tubes Bardage'!$I$2:$I$501,0))&"","")="C","☒","☐")&" C"&" "&IF(IFERROR(INDEX('Tubes Bardage'!$H$2:$H$501,MATCH($H$8&"|11",'Tubes Bardage'!$I$2:$I$501,0))&"","")="NC","☒","☐")&" NC"
A23: =IF(IFERROR(INDEX('Tubes Bardage'!$B$2:$B$501,MATCH($H$8&"|12",'Tubes Bardage'!$I$2:$I$501,0))&"","")="","",TEXT(12,"00")) | B23: =IFERROR(INDEX('Tubes Bardage'!$B$2:$B$501,MATCH($H$8&"|12",'Tubes Bardage'!$I$2:$I$501,0))&"","") | C23: =IFERROR(INDEX('Tubes Bardage'!$C$2:$C$501,MATCH($H$8&"|12",'Tubes Bardage'!$I$2:$I$501,0))&"","") | D23: =IFERROR(INDEX('Tubes Bardage'!$D$2:$D$501,MATCH($H$8&"|12",'Tubes Bardage'!$I$2:$I$501,0))&"","") | E23: =IFERROR(INDEX('Tubes Bardage'!$E$2:$E$501,MATCH($H$8&"|12",'Tubes Bardage'!$I$2:$I$501,0))&"","") | F23: =IFERROR(INDEX('Tubes Bardage'!$F$2:$F$501,MATCH($H$8&"|12",'Tubes Bardage'!$I$2:$I$501,0))&"","") | G23: =IFERROR(INDEX('Tubes Bardage'!$G$2:$G$501,MATCH($H$8&"|12",'Tubes Bardage'!$I$2:$I$501,0))&"","") | I23: =IF(IFERROR(INDEX('Tubes Bardage'!$H$2:$H$501,MATCH($H$8&"|12",'Tubes Bardage'!$I$2:$I$501,0))&"","")="C","☒","☐")&" C"&" "&IF(IFERROR(INDEX('Tubes Bardage'!$H$2:$H$501,MATCH($H$8&"|12",'Tubes Bardage'!$I$2:$I$501,0))&"","")="NC","☒","☐")&" NC"
A24: =IF(IFERROR(INDEX('Tubes Bardage'!$B$2:$B$501,MATCH($H$8&"|13",'Tubes Bardage'!$I$2:$I$501,0))&"","")="","",TEXT(13,"00")) | B24: =IFERROR(INDEX('Tubes Bardage'!$B$2:$B$501,MATCH($H$8&"|13",'Tubes Bardage'!$I$2:$I$501,0))&"","") | C24: =IFERROR(INDEX('Tubes Bardage'!$C$2:$C$501,MATCH($H$8&"|13",'Tubes Bardage'!$I$2:$I$501,0))&"","") | D24: =IFERROR(INDEX('Tubes Bardage'!$D$2:$D$501,MATCH($H$8&"|13",'Tubes Bardage'!$I$2:$I$501,0))&"","") | E24: =IFERROR(INDEX('Tubes Bardage'!$E$2:$E$501,MATCH($H$8&"|13",'Tubes Bardage'!$I$2:$I$501,0))&"","") | F24: =IFERROR(INDEX('Tubes Bardage'!$F$2:$F$501,MATCH($H$8&"|13",'Tubes Bardage'!$I$2:$I$501,0))&"","") | G24: =IFERROR(INDEX('Tubes Bardage'!$G$2:$G$501,MATCH($H$8&"|13",'Tubes Bardage'!$I$2:$I$501,0))&"","") | I24: =IF(IFERROR(INDEX('Tubes Bardage'!$H$2:$H$501,MATCH($H$8&"|13",'Tubes Bardage'!$I$2:$I$501,0))&"","")="C","☒","☐")&" C"&" "&IF(IFERROR(INDEX('Tubes Bardage'!$H$2:$H$501,MATCH($H$8&"|13",'Tubes Bardage'!$I$2:$I$501,0))&"","")="NC","☒","☐")&" NC"
A25: =IF(IFERROR(INDEX('Tubes Bardage'!$B$2:$B$501,MATCH($H$8&"|14",'Tubes Bardage'!$I$2:$I$501,0))&"","")="","",TEXT(14,"00")) | B25: =IFERROR(INDEX('Tubes Bardage'!$B$2:$B$501,MATCH($H$8&"|14",'Tubes Bardage'!$I$2:$I$501,0))&"","") | C25: =IFERROR(INDEX('Tubes Bardage'!$C$2:$C$501,MATCH($H$8&"|14",'Tubes Bardage'!$I$2:$I$501,0))&"","") | D25: =IFERROR(INDEX('Tubes Bardage'!$D$2:$D$501,MATCH($H$8&"|14",'Tubes Bardage'!$I$2:$I$501,0))&"","") | E25: =IFERROR(INDEX('Tubes Bardage'!$E$2:$E$501,MATCH($H$8&"|14",'Tubes Bardage'!$I$2:$I$501,0))&"","") | F25: =IFERROR(INDEX('Tubes Bardage'!$F$2:$F$501,MATCH($H$8&"|14",'Tubes Bardage'!$I$2:$I$501,0))&"","") | G25: =IFERROR(INDEX('Tubes Bardage'!$G$2:$G$501,MATCH($H$8&"|14",'Tubes Bardage'!$I$2:$I$501,0))&"","") | I25: =IF(IFERROR(INDEX('Tubes Bardage'!$H$2:$H$501,MATCH($H$8&"|14",'Tubes Bardage'!$I$2:$I$501,0))&"","")="C","☒","☐")&" C"&" "&IF(IFERROR(INDEX('Tubes Bardage'!$H$2:$H$501,MATCH($H$8&"|14",'Tubes Bardage'!$I$2:$I$501,0))&"","")="NC","☒","☐")&" NC"
A26: =IF(IFERROR(INDEX('Tubes Bardage'!$B$2:$B$501,MATCH($H$8&"|15",'Tubes Bardage'!$I$2:$I$501,0))&"","")="","",TEXT(15,"00")) | B26: =IFERROR(INDEX('Tubes Bardage'!$B$2:$B$501,MATCH($H$8&"|15",'Tubes Bardage'!$I$2:$I$501,0))&"","") | C26: =IFERROR(INDEX('Tubes Bardage'!$C$2:$C$501,MATCH($H$8&"|15",'Tubes Bardage'!$I$2:$I$501,0))&"","") | D26: =IFERROR(INDEX('Tubes Bardage'!$D$2:$D$501,MATCH($H$8&"|15",'Tubes Bardage'!$I$2:$I$501,0))&"","") | E26: =IFERROR(INDEX('Tubes Bardage'!$E$2:$E$501,MATCH($H$8&"|15",'Tubes Bardage'!$I$2:$I$501,0))&"","") | F26: =IFERROR(INDEX('Tubes Bardage'!$F$2:$F$501,MATCH($H$8&"|15",'Tubes Bardage'!$I$2:$I$501,0))&"","") | G26: =IFERROR(INDEX('Tubes Bardage'!$G$2:$G$501,MATCH($H$8&"|15",'Tubes Bardage'!$I$2:$I$501,0))&"","") | I26: =IF(IFERROR(INDEX('Tubes Bardage'!$H$2:$H$501,MATCH($H$8&"|15",'Tubes Bardage'!$I$2:$I$501,0))&"","")="C","☒","☐")&" C"&" "&IF(IFERROR(INDEX('Tubes Bardage'!$H$2:$H$501,MATCH($H$8&"|15",'Tubes Bardage'!$I$2:$I$501,0))&"","")="NC","☒","☐")&" NC"
A27: =IF(IFERROR(INDEX('Tubes Bardage'!$B$2:$B$501,MATCH($H$8&"|16",'Tubes Bardage'!$I$2:$I$501,0))&"","")="","",TEXT(16,"00")) | B27: =IFERROR(INDEX('Tubes Bardage'!$B$2:$B$501,MATCH($H$8&"|16",'Tubes Bardage'!$I$2:$I$501,0))&"","") | C27: =IFERROR(INDEX('Tubes Bardage'!$C$2:$C$501,MATCH($H$8&"|16",'Tubes Bardage'!$I$2:$I$501,0))&"","") | D27: =IFERROR(INDEX('Tubes Bardage'!$D$2:$D$501,MATCH($H$8&"|16",'Tubes Bardage'!$I$2:$I$501,0))&"","") | E27: =IFERROR(INDEX('Tubes Bardage'!$E$2:$E$501,MATCH($H$8&"|16",'Tubes Bardage'!$I$2:$I$501,0))&"","") | F27: =IFERROR(INDEX('Tubes Bardage'!$F$2:$F$501,MATCH($H$8&"|16",'Tubes Bardage'!$I$2:$I$501,0))&"","") | G27: =IFERROR(INDEX('Tubes Bardage'!$G$2:$G$501,MATCH($H$8&"|16",'Tubes Bardage'!$I$2:$I$501,0))&"","") | I27: =IF(IFERROR(INDEX('Tubes Bardage'!$H$2:$H$501,MATCH($H$8&"|16",'Tubes Bardage'!$I$2:$I$501,0))&"","")="C","☒","☐")&" C"&" "&IF(IFERROR(INDEX('Tubes Bardage'!$H$2:$H$501,MATCH($H$8&"|16",'Tubes Bardage'!$I$2:$I$501,0))&"","")="NC","☒","☐")&" NC"
A28: =IF(IFERROR(INDEX('Tubes Bardage'!$B$2:$B$501,MATCH($H$8&"|17",'Tubes Bardage'!$I$2:$I$501,0))&"","")="","",TEXT(17,"00")) | B28: =IFERROR(INDEX('Tubes Bardage'!$B$2:$B$501,MATCH($H$8&"|17",'Tubes Bardage'!$I$2:$I$501,0))&"","") | C28: =IFERROR(INDEX('Tubes Bardage'!$C$2:$C$501,MATCH($H$8&"|17",'Tubes Bardage'!$I$2:$I$501,0))&"","") | D28: =IFERROR(INDEX('Tubes Bardage'!$D$2:$D$501,MATCH($H$8&"|17",'Tubes Bardage'!$I$2:$I$501,0))&"","") | E28: =IFERROR(INDEX('Tubes Bardage'!$E$2:$E$501,MATCH($H$8&"|17",'Tubes Bardage'!$I$2:$I$501,0))&"","") | F28: =IFERROR(INDEX('Tubes Bardage'!$F$2:$F$501,MATCH($H$8&"|17",'Tubes Bardage'!$I$2:$I$501,0))&"","") | G28: =IFERROR(INDEX('Tubes Bardage'!$G$2:$G$501,MATCH($H$8&"|17",'Tubes Bardage'!$I$2:$I$501,0))&"","") | I28: =IF(IFERROR(INDEX('Tubes Bardage'!$H$2:$H$501,MATCH($H$8&"|17",'Tubes Bardage'!$I$2:$I$501,0))&"","")="C","☒","☐")&" C"&" "&IF(IFERROR(INDEX('Tubes Bardage'!$H$2:$H$501,MATCH($H$8&"|17",'Tubes Bardage'!$I$2:$I$501,0))&"","")="NC","☒","☐")&" NC"
A29: ="Remarques : "&IFERROR(INDEX(Registre!$O$2:$O$2001,$L$2)&"","")
A30: Conclusion de l’inspection | C30: =IF(IFERROR(INDEX(Registre!$N$2:$N$2001,$L$2)&"","")="Non applicable","☒","☐")&" Non applicable" | G30: =IF(IFERROR(INDEX(Registre!$N$2:$N$2001,$L$2)&"","")="Accepté","☒","☐")&" Accepté" | I30: =IF(IFERROR(INDEX(Registre!$N$2:$N$2001,$L$2)&"","")="Rejeté","☒","☐")&" Rejeté"
A31: APPROBATION | C31: C3 | G31: C1 | I31: CA
C32: CST | E32: QCI
A33: Nom
A34: Signature
A35: Date

Sheet PV Cintrage
C1: =Paramètres!$C$6 | I1: =Paramètres!$D$6 | L1: Calcul (ne pas modifier) – ligne registre :
I2: ="Date: "&Paramètres!$E$6 | L2: =IFERROR(MATCH($H$8,Registre!$B$2:$B$2001,0),0)
I3: Page 1/1 | L3: =IFERROR(MATCH($H$8,'Données Cintrage'!$A$2:$A$501,0),0)
A4: Procès-Verbal De Cintrage Pipe | L4: =IF($H$8="","",IF($L$2=0,"⚠ RFI absent du Registre",IF(INDEX(Registre!$A$2:$A$2001,$L$2)<>"Cintrage","⚠ Ce RFI est de type : "&INDEX(Registre!$A$2:$A$2001,$L$2),"")))
A5: Ouvrages | C5: =IFERROR(INDEX(Registre!$E$2:$E$2001,$L$2)&"","")
A6: Plan nº | C6: =IFERROR(INDEX(Registre!$F$2:$F$2001,$L$2)&"","") | L6: ◀ Choisissez le RFI dans la case jaune
A7: Désignation | C7: =IFERROR(INDEX(Registre!$G$2:$G$2001,$L$2)&"","")
A8: Rapport nº | C8: =IFERROR(INDEX(Registre!$C$2:$C$2001,$L$2)&"","") | E8: DI/ (RFI) nº | H8: 21063-G26-PPL-RFI-00188
A9: Caractéristique De La Section
A10: N° pipe | C10: N° de coulée | E10: Diamètre | F10: Matériel | G10: Epaisseur Nominale (mm) | I10: Epaisseur Mesurée (mm)
A11: =IFERROR(INDEX('Données Cintrage'!$B$2:$B$501,$L$3)&"","") | C11: =IFERROR(INDEX('Données Cintrage'!$C$2:$C$501,$L$3)&"","") | E11: =IFERROR(INDEX('Données Cintrage'!$D$2:$D$501,$L$3)&"","") | F11: =IFERROR(INDEX('Données Cintrage'!$E$2:$E$501,$L$3)&"","") | G11: =IFERROR(INDEX('Données Cintrage'!$F$2:$F$501,$L$3)&"","") | I11: =IFERROR(INDEX('Données Cintrage'!$G$2:$G$501,$L$3)&"","")
A12: ="Rayon de courbure : "&IFERROR(INDEX('Données Cintrage'!$H$2:$H$501,$L$3)&"","") | F12: ="Angle : "&IFERROR(INDEX('Données Cintrage'!$I$2:$I$501,$L$3)&"","")
A13: Jauge 97 % ND interne appliqué | F13: =IF(IFERROR(INDEX('Données Cintrage'!$J$2:$J$501,$L$3)&"","")="Oui","☒","☐")&" Oui"&" "&IF(IFERROR(INDEX('Données Cintrage'!$J$2:$J$501,$L$3)&"","")="Non","☒","☐")&" Non"
A14: Vérification de la section cintrée
A15: Position longitudinale de la soudure | E15: ="Extrémités rectilignes"&CHAR(10)&">= 1.5 m"&CHAR(10)&CHAR(10)&CHAR(10)&IF(IFERROR(INDEX('Données Cintrage'!$K$2:$K$501,$L$3)&"","")="Oui","☒","☐")&" Oui"&" "&IF(IFERROR(INDEX('Données Cintrage'!$K$2:$K$501,$L$3)&"","")="Non","☒","☐")&" Non" | H15: ="Traçabilité du pipe cintrée"&CHAR(10)&"Ligne, diamètre, angle"&CHAR(10)&"N du PK d’installation"&CHAR(10)&CHAR(10)&IF(IFERROR(INDEX('Données Cintrage'!$L$2:$L$501,$L$3)&"","")="C","☒","☐")&" C"&" "&IF(IFERROR(INDEX('Données Cintrage'!$L$2:$L$501,$L$3)&"","")="NC","☒","☐")&" NC"
A21: Évaluation générale | E21: =IF(IFERROR(INDEX('Données Cintrage'!$M$2:$M$501,$L$3)&"","")="Acc","☒","☐")&" Acc" | H21: =IF(IFERROR(INDEX('Données Cintrage'!$M$2:$M$501,$L$3)&"","")="Rej","☒","☐")&" Rej"
A22: ="Remarques : "&IFERROR(INDEX(Registre!$O$2:$O$2001,$L$2)&"","")
A23: Conclusion de l’inspection | C23: =IF(IFERROR(INDEX(Registre!$N$2:$N$2001,$L$2)&"","")="Non applicable","☒","☐")&" Non applicable" | G23: =IF(IFERROR(INDEX(Registre!$N$2:$N$2001,$L$2)&"","")="Accepté","☒","☐")&" Accepté" | I23: =IF(IFERROR(INDEX(Registre!$N$2:$N$2001,$L$2)&"","")="Rejeté","☒","☐")&" Rejeté"
A24: APPROBATION | C24: C3 | G24: C1 | I24: CA
C25: CST | E25: QCI
A26: Nom
A27: Signature
A28: Date

Sheet PV Enrobage
C1: =Paramètres!$C$7 | L1: =Paramètres!$D$7 | O1: Calcul (ne pas modifier) – ligne registre :
L2: ="Date: "&Paramètres!$E$7 | O2: =IFERROR(MATCH($K$7,Registre!$B$2:$B$2001,0),0)
L3: Page 1/1 | O3: =IFERROR(MATCH($K$7,'Données Enrobage'!$A$2:$A$501,0),0)
A4: Procès-Verbal d’enrobage | O4: =IF($K$7="","",IF($O$2=0,"⚠ RFI absent du Registre",IF(INDEX(Registre!$A$2:$A$2001,$O$2)<>"Enrobage","⚠ Ce RFI est de type : "&INDEX(Registre!$A$2:$A$2001,$O$2),"")))
A5: ="Ouvrages : "&IFERROR(INDEX(Registre!$E$2:$E$2001,$O$2)&"","") | K5: ="Date : "&IFERROR(TEXT(INDEX(Registre!$D$2:$D$2001,$O$2),"dd/mm/yyyy"),"")
A6: ="Désignation : "&IFERROR(INDEX(Registre!$G$2:$G$2001,$O$2)&"","") | O6: ◀ Choisissez le RFI dans la case jaune
A7: ="Plan Nº : "&IFERROR(INDEX(Registre!$F$2:$F$2001,$O$2)&"","") | G7: ="Report No : "&IFERROR(INDEX(Registre!$C$2:$C$2001,$O$2)&"","") | I7: DI/ (RFI) No : | K7: 21063-G26-PPL-RFI-0194
A8: ="Tronçon N° : "&IFERROR(INDEX(Registre!$H$2:$H$2001,$O$2)&"","")&" du PK "&IFERROR(INDEX(Registre!$K$2:$K$2001,$O$2)&"","")&" au PK "&IFERROR(INDEX(Registre!$L$2:$L$2001,$O$2)&"","") | G8: ="Long : "&IFERROR(INDEX(Registre!$M$2:$M$2001,$O$2)&"","")&" ml" | I8: CONDITIONS ENVIRONNEMENTALES
A9: Abrasif | C9: ="N° de lot : "&IFERROR(INDEX('Données Enrobage'!$B$2:$B$501,$O$3)&"","") | I9: Temp de l'air | J9: =IFERROR(INDEX('Données Enrobage'!$F$2:$F$501,$O$3)&"","") | K9: =IFERROR(INDEX('Données Enrobage'!$G$2:$G$501,$O$3)&"","") | L9: =IFERROR(INDEX('Données Enrobage'!$H$2:$H$501,$O$3)&"","") | M9: =IFERROR(INDEX('Données Enrobage'!$I$2:$I$501,$O$3)&"","")
A10: Apprêt / FBE | C10: ="N° de lot : "&IFERROR(INDEX('Données Enrobage'!$C$2:$C$501,$O$3)&"","") | I10: Point de rosée | J10: =IFERROR(INDEX('Données Enrobage'!$J$2:$J$501,$O$3)&"","") | K10: =IFERROR(INDEX('Données Enrobage'!$K$2:$K$501,$O$3)&"","") | L10: =IFERROR(INDEX('Données Enrobage'!$L$2:$L$501,$O$3)&"","") | M10: =IFERROR(INDEX('Données Enrobage'!$M$2:$M$501,$O$3)&"","")
A11: HSS | C11: ="N° de lot : "&IFERROR(INDEX('Données Enrobage'!$D$2:$D$501,$O$3)&"","") | I11: Humidité relative (RH) | J11: =IFERROR(INDEX('Données Enrobage'!$N$2:$N$501,$O$3)&"","") | K11: =IFERROR(INDEX('Données Enrobage'!$O$2:$O$501,$O$3)&"","") | L11: =IFERROR(INDEX('Données Enrobage'!$P$2:$P$501,$O$3)&"","") | M11: =IFERROR(INDEX('Données Enrobage'!$Q$2:$Q$501,$O$3)&"","")
A12: Solvant | C12: ="N° de lot : "&IFERROR(INDEX('Données Enrobage'!$E$2:$E$501,$O$3)&"","") | I12: Qualité de l'air comprimé | J12: =IFERROR(INDEX('Données Enrobage'!$R$2:$R$501,$O$3)&"","") | K12: =IFERROR(INDEX('Données Enrobage'!$S$2:$S$501,$O$3)&"","") | L12: =IFERROR(INDEX('Données Enrobage'!$T$2:$T$501,$O$3)&"","") | M12: =IFERROR(INDEX('Données Enrobage'!$U$2:$U$501,$O$3)&"","")
A13: SURFACE PREPARATION | H13: FINAL INSPECTION AND TESTING
A14: N° de joint | B14: État de surface avant sablage | C14: Temp de surface | D14: Profil de sablage µm | E14: Chlorures en surface µg/cm² | F14: Test poussière (ruban adhésif) | G14: Température de préchauffage °C | H14: Visuel | I14: Test d'adhérence | J14: Détection de porosités (Holiday Test – 25 kV / 100) | K14: Accepté / Rejeté | L14: Remarques
A15: =IFERROR(INDEX('Joints Enrobage'!$B$2:$B$501,MATCH($K$7&"|1",'Joints Enrobage'!$N$2:$N$501,0))&"","") | B15: =IFERROR(INDEX('Joints Enrobage'!$C$2:$C$501,MATCH($K$7&"|1",'Joints Enrobage'!$N$2:$N$501,0))&"","") | C15: =IFERROR(INDEX('Joints Enrobage'!$D$2:$D$501,MATCH($K$7&"|1",'Joints Enrobage'!$N$2:$N$501,0))&"","") | D15: =IFERROR(INDEX('Joints Enrobage'!$E$2:$E$501,MATCH($K$7&"|1",'Joints Enrobage'!$N$2:$N$501,0))&"","") | E15: =IFERROR(INDEX('Joints Enrobage'!$F$2:$F$501,MATCH($K$7&"|1",'Joints Enrobage'!$N$2:$N$501,0))&"","") | F15: =IFERROR(INDEX('Joints Enrobage'!$G$2:$G$501,MATCH($K$7&"|1",'Joints Enrobage'!$N$2:$N$501,0))&"","") | G15: =IFERROR(INDEX('Joints Enrobage'!$H$2:$H$501,MATCH($K$7&"|1",'Joints Enrobage'!$N$2:$N$501,0))&"","") | H15: =IFERROR(INDEX('Joints Enrobage'!$I$2:$I$501,MATCH($K$7&"|1",'Joints Enrobage'!$N$2:$N$501,0))&"","") | I15: =IFERROR(INDEX('Joints Enrobage'!$J$2:$J$501,MATCH($K$7&"|1",'Joints Enrobage'!$N$2:$N$501,0))&"","") | J15: =IFERROR(INDEX('Joints Enrobage'!$K$2:$K$501,MATCH($K$7&"|1",'Joints Enrobage'!$N$2:$N$501,0))&"","") | K15: =IFERROR(INDEX('Joints Enrobage'!$L$2:$L$501,MATCH($K$7&"|1",'Joints Enrobage'!$N$2:$N$501,0))&"","") | L15: =IFERROR(INDEX('Joints Enrobage'!$M$2:$M$501,MATCH($K$7&"|1",'Joints Enrobage'!$N$2:$N$501,0))&"","")
A16: =IFERROR(INDEX('Joints Enrobage'!$B$2:$B$501,MATCH($K$7&"|2",'Joints Enrobage'!$N$2:$N$501,0))&"","") | B16: =IFERROR(INDEX('Joints Enrobage'!$C$2:$C$501,MATCH($K$7&"|2",'Joints Enrobage'!$N$2:$N$501,0))&"","") | C16: =IFERROR(INDEX('Joints Enrobage'!$D$2:$D$501,MATCH($K$7&"|2",'Joints Enrobage'!$N$2:$N$501,0))&"","") | D16: =IFERROR(INDEX('Joints Enrobage'!$E$2:$E$501,MATCH($K$7&"|2",'Joints Enrobage'!$N$2:$N$501,0))&"","") | E16: =IFERROR(INDEX('Joints Enrobage'!$F$2:$F$501,MATCH($K$7&"|2",'Joints Enrobage'!$N$2:$N$501,0))&"","") | F16: =IFERROR(INDEX('Joints Enrobage'!$G$2:$G$501,MATCH($K$7&"|2",'Joints Enrobage'!$N$2:$N$501,0))&"","") | G16: =IFERROR(INDEX('Joints Enrobage'!$H$2:$H$501,MATCH($K$7&"|2",'Joints Enrobage'!$N$2:$N$501,0))&"","") | H16: =IFERROR(INDEX('Joints Enrobage'!$I$2:$I$501,MATCH($K$7&"|2",'Joints Enrobage'!$N$2:$N$501,0))&"","") | I16: =IFERROR(INDEX('Joints Enrobage'!$J$2:$J$501,MATCH($K$7&"|2",'Joints Enrobage'!$N$2:$N$501,0))&"","") | J16: =IFERROR(INDEX('Joints Enrobage'!$K$2:$K$501,MATCH($K$7&"|2",'Joints Enrobage'!$N$2:$N$501,0))&"","") | K16: =IFERROR(INDEX('Joints Enrobage'!$L$2:$L$501,MATCH($K$7&"|2",'Joints Enrobage'!$N$2:$N$501,0))&"","") | L16: =IFERROR(INDEX('Joints Enrobage'!$M$2:$M$501,MATCH($K$7&"|2",'Joints Enrobage'!$N$2:$N$501,0))&"","")
A17: =IFERROR(INDEX('Joints Enrobage'!$B$2:$B$501,MATCH($K$7&"|3",'Joints Enrobage'!$N$2:$N$501,0))&"","") | B17: =IFERROR(INDEX('Joints Enrobage'!$C$2:$C$501,MATCH($K$7&"|3",'Joints Enrobage'!$N$2:$N$501,0))&"","") | C17: =IFERROR(INDEX('Joints Enrobage'!$D$2:$D$501,MATCH($K$7&"|3",'Joints Enrobage'!$N$2:$N$501,0))&"","") | D17: =IFERROR(INDEX('Joints Enrobage'!$E$2:$E$501,MATCH($K$7&"|3",'Joints Enrobage'!$N$2:$N$501,0))&"","") | E17: =IFERROR(INDEX('Joints Enrobage'!$F$2:$F$501,MATCH($K$7&"|3",'Joints Enrobage'!$N$2:$N$501,0))&"","") | F17: =IFERROR(INDEX('Joints Enrobage'!$G$2:$G$501,MATCH($K$7&"|3",'Joints Enrobage'!$N$2:$N$501,0))&"","") | G17: =IFERROR(INDEX('Joints Enrobage'!$H$2:$H$501,MATCH($K$7&"|3",'Joints Enrobage'!$N$2:$N$501,0))&"","") | H17: =IFERROR(INDEX('Joints Enrobage'!$I$2:$I$501,MATCH($K$7&"|3",'Joints Enrobage'!$N$2:$N$501,0))&"","") | I17: =IFERROR(INDEX('Joints Enrobage'!$J$2:$J$501,MATCH($K$7&"|3",'Joints Enrobage'!$N$2:$N$501,0))&"","") | J17: =IFERROR(INDEX('Joints Enrobage'!$K$2:$K$501,MATCH($K$7&"|3",'Joints Enrobage'!$N$2:$N$501,0))&"","") | K17: =IFERROR(INDEX('Joints Enrobage'!$L$2:$L$501,MATCH($K$7&"|3",'Joints Enrobage'!$N$2:$N$501,0))&"","") | L17: =IFERROR(INDEX('Joints Enrobage'!$M$2:$M$501,MATCH($K$7&"|3",'Joints Enrobage'!$N$2:$N$501,0))&"","")
A18: =IFERROR(INDEX('Joints Enrobage'!$B$2:$B$501,MATCH($K$7&"|4",'Joints Enrobage'!$N$2:$N$501,0))&"","") | B18: =IFERROR(INDEX('Joints Enrobage'!$C$2:$C$501,MATCH($K$7&"|4",'Joints Enrobage'!$N$2:$N$501,0))&"","") | C18: =IFERROR(INDEX('Joints Enrobage'!$D$2:$D$501,MATCH($K$7&"|4",'Joints Enrobage'!$N$2:$N$501,0))&"","") | D18: =IFERROR(INDEX('Joints Enrobage'!$E$2:$E$501,MATCH($K$7&"|4",'Joints Enrobage'!$N$2:$N$501,0))&"","") | E18: =IFERROR(INDEX('Joints Enrobage'!$F$2:$F$501,MATCH($K$7&"|4",'Joints Enrobage'!$N$2:$N$501,0))&"","") | F18: =IFERROR(INDEX('Joints Enrobage'!$G$2:$G$501,MATCH($K$7&"|4",'Joints Enrobage'!$N$2:$N$501,0))&"","") | G18: =IFERROR(INDEX('Joints Enrobage'!$H$2:$H$501,MATCH($K$7&"|4",'Joints Enrobage'!$N$2:$N$501,0))&"","") | H18: =IFERROR(INDEX('Joints Enrobage'!$I$2:$I$501,MATCH($K$7&"|4",'Joints Enrobage'!$N$2:$N$501,0))&"","") | I18: =IFERROR(INDEX('Joints Enrobage'!$J$2:$J$501,MATCH($K$7&"|4",'Joints Enrobage'!$N$2:$N$501,0))&"","") | J18: =IFERROR(INDEX('Joints Enrobage'!$K$2:$K$501,MATCH($K$7&"|4",'Joints Enrobage'!$N$2:$N$501,0))&"","") | K18: =IFERROR(INDEX('Joints Enrobage'!$L$2:$L$501,MATCH($K$7&"|4",'Joints Enrobage'!$N$2:$N$501,0))&"","") | L18: =IFERROR(INDEX('Joints Enrobage'!$M$2:$M$501,MATCH($K$7&"|4",'Joints Enrobage'!$N$2:$N$501,0))&"","")
A19: =IFERROR(INDEX('Joints Enrobage'!$B$2:$B$501,MATCH($K$7&"|5",'Joints Enrobage'!$N$2:$N$501,0))&"","") | B19: =IFERROR(INDEX('Joints Enrobage'!$C$2:$C$501,MATCH($K$7&"|5",'Joints Enrobage'!$N$2:$N$501,0))&"","") | C19: =IFERROR(INDEX('Joints Enrobage'!$D$2:$D$501,MATCH($K$7&"|5",'Joints Enrobage'!$N$2:$N$501,0))&"","") | D19: =IFERROR(INDEX('Joints Enrobage'!$E$2:$E$501,MATCH($K$7&"|5",'Joints Enrobage'!$N$2:$N$501,0))&"","") | E19: =IFERROR(INDEX('Joints Enrobage'!$F$2:$F$501,MATCH($K$7&"|5",'Joints Enrobage'!$N$2:$N$501,0))&"","") | F19: =IFERROR(INDEX('Joints Enrobage'!$G$2:$G$501,MATCH($K$7&"|5",'Joints Enrobage'!$N$2:$N$501,0))&"","") | G19: =IFERROR(INDEX('Joints Enrobage'!$H$2:$H$501,MATCH($K$7&"|5",'Joints Enrobage'!$N$2:$N$501,0))&"","") | H19: =IFERROR(INDEX('Joints Enrobage'!$I$2:$I$501,MATCH($K$7&"|5",'Joints Enrobage'!$N$2:$N$501,0))&"","") | I19: =IFERROR(INDEX('Joints Enrobage'!$J$2:$J$501,MATCH($K$7&"|5",'Joints Enrobage'!$N$2:$N$501,0))&"","") | J19: =IFERROR(INDEX('Joints Enrobage'!$K$2:$K$501,MATCH($K$7&"|5",'Joints Enrobage'!$N$2:$N$501,0))&"","") | K19: =IFERROR(INDEX('Joints Enrobage'!$L$2:$L$501,MATCH($K$7&"|5",'Joints Enrobage'!$N$2:$N$501,0))&"","") | L19: =IFERROR(INDEX('Joints Enrobage'!$M$2:$M$501,MATCH($K$7&"|5",'Joints Enrobage'!$N$2:$N$501,0))&"","")
A20: =IFERROR(INDEX('Joints Enrobage'!$B$2:$B$501,MATCH($K$7&"|6",'Joints Enrobage'!$N$2:$N$501,0))&"","") | B20: =IFERROR(INDEX('Joints Enrobage'!$C$2:$C$501,MATCH($K$7&"|6",'Joints Enrobage'!$N$2:$N$501,0))&"","") | C20: =IFERROR(INDEX('Joints Enrobage'!$D$2:$D$501,MATCH($K$7&"|6",'Joints Enrobage'!$N$2:$N$501,0))&"","") | D20: =IFERROR(INDEX('Joints Enrobage'!$E$2:$E$501,MATCH($K$7&"|6",'Joints Enrobage'!$N$2:$N$501,0))&"","") | E20: =IFERROR(INDEX('Joints Enrobage'!$F$2:$F$501,MATCH($K$7&"|6",'Joints Enrobage'!$N$2:$N$501,0))&"","") | F20: =IFERROR(INDEX('Joints Enrobage'!$G$2:$G$501,MATCH($K$7&"|6",'Joints Enrobage'!$N$2:$N$501,0))&"","") | G20: =IFERROR(INDEX('Joints Enrobage'!$H$2:$H$501,MATCH($K$7&"|6",'Joints Enrobage'!$N$2:$N$501,0))&"","") | H20: =IFERROR(INDEX('Joints Enrobage'!$I$2:$I$501,MATCH($K$7&"|6",'Joints Enrobage'!$N$2:$N$501,0))&"","") | I20: =IFERROR(INDEX('Joints Enrobage'!$J$2:$J$501,MATCH($K$7&"|6",'Joints Enrobage'!$N$2:$N$501,0))&"","") | J20: =IFERROR(INDEX('Joints Enrobage'!$K$2:$K$501,MATCH($K$7&"|6",'Joints Enrobage'!$N$2:$N$501,0))&"","") | K20: =IFERROR(INDEX('Joints Enrobage'!$L$2:$L$501,MATCH($K$7&"|6",'Joints Enrobage'!$N$2:$N$501,0))&"","") | L20: =IFERROR(INDEX('Joints Enrobage'!$M$2:$M$501,MATCH($K$7&"|6",'Joints Enrobage'!$N$2:$N$501,0))&"","")
A21: =IFERROR(INDEX('Joints Enrobage'!$B$2:$B$501,MATCH($K$7&"|7",'Joints Enrobage'!$N$2:$N$501,0))&"","") | B21: =IFERROR(INDEX('Joints Enrobage'!$C$2:$C$501,MATCH($K$7&"|7",'Joints Enrobage'!$N$2:$N$501,0))&"","") | C21: =IFERROR(INDEX('Joints Enrobage'!$D$2:$D$501,MATCH($K$7&"|7",'Joints Enrobage'!$N$2:$N$501,0))&"","") | D21: =IFERROR(INDEX('Joints Enrobage'!$E$2:$E$501,MATCH($K$7&"|7",'Joints Enrobage'!$N$2:$N$501,0))&"","") | E21: =IFERROR(INDEX('Joints Enrobage'!$F$2:$F$501,MATCH($K$7&"|7",'Joints Enrobage'!$N$2:$N$501,0))&"","") | F21: =IFERROR(INDEX('Joints Enrobage'!$G$2:$G$501,MATCH($K$7&"|7",'Joints Enrobage'!$N$2:$N$501,0))&"","") | G21: =IFERROR(INDEX('Joints Enrobage'!$H$2:$H$501,MATCH($K$7&"|7",'Joints Enrobage'!$N$2:$N$501,0))&"","") | H21: =IFERROR(INDEX('Joints Enrobage'!$I$2:$I$501,MATCH($K$7&"|7",'Joints Enrobage'!$N$2:$N$501,0))&"","") | I21: =IFERROR(INDEX('Joints Enrobage'!$J$2:$J$501,MATCH($K$7&"|7",'Joints Enrobage'!$N$2:$N$501,0))&"","") | J21: =IFERROR(INDEX('Joints Enrobage'!$K$2:$K$501,MATCH($K$7&"|7",'Joints Enrobage'!$N$2:$N$501,0))&"","") | K21: =IFERROR(INDEX('Joints Enrobage'!$L$2:$L$501,MATCH($K$7&"|7",'Joints Enrobage'!$N$2:$N$501,0))&"","") | L21: =IFERROR(INDEX('Joints Enrobage'!$M$2:$M$501,MATCH($K$7&"|7",'Joints Enrobage'!$N$2:$N$501,0))&"","")
A22: =IFERROR(INDEX('Joints Enrobage'!$B$2:$B$501,MATCH($K$7&"|8",'Joints Enrobage'!$N$2:$N$501,0))&"","") | B22: =IFERROR(INDEX('Joints Enrobage'!$C$2:$C$501,MATCH($K$7&"|8",'Joints Enrobage'!$N$2:$N$501,0))&"","") | C22: =IFERROR(INDEX('Joints Enrobage'!$D$2:$D$501,MATCH($K$7&"|8",'Joints Enrobage'!$N$2:$N$501,0))&"","") | D22: =IFERROR(INDEX('Joints Enrobage'!$E$2:$E$501,MATCH($K$7&"|8",'Joints Enrobage'!$N$2:$N$501,0))&"","") | E22: =IFERROR(INDEX('Joints Enrobage'!$F$2:$F$501,MATCH($K$7&"|8",'Joints Enrobage'!$N$2:$N$501,0))&"","") | F22: =IFERROR(INDEX('Joints Enrobage'!$G$2:$G$501,MATCH($K$7&"|8",'Joints Enrobage'!$N$2:$N$501,0))&"","") | G22: =IFERROR(INDEX('Joints Enrobage'!$H$2:$H$501,MATCH($K$7&"|8",'Joints Enrobage'!$N$2:$N$501,0))&"","") | H22: =IFERROR(INDEX('Joints Enrobage'!$I$2:$I$501,MATCH($K$7&"|8",'Joints Enrobage'!$N$2:$N$501,0))&"","") | I22: =IFERROR(INDEX('Joints Enrobage'!$J$2:$J$501,MATCH($K$7&"|8",'Joints Enrobage'!$N$2:$N$501,0))&"","") | J22: =IFERROR(INDEX('Joints Enrobage'!$K$2:$K$501,MATCH($K$7&"|8",'Joints Enrobage'!$N$2:$N$501,0))&"","") | K22: =IFERROR(INDEX('Joints Enrobage'!$L$2:$L$501,MATCH($K$7&"|8",'Joints Enrobage'!$N$2:$N$501,0))&"","") | L22: =IFERROR(INDEX('Joints Enrobage'!$M$2:$M$501,MATCH($K$7&"|8",'Joints Enrobage'!$N$2:$N$501,0))&"","")
A23: =IFERROR(INDEX('Joints Enrobage'!$B$2:$B$501,MATCH($K$7&"|9",'Joints Enrobage'!$N$2:$N$501,0))&"","") | B23: =IFERROR(INDEX('Joints Enrobage'!$C$2:$C$501,MATCH($K$7&"|9",'Joints Enrobage'!$N$2:$N$501,0))&"","") | C23: =IFERROR(INDEX('Joints Enrobage'!$D$2:$D$501,MATCH($K$7&"|9",'Joints Enrobage'!$N$2:$N$501,0))&"","") | D23: =IFERROR(INDEX('Joints Enrobage'!$E$2:$E$501,MATCH($K$7&"|9",'Joints Enrobage'!$N$2:$N$501,0))&"","") | E23: =IFERROR(INDEX('Joints Enrobage'!$F$2:$F$501,MATCH($K$7&"|9",'Joints Enrobage'!$N$2:$N$501,0))&"","") | F23: =IFERROR(INDEX('Joints Enrobage'!$G$2:$G$501,MATCH($K$7&"|9",'Joints Enrobage'!$N$2:$N$501,0))&"","") | G23: =IFERROR(INDEX('Joints Enrobage'!$H$2:$H$501,MATCH($K$7&"|9",'Joints Enrobage'!$N$2:$N$501,0))&"","") | H23: =IFERROR(INDEX('Joints Enrobage'!$I$2:$I$501,MATCH($K$7&"|9",'Joints Enrobage'!$N$2:$N$501,0))&"","") | I23: =IFERROR(INDEX('Joints Enrobage'!$J$2:$J$501,MATCH($K$7&"|9",'Joints Enrobage'!$N$2:$N$501,0))&"","") | J23: =IFERROR(INDEX('Joints Enrobage'!$K$2:$K$501,MATCH($K$7&"|9",'Joints Enrobage'!$N$2:$N$501,0))&"","") | K23: =IFERROR(INDEX('Joints Enrobage'!$L$2:$L$501,MATCH($K$7&"|9",'Joints Enrobage'!$N$2:$N$501,0))&"","") | L23: =IFERROR(INDEX('Joints Enrobage'!$M$2:$M$501,MATCH($K$7&"|9",'Joints Enrobage'!$N$2:$N$501,0))&"","")
A24: =IFERROR(INDEX('Joints Enrobage'!$B$2:$B$501,MATCH($K$7&"|10",'Joints Enrobage'!$N$2:$N$501,0))&"","") | B24: =IFERROR(INDEX('Joints Enrobage'!$C$2:$C$501,MATCH($K$7&"|10",'Joints Enrobage'!$N$2:$N$501,0))&"","") | C24: =IFERROR(INDEX('Joints Enrobage'!$D$2:$D$501,MATCH($K$7&"|10",'Joints Enrobage'!$N$2:$N$501,0))&"","") | D24: =IFERROR(INDEX('Joints Enrobage'!$E$2:$E$501,MATCH($K$7&"|10",'Joints Enrobage'!$N$2:$N$501,0))&"","") | E24: =IFERROR(INDEX('Joints Enrobage'!$F$2:$F$501,MATCH($K$7&"|10",'Joints Enrobage'!$N$2:$N$501,0))&"","") | F24: =IFERROR(INDEX('Joints Enrobage'!$G$2:$G$501,MATCH($K$7&"|10",'Joints Enrobage'!$N$2:$N$501,0))&"","") | G24: =IFERROR(INDEX('Joints Enrobage'!$H$2:$H$501,MATCH($K$7&"|10",'Joints Enrobage'!$N$2:$N$501,0))&"","") | H24: =IFERROR(INDEX('Joints Enrobage'!$I$2:$I$501,MATCH($K$7&"|10",'Joints Enrobage'!$N$2:$N$501,0))&"","") | I24: =IFERROR(INDEX('Joints Enrobage'!$J$2:$J$501,MATCH($K$7&"|10",'Joints Enrobage'!$N$2:$N$501,0))&"","") | J24: =IFERROR(INDEX('Joints Enrobage'!$K$2:$K$501,MATCH($K$7&"|10",'Joints Enrobage'!$N$2:$N$501,0))&"","") | K24: =IFERROR(INDEX('Joints Enrobage'!$L$2:$L$501,MATCH($K$7&"|10",'Joints Enrobage'!$N$2:$N$501,0))&"","") | L24: =IFERROR(INDEX('Joints Enrobage'!$M$2:$M$501,MATCH($K$7&"|10",'Joints Enrobage'!$N$2:$N$501,0))&"","")
A25: =IFERROR(INDEX('Joints Enrobage'!$B$2:$B$501,MATCH($K$7&"|11",'Joints Enrobage'!$N$2:$N$501,0))&"","") | B25: =IFERROR(INDEX('Joints Enrobage'!$C$2:$C$501,MATCH($K$7&"|11",'Joints Enrobage'!$N$2:$N$501,0))&"","") | C25: =IFERROR(INDEX('Joints Enrobage'!$D$2:$D$501,MATCH($K$7&"|11",'Joints Enrobage'!$N$2:$N$501,0))&"","") | D25: =IFERROR(INDEX('Joints Enrobage'!$E$2:$E$501,MATCH($K$7&"|11",'Joints Enrobage'!$N$2:$N$501,0))&"","") | E25: =IFERROR(INDEX('Joints Enrobage'!$F$2:$F$501,MATCH($K$7&"|11",'Joints Enrobage'!$N$2:$N$501,0))&"","") | F25: =IFERROR(INDEX('Joints Enrobage'!$G$2:$G$501,MATCH($K$7&"|11",'Joints Enrobage'!$N$2:$N$501,0))&"","") | G25: =IFERROR(INDEX('Joints Enrobage'!$H$2:$H$501,MATCH($K$7&"|11",'Joints Enrobage'!$N$2:$N$501,0))&"","") | H25: =IFERROR(INDEX('Joints Enrobage'!$I$2:$I$501,MATCH($K$7&"|11",'Joints Enrobage'!$N$2:$N$501,0))&"","") | I25: =IFERROR(INDEX('Joints Enrobage'!$J$2:$J$501,MATCH($K$7&"|11",'Joints Enrobage'!$N$2:$N$501,0))&"","") | J25: =IFERROR(INDEX('Joints Enrobage'!$K$2:$K$501,MATCH($K$7&"|11",'Joints Enrobage'!$N$2:$N$501,0))&"","") | K25: =IFERROR(INDEX('Joints Enrobage'!$L$2:$L$501,MATCH($K$7&"|11",'Joints Enrobage'!$N$2:$N$501,0))&"","") | L25: =IFERROR(INDEX('Joints Enrobage'!$M$2:$M$501,MATCH($K$7&"|11",'Joints Enrobage'!$N$2:$N$501,0))&"","")
A26: =IFERROR(INDEX('Joints Enrobage'!$B$2:$B$501,MATCH($K$7&"|12",'Joints Enrobage'!$N$2:$N$501,0))&"","") | B26: =IFERROR(INDEX('Joints Enrobage'!$C$2:$C$501,MATCH($K$7&"|12",'Joints Enrobage'!$N$2:$N$501,0))&"","") | C26: =IFERROR(INDEX('Joints Enrobage'!$D$2:$D$501,MATCH($K$7&"|12",'Joints Enrobage'!$N$2:$N$501,0))&"","") | D26: =IFERROR(INDEX('Joints Enrobage'!$E$2:$E$501,MATCH($K$7&"|12",'Joints Enrobage'!$N$2:$N$501,0))&"","") | E26: =IFERROR(INDEX('Joints Enrobage'!$F$2:$F$501,MATCH($K$7&"|12",'Joints Enrobage'!$N$2:$N$501,0))&"","") | F26: =IFERROR(INDEX('Joints Enrobage'!$G$2:$G$501,MATCH($K$7&"|12",'Joints Enrobage'!$N$2:$N$501,0))&"","") | G26: =IFERROR(INDEX('Joints Enrobage'!$H$2:$H$501,MATCH($K$7&"|12",'Joints Enrobage'!$N$2:$N$501,0))&"","") | H26: =IFERROR(INDEX('Joints Enrobage'!$I$2:$I$501,MATCH($K$7&"|12",'Joints Enrobage'!$N$2:$N$501,0))&"","") | I26: =IFERROR(INDEX('Joints Enrobage'!$J$2:$J$501,MATCH($K$7&"|12",'Joints Enrobage'!$N$2:$N$501,0))&"","") | J26: =IFERROR(INDEX('Joints Enrobage'!$K$2:$K$501,MATCH($K$7&"|12",'Joints Enrobage'!$N$2:$N$501,0))&"","") | K26: =IFERROR(INDEX('Joints Enrobage'!$L$2:$L$501,MATCH($K$7&"|12",'Joints Enrobage'!$N$2:$N$501,0))&"","") | L26: =IFERROR(INDEX('Joints Enrobage'!$M$2:$M$501,MATCH($K$7&"|12",'Joints Enrobage'!$N$2:$N$501,0))&"","")
A27: =IFERROR(INDEX('Joints Enrobage'!$B$2:$B$501,MATCH($K$7&"|13",'Joints Enrobage'!$N$2:$N$501,0))&"","") | B27: =IFERROR(INDEX('Joints Enrobage'!$C$2:$C$501,MATCH($K$7&"|13",'Joints Enrobage'!$N$2:$N$501,0))&"","") | C27: =IFERROR(INDEX('Joints Enrobage'!$D$2:$D$501,MATCH($K$7&"|13",'Joints Enrobage'!$N$2:$N$501,0))&"","") | D27: =IFERROR(INDEX('Joints Enrobage'!$E$2:$E$501,MATCH($K$7&"|13",'Joints Enrobage'!$N$2:$N$501,0))&"","") | E27: =IFERROR(INDEX('Joints Enrobage'!$F$2:$F$501,MATCH($K$7&"|13",'Joints Enrobage'!$N$2:$N$501,0))&"","") | F27: =IFERROR(INDEX('Joints Enrobage'!$G$2:$G$501,MATCH($K$7&"|13",'Joints Enrobage'!$N$2:$N$501,0))&"","") | G27: =IFERROR(INDEX('Joints Enrobage'!$H$2:$H$501,MATCH($K$7&"|13",'Joints Enrobage'!$N$2:$N$501,0))&"","") | H27: =IFERROR(INDEX('Joints Enrobage'!$I$2:$I$501,MATCH($K$7&"|13",'Joints Enrobage'!$N$2:$N$501,0))&"","") | I27: =IFERROR(INDEX('Joints Enrobage'!$J$2:$J$501,MATCH($K$7&"|13",'Joints Enrobage'!$N$2:$N$501,0))&"","") | J27: =IFERROR(INDEX('Joints Enrobage'!$K$2:$K$501,MATCH($K$7&"|13",'Joints Enrobage'!$N$2:$N$501,0))&"","") | K27: =IFERROR(INDEX('Joints Enrobage'!$L$2:$L$501,MATCH($K$7&"|13",'Joints Enrobage'!$N$2:$N$501,0))&"","") | L27: =IFERROR(INDEX('Joints Enrobage'!$M$2:$M$501,MATCH($K$7&"|13",'Joints Enrobage'!$N$2:$N$501,0))&"","")
A28: =IFERROR(INDEX('Joints Enrobage'!$B$2:$B$501,MATCH($K$7&"|14",'Joints Enrobage'!$N$2:$N$501,0))&"","") | B28: =IFERROR(INDEX('Joints Enrobage'!$C$2:$C$501,MATCH($K$7&"|14",'Joints Enrobage'!$N$2:$N$501,0))&"","") | C28: =IFERROR(INDEX('Joints Enrobage'!$D$2:$D$501,MATCH($K$7&"|14",'Joints Enrobage'!$N$2:$N$501,0))&"","") | D28: =IFERROR(INDEX('Joints Enrobage'!$E$2:$E$501,MATCH($K$7&"|14",'Joints Enrobage'!$N$2:$N$501,0))&"","") | E28: =IFERROR(INDEX('Joints Enrobage'!$F$2:$F$501,MATCH($K$7&"|14",'Joints Enrobage'!$N$2:$N$501,0))&"","") | F28: =IFERROR(INDEX('Joints Enrobage'!$G$2:$G$501,MATCH($K$7&"|14",'Joints Enrobage'!$N$2:$N$501,0))&"","") | G28: =IFERROR(INDEX('Joints Enrobage'!$H$2:$H$501,MATCH($K$7&"|14",'Joints Enrobage'!$N$2:$N$501,0))&"","") | H28: =IFERROR(INDEX('Joints Enrobage'!$I$2:$I$501,MATCH($K$7&"|14",'Joints Enrobage'!$N$2:$N$501,0))&"","") | I28: =IFERROR(INDEX('Joints Enrobage'!$J$2:$J$501,MATCH($K$7&"|14",'Joints Enrobage'!$N$2:$N$501,0))&"","") | J28: =IFERROR(INDEX('Joints Enrobage'!$K$2:$K$501,MATCH($K$7&"|14",'Joints Enrobage'!$N$2:$N$501,0))&"","") | K28: =IFERROR(INDEX('Joints Enrobage'!$L$2:$L$501,MATCH($K$7&"|14",'Joints Enrobage'!$N$2:$N$501,0))&"","") | L28: =IFERROR(INDEX('Joints Enrobage'!$M$2:$M$501,MATCH($K$7&"|14",'Joints Enrobage'!$N$2:$N$501,0))&"","")
