Workbook
Name Liste_BAR: OFFSET(Listes!$Q$2,0,0,MAX(1,COUNTIF(Listes!$Q$2:$Q$501,"?*")),1)
Name Liste_CIN: OFFSET(Listes!$R$2,0,0,MAX(1,COUNTIF(Listes!$R$2:$R$501,"?*")),1)
Name Liste_ENR: OFFSET(Listes!$S$2,0,0,MAX(1,COUNTIF(Listes!$S$2:$S$501,"?*")),1)
Name Liste_LIT: OFFSET(Listes!$T$2,0,0,MAX(1,COUNTIF(Listes!$T$2:$T$501,"?*")),1)
Name Liste_MEF: OFFSET(Listes!$U$2,0,0,MAX(1,COUNTIF(Listes!$U$2:$U$501,"?*")),1)
Name Liste_OUV: OFFSET(Listes!$O$2,0,0,MAX(1,COUNTIF(Listes!$O$2:$O$501,"?*")),1)
Name Liste_PIS: OFFSET(Listes!$P$2,0,0,MAX(1,COUNTIF(Listes!$P$2:$P$501,"?*")),1)
Name Liste_PRE: OFFSET(Listes!$V$2,0,0,MAX(1,COUNTIF(Listes!$V$2:$V$501,"?*")),1)
Name Liste_RFI: OFFSET(Registre!$B$2,0,0,MAX(1,COUNTA(Registre!$B$2:$B$1999)),1)

Sheet Mode d'emploi
B2: REGISTRE QA/QC – PV & RFI (sans macro)
B4: 1. Saisie
B5: • Feuille « Registre » : une ligne par inspection. Choisissez le Type, saisissez le RFI No (unique), le N° de rapport, l'ouvrage, le plan, la désignation, le tronçon et la conclusion.
B6: • Feuilles grises « Données … » / « Tubes Bardage » / « Joints Enrobage » : informations propres à certains PV (une ligne par RFI, ou une ligne par tube / joint).
B7: • Item No et points d'intervention (CST, QCI, C1, CA, TPI1, TPI2) se remplissent automatiquement selon le Type et la Désignation, d'après les ITP 21063-G0-QAQC-ITP-0053 et ITP-0051 (feuille « ITP »). Une saisie manuelle dans la cellule remplace la valeur automatique.
B8: 2. Édition
B9: • Ouvrez la feuille du PV (onglets bleus) ou la feuille « RFI » (onglet rouge).
B10: • Cliquez sur la case « RFI nº » (liste déroulante) et choisissez le RFI No : la liste ne propose que les RFI du bon type, et la fiche se remplit automatiquement.
B11: • Imprimez (Ctrl+P) ou Fichier > Exporter > PDF : la fiche tient sur une page A4.
B13: 3. Cases à cocher
B14: • La conclusion (Accepté / Rejeté / Non applicable) saisie dans le Registre coche automatiquement la bonne case.
B15: • Les points d'inspection sans colonne dédiée sont cochés « C » quand la conclusion est « Accepté » ; sinon ils restent vides pour être cochés à la main.
... B23: • Les colonnes sont au format Texte : les zéros de « 0001 » sont conservés.

Sheet Registre
A1: Type | B1: RFI No | C1: N° Rapport | D1: Date d'inspection | E1: Ouvrage | F1: Plan nº | G1: Désignation | H1: Tronçon N° | I1: Joint début | J1: Joint fin | K1: PK début | L1: PK fin | M1: Longueur (ml) | N1: Conclusion | O1: Remarques | P1: Discipline (RFI) | Q1: Lieu (RFI) – vide = Ouvrage | R1: Item No (RFI) | S1: Heure (RFI) | T1: Description (RFI) – vide = Désignation | U1: CST | V1: QCI | W1: C1 | X1: CA | Y1: TPI1 | Z1: TPI2 | AA1: Clé (auto) | AB1: Clé ITP (auto)
A2: Relevé topographique | B2: 21063-G26-PPL-RFI-0001 | D2: 45933 | E2: TRUNKLINE FROM ISW MFD TO TFTⅡCPF | F2: 21061-0000-PPL-TDW-0009 | G2: Relevé Topographique pré-construction | K2: pk (18+650 Au 19+450 ) | P2: PPL | R2: =IF($AB2="","",IFERROR(INDEX(ITP!$G$3:$G$46,MATCH($AB2,ITP!$E$3:$E$46,0)),"")) | S2: 08:00 | U2: =IF($AB2="","",IFERROR(INDEX(ITP!$I$3:$I$46,MATCH($AB2,ITP!$E$3:$E$46,0)),"")) | V2: =IF($AB2="","",IFERROR(INDEX(ITP!$J$3:$J$46,MATCH($AB2,ITP!$E$3:$E$46,0)),"")) | W2: =IF($AB2="","",IFERROR(INDEX(ITP!$K$3:$K$46,MATCH($AB2,ITP!$E$3:$E$46,0)),"")) | X2: =IF($AB2="","",IFERROR(INDEX(ITP!$L$3:$L$46,MATCH($AB2,ITP!$E$3:$E$46,0)),"")) | Y2: =IF($AB2="","",IFERROR(INDEX(ITP!$M$3:$M$46,MATCH($AB2,ITP!$E$3:$E$46,0)),"")) | Z2: =IF($AB2="","",IFERROR(INDEX(ITP!$N$3:$N$46,MATCH($AB2,ITP!$E$3:$E$46,0)),"")) | AA2: =IF(A2="","",A2&"|"&COUNTIF($A$2:A2,A2)) | AB2: =IF($A2="","",IFERROR(INDEX(ITP!$C$3:$C$21,MATCH(1,INDEX((ITP!$A$3:$A$21=$A2)*(((ITP!$B$3:$B$21="")+ISNUMBER(SEARCH(ITP!$B$3:$B$21,$G2&" "&$T2)))>0),0),0)),""))
A3: Piste de travail | B3: 21063-G26-PPL-RFI-0002 | D3: 45935 | E3: TRUNKLINE FROM ISW MFD TO TFTⅡCPF | F3: 21063-G0-PPL-PR-0007 | G3: Inspection piste de travail | K3: PK( 18+650 Au 19+450 ) | P3: PPL | R3: =IF($AB3="","",IFERROR(INDEX(ITP!$G$3:$G$46,MATCH($AB3,ITP!$E$3:$E$46,0)),"")) | S3: 08:00 | U3: =IF($AB3="","",IFERROR(INDEX(ITP!$I$3:$I$46,MATCH($AB3,ITP!$E$3:$E$46,0)),"")) | V3: =IF($AB3="","",IFERROR(INDEX(ITP!$J$3:$J$46,MATCH($AB3,ITP!$E$3:$E$46,0)),"")) | W3: =IF($AB3="","",IFERROR(INDEX(ITP!$K$3:$K$46,MATCH($AB3,ITP!$E$3:$E$46,0)),"")) | X3: =IF($AB3="","",IFERROR(INDEX(ITP!$L$3:$L$46,MATCH($AB3,ITP!$E$3:$E$46,0)),"")) | Y3: =IF($AB3="","",IFERROR(INDEX(ITP!$M$3:$M$46,MATCH($AB3,ITP!$E$3:$E$46,0)),"")) | Z3: =IF($AB3="","",IFERROR(INDEX(ITP!$N$3:$N$46,MATCH($AB3,ITP!$E$3:$E$46,0)),"")) | AA3: =IF(A3="","",A3&"|"&COUNTIF($A$2:A3,A3)) | AB3: =IF($A3="","",IFERROR(INDEX(ITP!$C$3:$C$21,MATCH(1,INDEX((ITP!$A$3:$A$21=$A3)*(((ITP!$B$3:$B$21="")+ISNUMBER(SEARCH(ITP!$B$3:$B$21,$G3&" "&$T3)))>0),0),0)),""))
A4: Relevé topographique | B4: 21063-G26-PPL-RFI-0003 | D4: 45936 | E4: TRUNKLINE FROM ISW MFD TO TFTⅡCPF | F4: 21061-0000-PPL-TDW-0008 | G4: Relevé Topographique pré-construction | K4: pk (12+200 Au 16+300 ) (19+450 Au 24+730 ) | P4: PPL | R4: =IF($AB4="","",IFERROR(INDEX(ITP!$G$3:$G$46,MATCH($AB4,ITP!$E$3:$E$46,0)),"")) | S4: 08:00 | U4: =IF($AB4="","",IFERROR(INDEX(ITP!$I$3:$I$46,MATCH($AB4,ITP!$E$3:$E$46,0)),"")) | V4: =IF($AB4="","",IFERROR(INDEX(ITP!$J$3:$J$46,MATCH($AB4,ITP!$E$3:$E$46,0)),"")) | W4: =IF($AB4="","",IFERROR(INDEX(ITP!$K$3:$K$46,MATCH($AB4,ITP!$E$3:$E$46,0)),"")) | X4: =IF($AB4="","",IFERROR(INDEX(ITP!$L$3:$L$46,MATCH($AB4,ITP!$E$3:$E$46,0)),"")) | Y4: =IF($AB4="","",IFERROR(INDEX(ITP!$M$3:$M$46,MATCH($AB4,ITP!$E$3:$E$46,0)),"")) | Z4: =IF($AB4="","",IFERROR(INDEX(ITP!$N$3:$N$46,MATCH($AB4,ITP!$E$3:$E$46,0)),"")) | AA4: =IF(A4="","",A4&"|"&COUNTIF($A$2:A4,A4)) | AB4: =IF($A4="","",IFERROR(INDEX(ITP!$C$3:$C$21,MATCH(1,INDEX((ITP!$A$3:$A$21=$A4)*(((ITP!$B$3:$B$21="")+ISNUMBER(SEARCH(ITP!$B$3:$B$21,$G4&" "&$T4)))>0),0),0)),""))
A5: Piste de travail | B5: 21063-G26-PPL-RFI-0004 | D5: 45936 | E5: TRUNKLINE FROM ISW MFD TO TFTⅡCPF | F5: 21063-G0-PPL-PR-0007 | G5: Inspection piste de travail | K5: PK( 16+300 Au 18+400 ) | P5: PPL | R5: =IF($AB5="","",IFERROR(INDEX(ITP!$G$3:$G$46,MATCH($AB5,ITP!$E$3:$E$46,0)),"")) | S5: 08:00 | U5: =IF($AB5="","",IFERROR(INDEX(ITP!$I$3:$I$46,MATCH($AB5,ITP!$E$3:$E$46,0)),"")) | V5: =IF($AB5="","",IFERROR(INDEX(ITP!$J$3:$J$46,MATCH($AB5,ITP!$E$3:$E$46,0)),"")) | W5: =IF($AB5="","",IFERROR(INDEX(ITP!$K$3:$K$46,MATCH($AB5,ITP!$E$3:$E$46,0)),"")) | X5: =IF($AB5="","",IFERROR(INDEX(ITP!$L$3:$L$46,MATCH($AB5,ITP!$E$3:$E$46,0)),"")) | Y5: =IF($AB5="","",IFERROR(INDEX(ITP!$M$3:$M$46,MATCH($AB5,ITP!$E$3:$E$46,0)),"")) | Z5: =IF($AB5="","",IFERROR(INDEX(ITP!$N$3:$N$46,MATCH($AB5,ITP!$E$3:$E$46,0)),"")) | AA5: =IF(A5="","",A5&"|"&COUNTIF($A$2:A5,A5)) | AB5: =IF($A5="","",IFERROR(INDEX(ITP!$C$3:$C$21,MATCH(1,INDEX((ITP!$A$3:$A$21=$A5)*(((ITP!$B$3:$B$21="")+ISNUMBER(SEARCH(ITP!$B$3:$B$21,$G5&" "&$T5)))>0),0),0)),""))
A6: Piste de travail | B6: 21063-G26-PPL-RFI-0005 | D6: 45940 | E6: TRUNKLINE FROM ISW MFD TO TFTⅡCPF | F6: 21063-G0-PPL-PR-0007 | G6: Inspection piste de travail | K6: PK( 14+850 Au 16+300 ) | P6: PPL | R6: =IF($AB6="","",IFERROR(INDEX(ITP!$G$3:$G$46,MATCH($AB6,ITP!$E$3:$E$46,0)),"")) | S6: 08:00 | U6: =IF($AB6="","",IFERROR(INDEX(ITP!$I$3:$I$46,MATCH($AB6,ITP!$E$3:$E$46,0)),"")) | V6: =IF($AB6="","",IFERROR(INDEX(ITP!$J$3:$J$46,MATCH($AB6,ITP!$E$3:$E$46,0)),"")) | W6: =IF($AB6="","",IFERROR(INDEX(ITP!$K$3:$K$46,MATCH($AB6,ITP!$E$3:$E$46,0)),"")) | X6: =IF($AB6="","",IFERROR(INDEX(ITP!$L$3:$L$46,MATCH($AB6,ITP!$E$3:$E$46,0)),"")) | Y6: =IF($AB6="","",IFERROR(INDEX(ITP!$M$3:$M$46,MATCH($AB6,ITP!$E$3:$E$46,0)),"")) | Z6: =IF($AB6="","",IFERROR(INDEX(ITP!$N$3:$N$46,MATCH($AB6,ITP!$E$3:$E$46,0)),"")) | AA6: =IF(A6="","",A6&"|"&COUNTIF($A$2:A6,A6)) | AB6: =IF($A6="","",IFERROR(INDEX(ITP!$C$3:$C$21,MATCH(1,INDEX((ITP!$A$3:$A$21=$A6)*(((ITP!$B$3:$B$21="")+ISNUMBER(SEARCH(ITP!$B$3:$B$21,$G6&" "&$T6)))>0),0),0)),""))
A7: Piste de travail | B7: 21063-G26-PPL-RFI-0006 | D7: 45946 | E7: TRUNKLINE FROM ISW MFD TO TFTⅡCPF | F7: 21063-G0-PPL-PR-0007 | G7: Inspection piste de travail | K7: PK( 12+300 Au 13+000 ) | P7: PPL | R7: =IF($AB7="","",IFERROR(INDEX(ITP!$G$3:$G$46,MATCH($AB7,ITP!$E$3:$E$46,0)),"")) | S7: 08:00 | U7: =IF($AB7="","",IFERROR(INDEX(ITP!$I$3:$I$46,MATCH($AB7,ITP!$E$3:$E$46,0)),"")) | V7: =IF($AB7="","",IFERROR(INDEX(ITP!$J$3:$J$46,MATCH($AB7,ITP!$E$3:$E$46,0)),"")) | W7: =IF($AB7="","",IFERROR(INDEX(ITP!$K$3:$K$46,MATCH($AB7,ITP!$E$3:$E$46,0)),"")) | X7: =IF($AB7="","",IFERROR(INDEX(ITP!$L$3:$L$46,MATCH($AB7,ITP!$E$3:$E$46,0)),"")) | Y7: =IF($AB7="","",IFERROR(INDEX(ITP!$M$3:$M$46,MATCH($AB7,ITP!$E$3:$E$46,0)),"")) | Z7: =IF($AB7="","",IFERROR(INDEX(ITP!$N$3:$N$46,MATCH($AB7,ITP!$E$3:$E$46,0)),"")) | AA7: =IF(A7="","",A7&"|"&COUNTIF($A$2:A7,A7)) | AB7: =IF($A7="","",IFERROR(INDEX(ITP!$C$3:$C$21,MATCH(1,INDEX((ITP!$A$3:$A$21=$A7)*(((ITP!$B$3:$B$21="")+ISNUMBER(SEARCH(ITP!$B$3:$B$21,$G7&" "&$T7)))>0),0),0)),""))
A8: Piste de travail | B8: 21063-G26-PPL-RFI-0007 | D8: 45946 | E8: TRUNKLINE FROM ISW MFD TO TFTⅡCPF | F8: 21063-G0-PPL-PR-0007 | G8: Inspection piste de travail | K8: PK( 13+300 Au 14+800 ) | P8: PPL | R8: =IF($AB8="","",IFERROR(INDEX(ITP!$G$3:$G$46,MATCH($AB8,ITP!$E$3:$E$46,0)),"")) | S8: 08:00 | U8: =IF($AB8="","",IFERROR(INDEX(ITP!$I$3:$I$46,MATCH($AB8,ITP!$E$3:$E$46,0)),"")) | V8: =IF($AB8="","",IFERROR(INDEX(ITP!$J$3:$J$46,MATCH($AB8,ITP!$E$3:$E$46,0)),"")) | W8: =IF($AB8="","",IFERROR(INDEX(ITP!$K$3:$K$46,MATCH($AB8,ITP!$E$3:$E$46,0)),"")) | X8: =IF($AB8="","",IFERROR(INDEX(ITP!$L$3:$L$46,MATCH($AB8,ITP!$E$3:$E$46,0)),"")) | Y8: =IF($AB8="","",IFERROR(INDEX(ITP!$M$3:$M$46,MATCH($AB8,ITP!$E$3:$E$46,0)),"")) | Z8: =IF($AB8="","",IFERROR(INDEX(ITP!$N$3:$N$46,MATCH($AB8,ITP!$E$3:$E$46,0)),"")) | AA8: =IF(A8="","",A8&"|"&COUNTIF($A$2:A8,A8)) | AB8: =IF($A8="","",IFERROR(INDEX(ITP!$C$3:$C$21,MATCH(1,INDEX((ITP!$A$3:$A$21=$A8)*(((ITP!$B$3:$B$21="")+ISNUMBER(SEARCH(ITP!$B$3:$B$21,$G8&" "&$T8)))>0),0),0)),""))
A9: Piste de travail | B9: 21063-G26-PPL-RFI-0008 | D9: 45946 | E9: TRUNKLINE FROM ISW MFD TO TFTⅡCPF | F9: 21063-G0-PPL-PR-0007 | G9: Inspection piste de travail ISW-CPF | K9: PK( 19+700 Au 21+100 ) | P9: PPL | R9: =IF($AB9="","",IFERROR(INDEX(ITP!$G$3:$G$46,MATCH($AB9,ITP!$E$3:$E$46,0)),"")) | S9: 08:00 | U9: =IF($AB9="","",IFERROR(INDEX(ITP!$I$3:$I$46,MATCH($AB9,ITP!$E$3:$E$46,0)),"")) | V9: =IF($AB9="","",IFERROR(INDEX(ITP!$J$3:$J$46,MATCH($AB9,ITP!$E$3:$E$46,0)),"")) | W9: =IF($AB9="","",IFERROR(INDEX(ITP!$K$3:$K$46,MATCH($AB9,ITP!$E$3:$E$46,0)),"")) | X9: =IF($AB9="","",IFERROR(INDEX(ITP!$L$3:$L$46,MATCH($AB9,ITP!$E$3:$E$46,0)),"")) | Y9: =IF($AB9="","",IFERROR(INDEX(ITP!$M$3:$M$46,MATCH($AB9,ITP!$E$3:$E$46,0)),"")) | Z9: =IF($AB9="","",IFERROR(INDEX(ITP!$N$3:$N$46,MATCH($AB9,ITP!$E$3:$E$46,0)),"")) | AA9: =IF(A9="","",A9&"|"&COUNTIF($A$2:A9,A9)) | AB9: =IF($A9="","",IFERROR(INDEX(ITP!$C$3:$C$21,MATCH(1,INDEX((ITP!$A$3:$A$21=$A9)*(((ITP!$B$3:$B$21="")+ISNUMBER(SEARCH(ITP!$B$3:$B$21,$G9&" "&$T9)))>0),0),0)),""))
A10: Relevé topographique | B10: 21063-G26-PPL-RFI-0009 | D10: 45949 | E10: TRUNKLINE FROM ISW MFD TO TFTⅡCPF | F10: 21061-0000-PPL-SPC-0006 | G10: Relevé Topographique pré-construction | K10: pk (21+211 Au 22+100 ) (22+130 Au 22+230 ) | P10: PPL | R10: =IF($AB10="","",IFERROR(INDEX(ITP!$G$3:$G$46,MATCH($AB10,ITP!$E$3:$E$46,0)),"")) | S10: 08:00 | U10: =IF($AB10="","",IFERROR(INDEX(ITP!$I$3:$I$46,MATCH($AB10,ITP!$E$3:$E$46,0)),"")) | V10: =IF($AB10="","",IFERROR(INDEX(ITP!$J$3:$J$46,MATCH($AB10,ITP!$E$3:$E$46,0)),"")) | W10: =IF($AB10="","",IFERROR(INDEX(ITP!$K$3:$K$46,MATCH($AB10,ITP!$E$3:$E$46,0)),"")) | X10: =IF($AB10="","",IFERROR(INDEX(ITP!$L$3:$L$46,MATCH($AB10,ITP!$E$3:$E$46,0)),"")) | Y10: =IF($AB10="","",IFERROR(INDEX(ITP!$M$3:$M$46,MATCH($AB10,ITP!$E$3:$E$46,0)),"")) | Z10: =IF($AB10="","",IFERROR(INDEX(ITP!$N$3:$N$46,MATCH($AB10,ITP!$E$3:$E$46,0)),"")) | AA10: =IF(A10="","",A10&"|"&COUNTIF($A$2:A10,A10)) | AB10: =IF($A10="","",IFERROR(INDEX(ITP!$C$3:$C$21,MATCH(1,INDEX((ITP!$A$3:$A$21=$A10)*(((ITP!$B$3:$B$21="")+ISNUMBER(SEARCH(ITP!$B$3:$B$21,$G10&" "&$T10)))>0),0),0)),""))
A11: Piste de travail | B11: 21063-G26-PPL-RFI-0010 | D11: 45949 | E11: TRUNKLINE FROM ISW MFD TO TFTⅡCPF | F11: 21063-G0-PPL-PR-0007 | G11: Inspection piste de travail | K11: PK( 21+200 Au 22+100 ) (22+130 Au 22+230 ) | P11: PPL | R11: =IF($AB11="","",IFERROR(INDEX(ITP!$G$3:$G$46,MATCH($AB11,ITP!$E$3:$E$46,0)),"")) | S11: 08:00 | U11: =IF($AB11="","",IFERROR(INDEX(ITP!$I$3:$I$46,MATCH($AB11,ITP!$E$3:$E$46,0)),"")) | V11: =IF($AB11="","",IFERROR(INDEX(ITP!$J$3:$J$46,MATCH($AB11,ITP!$E$3:$E$46,0)),"")) | W11: =IF($AB11="","",IFERROR(INDEX(ITP!$K$3:$K$46,MATCH($AB11,ITP!$E$3:$E$46,0)),"")) | X11: =IF($AB11="","",IFERROR(INDEX(ITP!$L$3:$L$46,MATCH($AB11,ITP!$E$3:$E$46,0)),"")) | Y11: =IF($AB11="","",IFERROR(INDEX(ITP!$M$3:$M$46,MATCH($AB11,ITP!$E$3:$E$46,0)),"")) | Z11: =IF($AB11="","",IFERROR(INDEX(ITP!$N$3:$N$46,MATCH($AB11,ITP!$E$3:$E$46,0)),"")) | AA11: =IF(A11="","",A11&"|"&COUNTIF($A$2:A11,A11)) | AB11: =IF($A11="","",IFERROR(INDEX(ITP!$C$3:$C$21,MATCH(1,INDEX((ITP!$A$3:$A$21=$A11)*(((ITP!$B$3:$B$21="")+ISNUMBER(SEARCH(ITP!$B$3:$B$21,$G11&" "&$T11)))>0),0),0)),""))
A12: Piste de travail | B12: 21063-G26-PPL-RFI-0011 | D12: 45952 | E12: TRUNKLINE FROM ISW MFD TO TFTⅡCPF | F12: 21063-G0-PPL-PR-0007 | G12: Inspection piste de travail | K12: PK( 22+300 Au 22+850 )(22+900 Au 23+250 ) (23+300 Au 23+350) | P12: PPL | R12: =IF($AB12="","",IFERROR(INDEX(ITP!$G$3:$G$46,MATCH($AB12,ITP!$E$3:$E$46,0)),"")) | S12: 08:00 | U12: =IF($AB12="","",IFERROR(INDEX(ITP!$I$3:$I$46,MATCH($AB12,ITP!$E$3:$E$46,0)),"")) | V12: =IF($AB12="","",IFERROR(INDEX(ITP!$J$3:$J$46,MATCH($AB12,ITP!$E$3:$E$46,0)),"")) | W12: =IF($AB12="","",IFERROR(INDEX(ITP!$K$3:$K$46,MATCH($AB12,ITP!$E$3:$E$46,0)),"")) | X12: =IF($AB12="","",IFERROR(INDEX(ITP!$L$3:$L$46,MATCH($AB12,ITP!$E$3:$E$46,0)),"")) | Y12: =IF($AB12="","",IFERROR(INDEX(ITP!$M$3:$M$46,MATCH($AB12,ITP!$E$3:$E$46,0)),"")) | Z12: =IF($AB12="","",IFERROR(INDEX(ITP!$N$3:$N$46,MATCH($AB12,ITP!$E$3:$E$46,0)),"")) | AA12: =IF(A12="","",A12&"|"&COUNTIF($A$2:A12,A12)) | AB12: =IF($A12="","",IFERROR(INDEX(ITP!$C$3:$C$21,MATCH(1,INDEX((ITP!$A$3:$A$21=$A12)*(((ITP!$B$3:$B$21="")+ISNUMBER(SEARCH(ITP!$B$3:$B$21,$G12&" "&$T12)))>0),0),0)),""))
A13: Piste de travail | B13: 21063-G26-PPL-RFI-0012 | D13: 45956 | E13: TRUNKLINE FROM ISW MFD TO TFTⅡCPF | F13: 21063-G0-PPL-PR-0007 | G13: Inspection piste de travail ISW-CPF | K13: PK( 23+400 Au 24+000 ) | P13: PPL | R13: =IF($AB13="","",IFERROR(INDEX(ITP!$G$3:$G$46,MATCH($AB13,ITP!$E$3:$E$46,0)),"")) | S13: 08:00 | U13: =IF($AB13="","",IFERROR(INDEX(ITP!$I$3:$I$46,MATCH($AB13,ITP!$E$3:$E$46,0)),"")) | V13: =IF($AB13="","",IFERROR(INDEX(ITP!$J$3:$J$46,MATCH($AB13,ITP!$E$3:$E$46,0)),"")) | W13: =IF($AB13="","",IFERROR(INDEX(ITP!$K$3:$K$46,MATCH($AB13,ITP!$E$3:$E$46,0)),"")) | X13: =IF($AB13="","",IFERROR(INDEX(ITP!$L$3:$L$46,MATCH($AB13,ITP!$E$3:$E$46,0)),"")) | Y13: =IF($AB13="","",IFERROR(INDEX(ITP!$M$3:$M$46,MATCH($AB13,ITP!$E$3:$E$46,0)),"")) | Z13: =IF($AB13="","",IFERROR(INDEX(ITP!$N$3:$N$46,MATCH($AB13,ITP!$E$3:$E$46,0)),"")) | AA13: =IF(A13="","",A13&"|"&COUNTIF($A$2:A13,A13)) | AB13: =IF($A13="","",IFERROR(INDEX(ITP!$C$3:$C$21,MATCH(1,INDEX((ITP!$A$3:$A$21=$A13)*(((ITP!$B$3:$B$21="")+ISNUMBER(SEARCH(ITP!$B$3:$B$21,$G13&" "&$T13)))>0),0),0)),""))
A14: Relevé topographique | B14: 21063-G26-PPL-RFI-0013 | D14: 45957 | E14: TRUNKLINE FROM ISW MFD TO TFTⅡCPF | G14: Relevé Topographique pré-construction | K14: pk (16+300 Au 18+650 ) | P14: PPL | R14: =IF($AB14="","",IFERROR(INDEX(ITP!$G$3:$G$46,MATCH($AB14,ITP!$E$3:$E$46,0)),"")) | S14: 08:00 | U14: =IF($AB14="","",IFERROR(INDEX(ITP!$I$3:$I$46,MATCH($AB14,ITP!$E$3:$E$46,0)),"")) | V14: =IF($AB14="","",IFERROR(INDEX(ITP!$J$3:$J$46,MATCH($AB14,ITP!$E$3:$E$46,0)),"")) | W14: =IF($AB14="","",IFERROR(INDEX(ITP!$K$3:$K$46,MATCH($AB14,ITP!$E$3:$E$46,0)),"")) | X14: =IF($AB14="","",IFERROR(INDEX(ITP!$L$3:$L$46,MATCH($AB14,ITP!$E$3:$E$46,0)),"")) | Y14: =IF($AB14="","",IFERROR(INDEX(ITP!$M$3:$M$46,MATCH($AB14,ITP!$E$3:$E$46,0)),"")) | Z14: =IF($AB14="","",IFERROR(INDEX(ITP!$N$3:$N$46,MATCH($AB14,ITP!$E$3:$E$46,0)),"")) | AA14: =IF(A14="","",A14&"|"&COUNTIF($A$2:A14,A14)) | AB14: =IF($A14="","",IFERROR(INDEX(ITP!$C$3:$C$21,MATCH(1,INDEX((ITP!$A$3:$A$21=$A14)*(((ITP!$B$3:$B$21="")+ISNUMBER(SEARCH(ITP!$B$3:$B$21,$G14&" "&$T14)))>0),0),0)),""))
A15: Piste de travail | B15: 21063-G26-PPL-RFI-0014 | D15: 45959 | E15: TRUNKLINE FROM ISW MFD TO TFTⅡCPF | F15: 21063-G0-PPL-PR-0007 | G15: Inspection piste de travail | K15: PK( 18+400 Au 18+650 ) | P15: PPL | R15: =IF($AB15="","",IFERROR(INDEX(ITP!$G$3:$G$46,MATCH($AB15,ITP!$E$3:$E$46,0)),"")) | S15: 08:00 | U15: =IF($AB15="","",IFERROR(INDEX(ITP!$I$3:$I$46,MATCH($AB15,ITP!$E$3:$E$46,0)),"")) | V15: =IF($AB15="","",IFERROR(INDEX(ITP!$J$3:$J$46,MATCH($AB15,ITP!$E$3:$E$46,0)),"")) | W15: =IF($AB15="","",IFERROR(INDEX(ITP!$K$3:$K$46,MATCH($AB15,ITP!$E$3:$E$46,0)),"")) | X15: =IF($AB15="","",IFERROR(INDEX(ITP!$L$3:$L$46,MATCH($AB15,ITP!$E$3:$E$46,0)),"")) | Y15: =IF($AB15="","",IFERROR(INDEX(ITP!$M$3:$M$46,MATCH($AB15,ITP!$E$3:$E$46,0)),"")) | Z15: =IF($AB15="","",IFERROR(INDEX(ITP!$N$3:$N$46,MATCH($AB15,ITP!$E$3:$E$46,0)),"")) | AA15: =IF(A15="","",A15&"|"&COUNTIF($A$2:A15,A15)) | AB15: =IF($A15="","",IFERROR(INDEX(ITP!$C$3:$C$21,MATCH(1,INDEX((ITP!$A$3:$A$21=$A15)*(((ITP!$B$3:$B$21="")+ISNUMBER(SEARCH(ITP!$B$3:$B$21,$G15&" "&$T15)))>0),0),0)),""))
A16: Piste de travail | B16: 21063-G26-PPL-RFI-0015 | D16: 45968 | E16: TRUNKLINE FROM ISW MFD TO TFTⅡCPF | F16: 21063-G0-PPL-PR-0007 | G16: Inspection piste de travail ISW-CPF | K16: PK( 24+057 Au 24+701 ) | P16: PPL | R16: =IF($AB16="","",IFERROR(INDEX(ITP!$G$3:$G$46,MATCH($AB16,ITP!$E$3:$E$46,0)),"")) | S16: 08:00 | U16: =IF($AB16="","",IFERROR(INDEX(ITP!$I$3:$I$46,MATCH($AB16,ITP!$E$3:$E$46,0)),"")) | V16: =IF($AB16="","",IFERROR(INDEX(ITP!$J$3:$J$46,MATCH($AB16,ITP!$E$3:$E$46,0)),"")) | W16: =IF($AB16="","",IFERROR(INDEX(ITP!$K$3:$K$46,MATCH($AB16,ITP!$E$3:$E$46,0)),"")) | X16: =IF($AB16="","",IFERROR(INDEX(ITP!$L$3:$L$46,MATCH($AB16,ITP!$E$3:$E$46,0)),"")) | Y16: =IF($AB16="","",IFERROR(INDEX(ITP!$M$3:$M$46,MATCH($AB16,ITP!$E$3:$E$46,0)),"")) | Z16: =IF($AB16="","",IFERROR(INDEX(ITP!$N$3:$N$46,MATCH($AB16,ITP!$E$3:$E$46,0)),"")) | AA16: =IF(A16="","",A16&"|"&COUNTIF($A$2:A16,A16)) | AB16: =IF($A16="","",IFERROR(INDEX(ITP!$C$3:$C$21,MATCH(1,INDEX((ITP!$A$3:$A$21=$A16)*(((ITP!$B$3:$B$21="")+ISNUMBER(SEARCH(ITP!$B$3:$B$21,$G16&" "&$T16)))>0),0),0)),""))
A17: Ouverture de la tranchée | B17: 21063-G26-PPL-RFI-0016 | D17: 45973 | E17: TRUNKLINE FROM ISW MFD TO TFTⅡCPF | F17: 21061-0000-PPL-TDW-0009 | G17: Inspection de tranchée | K17: PK( 23+350 Au 23+850 ) | M17: 500 | P17: PPL | R17: =IF($AB17="","",IFERROR(INDEX(ITP!$G$3:$G$46,MATCH($AB17,ITP!$E$3:$E$46,0)),"")) | S17: 08:00 | U17: =IF($AB17="","",IFERROR(INDEX(ITP!$I$3:$I$46,MATCH($AB17,ITP!$E$3:$E$46,0)),"")) | V17: =IF($AB17="","",IFERROR(INDEX(ITP!$J$3:$J$46,MATCH($AB17,ITP!$E$3:$E$46,0)),"")) | W17: =IF($AB17="","",IFERROR(INDEX(ITP!$K$3:$K$46,MATCH($AB17,ITP!$E$3:$E$46,0)),"")) | X17: =IF($AB17="","",IFERROR(INDEX(ITP!$L$3:$L$46,MATCH($AB17,ITP!$E$3:$E$46,0)),"")) | Y17: =IF($AB17="","",IFERROR(INDEX(ITP!$M$3:$M$46,MATCH($AB17,ITP!$E$3:$E$46,0)),"")) | Z17: =IF($AB17="","",IFERROR(INDEX(ITP!$N$3:$N$46,MATCH($AB17,ITP!$E$3:$E$46,0)),"")) | AA17: =IF(A17="","",A17&"|"&COUNTIF($A$2:A17,A17)) | AB17: =IF($A17="","",IFERROR(INDEX(ITP!$C$3:$C$21,MATCH(1,INDEX((ITP!$A$3:$A$21=$A17)*(((ITP!$B$3:$B$21="")+ISNUMBER(SEARCH(ITP!$B$3:$B$21,$G17&" "&$T17)))>0),0),0)),""))
A18: Ouverture de la tranchée | B18: 21063-G26-PPL-RFI-0017 | D18: 45980 | E18: TRUNKLINE FROM ISW MFD TO TFTⅡCPF | F18: 21061-0000-PPL-TDW-0009 | G18: Inspection de tranchée | K18: PK( 23+800 Au 24+070 ) | M18: 270 | P18: PPL | R18: =IF($AB18="","",IFERROR(INDEX(ITP!$G$3:$G$46,MATCH($AB18,ITP!$E$3:$E$46,0)),"")) | S18: 08:00 | U18: =IF($AB18="","",IFERROR(INDEX(ITP!$I$3:$I$46,MATCH($AB18,ITP!$E$3:$E$46,0)),"")) | V18: =IF($AB18="","",IFERROR(INDEX(ITP!$J$3:$J$46,MATCH($AB18,ITP!$E$3:$E$46,0)),"")) | W18: =IF($AB18="","",IFERROR(INDEX(ITP!$K$3:$K$46,MATCH($AB18,ITP!$E$3:$E$46,0)),"")) | X18: =IF($AB18="","",IFERROR(INDEX(ITP!$L$3:$L$46,MATCH($AB18,ITP!$E$3:$E$46,0)),"")) | Y18: =IF($AB18="","",IFERROR(INDEX(ITP!$M$3:$M$46,MATCH($AB18,ITP!$E$3:$E$46,0)),"")) | Z18: =IF($AB18="","",IFERROR(INDEX(ITP!$N$3:$N$46,MATCH($AB18,ITP!$E$3:$E$46,0)),"")) | AA18: =IF(A18="","",A18&"|"&COUNTIF($A$2:A18,A18)) | AB18: =IF($A18="","",IFERROR(INDEX(ITP!$C$3:$C$21,MATCH(1,INDEX((ITP!$A$3:$A$21=$A18)*(((ITP!$B$3:$B$21="")+ISNUMBER(SEARCH(ITP!$B$3:$B$21,$G18&" "&$T18)))>0),0),0)),""))
A19: Relevé topographique | B19: 21063-G26-PPL-RFI-0018 | D19: 45981 | E19: TRUNKLINE FROM ISW MFD TO TFTⅡCPF | G19: Relevé Topographique pré-construction | K19: pk (10+687 Au 12+053 ) | M19: 1366 | P19: PPL | R19: =IF($AB19="","",IFERROR(INDEX(ITP!$G$3:$G$46,MATCH($AB19,ITP!$E$3:$E$46,0)),"")) | S19: 08:00 | U19: =IF($AB19="","",IFERROR(INDEX(ITP!$I$3:$I$46,MATCH($AB19,ITP!$E$3:$E$46,0)),"")) | V19: =IF($AB19="","",IFERROR(INDEX(ITP!$J$3:$J$46,MATCH($AB19,ITP!$E$3:$E$46,0)),"")) | W19: =IF($AB19="","",IFERROR(INDEX(ITP!$K$3:$K$46,MATCH($AB19,ITP!$E$3:$E$46,0)),"")) | X19: =IF($AB19="","",IFERROR(INDEX(ITP!$L$3:$L$46,MATCH($AB19,ITP!$E$3:$E$46,0)),"")) | Y19: =IF($AB19="","",IFERROR(INDEX(ITP!$M$3:$M$46,MATCH($AB19,ITP!$E$3:$E$46,0)),"")) | Z19: =IF($AB19="","",IFERROR(INDEX(ITP!$N$3:$N$46,MATCH($AB19,ITP!$E$3:$E$46,0)),"")) | AA19: =IF(A19="","",A19&"|"&COUNTIF($A$2:A19,A19)) | AB19: =IF($A19="","",IFERROR(INDEX(ITP!$C$3:$C$21,MATCH(1,INDEX((ITP!$A$3:$A$21=$A19)*(((ITP!$B$3:$B$21="")+ISNUMBER(SEARCH(ITP!$B$3:$B$21,$G19&" "&$T19)))>0),0),0)),""))
A20: Relevé topographique | B20: 21063-G26-PPL-RFI-0019 | D20: 45982 | E20: TRUNKLINE FROM ISW MFD TO TFTⅡCPF | G20: Relevé Topographique pré-construction | K20: pk (6+272 Au 10+687 ) | M20: 4415 | P20: PPL | R20: =IF($AB20="","",IFERROR(INDEX(ITP!$G$3:$G$46,MATCH($AB20,ITP!$E$3:$E$46,0)),"")) | S20: 08:00 | U20: =IF($AB20="","",IFERROR(INDEX(ITP!$I$3:$I$46,MATCH($AB20,ITP!$E$3:$E$46,0)),"")) | V20: =IF($AB20="","",IFERROR(INDEX(ITP!$J$3:$J$46,MATCH($AB20,ITP!$E$3:$E$46,0)),"")) | W20: =IF($AB20="","",IFERROR(INDEX(ITP!$K$3:$K$46,MATCH($AB20,ITP!$E$3:$E$46,0)),"")) | X20: =IF($AB20="","",IFERROR(INDEX(ITP!$L$3:$L$46,MATCH($AB20,ITP!$E$3:$E$46,0)),"")) | Y20: =IF($AB20="","",IFERROR(INDEX(ITP!$M$3:$M$46,MATCH($AB20,ITP!$E$3:$E$46,0)),"")) | Z20: =IF($AB20="","",IFERROR(INDEX(ITP!$N$3:$N$46,MATCH($AB20,ITP!$E$3:$E$46,0)),"")) | AA20: =IF(A20="","",A20&"|"&COUNTIF($A$2:A20,A20)) | AB20: =IF($A20="","",IFERROR(INDEX(ITP!$C$3:$C$21,MATCH(1,INDEX((ITP!$A$3:$A$21=$A20)*(((ITP!$B$3:$B$21="")+ISNUMBER(SEARCH(ITP!$B$3:$B$21,$G20&" "&$T20)))>0),0),0)),""))
A21: Relevé topographique | B21: 21063-G26-PPL-RFI-0020 | D21: 45983 | E21: TRUNKLINE FROM ISW MFD TO TFTⅡCPF | G21: Relevé Topographique pré-construction ISW/CPF | K21: pk (0+031 Au 4+101 ) | M21: 4070 | P21: PPL | R21: =IF($AB21="","",IFERROR(INDEX(ITP!$G$3:$G$46,MATCH($AB21,ITP!$E$3:$E$46,0)),"")) | S21: 08:00 | U21: =IF($AB21="","",IFERROR(INDEX(ITP!$I$3:$I$46,MATCH($AB21,ITP!$E$3:$E$46,0)),"")) | V21: =IF($AB21="","",IFERROR(INDEX(ITP!$J$3:$J$46,MATCH($AB21,ITP!$E$3:$E$46,0)),"")) | W21: =IF($AB21="","",IFERROR(INDEX(ITP!$K$3:$K$46,MATCH($AB21,ITP!$E$3:$E$46,0)),"")) | X21: =IF($AB21="","",IFERROR(INDEX(ITP!$L$3:$L$46,MATCH($AB21,ITP!$E$3:$E$46,0)),"")) | Y21: =IF($AB21="","",IFERROR(INDEX(ITP!$M$3:$M$46,MATCH($AB21,ITP!$E$3:$E$46,0)),"")) | Z21: =IF($AB21="","",IFERROR(INDEX(ITP!$N$3:$N$46,MATCH($AB21,ITP!$E$3:$E$46,0)),"")) | AA21: =IF(A21="","",A21&"|"&COUNTIF($A$2:A21,A21)) | AB21: =IF($A21="","",IFERROR(INDEX(ITP!$C$3:$C$21,MATCH(1,INDEX((ITP!$A$3:$A$21=$A21)*(((ITP!$B$3:$B$21="")+ISNUMBER(SEARCH(ITP!$B$3:$B$21,$G21&" "&$T21)))>0),0),0)),""))
A22: Ouverture de la tranchée | B22: 21063-G26-PPL-RFI-0021 | D22: 45985 | E22: TRUNKLINE FROM ISW MFD TO TFTⅡCPF | F22: 21061-0000-PPL-TDW-0009 | G22: Inspection de tranchée | K22: ( 24+110 au 24+180 ) ( 24+190 au 24+360 ) | M22: 70 | P22: PPL | R22: =IF($AB22="","",IFERROR(INDEX(ITP!$G$3:$G$46,MATCH($AB22,ITP!$E$3:$E$46,0)),"")) | S22: 08:00 | U22: =IF($AB22="","",IFERROR(INDEX(ITP!$I$3:$I$46,MATCH($AB22,ITP!$E$3:$E$46,0)),"")) | V22: =IF($AB22="","",IFERROR(INDEX(ITP!$J$3:$J$46,MATCH($AB22,ITP!$E$3:$E$46,0)),"")) | W22: =IF($AB22="","",IFERROR(INDEX(ITP!$K$3:$K$46,MATCH($AB22,ITP!$E$3:$E$46,0)),"")) | X22: =IF($AB22="","",IFERROR(INDEX(ITP!$L$3:$L$46,MATCH($AB22,ITP!$E$3:$E$46,0)),"")) | Y22: =IF($AB22="","",IFERROR(INDEX(ITP!$M$3:$M$46,MATCH($AB22,ITP!$E$3:$E$46,0)),"")) | Z22: =IF($AB22="","",IFERROR(INDEX(ITP!$N$3:$N$46,MATCH($AB22,ITP!$E$3:$E$46,0)),"")) | AA22: =IF(A22="","",A22&"|"&COUNTIF($A$2:A22,A22)) | AB22: =IF($A22="","",IFERROR(INDEX(ITP!$C$3:$C$21,MATCH(1,INDEX((ITP!$A$3:$A$21=$A22)*(((ITP!$B$3:$B$21="")+ISNUMBER(SEARCH(ITP!$B$3:$B$21,$G22&" "&$T22)))>0),0),0)),""))
A23: Piste de travail | B23: 21063-G26-PPL-RFI-0022 | D23: 45990 | E23: TRUNKLINE FROM ISW MFD TO TFTⅡCPF | F23: 21063-G0-PPL-PR-0007 | G23: Inspection piste de travail | K23: PK( 8+217 Au 8+243 ) ( 8+250 Au 9+030 ) | M23: 806 | P23: PPL | R23: =IF($AB23="","",IFERROR(INDEX(ITP!$G$3:$G$46,MATCH($AB23,ITP!$E$3:$E$46,0)),"")) | S23: 08:00 | U23: =IF($AB23="","",IFERROR(INDEX(ITP!$I$3:$I$46,MATCH($AB23,ITP!$E$3:$E$46,0)),"")) | V23: =IF($AB23="","",IFERROR(INDEX(ITP!$J$3:$J$46,MATCH($AB23,ITP!$E$3:$E$46,0)),"")) | W23: =IF($AB23="","",IFERROR(INDEX(ITP!$K$3:$K$46,MATCH($AB23,ITP!$E$3:$E$46,0)),"")) | X23: =IF($AB23="","",IFERROR(INDEX(ITP!$L$3:$L$46,MATCH($AB23,ITP!$E$3:$E$46,0)),"")) | Y23: =IF($AB23="","",IFERROR(INDEX(ITP!$M$3:$M$46,MATCH($AB23,ITP!$E$3:$E$46,0)),"")) | Z23: =IF($AB23="","",IFERROR(INDEX(ITP!$N$3:$N$46,MATCH($AB23,ITP!$E$3:$E$46,0)),"")) | AA23: =IF(A23="","",A23&"|"&COUNTIF($A$2:A23,A23)) | AB23: =IF($A23="","",IFERROR(INDEX(ITP!$C$3:$C$21,MATCH(1,INDEX((ITP!$A$3:$A$21=$A23)*(((ITP!$B$3:$B$21="")+ISNUMBER(SEARCH(ITP!$B$3:$B$21,$G23&" "&$T23)))>0),0),0)),""))
A24: Piste de travail | B24: 21063-G26-PPL-RFI-0023 | D24: 45991 | E24: TRUNKLINE FROM ISW MFD TO TFTⅡCPF | F24: 21063-G0-PPL-PR-0007 | G24: Inspection piste de travail | K24: PK( 9+470 Au 9+700 ) ( 10+720 Au 10+580 ) | M24: 170 | P24: PPL | R24: =IF($AB24="","",IFERROR(INDEX(ITP!$G$3:$G$46,MATCH($AB24,ITP!$E$3:$E$46,0)),"")) | S24: 08:00 | U24: =IF($AB24="","",IFERROR(INDEX(ITP!$I$3:$I$46,MATCH($AB24,ITP!$E$3:$E$46,0)),"")) | V24: =IF($AB24="","",IFERROR(INDEX(ITP!$J$3:$J$46,MATCH($AB24,ITP!$E$3:$E$46,0)),"")) | W24: =IF($AB24="","",IFERROR(INDEX(ITP!$K$3:$K$46,MATCH($AB24,ITP!$E$3:$E$46,0)),"")) | X24: =IF($AB24="","",IFERROR(INDEX(ITP!$L$3:$L$46,MATCH($AB24,ITP!$E$3:$E$46,0)),"")) | Y24: =IF($AB24="","",IFERROR(INDEX(ITP!$M$3:$M$46,MATCH($AB24,ITP!$E$3:$E$46,0)),"")) | Z24: =IF($AB24="","",IFERROR(INDEX(ITP!$N$3:$N$46,MATCH($AB24,ITP!$E$3:$E$46,0)),"")) | AA24: =IF(A24="","",A24&"|"&COUNTIF($A$2:A24,A24)) | AB24: =IF($A24="","",IFERROR(INDEX(ITP!$C$3:$C$21,MATCH(1,INDEX((ITP!$A$3:$A$21=$A24)*(((ITP!$B$3:$B$21="")+ISNUMBER(SEARCH(ITP!$B$3:$B$21,$G24&" "&$T24)))>0),0),0)),""))
A25: Ouverture de la tranchée | B25: 21063-G26-PPL-RFI-0024 | D25: 45992 | E25: TRUNKLINE FROM ISW MFD TO TFTⅡCPF | F25: 21061-0000-PPL-TDW-0009 | G25: Inspection de tranchée | K25: PK( 24+180 Au 24+190) ( 24+360 Au 24+680 ) | M25: 330 | P25: PPL | R25: =IF($AB25="","",IFERROR(INDEX(ITP!$G$3:$G$46,MATCH($AB25,ITP!$E$3:$E$46,0)),"")) | S25: 08:00 | U25: =IF($AB25="","",IFERROR(INDEX(ITP!$I$3:$I$46,MATCH($AB25,ITP!$E$3:$E$46,0)),"")) | V25: =IF($AB25="","",IFERROR(INDEX(ITP!$J$3:$J$46,MATCH($AB25,ITP!$E$3:$E$46,0)),"")) | W25: =IF($AB25="","",IFERROR(INDEX(ITP!$K$3:$K$46,MATCH($AB25,ITP!$E$3:$E$46,0)),"")) | X25: =IF($AB25="","",IFERROR(INDEX(ITP!$L$3:$L$46,MATCH($AB25,ITP!$E$3:$E$46,0)),"")) | Y25: =IF($AB25="","",IFERROR(INDEX(ITP!$M$3:$M$46,MATCH($AB25,ITP!$E$3:$E$46,0)),"")) | Z25: =IF($AB25="","",IFERROR(INDEX(ITP!$N$3:$N$46,MATCH($AB25,ITP!$E$3:$E$46,0)),"")) | AA25: =IF(A25="","",A25&"|"&COUNTIF($A$2:A25,A25)) | AB25: =IF($A25="","",IFERROR(INDEX(ITP!$C$3:$C$21,MATCH(1,INDEX((ITP!$A$3:$A$21=$A25)*(((ITP!$B$3:$B$21="")+ISNUMBER(SEARCH(ITP!$B$3:$B$21,$G25&" "&$T25)))>0),0),0)),""))
A26: Piste de travail | B26: 21063-G26-PPL-RFI-0025 | D26: 45997 | E26: TRUNKLINE FROM ISW MFD TO TFTⅡCPF | F26: 21063-G0-PPL-PR-0007 | G26: Inspection piste de travail | K26: PK( 10+200 Au 10+580 ) | M26: 380 | P26: PPL | R26: =IF($AB26="","",IFERROR(INDEX(ITP!$G$3:$G$46,MATCH($AB26,ITP!$E$3:$E$46,0)),"")) | S26: 08:00 | U26: =IF($AB26="","",IFERROR(INDEX(ITP!$I$3:$I$46,MATCH($AB26,ITP!$E$3:$E$46,0)),"")) | V26: =IF($AB26="","",IFERROR(INDEX(ITP!$J$3:$J$46,MATCH($AB26,ITP!$E$3:$E$46,0)),"")) | W26: =IF($AB26="","",IFERROR(INDEX(ITP!$K$3:$K$46,MATCH($AB26,ITP!$E$3:$E$46,0)),"")) | X26: =IF($AB26="","",IFERROR(INDEX(ITP!$L$3:$L$46,MATCH($AB26,ITP!$E$3:$E$46,0)),"")) | Y26: =IF($AB26="","",IFERROR(INDEX(ITP!$M$3:$M$46,MATCH($AB26,ITP!$E$3:$E$46,0)),"")) | Z26: =IF($AB26="","",IFERROR(INDEX(ITP!$N$3:$N$46,MATCH($AB26,ITP!$E$3:$E$46,0)),"")) | AA26: =IF(A26="","",A26&"|"&COUNTIF($A$2:A26,A26)) | AB26: =IF($A26="","",IFERROR(INDEX(ITP!$C$3:$C$21,MATCH(1,INDEX((ITP!$A$3:$A$21=$A26)*(((ITP!$B$3:$B$21="")+ISNUMBER(SEARCH(ITP!$B$3:$B$21,$G26&" "&$T26)))>0),0),0)),""))
A27: Ouverture de la tranchée | B27: 21063-G26-PPL-RFI-0026 | D27: 45998 | E27: TRUNKLINE FROM ISW MFD TO TFTⅡCPF | F27: 21061-0000-PPL-TDW-0009 | G27: Inspection de tranchée | K27: PK 23+ 000 AU PK 23+270 23+290 AU PK 23+330) | M27: 310 | P27: PPL | R27: =IF($AB27="","",IFERROR(INDEX(ITP!$G$3:$G$46,MATCH($AB27,ITP!$E$3:$E$46,0)),"")) | S27: 08:00 | U27: =IF($AB27="","",IFERROR(INDEX(ITP!$I$3:$I$46,MATCH($AB27,ITP!$E$3:$E$46,0)),"")) | V27: =IF($AB27="","",IFERROR(INDEX(ITP!$J$3:$J$46,MATCH($AB27,ITP!$E$3:$E$46,0)),"")) | W27: =IF($AB27="","",IFERROR(INDEX(ITP!$K$3:$K$46,MATCH($AB27,ITP!$E$3:$E$46,0)),"")) | X27: =IF($AB27="","",IFERROR(INDEX(ITP!$L$3:$L$46,MATCH($AB27,ITP!$E$3:$E$46,0)),"")) | Y27: =IF($AB27="","",IFERROR(INDEX(ITP!$M$3:$M$46,MATCH($AB27,ITP!$E$3:$E$46,0)),"")) | Z27: =IF($AB27="","",IFERROR(INDEX(ITP!$N$3:$N$46,MATCH($AB27,ITP!$E$3:$E$46,0)),"")) | AA27: =IF(A27="","",A27&"|"&COUNTIF($A$2:A27,A27)) | AB27: =IF($A27="","",IFERROR(INDEX(ITP!$C$3:$C$21,MATCH(1,INDEX((ITP!$A$3:$A$21=$A27)*(((ITP!$B$3:$B$21="")+ISNUMBER(SEARCH(ITP!$B$3:$B$21,$G27&" "&$T27)))>0),0),0)),""))
A28: Ouverture de la tranchée | B28: 21063-G26-PPL-RFI-0027 | D28: 46014 | E28: TRUNKLINE FROM ISW MFD TO TFTⅡCPF | F28: 21061-0000-PPL-TDW-0009 | G28: Inspection final de la tranchée | K28: 22+ 816 AU PK 23+000 22+237 AU PK 22+779 | M28: 726 | P28: PPL | R28: =IF($AB28="","",IFERROR(INDEX(ITP!$G$3:$G$46,MATCH($AB28,ITP!$E$3:$E$46,0)),"")) | S28: 08:00 | U28: =IF($AB28="","",IFERROR(INDEX(ITP!$I$3:$I$46,MATCH($AB28,ITP!$E$3:$E$46,0)),"")) | V28: =IF($AB28="","",IFERROR(INDEX(ITP!$J$3:$J$46,MATCH($AB28,ITP!$E$3:$E$46,0)),"")) | W28: =IF($AB28="","",IFERROR(INDEX(ITP!$K$3:$K$46,MATCH($AB28,ITP!$E$3:$E$46,0)),"")) | X28: =IF($AB28="","",IFERROR(INDEX(ITP!$L$3:$L$46,MATCH($AB28,ITP!$E$3:$E$46,0)),"")) | Y28: =IF($AB28="","",IFERROR(INDEX(ITP!$M$3:$M$46,MATCH($AB28,ITP!$E$3:$E$46,0)),"")) | Z28: =IF($AB28="","",IFERROR(INDEX(ITP!$N$3:$N$46,MATCH($AB28,ITP!$E$3:$E$46,0)),"")) | AA28: =IF(A28="","",A28&"|"&COUNTIF($A$2:A28,A28)) | AB28: =IF($A28="","",IFERROR(INDEX(ITP!$C$3:$C$21,MATCH(1,INDEX((ITP!$A$3:$A$21=$A28)*(((ITP!$B$3:$B$21="")+ISNUMBER(SEARCH(ITP!$B$3:$B$21,$G28&" "&$T28)))>0),0),0)),""))
A29: Relevé topographique | B29: 21063-G2-PPL-RFI-0028 | D29: 46023 | E29: ISB 302Z Vers MFD-ISB | G29: Relvé Topoghraphique de FLOWLINE | P29: PPL | R29: =IF($AB29="","",IFERROR(INDEX(ITP!$G$3:$G$46,MATCH($AB29,ITP!$E$3:$E$46,0)),"")) | S29: 08:00 | U29: =IF($AB29="","",IFERROR(INDEX(ITP!$I$3:$I$46,MATCH($AB29,ITP!$E$3:$E$46,0)),"")) | V29: =IF($AB29="","",IFERROR(INDEX(ITP!$J$3:$J$46,MATCH($AB29,ITP!$E$3:$E$46,0)),"")) | W29: =IF($AB29="","",IFERROR(INDEX(ITP!$K$3:$K$46,MATCH($AB29,ITP!$E$3:$E$46,0)),"")) | X29: =IF($AB29="","",IFERROR(INDEX(ITP!$L$3:$L$46,MATCH($AB29,ITP!$E$3:$E$46,0)),"")) | Y29: =IF($AB29="","",IFERROR(INDEX(ITP!$M$3:$M$46,MATCH($AB29,ITP!$E$3:$E$46,0)),"")) | Z29: =IF($AB29="","",IFERROR(INDEX(ITP!$N$3:$N$46,MATCH($AB29,ITP!$E$3:$E$46,0)),"")) | AA29: =IF(A29="","",A29&"|"&COUNTIF($A$2:A29,A29)) | AB29: =IF($A29="","",IFERROR(INDEX(ITP!$C$3:$C$21,MATCH(1,INDEX((ITP!$A$3:$A$21=$A29)*(((ITP!$B$3:$B$21="")+ISNUMBER(SEARCH(ITP!$B$3:$B$21,$G29&" "&$T29)))>0),0),0)),""))
A30: Relevé topographique | B30: 21063-G3-PPL-RFI-0029 | D30: 46023 | E30: ISB 303 Vers MFD-ISB | G30: Relvé Topoghraphique de FLOWLINE | P30: PPL | R30: =IF($AB30="","",IFERROR(INDEX(ITP!$G$3:$G$46,MATCH($AB30,ITP!$E$3:$E$46,0)),"")) | S30: 08:00 | U30: =IF($AB30="","",IFERROR(INDEX(ITP!$I$3:$I$46,MATCH($AB30,ITP!$E$3:$E$46,0)),"")) | V30: =IF($AB30="","",IFERROR(INDEX(ITP!$J$3:$J$46,MATCH($AB30,ITP!$E$3:$E$46,0)),"")) | W30: =IF($AB30="","",IFERROR(INDEX(ITP!$K$3:$K$46,MATCH($AB30,ITP!$E$3:$E$46,0)),"")) | X30: =IF($AB30="","",IFERROR(INDEX(ITP!$L$3:$L$46,MATCH($AB30,ITP!$E$3:$E$46,0)),"")) | Y30: =IF($AB30="","",IFERROR(INDEX(ITP!$M$3:$M$46,MATCH($AB30,ITP!$E$3:$E$46,0)),"")) | Z30: =IF($AB30="","",IFERROR(INDEX(ITP!$N$3:$N$46,MATCH($AB30,ITP!$E$3:$E$46,0)),"")) | AA30: =IF(A30="","",A30&"|"&COUNTIF($A$2:A30,A30)) | AB30: =IF($A30="","",IFERROR(INDEX(ITP!$C$3:$C$21,MATCH(1,INDEX((ITP!$A$3:$A$21=$A30)*(((ITP!$B$3:$B$21="")+ISNUMBER(SEARCH(ITP!$B$3:$B$21,$G30&" "&$T30)))>0),0),0)),""))
A31: Relevé topographique | B31: 21063-G4-PPL-RFI-0030 | D31: 46023 | E31: FLOWLINE ISB 304 Vers MFD-ISB | G31: Relvé Topoghraphique | P31: PPL | R31: =IF($AB31="","",IFERROR(INDEX(ITP!$G$3:$G$46,MATCH($AB31,ITP!$E$3:$E$46,0)),"")) | S31: 08:00 | U31: =IF($AB31="","",IFERROR(INDEX(ITP!$I$3:$I$46,MATCH($AB31,ITP!$E$3:$E$46,0)),"")) | V31: =IF($AB31="","",IFERROR(INDEX(ITP!$J$3:$J$46,MATCH($AB31,ITP!$E$3:$E$46,0)),"")) | W31: =IF($AB31="","",IFERROR(INDEX(ITP!$K$3:$K$46,MATCH($AB31,ITP!$E$3:$E$46,0)),"")) | X31: =IF($AB31="","",IFERROR(INDEX(ITP!$L$3:$L$46,MATCH($AB31,ITP!$E$3:$E$46,0)),"")) | Y31: =IF($AB31="","",IFERROR(INDEX(ITP!$M$3:$M$46,MATCH($AB31,ITP!$E$3:$E$46,0)),"")) | Z31: =IF($AB31="","",IFERROR(INDEX(ITP!$N$3:$N$46,MATCH($AB31,ITP!$E$3:$E$46,0)),"")) | AA31: =IF(A31="","",A31&"|"&COUNTIF($A$2:A31,A31)) | AB31: =IF($A31="","",IFERROR(INDEX(ITP!$C$3:$C$21,MATCH(1,INDEX((ITP!$A$3:$A$21=$A31)*(((ITP!$B$3:$B$21="")+ISNUMBER(SEARCH(ITP!$B$3:$B$21,$G31&" "&$T31)))>0),0),0)),""))
A32: Ouverture de la tranchée | B32: 21063-G26-PPL-RFI-0031 | D32: 46025 | F32: 21061-0000-PPL-TDW-0009 | G32: Inspection Final de la Tranchée | K32: 21+ 401 AU 21+550 21+600 au 22+250 | M32: 799 | P32: PPL | R32: =IF($AB32="","",IFERROR(INDEX(ITP!$G$3:$G$46,MATCH($AB32,ITP!$E$3:$E$46,0)),"")) | S32: 08:00 | U32: =IF($AB32="","",IFERROR(INDEX(ITP!$I$3:$I$46,MATCH($AB32,ITP!$E$3:$E$46,0)),"")) | V32: =IF($AB32="","",IFERROR(INDEX(ITP!$J$3:$J$46,MATCH($AB32,ITP!$E$3:$E$46,0)),"")) | W32: =IF($AB32="","",IFERROR(INDEX(ITP!$K$3:$K$46,MATCH($AB32,ITP!$E$3:$E$46,0)),"")) | X32: =IF($AB32="","",IFERROR(INDEX(ITP!$L$3:$L$46,MATCH($AB32,ITP!$E$3:$E$46,0)),"")) | Y32: =IF($AB32="","",IFERROR(INDEX(ITP!$M$3:$M$46,MATCH($AB32,ITP!$E$3:$E$46,0)),"")) | Z32: =IF($AB32="","",IFERROR(INDEX(ITP!$N$3:$N$46,MATCH($AB32,ITP!$E$3:$E$46,0)),"")) | AA32: =IF(A32="","",A32&"|"&COUNTIF($A$2:A32,A32)) | AB32: =IF($A32="","",IFERROR(INDEX(ITP!$C$3:$C$21,MATCH(1,INDEX((ITP!$A$3:$A$21=$A32)*(((ITP!$B$3:$B$21="")+ISNUMBER(SEARCH(ITP!$B$3:$B$21,$G32&" "&$T32)))>0),0),0)),""))
A33: Piste de travail | B33: 21063-G26-PPL-RFI-0032 | D33: 46039 | E33: TRUNKLINE FROM ISW MFD TO TFTⅡCPF | F33: 21063-G0-PPL-PR-0007 | G33: Inspection final de la Piste de travail | K33: 5+431 au 6+952 et 7+135 au 7+231 7+373 au 7+980 et 8+060 au 8+549 | M33: 2713 | P33: PPL | R33: =IF($AB33="","",IFERROR(INDEX(ITP!$G$3:$G$46,MATCH($AB33,ITP!$E$3:$E$46,0)),"")) | S33: 08:00 | U33: =IF($AB33="","",IFERROR(INDEX(ITP!$I$3:$I$46,MATCH($AB33,ITP!$E$3:$E$46,0)),"")) | V33: =IF($AB33="","",IFERROR(INDEX(ITP!$J$3:$J$46,MATCH($AB33,ITP!$E$3:$E$46,0)),"")) | W33: =IF($AB33="","",IFERROR(INDEX(ITP!$K$3:$K$46,MATCH($AB33,ITP!$E$3:$E$46,0)),"")) | X33: =IF($AB33="","",IFERROR(INDEX(ITP!$L$3:$L$46,MATCH($AB33,ITP!$E$3:$E$46,0)),"")) | Y33: =IF($AB33="","",IFERROR(INDEX(ITP!$M$3:$M$46,MATCH($AB33,ITP!$E$3:$E$46,0)),"")) | Z33: =IF($AB33="","",IFERROR(INDEX(ITP!$N$3:$N$46,MATCH($AB33,ITP!$E$3:$E$46,0)),"")) | AA33: =IF(A33="","",A33&"|"&COUNTIF($A$2:A33,A33)) | AB33: =IF($A33="","",IFERROR(INDEX(ITP!$C$3:$C$21,MATCH(1,INDEX((ITP!$A$3:$A$21=$A33)*(((ITP!$B$3:$B$21="")+ISNUMBER(SEARCH(ITP!$B$3:$B$21,$G33&" "&$T33)))>0),0),0)),""))
A34: Piste de travail | B34: 21063-G2-PPL-RFI-0033 | D34: 46039 | E34: ISB-302 | F34: 21063-G0-PPL-PR-0007 | G34: Inspection final de la Piste de travail | K34: PK 0+000 au 0+650 | M34: 650 | P34: PPL | R34: =IF($AB34="","",IFERROR(INDEX(ITP!$G$3:$G$46,MATCH($AB34,ITP!$E$3:$E$46,0)),"")) | S34: 08:00 | U34: =IF($AB34="","",IFERROR(INDEX(ITP!$I$3:$I$46,MATCH($AB34,ITP!$E$3:$E$46,0)),"")) | V34: =IF($AB34="","",IFERROR(INDEX(ITP!$J$3:$J$46,MATCH($AB34,ITP!$E$3:$E$46,0)),"")) | W34: =IF($AB34="","",IFERROR(INDEX(ITP!$K$3:$K$46,MATCH($AB34,ITP!$E$3:$E$46,0)),"")) | X34: =IF($AB34="","",IFERROR(INDEX(ITP!$L$3:$L$46,MATCH($AB34,ITP!$E$3:$E$46,0)),"")) | Y34: =IF($AB34="","",IFERROR(INDEX(ITP!$M$3:$M$46,MATCH($AB34,ITP!$E$3:$E$46,0)),"")) | Z34: =IF($AB34="","",IFERROR(INDEX(ITP!$N$3:$N$46,MATCH($AB34,ITP!$E$3:$E$46,0)),"")) | AA34: =IF(A34="","",A34&"|"&COUNTIF($A$2:A34,A34)) | AB34: =IF($A34="","",IFERROR(INDEX(ITP!$C$3:$C$21,MATCH(1,INDEX((ITP!$A$3:$A$21=$A34)*(((ITP!$B$3:$B$21="")+ISNUMBER(SEARCH(ITP!$B$3:$B$21,$G34&" "&$T34)))>0),0),0)),""))
A35: Piste de travail | B35: 21063-G3-PPL-RFI-0034 | D35: 46039 | E35: ISB-303 | F35: 21063-G0-PPL-PR-0007 | G35: Inspection final de la Piste de travail | K35: PK 0+000 au 0+619 | M35: 619 | P35: PPL | R35: =IF($AB35="","",IFERROR(INDEX(ITP!$G$3:$G$46,MATCH($AB35,ITP!$E$3:$E$46,0)),"")) | S35: 08:00 | U35: =IF($AB35="","",IFERROR(INDEX(ITP!$I$3:$I$46,MATCH($AB35,ITP!$E$3:$E$46,0)),"")) | V35: =IF($AB35="","",IFERROR(INDEX(ITP!$J$3:$J$46,MATCH($AB35,ITP!$E$3:$E$46,0)),"")) | W35: =IF($AB35="","",IFERROR(INDEX(ITP!$K$3:$K$46,MATCH($AB35,ITP!$E$3:$E$46,0)),"")) | X35: =IF($AB35="","",IFERROR(INDEX(ITP!$L$3:$L$46,MATCH($AB35,ITP!$E$3:$E$46,0)),"")) | Y35: =IF($AB35="","",IFERROR(INDEX(ITP!$M$3:$M$46,MATCH($AB35,ITP!$E$3:$E$46,0)),"")) | Z35: =IF($AB35="","",IFERROR(INDEX(ITP!$N$3:$N$46,MATCH($AB35,ITP!$E$3:$E$46,0)),"")) | AA35: =IF(A35="","",A35&"|"&COUNTIF($A$2:A35,A35)) | AB35: =IF($A35="","",IFERROR(INDEX(ITP!$C$3:$C$21,MATCH(1,INDEX((ITP!$A$3:$A$21=$A35)*(((ITP!$B$3:$B$21="")+ISNUMBER(SEARCH(ITP!$B$3:$B$21,$G35&" "&$T35)))>0),0),0)),""))
A36: Ouverture de la tranchée | B36: 21063-G26-PPL-RFI-0035 | D36: 46039 | E36: TRUNKLINE FROM ISW MFD TO TFTⅡCPF | F36: 21061-0000-PPL-TDW-0009 | G36: Inspection final de la tranchée | K36: PK (7+ 800 AU 8+000 et 8+020 AU 9+170) (9+ 710 AU 9+850 et 9+900 AU 10+800) (11+ 430 AU 11+530 et 11+620 AU 11+850) | M36: 1350 | P36: PPL | R36: =IF($AB36="","",IFERROR(INDEX(ITP!$G$3:$G$46,MATCH($AB36,ITP!$E$3:$E$46,0)),"")) | S36: 08:00 | U36: =IF($AB36="","",IFERROR(INDEX(ITP!$I$3:$I$46,MATCH($AB36,ITP!$E$3:$E$46,0)),"")) | V36: =IF($AB36="","",IFERROR(INDEX(ITP!$J$3:$J$46,MATCH($AB36,ITP!$E$3:$E$46,0)),"")) | W36: =IF($AB36="","",IFERROR(INDEX(ITP!$K$3:$K$46,MATCH($AB36,ITP!$E$3:$E$46,0)),"")) | X36: =IF($AB36="","",IFERROR(INDEX(ITP!$L$3:$L$46,MATCH($AB36,ITP!$E$3:$E$46,0)),"")) | Y36: =IF($AB36="","",IFERROR(INDEX(ITP!$M$3:$M$46,MATCH($AB36,ITP!$E$3:$E$46,0)),"")) | Z36: =IF($AB36="","",IFERROR(INDEX(ITP!$N$3:$N$46,MATCH($AB36,ITP!$E$3:$E$46,0)),"")) | AA36: =IF(A36="","",A36&"|"&COUNTIF($A$2:A36,A36)) | AB36: =IF($A36="","",IFERROR(INDEX(ITP!$C$3:$C$21,MATCH(1,INDEX((ITP!$A$3:$A$21=$A36)*(((ITP!$B$3:$B$21="")+ISNUMBER(SEARCH(ITP!$B$3:$B$21,$G36&" "&$T36)))>0),0),0)),""))
A37: Ouverture de la tranchée | B37: 21063-G26-PPL-RFI-0036 | D37: 46045 | E37: TRUNKLINE FROM ISW MFD TO TFTⅡCPF | F37: 21061-0000-PPL-TDW-0009 | G37: Inspection final de la tranchée | K37: PK 14+850 au 16+200 et 19+650 au 19+730 19+780 au 21+120 et 21+160 au 21+240 21+270 au 21+350 | M37: 2930 | P37: PPL | R37: =IF($AB37="","",IFERROR(INDEX(ITP!$G$3:$G$46,MATCH($AB37,ITP!$E$3:$E$46,0)),"")) | S37: 08:00 | U37: =IF($AB37="","",IFERROR(INDEX(ITP!$I$3:$I$46,MATCH($AB37,ITP!$E$3:$E$46,0)),"")) | V37: =IF($AB37="","",IFERROR(INDEX(ITP!$J$3:$J$46,MATCH($AB37,ITP!$E$3:$E$46,0)),"")) | W37: =IF($AB37="","",IFERROR(INDEX(ITP!$K$3:$K$46,MATCH($AB37,ITP!$E$3:$E$46,0)),"")) | X37: =IF($AB37="","",IFERROR(INDEX(ITP!$L$3:$L$46,MATCH($AB37,ITP!$E$3:$E$46,0)),"")) | Y37: =IF($AB37="","",IFERROR(INDEX(ITP!$M$3:$M$46,MATCH($AB37,ITP!$E$3:$E$46,0)),"")) | Z37: =IF($AB37="","",IFERROR(INDEX(ITP!$N$3:$N$46,MATCH($AB37,ITP!$E$3:$E$46,0)),"")) | AA37: =IF(A37="","",A37&"|"&COUNTIF($A$2:A37,A37)) | AB37: =IF($A37="","",IFERROR(INDEX(ITP!$C$3:$C$21,MATCH(1,INDEX((ITP!$A$3:$A$21=$A37)*(((ITP!$B$3:$B$21="")+ISNUMBER(SEARCH(ITP!$B$3:$B$21,$G37&" "&$T37)))>0),0),0)),""))
A38: Piste de travail | B38: 21063-G4-PPL-RFI-0037 | D38: 46046 | E38: ISB-304 | F38: 21063-G0-PPL-PR-0007 | G38: Inspection final de la Piste de travail | K38: PK 2+345 au 4+146 | M38: 1801 | P38: PPL | R38: =IF($AB38="","",IFERROR(INDEX(ITP!$G$3:$G$46,MATCH($AB38,ITP!$E$3:$E$46,0)),"")) | S38: 08:00 | U38: =IF($AB38="","",IFERROR(INDEX(ITP!$I$3:$I$46,MATCH($AB38,ITP!$E$3:$E$46,0)),"")) | V38: =IF($AB38="","",IFERROR(INDEX(ITP!$J$3:$J$46,MATCH($AB38,ITP!$E$3:$E$46,0)),"")) | W38: =IF($AB38="","",IFERROR(INDEX(ITP!$K$3:$K$46,MATCH($AB38,ITP!$E$3:$E$46,0)),"")) | X38: =IF($AB38="","",IFERROR(INDEX(ITP!$L$3:$L$46,MATCH($AB38,ITP!$E$3:$E$46,0)),"")) | Y38: =IF($AB38="","",IFERROR(INDEX(ITP!$M$3:$M$46,MATCH($AB38,ITP!$E$3:$E$46,0)),"")) | Z38: =IF($AB38="","",IFERROR(INDEX(ITP!$N$3:$N$46,MATCH($AB38,ITP!$E$3:$E$46,0)),"")) | AA38: =IF(A38="","",A38&"|"&COUNTIF($A$2:A38,A38)) | AB38: =IF($A38="","",IFERROR(INDEX(ITP!$C$3:$C$21,MATCH(1,INDEX((ITP!$A$3:$A$21=$A38)*(((ITP!$B$3:$B$21="")+ISNUMBER(SEARCH(ITP!$B$3:$B$21,$G38&" "&$T38)))>0),0),0)),""))
A39: Piste de travail | B39: 21063-G26-PPL-RFI-0038 | D39: 46048 | E39: TRUNKLINE FROM ISW MFD TO TFTⅡCPF | F39: 21063-G0-PPL-PR-0007 | G39: Inspection final de la Piste de travail | K39: PK 9+297 au 9+584 et 9+864 au 10+314 9+864 au 10+314 et 10+803 au 11+526 | M39: 1910 | P39: PPL | R39: =IF($AB39="","",IFERROR(INDEX(ITP!$G$3:$G$46,MATCH($AB39,ITP!$E$3:$E$46,0)),"")) | S39: 08:00 | U39: =IF($AB39="","",IFERROR(INDEX(ITP!$I$3:$I$46,MATCH($AB39,ITP!$E$3:$E$46,0)),"")) | V39: =IF($AB39="","",IFERROR(INDEX(ITP!$J$3:$J$46,MATCH($AB39,ITP!$E$3:$E$46,0)),"")) | W39: =IF($AB39="","",IFERROR(INDEX(ITP!$K$3:$K$46,MATCH($AB39,ITP!$E$3:$E$46,0)),"")) | X39: =IF($AB39="","",IFERROR(INDEX(ITP!$L$3:$L$46,MATCH($AB39,ITP!$E$3:$E$46,0)),"")) | Y39: =IF($AB39="","",IFERROR(INDEX(ITP!$M$3:$M$46,MATCH($AB39,ITP!$E$3:$E$46,0)),"")) | Z39: =IF($AB39="","",IFERROR(INDEX(ITP!$N$3:$N$46,MATCH($AB39,ITP!$E$3:$E$46,0)),"")) | AA39: =IF(A39="","",A39&"|"&COUNTIF($A$2:A39,A39)) | AB39: =IF($A39="","",IFERROR(INDEX(ITP!$C$3:$C$21,MATCH(1,INDEX((ITP!$A$3:$A$21=$A39)*(((ITP!$B$3:$B$21="")+ISNUMBER(SEARCH(ITP!$B$3:$B$21,$G39&" "&$T39)))>0),0),0)),""))
A40: Relevé topographique | B40: 21063-G25-PPL-RFI-0039 | D40: 46048 | E40: MFD-ISB Vers MFD-ISW | G40: Relvé Topoghraphique de FLOWLINE | P40: PPL | R40: =IF($AB40="","",IFERROR(INDEX(ITP!$G$3:$G$46,MATCH($AB40,ITP!$E$3:$E$46,0)),"")) | S40: 08:00 | U40: =IF($AB40="","",IFERROR(INDEX(ITP!$I$3:$I$46,MATCH($AB40,ITP!$E$3:$E$46,0)),"")) | V40: =IF($AB40="","",IFERROR(INDEX(ITP!$J$3:$J$46,MATCH($AB40,ITP!$E$3:$E$46,0)),"")) | W40: =IF($AB40="","",IFERROR(INDEX(ITP!$K$3:$K$46,MATCH($AB40,ITP!$E$3:$E$46,0)),"")) | X40: =IF($AB40="","",IFERROR(INDEX(ITP!$L$3:$L$46,MATCH($AB40,ITP!$E$3:$E$46,0)),"")) | Y40: =IF($AB40="","",IFERROR(INDEX(ITP!$M$3:$M$46,MATCH($AB40,ITP!$E$3:$E$46,0)),"")) | Z40: =IF($AB40="","",IFERROR(INDEX(ITP!$N$3:$N$46,MATCH($AB40,ITP!$E$3:$E$46,0)),"")) | AA40: =IF(A40="","",A40&"|"&COUNTIF($A$2:A40,A40)) | AB40: =IF($A40="","",IFERROR(INDEX(ITP!$C$3:$C$21,MATCH(1,INDEX((ITP!$A$3:$A$21=$A40)*(((ITP!$B$3:$B$21="")+ISNUMBER(SEARCH(ITP!$B$3:$B$21,$G40&" "&$T40)))>0),0),0)),""))
...

Sheet Impression groupée
A1: IMPRESSION GROUPÉE – collez ou choisissez les RFI à imprimer (colonne B), puis exportez les feuilles « Lot » en PDF
A2: Chaque feuille « Lot … » prend automatiquement les RFI de son type dans cette liste (max 20 par type). « Lot RFI » et « Lot RFI interne » prennent toute la liste (max 20).
A3: N° | B3: RFI No | C3: Type (auto) | D3: Rang dans le type (auto) | E3: Clé (auto) | F3: Ordre (auto) | H3: Feuille Lot | I3: Fiches à imprimer
A4: 1 | C4: =IF(B4="","",IFERROR(INDEX(Registre!$A$2:$A$1999,MATCH(B4,Registre!$B$2:$B$1999,0)),"⚠ absent du Registre")) | D4: =IF(OR(C4="",C4="⚠ absent du Registre"),"",COUNTIF(C$4:C4,C4)) | E4: =IF(D4="","",C4&"|"&D4) | F4: =IF(OR(B4="",C4="⚠ absent du Registre"),"",COUNTIFS(B$4:B4,"<>",C$4:C4,"<>⚠ absent du Registre")) | H4: Lot RFI | I4: =MIN(20,COUNT('Impression groupée'!$F$4:$F$103))
A5: 2 | C5: =IF(B5="","",IFERROR(INDEX(Registre!$A$2:$A$1999,MATCH(B5,Registre!$B$2:$B$1999,0)),"⚠ absent du Registre")) | D5: =IF(OR(C5="",C5="⚠ absent du Registre"),"",COUNTIF(C$4:C5,C5)) | E5: =IF(D5="","",C5&"|"&D5) | F5: =IF(OR(B5="",C5="⚠ absent du Registre"),"",COUNTIFS(B$4:B5,"<>",C$4:C5,"<>⚠ absent du Registre")) | H5: Lot RFI interne | I5: =MIN(20,COUNT('Impression groupée'!$F$4:$F$103))
A6: 3 | C6: =IF(B6="","",IFERROR(INDEX(Registre!$A$2:$A$1999,MATCH(B6,Registre!$B$2:$B$1999,0)),"⚠ absent du Registre")) | D6: =IF(OR(C6="",C6="⚠ absent du Registre"),"",COUNTIF(C$4:C6,C6)) | E6: =IF(D6="","",C6&"|"&D6) | F6: =IF(OR(B6="",C6="⚠ absent du Registre"),"",COUNTIFS(B$4:B6,"<>",C$4:C6,"<>⚠ absent du Registre")) | H6: Lot Ouverture | I6: =MIN(20,COUNTIF('Impression groupée'!$C$4:$C$103,"Ouverture de la tranchée"))
A7: 4 | C7: =IF(B7="","",IFERROR(INDEX(Registre!$A$2:$A$1999,MATCH(B7,Registre!$B$2:$B$1999,0)),"⚠ absent du Registre")) | D7: =IF(OR(C7="",C7="⚠ absent du Registre"),"",COUNTIF(C$4:C7,C7)) | E7: =IF(D7="","",C7&"|"&D7) | F7: =IF(OR(B7="",C7="⚠ absent du Registre"),"",COUNTIFS(B$4:B7,"<>",C$4:C7,"<>⚠ absent du Registre")) | H7: Lot Piste | I7: =MIN(20,COUNTIF('Impression groupée'!$C$4:$C$103,"Piste de travail"))
A8: 5 | C8: =IF(B8="","",IFERROR(INDEX(Registre!$A$2:$A$1999,MATCH(B8,Registre!$B$2:$B$1999,0)),"⚠ absent du Registre")) | D8: =IF(OR(C8="",C8="⚠ absent du Registre"),"",COUNTIF(C$4:C8,C8)) | E8: =IF(D8="","",C8&"|"&D8) | F8: =IF(OR(B8="",C8="⚠ absent du Registre"),"",COUNTIFS(B$4:B8,"<>",C$4:C8,"<>⚠ absent du Registre")) | H8: Lot Bardage | I8: =MIN(20,COUNTIF('Impression groupée'!$C$4:$C$103,"Transport et bardage"))
A9: 6 | C9: =IF(B9="","",IFERROR(INDEX(Registre!$A$2:$A$1999,MATCH(B9,Registre!$B$2:$B$1999,0)),"⚠ absent du Registre")) | D9: =IF(OR(C9="",C9="⚠ absent du Registre"),"",COUNTIF(C$4:C9,C9)) | E9: =IF(D9="","",C9&"|"&D9) | F9: =IF(OR(B9="",C9="⚠ absent du Registre"),"",COUNTIFS(B$4:B9,"<>",C$4:C9,"<>⚠ absent du Registre")) | H9: Lot Cintrage | I9: =MIN(20,COUNTIF('Impression groupée'!$C$4:$C$103,"Cintrage"))
A10: 7 | C10: =IF(B10="","",IFERROR(INDEX(Registre!$A$2:$A$1999,MATCH(B10,Registre!$B$2:$B$1999,0)),"⚠ absent du Registre")) | D10: =IF(OR(C10="",C10="⚠ absent du Registre"),"",COUNTIF(C$4:C10,C10)) | E10: =IF(D10="","",C10&"|"&D10) | F10: =IF(OR(B10="",C10="⚠ absent du Registre"),"",COUNTIFS(B$4:B10,"<>",C$4:C10,"<>⚠ absent du Registre")) | H10: Lot Enrobage | I10: =MIN(20,COUNTIF('Impression groupée'!$C$4:$C$103,"Enrobage"))
A11: 8 | C11: =IF(B11="","",IFERROR(INDEX(Registre!$A$2:$A$1999,MATCH(B11,Registre!$B$2:$B$1999,0)),"⚠ absent du Registre")) | D11: =IF(OR(C11="",C11="⚠ absent du Registre"),"",COUNTIF(C$4:C11,C11)) | E11: =IF(D11="","",C11&"|"&D11) | F11: =IF(OR(B11="",C11="⚠ absent du Registre"),"",COUNTIFS(B$4:B11,"<>",C$4:C11,"<>⚠ absent du Registre")) | H11: Lot Lit de pose | I11: =MIN(20,COUNTIF('Impression groupée'!$C$4:$C$103,"Lit de pose"))
A12: 9 | C12: =IF(B12="","",IFERROR(INDEX(Registre!$A$2:$A$1999,MATCH(B12,Registre!$B$2:$B$1999,0)),"⚠ absent du Registre")) | D12: =IF(OR(C12="",C12="⚠ absent du Registre"),"",COUNTIF(C$4:C12,C12)) | E12: =IF(D12="","",C12&"|"&D12) | F12: =IF(OR(B12="",C12="⚠ absent du Registre"),"",COUNTIFS(B$4:B12,"<>",C$4:C12,"<>⚠ absent du Registre")) | H12: Lot Mise en fouille | I12: =MIN(20,COUNTIF('Impression groupée'!$C$4:$C$103,"Mise en fouille"))
A13: 10 | C13: =IF(B13="","",IFERROR(INDEX(Registre!$A$2:$A$1999,MATCH(B13,Registre!$B$2:$B$1999,0)),"⚠ absent du Registre")) | D13: =IF(OR(C13="",C13="⚠ absent du Registre"),"",COUNTIF(C$4:C13,C13)) | E13: =IF(D13="","",C13&"|"&D13) | F13: =IF(OR(B13="",C13="⚠ absent du Registre"),"",COUNTIFS(B$4:B13,"<>",C$4:C13,"<>⚠ absent du Registre")) | H13: Lot Pre-remblai | I13: =MIN(20,COUNTIF('Impression groupée'!$C$4:$C$103,"Pré-remblai"))
A14: 11 | C14: =IF(B14="","",IFERROR(INDEX(Registre!$A$2:$A$1999,MATCH(B14,Registre!$B$2:$B$1999,0)),"⚠ absent du Registre")) | D14: =IF(OR(C14="",C14="⚠ absent du Registre"),"",COUNTIF(C$4:C14,C14)) | E14: =IF(D14="","",C14&"|"&D14) | F14: =IF(OR(B14="",C14="⚠ absent du Registre"),"",COUNTIFS(B$4:B14,"<>",C$4:C14,"<>⚠ absent du Registre"))
A15: 12 | C15: =IF(B15="","",IFERROR(INDEX(Registre!$A$2:$A$1999,MATCH(B15,Registre!$B$2:$B$1999,0)),"⚠ absent du Registre")) | D15: =IF(OR(C15="",C15="⚠ absent du Registre"),"",COUNTIF(C$4:C15,C15)) | E15: =IF(D15="","",C15&"|"&D15) | F15: =IF(OR(B15="",C15="⚠ absent du Registre"),"",COUNTIFS(B$4:B15,"<>",C$4:C15,"<>⚠ absent du Registre")) | H15: COMMENT EXPORTER EN UN SEUL PDF :
A16: 13 | C16: =IF(B16="","",IFERROR(INDEX(Registre!$A$2:$A$1999,MATCH(B16,Registre!$B$2:$B$1999,0)),"⚠ absent du Registre")) | D16: =IF(OR(C16="",C16="⚠ absent du Registre"),"",COUNTIF(C$4:C16,C16)) | E16: =IF(D16="","",C16&"|"&D16) | F16: =IF(OR(B16="",C16="⚠ absent du Registre"),"",COUNTIFS(B$4:B16,"<>",C$4:C16,"<>⚠ absent du Registre")) | H16: 1. Remplissez la colonne B (RFI à imprimer).
A17: 14 | C17: =IF(B17="","",IFERROR(INDEX(Registre!$A$2:$A$1999,MATCH(B17,Registre!$B$2:$B$1999,0)),"⚠ absent du Registre")) | D17: =IF(OR(C17="",C17="⚠ absent du Registre"),"",COUNTIF(C$4:C17,C17)) | E17: =IF(D17="","",C17&"|"&D17) | F17: =IF(OR(B17="",C17="⚠ absent du Registre"),"",COUNTIFS(B$4:B17,"<>",C$4:C17,"<>⚠ absent du Registre")) | H17: 2. Cliquez sur l'onglet du premier Lot utile, puis Ctrl + clic sur les autres Lots utiles.
A18: 15 | C18: =IF(B18="","",IFERROR(INDEX(Registre!$A$2:$A$1999,MATCH(B18,Registre!$B$2:$B$1999,0)),"⚠ absent du Registre")) | D18: =IF(OR(C18="",C18="⚠ absent du Registre"),"",COUNTIF(C$4:C18,C18)) | E18: =IF(D18="","",C18&"|"&D18) | F18: =IF(OR(B18="",C18="⚠ absent du Registre"),"",COUNTIFS(B$4:B18,"<>",C$4:C18,"<>⚠ absent du Registre")) | H18: 3. Fichier > Exporter > Créer PDF (ou Enregistrer sous > PDF).
A19: 16 | C19: =IF(B19="","",IFERROR(INDEX(Registre!$A$2:$A$1999,MATCH(B19,Registre!$B$2:$B$1999,0)),"⚠ absent du Registre")) | D19: =IF(OR(C19="",C19="⚠ absent du Registre"),"",COUNTIF(C$4:C19,C19)) | E19: =IF(D19="","",C19&"|"&D19) | F19: =IF(OR(B19="",C19="⚠ absent du Registre"),"",COUNTIFS(B$4:B19,"<>",C$4:C19,"<>⚠ absent du Registre")) | H19: Chaque RFI = une page ; seules les fiches remplies sont imprimées.
A20: 17 | C20: =IF(B20="","",IFERROR(INDEX(Registre!$A$2:$A$1999,MATCH(B20,Registre!$B$2:$B$1999,0)),"⚠ absent du Registre")) | D20: =IF(OR(C20="",C20="⚠ absent du Registre"),"",COUNTIF(C$4:C20,C20)) | E20: =IF(D20="","",C20&"|"&D20) | F20: =IF(OR(B20="",C20="⚠ absent du Registre"),"",COUNTIFS(B$4:B20,"<>",C$4:C20,"<>⚠ absent du Registre")) | H20: 4. Ensuite, cliquez sur l'onglet Registre pour désélectionner le groupe.
A21: 18 | C21: =IF(B21="","",IFERROR(INDEX(Registre!$A$2:$A$1999,MATCH(B21,Registre!$B$2:$B$1999,0)),"⚠ absent du Registre")) | D21: =IF(OR(C21="",C21="⚠ absent du Registre"),"",COUNTIF(C$4:C21,C21)) | E21: =IF(D21="","",C21&"|"&D21) | F21: =IF(OR(B21="",C21="⚠ absent du Registre"),"",COUNTIFS(B$4:B21,"<>",C$4:C21,"<>⚠ absent du Registre")) | H21: Si des pages vides sortent : Fichier > Imprimer > Pages de 1 à (nombre de la colonne I).
A22: 19 | C22: =IF(B22="","",IFERROR(INDEX(Registre!$A$2:$A$1999,MATCH(B22,Registre!$B$2:$B$1999,0)),"⚠ absent du Registre")) | D22: =IF(OR(C22="",C22="⚠ absent du Registre"),"",COUNTIF(C$4:C22,C22)) | E22: =IF(D22="","",C22&"|"&D22) | F22: =IF(OR(B22="",C22="⚠ absent du Registre"),"",COUNTIFS(B$4:B22,"<>",C$4:C22,"<>⚠ absent du Registre"))
A23: 20 | C23: =IF(B23="","",IFERROR(INDEX(Registre!$A$2:$A$1999,MATCH(B23,Registre!$B$2:$B$1999,0)),"⚠ absent du Registre")) | D23: =IF(OR(C23="",C23="⚠ absent du Registre"),"",COUNTIF(C$4:C23,C23)) | E23: =IF(D23="","",C23&"|"&D23) | F23: =IF(OR(B23="",C23="⚠ absent du Registre"),"",COUNTIFS(B$4:B23,"<>",C$4:C23,"<>⚠ absent du Registre"))
A24: 21 | C24: =IF(B24="","",IFERROR(INDEX(Registre!$A$2:$A$1999,MATCH(B24,Registre!$B$2:$B$1999,0)),"⚠ absent du Registre")) | D24: =IF(OR(C24="",C24="⚠ absent du Registre"),"",COUNTIF(C$4:C24,C24)) | E24: =IF(D24="","",C24&"|"&D24) | F24: =IF(OR(B24="",C24="⚠ absent du Registre"),"",COUNTIFS(B$4:B24,"<>",C$4:C24,"<>⚠ absent du Registre"))
A25: 22 | C25: =IF(B25="","",IFERROR(INDEX(Registre!$A$2:$A$1999,MATCH(B25,Registre!$B$2:$B$1999,0)),"⚠ absent du Registre")) | D25: =IF(OR(C25="",C25="⚠ absent du Registre"),"",COUNTIF(C$4:C25,C25)) | E25: =IF(D25="","",C25&"|"&D25) | F25: =IF(OR(B25="",C25="⚠ absent du Registre"),"",COUNTIFS(B$4:B25,"<>",C$4:C25,"<>⚠ absent du Registre"))
A26: 23 | C26: =IF(B26="","",IFERROR(INDEX(Registre!$A$2:$A$1999,MATCH(B26,Registre!$B$2:$B$1999,0)),"⚠ absent du Registre")) | D26: =IF(OR(C26="",C26="⚠ absent du Registre"),"",COUNTIF(C$4:C26,C26)) | E26: =IF(D26="","",C26&"|"&D26) | F26: =IF(OR(B26="",C26="⚠ absent du Registre"),"",COUNTIFS(B$4:B26,"<>",C$4:C26,"<>⚠ absent du Registre"))
A27: 24 | C27: =IF(B27="","",IFERROR(INDEX(Registre!$A$2:$A$1999,MATCH(B27,Registre!$B$2:$B$1999,0)),"⚠ absent du Registre")) | D27: =IF(OR(C27="",C27="⚠ absent du Registre"),"",COUNTIF(C$4:C27,C27)) | E27: =IF(D27="","",C27&"|"&D27) | F27: =IF(OR(B27="",C27="⚠ absent du Registre"),"",COUNTIFS(B$4:B27,"<>",C$4:C27,"<>⚠ absent du Registre"))
A28: 25 | C28: =IF(B28="","",IFERROR(INDEX(Registre!$A$2:$A$1999,MATCH(B28,Registre!$B$2:$B$1999,0)),"⚠ absent du Registre")) | D28: =IF(OR(C28="",C28="⚠ absent du Registre"),"",COUNTIF(C$4:C28,C28)) | E28: =IF(D28="","",C28&"|"&D28) | F28: =IF(OR(B28="",C28="⚠ absent du Registre"),"",COUNTIFS(B$4:B28,"<>",C$4:C28,"<>⚠ absent du Registre"))
A29: 26 | C29: =IF(B29="","",IFERROR(INDEX(Registre!$A$2:$A$1999,MATCH(B29,Registre!$B$2:$B$1999,0)),"⚠ absent du Registre")) | D29: =IF(OR(C29="",C29="⚠ absent du Registre"),"",COUNTIF(C$4:C29,C29)) | E29: =IF(D29="","",C29&"|"&D29) | F29: =IF(OR(B29="",C29="⚠ absent du Registre"),"",COUNTIFS(B$4:B29,"<>",C$4:C29,"<>⚠ absent du Registre"))
A30: 27 | C30: =IF(B30="","",IFERROR(INDEX(Registre!$A$2:$A$1999,MATCH(B30,Registre!$B$2:$B$1999,0)),"⚠ absent du Registre")) | D30: =IF(OR(C30="",C30="⚠ absent du Registre"),"",COUNTIF(C$4:C30,C30)) | E30: =IF(D30="","",C30&"|"&D30) | F30: =IF(OR(B30="",C30="⚠ absent du Registre"),"",COUNTIFS(B$4:B30,"<>",C$4:C30,"<>⚠ absent du Registre"))
A31: 28 | C31: =IF(B31="","",IFERROR(INDEX(Registre!$A$2:$A$1999,MATCH(B31,Registre!$B$2:$B$1999,0)),"⚠ absent du Registre")) | D31: =IF(OR(C31="",C31="⚠ absent du Registre"),"",COUNTIF(C$4:C31,C31)) | E31: =IF(D31="","",C31&"|"&D31) | F31: =IF(OR(B31="",C31="⚠ absent du Registre"),"",COUNTIFS(B$4:B31,"<>",C$4:C31,"<>⚠ absent du Registre"))
A32: 29 | C32: =IF(B32="","",IFERROR(INDEX(Registre!$A$2:$A$1999,MATCH(B32,Registre!$B$2:$B$1999,0)),"⚠ absent du Registre")) | D32: =IF(OR(C32="",C32="⚠ absent du Registre"),"",COUNTIF(C$4:C32,C32)) | E32: =IF(D32="","",C32&"|"&D32) | F32: =IF(OR(B32="",C32="⚠ absent du Registre"),"",COUNTIFS(B$4:B32,"<>",C$4:C32,"<>⚠ absent du Registre"))
A33: 30 | C33: =IF(B33="","",IFERROR(INDEX(Registre!$A$2:$A$1999,MATCH(B33,Registre!$B$2:$B$1999,0)),"⚠ absent du Registre")) | D33: =IF(OR(C33="",C33="⚠ absent du Registre"),"",COUNTIF(C$4:C33,C33)) | E33: =IF(D33="","",C33&"|"&D33) | F33: =IF(OR(B33="",C33="⚠ absent du Registre"),"",COUNTIFS(B$4:B33,"<>",C$4:C33,"<>⚠ absent du Registre"))
... A103: 100 | C103: =IF(B103="","",IFERROR(INDEX(Registre!$A$2:$A$1999,MATCH(B103,Registre!$B$2:$B$1999,0)),"⚠ absent du Registre")) | D103: =IF(OR(C103="",C103="⚠ absent du Registre"),"",COUNTIF(C$4:C103,C103)) | E103: =IF(D103="","",C103&"|"&D103) | F103: =IF(OR(B103="",C103="⚠ absent du Registre"),"",COUNTIFS(B$4:B103,"<>",C$4:C103,"<>⚠ absent du Registre"))

Sheet RFI
C1: =Paramètres!$C$2 | I1: =Paramètres!$D$2 | L1: Calcul (ne pas modifier) – ligne registre :
I2: ="Date: "&Paramètres!$E$2 | L2: =IFERROR(MATCH($G$5,Registre!$B$2:$B$1999,0),0)
I3: Page 1/1
A4: Demande d’inspection ( RFI )
A5: ="Discipline : "&IFERROR(IF(INDEX(Registre!$P$2:$P$1999,IF($L$2=0,-1,$L$2))&""<>"",INDEX(Registre!$P$2:$P$1999,IF($L$2=0,-1,$L$2))&"",TRIM(MID(SUBSTITUTE(INDEX(Registre!$B$2:$B$1999,IF($L$2=0,-1,$L$2)),"-",REPT(" ",100)),201,100))),"") | F5: RFI No: | G5: 21063-G26-PPL-RFI-0200
A6: ="Date d'inspection : "&IFERROR(RIGHT("0"&DAY(INDEX(Registre!$D$2:$D$1999,IF($L$2=0,-1,$L$2))),2)&"/"&RIGHT("0"&MONTH(INDEX(Registre!$D$2:$D$1999,IF($L$2=0,-1,$L$2))),2)&"/"&YEAR(INDEX(Registre!$D$2:$D$1999,IF($L$2=0,-1,$L$2))),IFERROR(INDEX(Registre!$D$2:$D$1999,IF($L$2=0,-1,$L$2))&"","")) | L6: ◀ Choisissez le RFI dans la case « RFI nº » (liste déroulante)
A7: ="Lieu : "&IF(IFERROR(INDEX(Registre!$Q$2:$Q$1999,IF($L$2=0,-1,$L$2))&"","")<>"",IFERROR(INDEX(Registre!$Q$2:$Q$1999,IF($L$2=0,-1,$L$2))&"",""),IFERROR(INDEX(Registre!$E$2:$E$1999,IF($L$2=0,-1,$L$2))&"",""))
A8: Heure de réception | C8: CPECC QA/QC | G8: GTFT QA/QC
C9: Nom/Date : | G9: Nom/Date :
A10: Item No. | B10: heure | C10: Description de l'inspection | E10: Point d'inspection
E11: C3 | G11: C1 | H11: CA | I11: TPI1 | J11: TPI2
E12: CST | F12: QCI
A13: =IFERROR(INDEX(Registre!$R$2:$R$1999,IF($L$2=0,-1,$L$2))&"","") | B13: =IFERROR(IF(ISNUMBER(INDEX(Registre!$S$2:$S$1999,IF($L$2=0,-1,$L$2))),RIGHT("0"&HOUR(INDEX(Registre!$S$2:$S$1999,IF($L$2=0,-1,$L$2))),2)&":"&RIGHT("0"&MINUTE(INDEX(Registre!$S$2:$S$1999,IF($L$2=0,-1,$L$2))),2),INDEX(Registre!$S$2:$S$1999,IF($L$2=0,-1,$L$2))&""),"") | C13: =IF(IFERROR(INDEX(Registre!$T$2:$T$1999,IF($L$2=0,-1,$L$2))&"","")<>"",IFERROR(INDEX(Registre!$T$2:$T$1999,IF($L$2=0,-1,$L$2))&"",""),IFERROR(INDEX(Registre!$G$2:$G$1999,IF($L$2=0,-1,$L$2))&"","")) | E13: =IFERROR(INDEX(Registre!$U$2:$U$1999,IF($L$2=0,-1,$L$2))&"","") | F13: =IFERROR(INDEX(Registre!$V$2:$V$1999,IF($L$2=0,-1,$L$2))&"","") | G13: =IFERROR(INDEX(Registre!$W$2:$W$1999,IF($L$2=0,-1,$L$2))&"","") | H13: =IFERROR(INDEX(Registre!$X$2:$X$1999,IF($L$2=0,-1,$L$2))&"","") | I13: =IFERROR(INDEX(Registre!$Y$2:$Y$1999,IF($L$2=0,-1,$L$2))&"","") | J13: =IFERROR(INDEX(Registre!$Z$2:$Z$1999,IF($L$2=0,-1,$L$2))&"","")
A14: CONCLUSION DE L'INSPECTION
A16: =IF(IFERROR(INDEX(Registre!$N$2:$N$1999,IF($L$2=0,-1,$L$2))&"","")="Accepté","☒","☐")&" Approuvé" | D16: =IF(IFERROR(INDEX(Registre!$N$2:$N$1999,IF($L$2=0,-1,$L$2))&"","")="Approuvé avec commentaires","☒","☐")&" Approuvé avec commentaires" | H16: =IF(IFERROR(INDEX(Registre!$N$2:$N$1999,IF($L$2=0,-1,$L$2))&"","")="Rejeté","☒","☐")&" Rejeté"
A17: ="Remarques : "&IFERROR(INDEX(Registre!$O$2:$O$1999,IF($L$2=0,-1,$L$2))&"","")
A18: APPROBATION | C18: C3 | G18: C1 | I18: CA
C19: CST | E19: QCI
A20: Nom
A21: Signature
A22: Date

Sheet RFI interne
C1: DEMANDE D'INSPECTION | H1: DIN-SMG-CQ-84 | L1: SAISIE (non imprimé)
H2: Date : 26/10/20 | L2: RFI (repris de la feuille RFI) | M2: =RFI!$G$5
H3: Page : 1/1 | L3: (N° interne = N° de la RFI)
L4: Corps d'état | M4: GENIE MECANIQUE
